Workbook
Name bin: Pricing_Asian_Options!$AD$6:$AD$21
Name bin_: Hedging!$P$6:$P$22
Name bin_2: Hedging!$V$6:$V$18
Name bin_3: Hedging!$AB$10:$AB$25
Name c_: Hedging!$D$9
Name CR0: Pricing_Asian_Options!$T$2
Name CR0_: Pricing_Asian_Options!$Y$3:$Y$1002
Name downside_risk1: Hedging!$M$2:$M$2001
Name downside_risk2: Hedging!$N$2:$N$2001
Name Dt: Pricing_Asian_Options!$D$6
Name Dt_: Hedging!$D$6
Name E_CR0: Pricing_Asian_Options!$AJ$6
Name E_PR0: Pricing_Asian_Options!$AJ$2
Name E_R0: Hedging!$Z$2
Name k: Pricing_Asian_Options!$D$4
Name k_: Hedging!$D$4
Name mean_payoff1: Hedging!$AC$2
Name mean_payoff2: Hedging!$AE$2
Name mean_ST: Hedging!$T$2
Name mu: Pricing_Asian_Options!$D$2
Name mu_: Hedging!$D$2
Name N: Pricing_Asian_Options!$D$8
Name N_: Hedging!$D$8
Name P_CR0_1.1: Pricing_Asian_Options!$AA$2:$AA$1002
Name P_PR0_1.1: Pricing_Asian_Options!$AB$2:$AB$1002
Name payoff1: Hedging!$K$2:$K$2001
Name payoff2: Hedging!$L$2:$L$2001
Name PC: Pricing_Asian_Options!$AM$6
Name PP: Pricing_Asian_Options!$AM$2
Name PR0: Pricing_Asian_Options!$T$3
Name PR0_: Pricing_Asian_Options!$Z$3:$Z$1002
Name R0_: Hedging!$J$2:$J$2001
Name rs: Pricing_Asian_Options!$D$7
Name rs_: Hedging!$D$7
Name S0: Pricing_Asian_Options!$D$1
Name S0_: Hedging!$D$1
Name Sav: Pricing_Asian_Options!$T$1
Name Sav_: Pricing_Asian_Options!$X$3:$X$1002
Name sigma: Pricing_Asian_Options!$D$3
Name sigma_: Hedging!$D$3
Name ST: Hedging!$I$2:$I$2001
Name T: Pricing_Asian_Options!$D$5
Name T_: Hedging!$D$5
Name var_payoff1: Hedging!$AC$3
Name var_payoff2: Hedging!$AE$3
Name year1_St: Pricing_Asian_Options!$H$2:$H$53
Name year2_St: Pricing_Asian_Options!$I$2:$I$53
Name year3_St: Pricing_Asian_Options!$J$2:$J$53

Sheet Project Overview
A1: Dynamic Simulation, Option Pricing & Financial Hedging
A3: Project Overview
A4: Financial outcomes evolve dynamically and stochastically over time. This project uses Monte Carlo simulation to model stock-price evolution, value path-dependent Asian options, and evaluate a protective-put hedging strategy. The analysis connects dynamic sample paths to derivative payoffs and then compares investment outcomes using expected payoff, confidence intervals, variance, downside risk, and full payoff distributions.
A9: Problem
A10: Two related decisions are examined. First, how should an Asian call or put option be valued when its payoff depends on the average stock price over an entire year? Second, how does buying a European put change the risk profile of an investor who holds the underlying stock?
A14: Model
A15: Dynamic stock-price process
A16: Stock prices follow a geometric random walk: S_t = S_(t-1) × exp[(μ − σ²/2)Δt + σ√Δt Z], Z ~ N(0,1).
A17: Asian option valuation
A18: The Asian option uses the average simulated stock price S̄ across the path. Present-value payoff is max(S̄−K,0)e^(−rT) for a call and max(K−S̄,0)e^(−rT) for a put; fair price is E[R₀].
A19: Hedging
A20: A protective put caps severe downside outcomes: if S_T < K, the investor can sell at K; otherwise the investor retains the stock payoff, less the option premium.
A21: Simulation Design
A22: Asian Option Simulation | B22: Value | C22: Hedging Simulation | D22: Value
A23: Initial stock price (S₀) | B23: =Pricing_Asian_Options!D1 -> 100 | C23: Initial stock price (S₀) | D23: =Hedging!D1 -> 100
A24: Annual drift (μ) | B24: =Pricing_Asian_Options!D2 -> 0.08 | C24: Annual drift (μ) | D24: =Hedging!D2 -> 0.08
A25: Annual volatility (σ) | B25: =Pricing_Asian_Options!D3 -> 0.12 | C25: Annual volatility (σ) | D25: =Hedging!D3 -> 0.12
A26: Strike price (K) | B26: =Pricing_Asian_Options!D4 -> 97 | C26: Strike price (K) | D26: =Hedging!D4 -> 97
A27: Replications (N) | B27: =Pricing_Asian_Options!D8 -> 1000 | C27: Replications (N) | D27: =Hedging!D8 -> 2000
A29: Analytical Questions
A30: 1 | B30: Generate dynamic stock-price paths using the geometric random walk.
A31: 2 | B31: For Asian options, convert each 52-week path into an average stock price and discounted call/put payoff.
A32: 3 | B32: Repeat the experiment across 1,000 paths and estimate payoff distributions, fair prices, probabilities, and confidence intervals.
A33: 4 | B33: For hedging, simulate 2,000 terminal stock prices and compare stock-only versus stock-plus-put payoffs.
A34: 5 | B34: Assess risk using distributions, variance, probability of a negative payoff, and extreme downside outcomes.
A35: 6 | B35: Use running Monte Carlo estimates to assess whether key results stabilize as the number of replications increases.
A37: Decision Relevance
A38: The project illustrates how simulation supports decisions when closed-form intuition is insufficient: path-dependent valuation requires modeling the entire price trajectory, while hedging decisions require examining the distribution of outcomes rather than expected payoff alone. The protective put is evaluated as insurance—an upfront premium is exchanged for a materially tighter downside tail.

Sheet Pricing_Asian_Options
A1: INPUT | B1: initial_price | C1: S0 | D1: 100 | F1: SAMPLE PATH | G1: week | H1: year1_St | I1: year2_St | J1: year3_St | L1: Q1 — How do simulated weekly stock-price paths evolve over the option horizon? | R1: STAT | S1: Sav | T1: =AVERAGE(year1_St) -> 106.83312 | V1: OUTPUT | W1: num_years | X1: Sav_ | Y1: CR0_ | Z1: PR0_ | AA1: P(CR0>1.1) | AB1: P(PR0>1.1) | AD1: Q2 — What does the simulated Asian put payoff distribution look like? | AI1: Q3 — What is the estimated fair value of the Asian put, with simulation uncertainty? | AL1: Q4 — What are the Asian call value and probabilities of economically meaningful payoffs?
B2: drift | C2: mu | D2: 0.08 | G2: {=_xlfn.SEQUENCE(52)} -> 1 | H2: =S0*EXP((mu-sigma^2/2)*Dt+sigma*SQRT(Dt)*_xlfn.NORM.INV(RAND(),0,1)) -> 101.78497 | I2: =S0*EXP((mu-sigma^2/2)*Dt+sigma*SQRT(Dt)*_xlfn.NORM.INV(RAND(),0,1)) -> 98.99457 | J2: 99.761576 | S2: CR0 | T2: =MAX(0,Sav-k)*EXP(-rs*T) -> 9.2697449 | X2: =Sav -> 106.83312 | Y2: =CR0 -> 9.2697449 | Z2: =PR0 -> 0 | AA2: {=IF(CR0_>1.1,1,0)} -> 1 | AB2: {=IF(PR0_>1.1,1,0)} -> 0 | AD2: max_PR0 | AE2: =MAX(PR0_) -> 13.763539 | AF2: max_CRO | AG2: =MAX(CR0_) -> 31.074967 | AI2: E(PR0) | AJ2: =AVERAGE(PR0_) -> 0.46508545 | AL2: P(PR0>1.1) | AM2: {=AVERAGE(1*(PR0_>1.1))} -> 0.115
B3: valatility | C3: sigma | D3: 0.12 | G3: 2 | H3: =H2*EXP((mu-sigma^2/2)*Dt+sigma*SQRT(Dt)*_xlfn.NORM.INV(RAND(),0,1)) -> 101.07896 | I3: =I2*EXP((mu-sigma^2/2)*Dt+sigma*SQRT(Dt)*_xlfn.NORM.INV(RAND(),0,1)) -> 98.137623 | J3: =J2*EXP((mu-sigma^2/2)*Dt+sigma*SQRT(Dt)*_xlfn.NORM.INV(RAND(),0,1)) -> 98.293091 | S3: PR0 | T3: =MAX(0,k-Sav)*EXP(-rs*T) -> 0 | W3: {=_xlfn.SEQUENCE(1000)} -> 1 | X3: 116.04771 | Y3: 18.494008 | Z3: 0 | AA3: 1 | AB3: 0 | AD3: min_PRO | AE3: =MIN(PR0_) -> 0 | AF3: min_CRO | AG3: =MIN(CR0_) -> 0 | AI3: 95%CI_LB | AJ3: =E_PR0-1.96*STDEV(PR0_)/SQRT(N) -> 0.37162761 | AL3: 95%CI_LB | AM3: =PP-1.96*STDEV(P_PR0_1.1)/SQRT(N) -> 0.095216921
B4: strike_price | C4: k | D4: 97 | G4: 3 | H4: =H3*EXP((mu-sigma^2/2)*Dt+sigma*SQRT(Dt)*_xlfn.NORM.INV(RAND(),0,1)) -> 102.43359 | I4: =I3*EXP((mu-sigma^2/2)*Dt+sigma*SQRT(Dt)*_xlfn.NORM.INV(RAND(),0,1)) -> 98.869836 | J4: =J3*EXP((mu-sigma^2/2)*Dt+sigma*SQRT(Dt)*_xlfn.NORM.INV(RAND(),0,1)) -> 97.502376 | W4: 2 | X4: 112.93347 | Y4: 15.470299 | Z4: 0 | AA4: 1 | AB4: 0 | AI4: 95%CI_UB | AJ4: =E_PR0+1.96*STDEV(PR0_)/SQRT(N) -> 0.55854329 | AL4: 95%CI_UB | AM4: =PP+1.96*STDEV(P_PR0_1.1)/SQRT(N) -> 0.13478308
B5: expiration_date | C5: T | D5: 1 | G5: 4 | H5: =H4*EXP((mu-sigma^2/2)*Dt+sigma*SQRT(Dt)*_xlfn.NORM.INV(RAND(),0,1)) -> 103.06513 | I5: =I4*EXP((mu-sigma^2/2)*Dt+sigma*SQRT(Dt)*_xlfn.NORM.INV(RAND(),0,1)) -> 102.208 | J5: =J4*EXP((mu-sigma^2/2)*Dt+sigma*SQRT(Dt)*_xlfn.NORM.INV(RAND(),0,1)) -> 100.26448 | W5: 3 | X5: 104.95184 | Y5: 7.7206839 | Z5: 0 | AA5: 1 | AB5: 0 | AD5: bin | AE5: f_PR0 | AF5: f_CR0
B6: step_size | C6: Dt | D6: =1/52 -> 0.019230769 | G6: 5 | H6: =H5*EXP((mu-sigma^2/2)*Dt+sigma*SQRT(Dt)*_xlfn.NORM.INV(RAND(),0,1)) -> 103.10894 | I6: =I5*EXP((mu-sigma^2/2)*Dt+sigma*SQRT(Dt)*_xlfn.NORM.INV(RAND(),0,1)) -> 103.9507 | J6: =J5*EXP((mu-sigma^2/2)*Dt+sigma*SQRT(Dt)*_xlfn.NORM.INV(RAND(),0,1)) -> 98.206896 | W6: 4 | X6: 109.8264 | Y6: 12.453546 | Z6: 0 | AA6: 1 | AB6: 0 | AD6: 0 | AE6: {=FREQUENCY(PR0_,bin)/N} -> 0.85 | AF6: {=FREQUENCY(CR0_,bin)/N} -> 0.15 | AI6: E(CR0) | AJ6: =AVERAGE(CR0_) -> 7.9093402 | AL6: P(CR0>1.1) | AM6: {=AVERAGE(1*(CR0_>1.1))} -> 0.816
B7: risk_free_interest_rate | C7: rs | D7: 0.059 | G7: 6 | H7: =H6*EXP((mu-sigma^2/2)*Dt+sigma*SQRT(Dt)*_xlfn.NORM.INV(RAND(),0,1)) -> 103.09626 | I7: =I6*EXP((mu-sigma^2/2)*Dt+sigma*SQRT(Dt)*_xlfn.NORM.INV(RAND(),0,1)) -> 103.01378 | J7: =J6*EXP((mu-sigma^2/2)*Dt+sigma*SQRT(Dt)*_xlfn.NORM.INV(RAND(),0,1)) -> 98.138753 | W7: 5 | X7: 105.47455 | Y7: 8.2282006 | Z7: 0 | AA7: 1 | AB7: 0 | AD7: 2.5 | AE7: 0.08 | AF7: 0.096 | AI7: 95%CI_LB | AJ7: =E_CR0-1.96*STDEV(CR0_)/SQRT(N) -> 7.5088527 | AL7: 95%CI_LB | AM7: =PC-1.96*STDEV(P_CR0_1.1)/SQRT(N) -> 0.79197146
B8: sample_size | C8: N | D8: 1000 | G8: 7 | H8: =H7*EXP((mu-sigma^2/2)*Dt+sigma*SQRT(Dt)*_xlfn.NORM.INV(RAND(),0,1)) -> 106.4214 | I8: =I7*EXP((mu-sigma^2/2)*Dt+sigma*SQRT(Dt)*_xlfn.NORM.INV(RAND(),0,1)) -> 98.927611 | J8: =J7*EXP((mu-sigma^2/2)*Dt+sigma*SQRT(Dt)*_xlfn.NORM.INV(RAND(),0,1)) -> 98.324114 | W8: 6 | X8: 99.685992 | Y8: 2.6079125 | Z8: 0 | AA8: 1 | AB8: 0 | AD8: 5 | AE8: 0.035 | AF8: 0.147 | AI8: 95%CI_UB | AJ8: =E_CR0+1.96*STDEV(CR0_)/SQRT(N) -> 8.3098276 | AL8: 95%CI_UB | AM8: =PC+1.96*STDEV(P_CR0_1.1)/SQRT(N) -> 0.84002854
G9: 8 | H9: =H8*EXP((mu-sigma^2/2)*Dt+sigma*SQRT(Dt)*_xlfn.NORM.INV(RAND(),0,1)) -> 105.33926 | I9: =I8*EXP((mu-sigma^2/2)*Dt+sigma*SQRT(Dt)*_xlfn.NORM.INV(RAND(),0,1)) -> 102.24908 | J9: =J8*EXP((mu-sigma^2/2)*Dt+sigma*SQRT(Dt)*_xlfn.NORM.INV(RAND(),0,1)) -> 98.126416 | W9: 7 | X9: 104.24493 | Y9: 7.0343279 | Z9: 0 | AA9: 1 | AB9: 0 | AD9: 7.5 | AE9: 0.026 | AF9: 0.136
G10: 9 | H10: =H9*EXP((mu-sigma^2/2)*Dt+sigma*SQRT(Dt)*_xlfn.NORM.INV(RAND(),0,1)) -> 105.39154 | I10: =I9*EXP((mu-sigma^2/2)*Dt+sigma*SQRT(Dt)*_xlfn.NORM.INV(RAND(),0,1)) -> 101.92497 | J10: =J9*EXP((mu-sigma^2/2)*Dt+sigma*SQRT(Dt)*_xlfn.NORM.INV(RAND(),0,1)) -> 97.53803 | W10: 8 | X10: 104.19445 | Y10: 6.9853143 | Z10: 0 | AA10: 1 | AB10: 0 | AD10: 10 | AE10: 0.005 | AF10: 0.122
G11: 10 | H11: =H10*EXP((mu-sigma^2/2)*Dt+sigma*SQRT(Dt)*_xlfn.NORM.INV(RAND(),0,1)) -> 101.90908 | I11: =I10*EXP((mu-sigma^2/2)*Dt+sigma*SQRT(Dt)*_xlfn.NORM.INV(RAND(),0,1)) -> 98.757692 | J11: =J10*EXP((mu-sigma^2/2)*Dt+sigma*SQRT(Dt)*_xlfn.NORM.INV(RAND(),0,1)) -> 97.105187 | W11: 9 | X11: 101.13527 | Y11: 4.0150657 | Z11: 0 | AA11: 0 | AB11: 0 | AD11: 12.5 | AE11: 0.003 | AF11: 0.104
G12: 11 | H12: =H11*EXP((mu-sigma^2/2)*Dt+sigma*SQRT(Dt)*_xlfn.NORM.INV(RAND(),0,1)) -> 103.4456 | I12: =I11*EXP((mu-sigma^2/2)*Dt+sigma*SQRT(Dt)*_xlfn.NORM.INV(RAND(),0,1)) -> 100.16061 | J12: =J11*EXP((mu-sigma^2/2)*Dt+sigma*SQRT(Dt)*_xlfn.NORM.INV(RAND(),0,1)) -> 98.125622 | W12: 10 | X12: 96.086648 | Y12: 0 | Z12: 0.88680142 | AA12: 1 | AB12: 0 | AD12: 15 | AE12: 0.001 | AF12: 0.091
G13: 12 | H13: =H12*EXP((mu-sigma^2/2)*Dt+sigma*SQRT(Dt)*_xlfn.NORM.INV(RAND(),0,1)) -> 101.8793 | I13: =I12*EXP((mu-sigma^2/2)*Dt+sigma*SQRT(Dt)*_xlfn.NORM.INV(RAND(),0,1)) -> 99.447167 | J13: =J12*EXP((mu-sigma^2/2)*Dt+sigma*SQRT(Dt)*_xlfn.NORM.INV(RAND(),0,1)) -> 97.648514 | W13: 11 | X13: 105.57209 | Y13: 8.3229036 | Z13: 0 | AA13: 1 | AB13: 0 | AD13: 17.5 | AE13: 0 | AF13: 0.062
G14: 13 | H14: =H13*EXP((mu-sigma^2/2)*Dt+sigma*SQRT(Dt)*_xlfn.NORM.INV(RAND(),0,1)) -> 102.22671 | I14: =I13*EXP((mu-sigma^2/2)*Dt+sigma*SQRT(Dt)*_xlfn.NORM.INV(RAND(),0,1)) -> 99.832481 | J14: =J13*EXP((mu-sigma^2/2)*Dt+sigma*SQRT(Dt)*_xlfn.NORM.INV(RAND(),0,1)) -> 94.697916 | W14: 12 | X14: 114.21265 | Y14: 16.712298 | Z14: 0 | AA14: 1 | AB14: 0 | AD14: 20 | AE14: 0 | AF14: 0.048
G15: 14 | H15: =H14*EXP((mu-sigma^2/2)*Dt+sigma*SQRT(Dt)*_xlfn.NORM.INV(RAND(),0,1)) -> 100.52261 | I15: =I14*EXP((mu-sigma^2/2)*Dt+sigma*SQRT(Dt)*_xlfn.NORM.INV(RAND(),0,1)) -> 97.885934 | J15: =J14*EXP((mu-sigma^2/2)*Dt+sigma*SQRT(Dt)*_xlfn.NORM.INV(RAND(),0,1)) -> 94.234703 | W15: 13 | X15: 101.82502 | Y15: 4.6847616 | Z15: 0 | AA15: 1 | AB15: 0 | AD15: 22.5 | AE15: 0 | AF15: 0.019
G16: 15 | H16: =H15*EXP((mu-sigma^2/2)*Dt+sigma*SQRT(Dt)*_xlfn.NORM.INV(RAND(),0,1)) -> 100.83676 | I16: =I15*EXP((mu-sigma^2/2)*Dt+sigma*SQRT(Dt)*_xlfn.NORM.INV(RAND(),0,1)) -> 100.9477 | J16: =J15*EXP((mu-sigma^2/2)*Dt+sigma*SQRT(Dt)*_xlfn.NORM.INV(RAND(),0,1)) -> 91.184995 | W16: 14 | X16: 101.03123 | Y16: 3.9140465 | Z16: 0 | AA16: 1 | AB16: 0 | AD16: 25 | AE16: 0 | AF16: 0.016
G17: 16 | H17: =H16*EXP((mu-sigma^2/2)*Dt+sigma*SQRT(Dt)*_xlfn.NORM.INV(RAND(),0,1)) -> 100.98459 | I17: =I16*EXP((mu-sigma^2/2)*Dt+sigma*SQRT(Dt)*_xlfn.NORM.INV(RAND(),0,1)) -> 102.3129 | J17: =J16*EXP((mu-sigma^2/2)*Dt+sigma*SQRT(Dt)*_xlfn.NORM.INV(RAND(),0,1)) -> 89.294227 | W17: 15 | X17: 98.306395 | Y17: 1.2684188 | Z17: 0 | AA17: 1 | AB17: 0 | AD17: 27.5 | AE17: 0 | AF17: 0.004
G18: 17 | H18: =H17*EXP((mu-sigma^2/2)*Dt+sigma*SQRT(Dt)*_xlfn.NORM.INV(RAND(),0,1)) -> 102.52289 | I18: =I17*EXP((mu-sigma^2/2)*Dt+sigma*SQRT(Dt)*_xlfn.NORM.INV(RAND(),0,1)) -> 103.29904 | J18: =J17*EXP((mu-sigma^2/2)*Dt+sigma*SQRT(Dt)*_xlfn.NORM.INV(RAND(),0,1)) -> 86.674477 | W18: 16 | X18: 100.50074 | Y18: 3.3989767 | Z18: 0 | AA18: 1 | AB18: 0 | AD18: 30 | AE18: 0 | AF18: 0.004
G19: 18 | H19: =H18*EXP((mu-sigma^2/2)*Dt+sigma*SQRT(Dt)*_xlfn.NORM.INV(RAND(),0,1)) -> 102.57492 | I19: =I18*EXP((mu-sigma^2/2)*Dt+sigma*SQRT(Dt)*_xlfn.NORM.INV(RAND(),0,1)) -> 105.31941 | J19: =J18*EXP((mu-sigma^2/2)*Dt+sigma*SQRT(Dt)*_xlfn.NORM.INV(RAND(),0,1)) -> 84.663872 | W19: 17 | X19: 115.10513 | Y19: 17.578831 | Z19: 0 | AA19: 1 | AB19: 0 | AD19: 32.5 | AE19: 0 | AF19: 0.001
G20: 19 | H20: =H19*EXP((mu-sigma^2/2)*Dt+sigma*SQRT(Dt)*_xlfn.NORM.INV(RAND(),0,1)) -> 104.34451 | I20: =I19*EXP((mu-sigma^2/2)*Dt+sigma*SQRT(Dt)*_xlfn.NORM.INV(RAND(),0,1)) -> 109.70277 | J20: =J19*EXP((mu-sigma^2/2)*Dt+sigma*SQRT(Dt)*_xlfn.NORM.INV(RAND(),0,1)) -> 85.165503 | W20: 18 | X20: 107.08772 | Y20: 9.79448 | Z20: 0 | AA20: 1 | AB20: 0 | AD20: 35 | AE20: 0 | AF20: 0
G21: 20 | H21: =H20*EXP((mu-sigma^2/2)*Dt+sigma*SQRT(Dt)*_xlfn.NORM.INV(RAND(),0,1)) -> 104.8124 | I21: =I20*EXP((mu-sigma^2/2)*Dt+sigma*SQRT(Dt)*_xlfn.NORM.INV(RAND(),0,1)) -> 106.19882 | J21: =J20*EXP((mu-sigma^2/2)*Dt+sigma*SQRT(Dt)*_xlfn.NORM.INV(RAND(),0,1)) -> 85.045562 | W21: 19 | X21: 113.45545 | Y21: 15.977107 | Z21: 0 | AA21: 1 | AB21: 0 | AD21: 37.5 | AE21: 0 | AF21: 0
G22: 21 | H22: =H21*EXP((mu-sigma^2/2)*Dt+sigma*SQRT(Dt)*_xlfn.NORM.INV(RAND(),0,1)) -> 103.49089 | I22: =I21*EXP((mu-sigma^2/2)*Dt+sigma*SQRT(Dt)*_xlfn.NORM.INV(RAND(),0,1)) -> 102.47461 | J22: =J21*EXP((mu-sigma^2/2)*Dt+sigma*SQRT(Dt)*_xlfn.NORM.INV(RAND(),0,1)) -> 83.973133 | W22: 20 | X22: 114.05979 | Y22: 16.563873 | Z22: 0 | AA22: 1 | AB22: 0 | AE22: 0 | AF22: 0
G23: 22 | H23: =H22*EXP((mu-sigma^2/2)*Dt+sigma*SQRT(Dt)*_xlfn.NORM.INV(RAND(),0,1)) -> 103.58984 | I23: =I22*EXP((mu-sigma^2/2)*Dt+sigma*SQRT(Dt)*_xlfn.NORM.INV(RAND(),0,1)) -> 103.89955 | J23: =J22*EXP((mu-sigma^2/2)*Dt+sigma*SQRT(Dt)*_xlfn.NORM.INV(RAND(),0,1)) -> 82.949666 | W23: 21 | X23: 113.5023 | Y23: 16.022596 | Z23: 0 | AA23: 1 | AB23: 0
G24: 23 | H24: =H23*EXP((mu-sigma^2/2)*Dt+sigma*SQRT(Dt)*_xlfn.NORM.INV(RAND(),0,1)) -> 106.61698 | I24: =I23*EXP((mu-sigma^2/2)*Dt+sigma*SQRT(Dt)*_xlfn.NORM.INV(RAND(),0,1)) -> 102.08015 | J24: =J23*EXP((mu-sigma^2/2)*Dt+sigma*SQRT(Dt)*_xlfn.NORM.INV(RAND(),0,1)) -> 83.329947 | W24: 22 | X24: 113.49275 | Y24: 16.013324 | Z24: 0 | AA24: 1 | AB24: 0
G25: 24 | H25: =H24*EXP((mu-sigma^2/2)*Dt+sigma*SQRT(Dt)*_xlfn.NORM.INV(RAND(),0,1)) -> 106.17803 | I25: =I24*EXP((mu-sigma^2/2)*Dt+sigma*SQRT(Dt)*_xlfn.NORM.INV(RAND(),0,1)) -> 102.24376 | J25: =J24*EXP((mu-sigma^2/2)*Dt+sigma*SQRT(Dt)*_xlfn.NORM.INV(RAND(),0,1)) -> 85.799665 | W25: 23 | X25: 112.92536 | Y25: 15.462423 | Z25: 0 | AA25: 1 | AB25: 0
G26: 25 | H26: =H25*EXP((mu-sigma^2/2)*Dt+sigma*SQRT(Dt)*_xlfn.NORM.INV(RAND(),0,1)) -> 108.06659 | I26: =I25*EXP((mu-sigma^2/2)*Dt+sigma*SQRT(Dt)*_xlfn.NORM.INV(RAND(),0,1)) -> 103.42111 | J26: =J25*EXP((mu-sigma^2/2)*Dt+sigma*SQRT(Dt)*_xlfn.NORM.INV(RAND(),0,1)) -> 86.598359 | W26: 24 | X26: 111.00048 | Y26: 13.593501 | Z26: 0 | AA26: 1 | AB26: 0
G27: 26 | H27: =H26*EXP((mu-sigma^2/2)*Dt+sigma*SQRT(Dt)*_xlfn.NORM.INV(RAND(),0,1)) -> 108.16151 | I27: =I26*EXP((mu-sigma^2/2)*Dt+sigma*SQRT(Dt)*_xlfn.NORM.INV(RAND(),0,1)) -> 103.97733 | J27: =J26*EXP((mu-sigma^2/2)*Dt+sigma*SQRT(Dt)*_xlfn.NORM.INV(RAND(),0,1)) -> 89.579153 | W27: 25 | X27: 113.78757 | Y27: 16.299573 | Z27: 0 | AA27: 1 | AB27: 0
G28: 27 | H28: =H27*EXP((mu-sigma^2/2)*Dt+sigma*SQRT(Dt)*_xlfn.NORM.INV(RAND(),0,1)) -> 111.6366 | I28: =I27*EXP((mu-sigma^2/2)*Dt+sigma*SQRT(Dt)*_xlfn.NORM.INV(RAND(),0,1)) -> 103.45182 | J28: =J27*EXP((mu-sigma^2/2)*Dt+sigma*SQRT(Dt)*_xlfn.NORM.INV(RAND(),0,1)) -> 88.250188 | W28: 26 | X28: 102.46376 | Y28: 5.3049325 | Z28: 0 | AA28: 1 | AB28: 0
G29: 28 | H29: =H28*EXP((mu-sigma^2/2)*Dt+sigma*SQRT(Dt)*_xlfn.NORM.INV(RAND(),0,1)) -> 110.81986 | I29: =I28*EXP((mu-sigma^2/2)*Dt+sigma*SQRT(Dt)*_xlfn.NORM.INV(RAND(),0,1)) -> 103.86819 | J29: =J28*EXP((mu-sigma^2/2)*Dt+sigma*SQRT(Dt)*_xlfn.NORM.INV(RAND(),0,1)) -> 89.776269 | W29: 27 | X29: 98.193254 | Y29: 1.1585673 | Z29: 0 | AA29: 1 | AB29: 0
G30: 29 | H30: =H29*EXP((mu-sigma^2/2)*Dt+sigma*SQRT(Dt)*_xlfn.NORM.INV(RAND(),0,1)) -> 111.47188 | I30: =I29*EXP((mu-sigma^2/2)*Dt+sigma*SQRT(Dt)*_xlfn.NORM.INV(RAND(),0,1)) -> 103.04934 | J30: =J29*EXP((mu-sigma^2/2)*Dt+sigma*SQRT(Dt)*_xlfn.NORM.INV(RAND(),0,1)) -> 91.36893 | W30: 28 | X30: 106.95096 | Y30: 9.6616969 | Z30: 0 | AA30: 0 | AB30: 0
G31: 30 | H31: =H30*EXP((mu-sigma^2/2)*Dt+sigma*SQRT(Dt)*_xlfn.NORM.INV(RAND(),0,1)) -> 110.88192 | I31: =I30*EXP((mu-sigma^2/2)*Dt+sigma*SQRT(Dt)*_xlfn.NORM.INV(RAND(),0,1)) -> 104.68528 | J31: =J30*EXP((mu-sigma^2/2)*Dt+sigma*SQRT(Dt)*_xlfn.NORM.INV(RAND(),0,1)) -> 88.386055 | W31: 29 | X31: 98.050744 | Y31: 1.0202 | Z31: 0 | AA31: 1 | AB31: 0
G32: 31 | H32: =H31*EXP((mu-sigma^2/2)*Dt+sigma*SQRT(Dt)*_xlfn.NORM.INV(RAND(),0,1)) -> 112.03622 | I32: =I31*EXP((mu-sigma^2/2)*Dt+sigma*SQRT(Dt)*_xlfn.NORM.INV(RAND(),0,1)) -> 105.79261 | J32: =J31*EXP((mu-sigma^2/2)*Dt+sigma*SQRT(Dt)*_xlfn.NORM.INV(RAND(),0,1)) -> 86.499861 | W32: 30 | X32: 113.27566 | Y32: 15.80254 | Z32: 0 | AA32: 1 | AB32: 0
G33: 32 | H33: =H32*EXP((mu-sigma^2/2)*Dt+sigma*SQRT(Dt)*_xlfn.NORM.INV(RAND(),0,1)) -> 110.93361 | I33: =I32*EXP((mu-sigma^2/2)*Dt+sigma*SQRT(Dt)*_xlfn.NORM.INV(RAND(),0,1)) -> 104.96334 | J33: =J32*EXP((mu-sigma^2/2)*Dt+sigma*SQRT(Dt)*_xlfn.NORM.INV(RAND(),0,1)) -> 87.68147 | W33: 31 | X33: 111.35649 | Y33: 13.93916 | Z33: 0 | AA33: 0 | AB33: 0
G34: 33 | H34: =H33*EXP((mu-sigma^2/2)*Dt+sigma*SQRT(Dt)*_xlfn.NORM.INV(RAND(),0,1)) -> 109.55133 | I34: =I33*EXP((mu-sigma^2/2)*Dt+sigma*SQRT(Dt)*_xlfn.NORM.INV(RAND(),0,1)) -> 104.72916 | J34: =J33*EXP((mu-sigma^2/2)*Dt+sigma*SQRT(Dt)*_xlfn.NORM.INV(RAND(),0,1)) -> 88.779832 | W34: 32 | X34: 96.84352 | Y34: 0 | Z34: 0.15193087 | AA34: 1 | AB34: 0
... G53: 52 | H53: =H52*EXP((mu-sigma^2/2)*Dt+sigma*SQRT(Dt)*_xlfn.NORM.INV(RAND(),0,1)) -> 109.22409 | I53: =I52*EXP((mu-sigma^2/2)*Dt+sigma*SQRT(Dt)*_xlfn.NORM.INV(RAND(),0,1)) -> 112.31483 | J53: =J52*EXP((mu-sigma^2/2)*Dt+sigma*SQRT(Dt)*_xlfn.NORM.INV(RAND(),0,1)) -> 93.217944 | W53: 51 | X53: 99.467495 | Y53: 2.395767 | Z53: 0 | AA53: 1 | AB53: 0
W54: 52 | X54: 111.4774 | Y54: 14.056557 | Z54: 0 | AA54: 0 | AB54: 0
W55: 53 | X55: 96.843707 | Y55: 0 | Z55: 0.15174971 | AA55: 1 | AB55: 0
W56: 54 | X56: 109.54855 | Y56: 12.183777 | Z56: 0 | AA56: 1 | AB56: 0
W57: 55 | X57: 116.55214 | Y57: 18.983777 | Z57: 0 | AA57: 1 | AB57: 0
W58: 56 | X58: 102.68179 | Y58: 5.5166209 | Z58: 0 | AA58: 1 | AB58: 0
...

Sheet Hedging
A1: INPUT | B1: initial_price | C1: S0_ | D1: 100 | F1: SAMPLE PATH | G1: run | H1: S0_ | I1: ST | J1: R0_ | K1: payoff1 | L1: payoff2 | M1: downside_risk1 | N1: downside_risk2 | P1: Q1 — What is the distribution and downside risk of the terminal stock price? | V1: Q2 — What is the simulated European put value, and is the quoted price within its 95% CI? | AB1: Q3 — How does a protective put change payoff, variance, and downside exposure versus no hedging?
B2: drift | C2: mu_ | D2: 0.08 | G2: {=_xlfn.SEQUENCE(2000)} -> 1 | H2: =S0_ -> 100 | I2: =S0_*EXP((mu_-sigma_^2/2)*Dt_+sigma_*SQRT(Dt_)*_xlfn.NORM.INV(RAND(),0,1)) -> 113.08156 | J2: =MAX(k_-I2,0)*EXP(-rs_*T_) -> 0 | K2: {=(ST-S0_)*EXP(-rs_*T_)} -> 12.701291 | L2: {=((k_-S0_)*(ST<k_)+(ST-S0_)*(ST>=k_))*EXP(-rs_*T_)-c_} -> 12.131291 | M2: {=IF(ST<S0_,1,0)} -> 0 | N2: {=IF(payoff2<0,1,0)} -> 0 | P2: max_ST | Q2: =MAX(ST) -> 137.82121 | S2: mean_ST | T2: =AVERAGE(ST) -> 103.93691 | V2: max_R0_ | W2: =MAX(R0_) -> 15.312567 | Y2: E(R0_) | Z2: =AVERAGE(R0_) -> 0.94921779 | AB2: mean_payoff1 | AC2: =AVERAGE(payoff1) -> 3.822463 | AD2: mean_payoff2 | AE2: =AVERAGE(payoff2) -> 4.2016808
B3: valatility | C3: sigma_ | D3: 0.12 | G3: 2 | H3: =S0_ -> 100 | I3: =S0_*EXP((mu_-sigma_^2/2)*Dt_+sigma_*SQRT(Dt_)*_xlfn.NORM.INV(RAND(),0,1)) -> 106.33647 | J3: =MAX(k_-I3,0)*EXP(-rs_*T_) -> 0 | K3: 6.1522792 | L3: 5.5822792 | M3: 0 | N3: 0 | P3: min_ST | Q3: =MIN(ST) -> 81.228983 | S3: 95%CI_LB | T3: =mean_ST-1.96*STDEV(ST)/SQRT(N_) -> 103.55325 | V3: min_R0_ | W3: =MIN(R0_) -> 0 | Y3: 95%CI_LB | Z3: =E_R0-1.96*STDEV(R0_)/SQRT(N_) -> 0.84518137 | AB3: var_payoff1 | AC3: =VAR(payoff1) -> 72.239509 | AD3: var_payoff2 | AE3: =VAR(payoff2) -> 52.008802 | AF3: risker | AG3: =IF(var_payoff1<var_payoff2,"Hedging","No Hedging") -> No Hedging
B4: strike_price | C4: k_ | D4: 97 | G4: 3 | H4: =S0_ -> 100 | I4: =S0_*EXP((mu_-sigma_^2/2)*Dt_+sigma_*SQRT(Dt_)*_xlfn.NORM.INV(RAND(),0,1)) -> 109.21836 | J4: =MAX(k_-I4,0)*EXP(-rs_*T_) -> 0 | K4: 8.9503932 | L4: 8.3803932 | M4: 0 | N4: 0 | S4: 95%CI_UB | T4: =mean_ST+1.96*STDEV(ST)/SQRT(N_) -> 104.32056 | Y4: 95%CI_UB | Z4: =E_R0+1.96*STDEV(R0_)/SQRT(N_) -> 1.0532542 | AB4: downside_risk1 | AC4: =AVERAGE(downside_risk1) -> 0.34 | AD4: downside_risk2 | AE4: =AVERAGE(downside_risk2) -> 0.363
B5: expiration_date | C5: T_ | D5: 0.5 | G5: 4 | H5: =S0_ -> 100 | I5: =S0_*EXP((mu_-sigma_^2/2)*Dt_+sigma_*SQRT(Dt_)*_xlfn.NORM.INV(RAND(),0,1)) -> 112.47425 | J5: =MAX(k_-I5,0)*EXP(-rs_*T_) -> 0 | K5: 12.111635 | L5: 11.541635 | M5: 0 | N5: 0 | P5: bin_ | Q5: f_ST | S5: P(ST-S0<0) | T5: =AVERAGE(downside_risk1) -> 0.34 | V5: bin_2 | W5: f_R0_ | Y5: Is c in CI | Z5: =AND(Z3<=c_,c_<=Z4) -> FALSE
B6: step_size | C6: Dt_ | D6: 0.5 | G6: 5 | H6: =S0_ -> 100 | I6: =S0_*EXP((mu_-sigma_^2/2)*Dt_+sigma_*SQRT(Dt_)*_xlfn.NORM.INV(RAND(),0,1)) -> 106.99865 | J6: =MAX(k_-I6,0)*EXP(-rs_*T_) -> 0 | K6: 6.7952012 | L6: 6.2252012 | M6: 0 | N6: 0 | P6: 70 | Q6: {=FREQUENCY(ST,bin_)/N_} -> 0 | V6: 0 | W6: {=FREQUENCY(R0_,bin_2)/N_} -> 0.7735 | AB6: max_payoff1 | AC6: =MAX(payoff1) -> 36.721784 | AD6: max_payoff2 | AE6: =MAX(payoff2) -> 36.151784
B7: risk_free_interest_rate | C7: rs_ | D7: 0.059 | G7: 6 | H7: =S0_ -> 100 | I7: =S0_*EXP((mu_-sigma_^2/2)*Dt_+sigma_*SQRT(Dt_)*_xlfn.NORM.INV(RAND(),0,1)) -> 104.20616 | J7: =MAX(k_-I7,0)*EXP(-rs_*T_) -> 0 | K7: 4.0838895 | L7: 3.5138895 | M7: 0 | N7: 0 | P7: 75 | Q7: 0 | V7: 2 | W7: 0.0765 | AB7: min_payoff1 | AC7: =MIN(payoff1) -> -18.22536 | AD7: min_payoff2 | AE7: =MIN(payoff2) -> -3.4827926
B8: sample_size | C8: N_ | D8: 2000 | G8: 7 | H8: =S0_ -> 100 | I8: =S0_*EXP((mu_-sigma_^2/2)*Dt_+sigma_*SQRT(Dt_)*_xlfn.NORM.INV(RAND(),0,1)) -> 106.54662 | J8: =MAX(k_-I8,0)*EXP(-rs_*T_) -> 0 | K8: 6.3563196 | L8: 5.7863196 | M8: 0 | N8: 0 | P8: 80 | Q8: 0 | V8: 4 | W8: 0.054
B9: put_option_price | C9: c_ | D9: 0.57 | G9: 8 | H9: =S0_ -> 100 | I9: =S0_*EXP((mu_-sigma_^2/2)*Dt_+sigma_*SQRT(Dt_)*_xlfn.NORM.INV(RAND(),0,1)) -> 101.73762 | J9: =MAX(k_-I9,0)*EXP(-rs_*T_) -> 0 | K9: 1.6871089 | L9: 1.1171089 | M9: 0 | N9: 0 | P9: 85 | Q9: 0.0075 | V9: 6 | W9: 0.033 | AB9: bin_3 | AC9: f_payoff1 | AD9: f_payoff2
G10: 9 | H10: =S0_ -> 100 | I10: =S0_*EXP((mu_-sigma_^2/2)*Dt_+sigma_*SQRT(Dt_)*_xlfn.NORM.INV(RAND(),0,1)) -> 105.05677 | J10: =MAX(k_-I10,0)*EXP(-rs_*T_) -> 0 | K10: 4.9097708 | L10: 4.3397708 | M10: 0 | N10: 0 | P10: 90 | Q10: 0.042 | V10: 8 | W10: 0.028 | AB10: -30 | AC10: {=FREQUENCY(payoff1,bin_3)/N_} -> 0 | AD10: {=FREQUENCY(payoff2,bin_3)/N_} -> 0
G11: 10 | H11: =S0_ -> 100 | I11: =S0_*EXP((mu_-sigma_^2/2)*Dt_+sigma_*SQRT(Dt_)*_xlfn.NORM.INV(RAND(),0,1)) -> 111.48728 | J11: =MAX(k_-I11,0)*EXP(-rs_*T_) -> 0 | K11: 11.153351 | L11: 10.583351 | M11: 0 | N11: 0 | P11: 95 | Q11: 0.1035 | V11: 10 | W11: 0.0195 | AB11: -25 | AC11: 0 | AD11: 0
G12: 11 | H12: =S0_ -> 100 | I12: =S0_*EXP((mu_-sigma_^2/2)*Dt_+sigma_*SQRT(Dt_)*_xlfn.NORM.INV(RAND(),0,1)) -> 100.89211 | J12: =MAX(k_-I12,0)*EXP(-rs_*T_) -> 0 | K12: 0.8661726 | L12: 0.2961726 | M12: 0 | N12: 0 | P12: 100 | Q12: 0.187 | V12: 12 | W12: 0.009 | AB12: -20 | AC12: 0 | AD12: 0
G13: 12 | H13: =S0_ -> 100 | I13: =S0_*EXP((mu_-sigma_^2/2)*Dt_+sigma_*SQRT(Dt_)*_xlfn.NORM.INV(RAND(),0,1)) -> 106.75667 | J13: =MAX(k_-I13,0)*EXP(-rs_*T_) -> 0 | K13: 6.5602583 | L13: 5.9902583 | M13: 0 | N13: 0 | P13: 105 | Q13: 0.223 | V13: 14 | W13: 0.005 | AB13: -15 | AC13: 0.0055 | AD13: 0
G14: 13 | H14: =S0_ -> 100 | I14: =S0_*EXP((mu_-sigma_^2/2)*Dt_+sigma_*SQRT(Dt_)*_xlfn.NORM.INV(RAND(),0,1)) -> 100.99032 | J14: =MAX(k_-I14,0)*EXP(-rs_*T_) -> 0 | K14: 0.96152973 | L14: 0.39152973 | M14: 0 | N14: 0 | P14: 110 | Q14: 0.1955 | V14: 16 | W14: 0.0015 | AB14: -10 | AC14: 0.039 | AD14: 0
G15: 14 | H15: =S0_ -> 100 | I15: =S0_*EXP((mu_-sigma_^2/2)*Dt_+sigma_*SQRT(Dt_)*_xlfn.NORM.INV(RAND(),0,1)) -> 97.595584 | J15: =MAX(k_-I15,0)*EXP(-rs_*T_) -> 0 | K15: -2.3345216 | L15: -2.9045216 | M15: 1 | N15: 1 | P15: 115 | Q15: 0.1295 | V15: 18 | W15: 0 | AB15: -5 | AC15: 0.1035 | AD15: 0
G16: 15 | H16: =S0_ -> 100 | I16: =S0_*EXP((mu_-sigma_^2/2)*Dt_+sigma_*SQRT(Dt_)*_xlfn.NORM.INV(RAND(),0,1)) -> 110.95986 | J16: =MAX(k_-I16,0)*EXP(-rs_*T_) -> 0 | K16: 10.641267 | L16: 10.071267 | M16: 0 | N16: 0 | P16: 120 | Q16: 0.0745 | V16: 20 | W16: 0 | AB16: 0 | AC16: 0.192 | AD16: 0.363
G17: 16 | H17: =S0_ -> 100 | I17: =S0_*EXP((mu_-sigma_^2/2)*Dt_+sigma_*SQRT(Dt_)*_xlfn.NORM.INV(RAND(),0,1)) -> 112.15851 | J17: =MAX(k_-I17,0)*EXP(-rs_*T_) -> 0 | K17: 11.805077 | L17: 11.235077 | M17: 0 | N17: 0 | P17: 125 | Q17: 0.0265 | V17: 22 | W17: 0 | AB17: 5 | AC17: 0.2305 | AD17: 0.2355
G18: 17 | H18: =S0_ -> 100 | I18: =S0_*EXP((mu_-sigma_^2/2)*Dt_+sigma_*SQRT(Dt_)*_xlfn.NORM.INV(RAND(),0,1)) -> 117.30347 | J18: =MAX(k_-I18,0)*EXP(-rs_*T_) -> 0 | K18: 16.800469 | L18: 16.230469 | M18: 0 | N18: 0 | P18: 130 | Q18: 0.0075 | V18: 24 | W18: 0 | AB18: 10 | AC18: 0.201 | AD18: 0.1915
G19: 18 | H19: =S0_ -> 100 | I19: =S0_*EXP((mu_-sigma_^2/2)*Dt_+sigma_*SQRT(Dt_)*_xlfn.NORM.INV(RAND(),0,1)) -> 121.7339 | J19: =MAX(k_-I19,0)*EXP(-rs_*T_) -> 0 | K19: 21.102112 | L19: 20.532112 | M19: 0 | N19: 0 | P19: 135 | Q19: 0.002 | W19: 0 | AB19: 15 | AC19: 0.1235 | AD19: 0.112
G20: 19 | H20: =S0_ -> 100 | I20: =S0_*EXP((mu_-sigma_^2/2)*Dt_+sigma_*SQRT(Dt_)*_xlfn.NORM.INV(RAND(),0,1)) -> 106.36299 | J20: =MAX(k_-I20,0)*EXP(-rs_*T_) -> 0 | K20: 6.1780242 | L20: 5.6080242 | M20: 0 | N20: 0 | P20: 140 | Q20: 0.0015 | AB20: 20 | AC20: 0.073 | AD20: 0.069
G21: 20 | H21: =S0_ -> 100 | I21: =S0_*EXP((mu_-sigma_^2/2)*Dt_+sigma_*SQRT(Dt_)*_xlfn.NORM.INV(RAND(),0,1)) -> 106.6954 | J21: =MAX(k_-I21,0)*EXP(-rs_*T_) -> 0 | K21: 6.5007674 | L21: 5.9307674 | M21: 0 | N21: 0 | P21: 145 | Q21: 0 | AB21: 25 | AC21: 0.0225 | AD21: 0.023
G22: 21 | H22: =S0_ -> 100 | I22: =S0_*EXP((mu_-sigma_^2/2)*Dt_+sigma_*SQRT(Dt_)*_xlfn.NORM.INV(RAND(),0,1)) -> 100.17184 | J22: =MAX(k_-I22,0)*EXP(-rs_*T_) -> 0 | K22: 0.16684356 | L22: -0.40315644 | M22: 0 | N22: 1 | P22: 150 | Q22: 0 | AB22: 30 | AC22: 0.007 | AD22: 0.0035
G23: 22 | H23: =S0_ -> 100 | I23: =S0_*EXP((mu_-sigma_^2/2)*Dt_+sigma_*SQRT(Dt_)*_xlfn.NORM.INV(RAND(),0,1)) -> 106.74201 | J23: =MAX(k_-I23,0)*EXP(-rs_*T_) -> 0 | K23: 6.5460275 | L23: 5.9760275 | M23: 0 | N23: 0 | Q23: 0 | AB23: 35 | AC23: 0.0015 | AD23: 0.002
G24: 23 | H24: =S0_ -> 100 | I24: =S0_*EXP((mu_-sigma_^2/2)*Dt_+sigma_*SQRT(Dt_)*_xlfn.NORM.INV(RAND(),0,1)) -> 100.07091 | J24: =MAX(k_-I24,0)*EXP(-rs_*T_) -> 0 | K24: 0.068847123 | L24: -0.50115288 | M24: 0 | N24: 1 | AB24: 40 | AC24: 0.001 | AD24: 0.0005
G25: 24 | H25: =S0_ -> 100 | I25: =S0_*EXP((mu_-sigma_^2/2)*Dt_+sigma_*SQRT(Dt_)*_xlfn.NORM.INV(RAND(),0,1)) -> 104.01967 | J25: =MAX(k_-I25,0)*EXP(-rs_*T_) -> 0 | K25: 3.9028243 | L25: 3.3328243 | M25: 0 | N25: 0 | AB25: 45 | AC25: 0 | AD25: 0
G26: 25 | H26: =S0_ -> 100 | I26: =S0_*EXP((mu_-sigma_^2/2)*Dt_+sigma_*SQRT(Dt_)*_xlfn.NORM.INV(RAND(),0,1)) -> 104.22028 | J26: =MAX(k_-I26,0)*EXP(-rs_*T_) -> 0 | K26: 4.0975973 | L26: 3.5275973 | M26: 0 | N26: 0 | AC26: 0 | AD26: 0
G27: 26 | H27: =S0_ -> 100 | I27: =S0_*EXP((mu_-sigma_^2/2)*Dt_+sigma_*SQRT(Dt_)*_xlfn.NORM.INV(RAND(),0,1)) -> 102.16413 | J27: =MAX(k_-I27,0)*EXP(-rs_*T_) -> 0 | K27: 2.1012192 | L27: 1.5312192 | M27: 0 | N27: 0
G28: 27 | H28: =S0_ -> 100 | I28: =S0_*EXP((mu_-sigma_^2/2)*Dt_+sigma_*SQRT(Dt_)*_xlfn.NORM.INV(RAND(),0,1)) -> 115.03661 | J28: =MAX(k_-I28,0)*EXP(-rs_*T_) -> 0 | K28: 14.599509 | L28: 14.029509 | M28: 0 | N28: 0
G29: 28 | H29: =S0_ -> 100 | I29: =S0_*EXP((mu_-sigma_^2/2)*Dt_+sigma_*SQRT(Dt_)*_xlfn.NORM.INV(RAND(),0,1)) -> 112.74383 | J29: =MAX(k_-I29,0)*EXP(-rs_*T_) -> 0 | K29: 12.373381 | L29: 11.803381 | M29: 0 | N29: 0
G30: 29 | H30: =S0_ -> 100 | I30: =S0_*EXP((mu_-sigma_^2/2)*Dt_+sigma_*SQRT(Dt_)*_xlfn.NORM.INV(RAND(),0,1)) -> 116.32531 | J30: =MAX(k_-I30,0)*EXP(-rs_*T_) -> 0 | K30: 15.850744 | L30: 15.280744 | M30: 0 | N30: 0
G31: 30 | H31: =S0_ -> 100 | I31: =S0_*EXP((mu_-sigma_^2/2)*Dt_+sigma_*SQRT(Dt_)*_xlfn.NORM.INV(RAND(),0,1)) -> 106.39428 | J31: =MAX(k_-I31,0)*EXP(-rs_*T_) -> 0 | K31: 6.2084081 | L31: 5.6384081 | M31: 0 | N31: 0
G32: 31 | H32: =S0_ -> 100 | I32: =S0_*EXP((mu_-sigma_^2/2)*Dt_+sigma_*SQRT(Dt_)*_xlfn.NORM.INV(RAND(),0,1)) -> 99.912544 | J32: =MAX(k_-I32,0)*EXP(-rs_*T_) -> 0 | K32: -0.084913926 | L32: -0.65491393 | M32: 1 | N32: 1
G33: 32 | H33: =S0_ -> 100 | I33: =S0_*EXP((mu_-sigma_^2/2)*Dt_+sigma_*SQRT(Dt_)*_xlfn.NORM.INV(RAND(),0,1)) -> 107.63442 | J33: =MAX(k_-I33,0)*EXP(-rs_*T_) -> 0 | K33: 7.4124915 | L33: 6.8424915 | M33: 0 | N33: 0
G34: 33 | H34: =S0_ -> 100 | I34: =S0_*EXP((mu_-sigma_^2/2)*Dt_+sigma_*SQRT(Dt_)*_xlfn.NORM.INV(RAND(),0,1)) -> 98.714227 | J34: =MAX(k_-I34,0)*EXP(-rs_*T_) -> 0 | K34: -1.2483969 | L34: -1.8183969 | M34: 1 | N34: 1
G35: 34 | H35: =S0_ -> 100 | I35: =S0_*EXP((mu_-sigma_^2/2)*Dt_+sigma_*SQRT(Dt_)*_xlfn.NORM.INV(RAND(),0,1)) -> 119.71515 | J35: =MAX(k_-I35,0)*EXP(-rs_*T_) -> 0 | K35: 19.142052 | L35: 18.572052 | M35: 0 | N35: 0
G36: 35 | H36: =S0_ -> 100 | I36: =S0_*EXP((mu_-sigma_^2/2)*Dt_+sigma_*SQRT(Dt_)*_xlfn.NORM.INV(RAND(),0,1)) -> 126.26963 | J36: =MAX(k_-I36,0)*EXP(-rs_*T_) -> 0 | K36: 25.505996 | L36: 24.935996 | M36: 0 | N36: 0
G37: 36 | H37: =S0_ -> 100 | I37: =S0_*EXP((mu_-sigma_^2/2)*Dt_+sigma_*SQRT(Dt_)*_xlfn.NORM.INV(RAND(),0,1)) -> 107.87528 | J37: =MAX(k_-I37,0)*EXP(-rs_*T_) -> 0 | K37: 7.6463507 | L37: 7.0763507 | M37: 0 | N37: 0
G38: 37 | H38: =S0_ -> 100 | I38: =S0_*EXP((mu_-sigma_^2/2)*Dt_+sigma_*SQRT(Dt_)*_xlfn.NORM.INV(RAND(),0,1)) -> 104.60085 | J38: =MAX(k_-I38,0)*EXP(-rs_*T_) -> 0 | K38: 4.4671048 | L38: 3.8971048 | M38: 0 | N38: 0
... G2001: 2000 | H2001: =S0_ -> 100 | I2001: =S0_*EXP((mu_-sigma_^2/2)*Dt_+sigma_*SQRT(Dt_)*_xlfn.NORM.INV(RAND(),0,1)) -> 117.16925 | J2001: =MAX(k_-I2001,0)*EXP(-rs_*T_) -> 0 | K2001: 16.670155 | L2001: 16.100155 | M2001: 0 | N2001: 0

Sheet Results & Interpretation
A1: Results & Interpretation
A3: 1. Asian Option Pricing — Monte Carlo Results
A5: Metric | B5: Estimate | C5: Lower 95% CI | D5: Upper 95% CI | F5: Interpretation
A6: Asian put fair price | B6: =Pricing_Asian_Options!AJ2 -> 0.46508545 | C6: =Pricing_Asian_Options!AJ3 -> 0.37162761 | D6: =Pricing_Asian_Options!AJ4 -> 0.55854329 | F6: Each replication generates an entire one-year price path, so the Asian option payoff reflects the average path rather than only the terminal stock price. The resulting payoff distributions are asymmetric because option payoffs are floored at zero. The Monte Carlo mean estimates the fair price, while the confidence interval quantifies sampling uncertainty around that estimate. Probability estimates summarize how often simulated discounted payoffs exceed the specified threshold.
A7: Asian call fair price | B7: =Pricing_Asian_Options!AJ6 -> 7.9093402 | C7: =Pricing_Asian_Options!AJ7 -> 7.5088527 | D7: =Pricing_Asian_Options!AJ8 -> 8.3098276
A8: P(Put payoff > 1.1) | B8: =Pricing_Asian_Options!AM2 -> 0.115 | C8: =Pricing_Asian_Options!AM3 -> 0.095216921 | D8: =Pricing_Asian_Options!AM4 -> 0.13478308
A9: P(Call payoff > 1.1) | B9: =Pricing_Asian_Options!AM6 -> 0.816 | C9: =Pricing_Asian_Options!AM7 -> 0.79197146 | D9: =Pricing_Asian_Options!AM8 -> 0.84002854
A10: Min put payoff | B10: =Pricing_Asian_Options!AE3 -> 0
A11: Max put payoff | B11: =Pricing_Asian_Options!AE2 -> 13.763539
A12: Max call payoff | B12: =Pricing_Asian_Options!AG2 -> 31.074967
A14: 2. Financial Hedging — Risk Comparison
A16: Metric | B16: Stock Only | C16: Stock + Put | D16: Analytical Focus | F16: Interpretation
A17: Expected payoff | B17: =Hedging!AC2 -> 3.822463 | C17: =Hedging!AE2 -> 4.2016808 | D17: Return level | F17: The protective put should be interpreted as insurance rather than as a mechanism for maximizing expected payoff. The option premium can slightly reduce favorable-state returns and can even increase the frequency of small negative payoffs. Its central benefit is tail protection: once the stock falls below the strike, the put limits further downside. Therefore, variance and minimum payoff are especially informative for judging hedging effectiveness.
A18: Payoff variance | B18: =Hedging!AC3 -> 72.239509 | C18: =Hedging!AE3 -> 52.008802 | D18: Dispersion / risk
A19: P(Payoff < 0) | B19: =Hedging!AC4 -> 0.34 | C19: =Hedging!AE4 -> 0.363 | D19: Frequency of loss
A20: Minimum payoff | B20: =Hedging!AC7 -> -18.22536 | C20: =Hedging!AE7 -> -3.4827926 | D20: Worst simulated downside
A21: Maximum payoff | B21: =Hedging!AC6 -> 36.721784 | C21: =Hedging!AE6 -> 36.151784 | D21: Upside observed
A22: Variance reduction | B22: =1-C18/B18 -> 0.28005045 | D22: Risk reduction from hedging
A23: Downside floor improvement | B23: =C20-B20 -> 14.742567 | D23: Tail protection
A24: Put fair value / market price | B24: =Hedging!Z2 -> 0.94921779 | C24: =Hedging!D9 -> 0.57 | D24: Pricing comparison
A26: 3. Managerial / Analytical Implications
A27: • | B27: Path dependence matters: when a contract depends on an average price, terminal-price analysis alone is insufficient.
A28: • | B28: Simulation turns uncertain dynamic processes into empirical distributions that can be summarized with expected values, confidence intervals, probabilities, and tail outcomes.
A29: • | B29: Risk management decisions should not rely on mean payoff alone; the shape and dispersion of the payoff distribution can materially change the decision.
A30: • | B30: A hedge can be valuable even when the probability of any loss does not decline, because it can sharply reduce the severity of adverse outcomes.
A31: • | B31: Monte Carlo convergence diagnostics help distinguish a stable simulation estimate from one that is still sensitive to sample size.
A33: 4. Limitations
A34: • | B34: The stock-price model assumes constant drift and volatility over the modeled horizon.
A35: • | B35: Random shocks are generated from a normal distribution within the geometric random-walk specification; alternative return dynamics are not modeled.
A36: • | B36: Monte Carlo estimates contain sampling error; results vary when the random-number generator recalculates.
A37: • | B37: The hedging comparison focuses on one put contract specification and one premium rather than optimizing strike, maturity, or hedge ratio.
A38: • | B38: The simulation evaluates modeled financial risk; it does not incorporate transaction costs, liquidity, taxes, or broader portfolio effects.

Sheet Simulation Convergence
A1: Simulation Convergence Diagnostics
A3: Monte Carlo estimates should stabilize as the number of replications increases. The tables below recompute running means at regular checkpoints using the existing simulation output. Flattening curves indicate that additional replications are producing progressively smaller changes in the estimated expected payoff.
A7: Asian option runs | B7: Running mean — Put | C7: Running mean — Call | E7: Hedging runs | F7: Running mean — Stock Only | G7: Running mean — Stock + Put
A8: 25 | B8: =AVERAGE(Pricing_Asian_Options!$Z$3:$Z$27) -> 0.035472057 | C8: =AVERAGE(Pricing_Asian_Options!$Y$3:$Y$27) -> 10.344659 | E8: 50 | F8: =AVERAGE(Hedging!$K$2:$K$51) -> 7.0622694 | G8: =AVERAGE(Hedging!$L$2:$L$51) -> 6.5882277
A9: 50 | B9: =AVERAGE(Pricing_Asian_Options!$Z$3:$Z$52) -> 0.38947007 | C9: =AVERAGE(Pricing_Asian_Options!$Y$3:$Y$52) -> 8.2841744 | E9: 100 | F9: =AVERAGE(Hedging!$K$2:$K$101) -> 4.8575711 | G9: =AVERAGE(Hedging!$L$2:$L$101) -> 4.8432646
A10: 75 | B10: =AVERAGE(Pricing_Asian_Options!$Z$3:$Z$77) -> 0.32782605 | C10: =AVERAGE(Pricing_Asian_Options!$Y$3:$Y$77) -> 8.2105303 | E10: 150 | F10: =AVERAGE(Hedging!$K$2:$K$151) -> 5.0455383 | G10: =AVERAGE(Hedging!$L$2:$L$151) -> 5.0117541
A11: 100 | B11: =AVERAGE(Pricing_Asian_Options!$Z$3:$Z$102) -> 0.53039528 | C11: =AVERAGE(Pricing_Asian_Options!$Y$3:$Y$102) -> 7.9190038 | E11: 200 | F11: =AVERAGE(Hedging!$K$2:$K$201) -> 4.9739545 | G11: =AVERAGE(Hedging!$L$2:$L$201) -> 4.9787087
A12: 125 | B12: =AVERAGE(Pricing_Asian_Options!$Z$3:$Z$127) -> 0.54181973 | C12: =AVERAGE(Pricing_Asian_Options!$Y$3:$Y$127) -> 8.2625784 | E12: 250 | F12: =AVERAGE(Hedging!$K$2:$K$251) -> 4.7836662 | G12: =AVERAGE(Hedging!$L$2:$L$251) -> 4.7015018
A13: 150 | B13: =AVERAGE(Pricing_Asian_Options!$Z$3:$Z$152) -> 0.49074259 | C13: =AVERAGE(Pricing_Asian_Options!$Y$3:$Y$152) -> 8.069374 | E13: 300 | F13: =AVERAGE(Hedging!$K$2:$K$301) -> 4.555165 | G13: =AVERAGE(Hedging!$L$2:$L$301) -> 4.5662879
A14: 175 | B14: =AVERAGE(Pricing_Asian_Options!$Z$3:$Z$177) -> 0.47378134 | C14: =AVERAGE(Pricing_Asian_Options!$Y$3:$Y$177) -> 7.8408301 | E14: 350 | F14: =AVERAGE(Hedging!$K$2:$K$351) -> 4.2981654 | G14: =AVERAGE(Hedging!$L$2:$L$351) -> 4.485336
A15: 200 | B15: =AVERAGE(Pricing_Asian_Options!$Z$3:$Z$202) -> 0.44379325 | C15: =AVERAGE(Pricing_Asian_Options!$Y$3:$Y$202) -> 7.7788735 | E15: 400 | F15: =AVERAGE(Hedging!$K$2:$K$401) -> 4.3133785 | G15: =AVERAGE(Hedging!$L$2:$L$401) -> 4.520249
A16: 225 | B16: =AVERAGE(Pricing_Asian_Options!$Z$3:$Z$227) -> 0.47918603 | C16: =AVERAGE(Pricing_Asian_Options!$Y$3:$Y$227) -> 7.7041432 | E16: 450 | F16: =AVERAGE(Hedging!$K$2:$K$451) -> 4.1970951 | G16: =AVERAGE(Hedging!$L$2:$L$451) -> 4.4361234
A17: 250 | B17: =AVERAGE(Pricing_Asian_Options!$Z$3:$Z$252) -> 0.47811062 | C17: =AVERAGE(Pricing_Asian_Options!$Y$3:$Y$252) -> 7.6615398 | E17: 500 | F17: =AVERAGE(Hedging!$K$2:$K$501) -> 4.1330356 | G17: =AVERAGE(Hedging!$L$2:$L$501) -> 4.3904189
A18: 275 | B18: =AVERAGE(Pricing_Asian_Options!$Z$3:$Z$277) -> 0.4655322 | C18: =AVERAGE(Pricing_Asian_Options!$Y$3:$Y$277) -> 7.8078689 | E18: 550 | F18: =AVERAGE(Hedging!$K$2:$K$551) -> 3.9861135 | G18: =AVERAGE(Hedging!$L$2:$L$551) -> 4.3131371
A19: 300 | B19: =AVERAGE(Pricing_Asian_Options!$Z$3:$Z$302) -> 0.4458075 | C19: =AVERAGE(Pricing_Asian_Options!$Y$3:$Y$302) -> 7.8466419 | E19: 600 | F19: =AVERAGE(Hedging!$K$2:$K$601) -> 4.0501449 | G19: =AVERAGE(Hedging!$L$2:$L$601) -> 4.3547133
A20: 325 | B20: =AVERAGE(Pricing_Asian_Options!$Z$3:$Z$327) -> 0.44663925 | C20: =AVERAGE(Pricing_Asian_Options!$Y$3:$Y$327) -> 7.6784326 | E20: 650 | F20: =AVERAGE(Hedging!$K$2:$K$651) -> 4.1023007 | G20: =AVERAGE(Hedging!$L$2:$L$651) -> 4.413876
A21: 350 | B21: =AVERAGE(Pricing_Asian_Options!$Z$3:$Z$352) -> 0.44658613 | C21: =AVERAGE(Pricing_Asian_Options!$Y$3:$Y$352) -> 7.7760784 | E21: 700 | F21: =AVERAGE(Hedging!$K$2:$K$701) -> 4.0268868 | G21: =AVERAGE(Hedging!$L$2:$L$701) -> 4.342939
A22: 375 | B22: =AVERAGE(Pricing_Asian_Options!$Z$3:$Z$377) -> 0.48894678 | C22: =AVERAGE(Pricing_Asian_Options!$Y$3:$Y$377) -> 7.6615711 | E22: 750 | F22: =AVERAGE(Hedging!$K$2:$K$751) -> 4.0765942 | G22: =AVERAGE(Hedging!$L$2:$L$751) -> 4.3692169
A23: 400 | B23: =AVERAGE(Pricing_Asian_Options!$Z$3:$Z$402) -> 0.47153617 | C23: =AVERAGE(Pricing_Asian_Options!$Y$3:$Y$402) -> 7.7233634 | E23: 800 | F23: =AVERAGE(Hedging!$K$2:$K$801) -> 4.1506245 | G23: =AVERAGE(Hedging!$L$2:$L$801) -> 4.4211583
A24: 425 | B24: =AVERAGE(Pricing_Asian_Options!$Z$3:$Z$427) -> 0.46804989 | C24: =AVERAGE(Pricing_Asian_Options!$Y$3:$Y$427) -> 7.8444392 | E24: 850 | F24: =AVERAGE(Hedging!$K$2:$K$851) -> 4.0387429 | G24: =AVERAGE(Hedging!$L$2:$L$851) -> 4.3377056
A25: 450 | B25: =AVERAGE(Pricing_Asian_Options!$Z$3:$Z$452) -> 0.47095262 | C25: =AVERAGE(Pricing_Asian_Options!$Y$3:$Y$452) -> 7.8040863 | E25: 900 | F25: =AVERAGE(Hedging!$K$2:$K$901) -> 4.036352 | G25: =AVERAGE(Hedging!$L$2:$L$901) -> 4.3383113
A26: 475 | B26: =AVERAGE(Pricing_Asian_Options!$Z$3:$Z$477) -> 0.48260694 | C26: =AVERAGE(Pricing_Asian_Options!$Y$3:$Y$477) -> 7.8915139 | E26: 950 | F26: =AVERAGE(Hedging!$K$2:$K$951) -> 4.06875 | G26: =AVERAGE(Hedging!$L$2:$L$951) -> 4.361257
A27: 500 | B27: =AVERAGE(Pricing_Asian_Options!$Z$3:$Z$502) -> 0.47796413 | C27: =AVERAGE(Pricing_Asian_Options!$Y$3:$Y$502) -> 7.9684986 | E27: 1000 | F27: =AVERAGE(Hedging!$K$2:$K$1001) -> 4.0524415 | G27: =AVERAGE(Hedging!$L$2:$L$1001) -> 4.3591418
A28: 525 | B28: =AVERAGE(Pricing_Asian_Options!$Z$3:$Z$527) -> 0.48087956 | C28: =AVERAGE(Pricing_Asian_Options!$Y$3:$Y$527) -> 7.9193363 | E28: 1050 | F28: =AVERAGE(Hedging!$K$2:$K$1051) -> 4.0654206 | G28: =AVERAGE(Hedging!$L$2:$L$1051) -> 4.3578835
A29: 550 | B29: =AVERAGE(Pricing_Asian_Options!$Z$3:$Z$552) -> 0.49554266 | C29: =AVERAGE(Pricing_Asian_Options!$Y$3:$Y$552) -> 7.8470096 | E29: 1100 | F29: =AVERAGE(Hedging!$K$2:$K$1101) -> 4.0819973 | G29: =AVERAGE(Hedging!$L$2:$L$1101) -> 4.3843956
A30: 575 | B30: =AVERAGE(Pricing_Asian_Options!$Z$3:$Z$577) -> 0.50581433 | C30: =AVERAGE(Pricing_Asian_Options!$Y$3:$Y$577) -> 7.8425152 | E30: 1150 | F30: =AVERAGE(Hedging!$K$2:$K$1151) -> 4.0569259 | G30: =AVERAGE(Hedging!$L$2:$L$1151) -> 4.3621505
A31: 600 | B31: =AVERAGE(Pricing_Asian_Options!$Z$3:$Z$602) -> 0.48706584 | C31: =AVERAGE(Pricing_Asian_Options!$Y$3:$Y$602) -> 7.920367 | E31: 1200 | F31: =AVERAGE(Hedging!$K$2:$K$1201) -> 4.1202923 | G31: =AVERAGE(Hedging!$L$2:$L$1201) -> 4.4167808
A32: 625 | B32: =AVERAGE(Pricing_Asian_Options!$Z$3:$Z$627) -> 0.49851381 | C32: =AVERAGE(Pricing_Asian_Options!$Y$3:$Y$627) -> 7.8895004 | E32: 1250 | F32: =AVERAGE(Hedging!$K$2:$K$1251) -> 4.0229878 | G32: =AVERAGE(Hedging!$L$2:$L$1251) -> 4.3426786
A33: 650 | B33: =AVERAGE(Pricing_Asian_Options!$Z$3:$Z$652) -> 0.48327248 | C33: =AVERAGE(Pricing_Asian_Options!$Y$3:$Y$652) -> 7.8987959 | E33: 1300 | F33: =AVERAGE(Hedging!$K$2:$K$1301) -> 4.0888529 | G33: =AVERAGE(Hedging!$L$2:$L$1301) -> 4.4073516
A34: 675 | B34: =AVERAGE(Pricing_Asian_Options!$Z$3:$Z$677) -> 0.47045008 | C34: =AVERAGE(Pricing_Asian_Options!$Y$3:$Y$677) -> 7.9296923 | E34: 1350 | F34: =AVERAGE(Hedging!$K$2:$K$1351) -> 4.0182429 | G34: =AVERAGE(Hedging!$L$2:$L$1351) -> 4.3612588
A35: 700 | B35: =AVERAGE(Pricing_Asian_Options!$Z$3:$Z$702) -> 0.46545258 | C35: =AVERAGE(Pricing_Asian_Options!$Y$3:$Y$702) -> 7.9046079 | E35: 1400 | F35: =AVERAGE(Hedging!$K$2:$K$1401) -> 3.9486431 | G35: =AVERAGE(Hedging!$L$2:$L$1401) -> 4.3205797
A36: 725 | B36: =AVERAGE(Pricing_Asian_Options!$Z$3:$Z$727) -> 0.46590648 | C36: =AVERAGE(Pricing_Asian_Options!$Y$3:$Y$727) -> 7.9033933 | E36: 1450 | F36: =AVERAGE(Hedging!$K$2:$K$1451) -> 3.9522962 | G36: =AVERAGE(Hedging!$L$2:$L$1451) -> 4.3140538
A37: 750 | B37: =AVERAGE(Pricing_Asian_Options!$Z$3:$Z$752) -> 0.45963276 | C37: =AVERAGE(Pricing_Asian_Options!$Y$3:$Y$752) -> 7.9231797 | E37: 1500 | F37: =AVERAGE(Hedging!$K$2:$K$1501) -> 3.9177913 | G37: =AVERAGE(Hedging!$L$2:$L$1501) -> 4.2787469
A38: 775 | B38: =AVERAGE(Pricing_Asian_Options!$Z$3:$Z$777) -> 0.45863689 | C38: =AVERAGE(Pricing_Asian_Options!$Y$3:$Y$777) -> 7.9160736 | E38: 1550 | F38: =AVERAGE(Hedging!$K$2:$K$1551) -> 3.9376035 | G38: =AVERAGE(Hedging!$L$2:$L$1551) -> 4.2854476
A39: 800 | B39: =AVERAGE(Pricing_Asian_Options!$Z$3:$Z$802) -> 0.47075119 | C39: =AVERAGE(Pricing_Asian_Options!$Y$3:$Y$802) -> 7.9078913 | E39: 1600 | F39: =AVERAGE(Hedging!$K$2:$K$1601) -> 3.8861055 | G39: =AVERAGE(Hedging!$L$2:$L$1601) -> 4.2576915
A40: 825 | B40: =AVERAGE(Pricing_Asian_Options!$Z$3:$Z$827) -> 0.46696809 | C40: =AVERAGE(Pricing_Asian_Options!$Y$3:$Y$827) -> 7.8501586 | E40: 1650 | F40: =AVERAGE(Hedging!$K$2:$K$1651) -> 3.9130115 | G40: =AVERAGE(Hedging!$L$2:$L$1651) -> 4.2807048
A41: 850 | B41: =AVERAGE(Pricing_Asian_Options!$Z$3:$Z$852) -> 0.48643943 | C41: =AVERAGE(Pricing_Asian_Options!$Y$3:$Y$852) -> 7.840073 | E41: 1700 | F41: =AVERAGE(Hedging!$K$2:$K$1701) -> 3.8989205 | G41: =AVERAGE(Hedging!$L$2:$L$1701) -> 4.2606195
A42: 875 | B42: =AVERAGE(Pricing_Asian_Options!$Z$3:$Z$877) -> 0.48573326 | C42: =AVERAGE(Pricing_Asian_Options!$Y$3:$Y$877) -> 7.824598 | E42: 1750 | F42: =AVERAGE(Hedging!$K$2:$K$1751) -> 3.8361655 | G42: =AVERAGE(Hedging!$L$2:$L$1751) -> 4.2351599
A43: 900 | B43: =AVERAGE(Pricing_Asian_Options!$Z$3:$Z$902) -> 0.4787061 | C43: =AVERAGE(Pricing_Asian_Options!$Y$3:$Y$902) -> 7.8859667 | E43: 1800 | F43: =AVERAGE(Hedging!$K$2:$K$1801) -> 3.8167892 | G43: =AVERAGE(Hedging!$L$2:$L$1801) -> 4.2152593
A44: 925 | B44: =AVERAGE(Pricing_Asian_Options!$Z$3:$Z$927) -> 0.47253 | C44: =AVERAGE(Pricing_Asian_Options!$Y$3:$Y$927) -> 7.893899 | E44: 1850 | F44: =AVERAGE(Hedging!$K$2:$K$1851) -> 3.8358434 | G44: =AVERAGE(Hedging!$L$2:$L$1851) -> 4.2256548
...
