Workbook
Name Adam_1st_class3: '2Social_Mobility'!$KE$1
Name Cooper_1st_class1: '2Social_Mobility'!$KE$2
Name f0_: '2Social_Mobility'!$C$10:$E$12
Name f0_1: '2Social_Mobility'!$C$10:$E$10
Name f0_2: '2Social_Mobility'!$C$11:$E$11
Name f0_3: '2Social_Mobility'!$C$12:$E$12
Name F0_CDF: '2Social_Mobility'!$C$13:$F$15
Name F0_CDF1: '2Social_Mobility'!$C$13:$F$13
Name F0_CDF2: '2Social_Mobility'!$C$14:$F$14
Name F0_CDF3: '2Social_Mobility'!$C$15:$F$15
Name first_class1: '2Social_Mobility'!$JS$2:$JS$1001
Name first_class3: '2Social_Mobility'!$HQ$2:$HQ$1001
Name lower_level: '2Social_Mobility'!$C$3
Name middle_level: '2Social_Mobility'!$C$2
Name N2_: '2Social_Mobility'!$C$17
Name p_: '2Social_Mobility'!$C$4:$E$6
Name Q_: '2Social_Mobility'!$C$7:$F$9
Name T: '2Social_Mobility'!$C$16
Name upper_level: '2Social_Mobility'!$C$1
Name x50_: '2Social_Mobility'!$BF$2:$BF$1001

Sheet 00_Project_Overview
A1: Social Mobility Across Generations — Markov Chain Simulation
A3: Monte Carlo analysis of persistence, convergence, and mobility across upper, middle, and lower social levels
A5: Problem
A6: A society is represented by three socioeconomic levels: 1 = upper (executive, managerial, high administrative, professional), 2 = middle (high-grade supervisor, non-manual, skilled manual), and 3 = lower (semi-skilled or unskilled). Intergenerational transition probabilities describe how an offspring’s social level depends on the parent’s level. The project asks whether starting social position persists over time, what the long-run class composition looks like, how quickly families starting at opposite extremes converge, and how long it takes to cross between the upper and lower levels.
A10: Model
A11: Transition Matrix P | B11: Next: Upper | C11: Next: Middle | D11: Next: Lower | F11: State / Parameter | G11: Meaning | H11: Value
A12: Current: Upper | B12: ='2Social_Mobility'!C4 -> 0.45 | C12: ='2Social_Mobility'!D4 -> 0.48 | D12: ='2Social_Mobility'!E4 -> 0.07 | F12: 1 | G12: Upper level | H12: ='2Social_Mobility'!C1 -> 1
A13: Current: Middle | B13: ='2Social_Mobility'!C5 -> 0.05 | C13: ='2Social_Mobility'!D5 -> 0.7 | D13: ='2Social_Mobility'!E5 -> 0.25 | F13: 2 | G13: Middle level | H13: ='2Social_Mobility'!C2 -> 2
A14: Current: Lower | B14: ='2Social_Mobility'!C6 -> 0.01 | C14: ='2Social_Mobility'!D6 -> 0.5 | D14: ='2Social_Mobility'!E6 -> 0.49 | F14: 3 | G14: Lower level | H14: ='2Social_Mobility'!C3 -> 3
A15: Interpretation | B15: Each row is the conditional distribution of the next generation given the current generation. | F15: Horizon / sample | G15: Generations / simulated families | H15: ="T="&'2Social_Mobility'!C16&"; N="&TEXT('2Social_Mobility'!C17,"#,##0") -> T=50; N=1,000
A17: Simulation Design
A18: The model simulates 1,000 family lines for 50 generations. Initial states are sampled from a specified initial distribution, and every subsequent generation is generated from the transition probabilities associated with the current state. The transition matrix is converted to cumulative probabilities, allowing RAND() to be mapped to a discrete state with MATCH()/INDEX(). Three initial distributions are compared: [0.5, 0, 0.5], [1, 0, 0], and [0, 0, 1]. Separate Adam and Cooper simulations evaluate upper-level probability paths and first-passage times across the social extremes.
A24: Research Questions
A25: Question | B25: What is being analyzed? | F25: Primary output
A26: Q1 — Long-run distribution | B26: Do three very different starting populations approach similar class shares by generation 50? | F26: Generation-50 frequencies
A27: Q2 — Mobility path | B27: How does P(Upper) evolve for Adam (starts Upper) versus Cooper (starts Lower) over generations 1–10? | F27: Adam / Cooper probability paths
A28: Q3 — First-passage time | B28: How many generations are required, on average, for Upper→Lower and Lower→Upper first passage? | F28: Mean + 95% confidence interval
A29: Q4 — Implications | B29: What do persistence, convergence, and directional mobility asymmetry imply for decision analysis and policy discussion? | F29: Interpretation with caveats
A30: Simulation convergence | B30: Does the effect of opposite initial states shrink across generations? | F30: Absolute Adam–Cooper gap
A31: Uncertainty | B31: How much sampling variation remains with 1,000 simulated family lines? | F31: Monte Carlo variability / CI
A35: Portfolio Roadmap
A36: Sheet | B36: Purpose | D36: Reviewer focus
A37: 00_Project_Overview | B37: Problem, model, simulation design, and research-question map. | D37: Start here for the analytical framing.
A38: 01_Results_Dashboard | B38: Linked results, charts, convergence interpretation, implications, and limitations. | D38: Main professor-facing analytical output.
A39: 2Social_Mobility | B39: Original simulation engine, formulas, random paths, and output calculations. | D39: Audit the mechanics; formulas and logic are preserved.
A40: 03_Documentation | B40: Variable dictionary, formula logic, assumptions, reproducibility, and interpretation guidance. | D40: Technical documentation and model limitations.

Sheet 2Social_Mobility
A1: INPUT | B1: upper_level | C1: 1 | G1: Sample Path | H1: familiy/generation | I1: x1 | J1: x2 | K1: x3 | L1: x4 | M1: x5 | N1: x6 | O1: x7 | P1: x8 | Q1: x9 | R1: x10 | S1: x11 | T1: x12 | U1: x13 | V1: x14 | W1: x15 | X1: x16 | Y1: x17 | Z1: x18 | AA1: x19 | AB1: x20 | AC1: x21 | AD1: x22 | AE1: x23 | AF1: x24 | AG1: x25 | AH1: x26 | AI1: x27 | AJ1: x28 | AK1: x29 | AL1: x30 | AM1: x31 | AN1: x32 | AO1: x33 | AP1: x34 | AQ1: x35 | AR1: x36 | AS1: x37 | AT1: x38 | AU1: x39 | AV1: x40 | AW1: x41 | AX1: x42 | AY1: x43 | AZ1: x44 | BA1: x45 | BB1: x46 | BC1: x47 | BD1: x48 | BE1: x49 | BF1: x50 | BI1: familiy/generation | BJ1: x1 | BK1: x2 | BL1: x3 | BM1: x4 | BN1: x5 | BO1: x6 | BP1: x7 | BQ1: x8 | BR1: x9 | BS1: x10 | BT1: x11 | BU1: x12 | BV1: x13 | BW1: x14 | BX1: x15 | BY1: x16 | BZ1: x17 | CA1: x18 | CB1: x19 | CC1: x20 | CD1: x21 | CE1: x22 | CF1: x23 | CG1: x24 | CH1: x25 | CI1: x26 | CJ1: x27 | CK1: x28 | CL1: x29 | CM1: x30 | CN1: x31 | CO1: x32 | CP1: x33 | CQ1: x34 | CR1: x35 | CS1: x36 | CT1: x37 | CU1: x38 | CV1: x39 | CW1: x40 | CX1: x41 | CY1: x42 | CZ1: x43 | DA1: x44 | DB1: x45 | DC1: x46 | DD1: x47 | DE1: x48 | DF1: x49 | DG1: x50 | DJ1: familiy/generation | DK1: x1 | DL1: x2 | DM1: x3 | DN1: x4 | DO1: x5 | DP1: x6 | DQ1: x7 | DR1: x8 | DS1: x9 | DT1: x10 | DU1: x11 | DV1: x12 | DW1: x13 | DX1: x14 | DY1: x15 | DZ1: x16 | EA1: x17 | EB1: x18 | EC1: x19 | ED1: x20 | EE1: x21 | EF1: x22 | EG1: x23 | EH1: x24 | EI1: x25 | EJ1: x26 | EK1: x27 | EL1: x28 | EM1: x29 | EN1: x30 | EO1: x31 | EP1: x32 | EQ1: x33 | ER1: x34 | ES1: x35 | ET1: x36 | EU1: x37 | EV1: x38 | EW1: x39 | EX1: x40 | EY1: x41 | EZ1: x42 | FA1: x43 | FB1: x44 | FC1: x45 | FD1: x46 | FE1: x47 | FF1: x48 | FG1: x49 | FH1: x50 | FJ1: Qa | FK1: When f0=[0.5,0,0.5] | FP1: Adam | FQ1: familiy/generation | FR1: x0 | FS1: x1 | FT1: x2 | FU1: x3 | FV1: x4 | FW1: x5 | FX1: x6 | FY1: x7 | FZ1: x8 | GA1: x9 | GB1: x10 | GC1: x11 | GD1: x12 | GE1: x13 | GF1: x14 | GG1: x15 | GH1: x16 | GI1: x17 | GJ1: x18 | GK1: x19 | GL1: x20 | GM1: x21 | GN1: x22 | GO1: x23 | GP1: x24 | GQ1: x25 | GR1: x26 | GS1: x27 | GT1: x28 | GU1: x29 | GV1: x30 | GW1: x31 | GX1: x32 | GY1: x33 | GZ1: x34 | HA1: x35 | HB1: x36 | HC1: x37 | HD1: x38 | HE1: x39 | HF1: x40 | HG1: x41 | HH1: x42 | HI1: x43 | HJ1: x44 | HK1: x45 | HL1: x46 | HM1: x47 | HN1: x48 | HO1: x49 | HP1: x50 | HQ1: first_class3 | HS1: Cooper familiy/generation | HT1: x0 | HU1: x1 | HV1: x2 | HW1: x3 | HX1: x4 | HY1: x5 | HZ1: x6 | IA1: x7 | IB1: x8 | IC1: x9 | ID1: x10 | IE1: x11 | IF1: x12 | IG1: x13 | IH1: x14 | II1: x15 | IJ1: x16 | IK1: x17 | IL1: x18 | IM1: x19 | IN1: x20 | IO1: x21 | IP1: x22 | IQ1: x23 | IR1: x24 | IS1: x25 | IT1: x26 | IU1: x27 | IV1: x28 | IW1: x29 | IX1: x30 | IY1: x31 | IZ1: x32 | JA1: x33 | JB1: x34 | JC1: x35 | JD1: x36 | JE1: x37 | JF1: x38 | JG1: x39 | JH1: x40 | JI1: x41 | JJ1: x42 | JK1: x43 | JL1: x44 | JM1: x45 | JN1: x46 | JO1: x47 | JP1: x48 | JQ1: x49 | JR1: x50 | JS1: first_class1 | JU1: Qb | JW1: Adam | JX1: Cooper | KC1: Qc | KD1: Adam_1st_class3 | KE1: =AVERAGE(first_class3) -> 5.346 | KF1: 95%CI_LB | KG1: =Adam_1st_class3-1.96*STDEV(first_class3)/SQRT(N2_) -> 5.0973628 | KH1: 95%CI_UB | KI1: =Adam_1st_class3+1.96*STDEV(first_class3)/SQRT(N2_) -> 5.5946372
B2: middle_level | C2: 2 | G2: when f0=[0.5,0,0.5] | H2: {=_xlfn.SEQUENCE(1000)} -> 1 | I2: =MATCH(RAND(),F0_CDF1) -> 1 | J2: =MATCH(RAND(),INDEX(Q_,I2,0)) -> 1 | K2: =MATCH(RAND(),INDEX(Q_,J2,0)) -> 1 | L2: =MATCH(RAND(),INDEX(Q_,K2,0)) -> 1 | M2: =MATCH(RAND(),INDEX(Q_,L2,0)) -> 2 | N2: =MATCH(RAND(),INDEX(Q_,M2,0)) -> 2 | O2: =MATCH(RAND(),INDEX(Q_,N2,0)) -> 2 | P2: =MATCH(RAND(),INDEX(Q_,O2,0)) -> 2 | Q2: =MATCH(RAND(),INDEX(Q_,P2,0)) -> 2 | ... BF2: =MATCH(RAND(),INDEX(Q_,BE2,0)) -> 2 | BH2: when f0=[1,0,0] | BI2: {=_xlfn.SEQUENCE(1000)} -> 1 | BJ2: =MATCH(RAND(),F0_CDF2) -> 1 | BK2: =MATCH(RAND(),INDEX(Q_,BJ2,0)) -> 1 | BL2: =MATCH(RAND(),INDEX(Q_,BK2,0)) -> 2 | BM2: =MATCH(RAND(),INDEX(Q_,BL2,0)) -> 3 | BN2: =MATCH(RAND(),INDEX(Q_,BM2,0)) -> 2 | BO2: =MATCH(RAND(),INDEX(Q_,BN2,0)) -> 2 | BP2: =MATCH(RAND(),INDEX(Q_,BO2,0)) -> 2 | BQ2: =MATCH(RAND(),INDEX(Q_,BP2,0)) -> 1 | BR2: =MATCH(RAND(),INDEX(Q_,BQ2,0)) -> 2 | ... DG2: =MATCH(RAND(),INDEX(Q_,DF2,0)) -> 1 | DI2: when f0=[0,0,1] | DJ2: {=_xlfn.SEQUENCE(1000)} -> 1 | DK2: =MATCH(RAND(),F0_CDF3) -> 3 | DL2: =MATCH(RAND(),INDEX(Q_,DK2,0)) -> 2 | DM2: =MATCH(RAND(),INDEX(Q_,DL2,0)) -> 2 | DN2: =MATCH(RAND(),INDEX(Q_,DM2,0)) -> 2 | DO2: =MATCH(RAND(),INDEX(Q_,DN2,0)) -> 2 | DP2: =MATCH(RAND(),INDEX(Q_,DO2,0)) -> 1 | DQ2: =MATCH(RAND(),INDEX(Q_,DP2,0)) -> 2 | DR2: =MATCH(RAND(),INDEX(Q_,DQ2,0)) -> 3 | DS2: =MATCH(RAND(),INDEX(Q_,DR2,0)) -> 3 | ... FH2: =MATCH(RAND(),INDEX(Q_,FG2,0)) -> 2 | FK2: OUTPUT | FL2: class | FM2: frequency | FQ2: {=_xlfn.SEQUENCE(1000)} -> 1 | FR2: 1 | FS2: =MATCH(RAND(),INDEX(Q_,FR2,0)) -> 2 | FT2: =MATCH(RAND(),INDEX(Q_,FS2,0)) -> 2 | FU2: =MATCH(RAND(),INDEX(Q_,FT2,0)) -> 2 | FV2: =MATCH(RAND(),INDEX(Q_,FU2,0)) -> 3 | FW2: =MATCH(RAND(),INDEX(Q_,FV2,0)) -> 3 | FX2: =MATCH(RAND(),INDEX(Q_,FW2,0)) -> 3 | FY2: =MATCH(RAND(),INDEX(Q_,FX2,0)) -> 3 | FZ2: =MATCH(RAND(),INDEX(Q_,FY2,0)) -> 2 | ... HP2: =MATCH(RAND(),INDEX(Q_,HO2,0)) -> 3 | HQ2: =IF(ISNUMBER(MATCH(3,FS2:HP2,0)),MATCH(3,FS2:HP2,0),51) -> 4 | HS2: {=_xlfn.SEQUENCE(1000)} -> 1 | HT2: 3 | HU2: =MATCH(RAND(),INDEX(Q_,HT2,0)) -> 3 | HV2: =MATCH(RAND(),INDEX(Q_,HU2,0)) -> 2 | HW2: =MATCH(RAND(),INDEX(Q_,HV2,0)) -> 3 | HX2: =MATCH(RAND(),INDEX(Q_,HW2,0)) -> 3 | HY2: =MATCH(RAND(),INDEX(Q_,HX2,0)) -> 2 | HZ2: =MATCH(RAND(),INDEX(Q_,HY2,0)) -> 2 | IA2: =MATCH(RAND(),INDEX(Q_,HZ2,0)) -> 2 | IB2: =MATCH(RAND(),INDEX(Q_,IA2,0)) -> 2 | ... JR2: =MATCH(RAND(),INDEX(Q_,JQ2,0)) -> 2 | JS2: =IF(ISNUMBER(MATCH(1,HU2:JR2,0)),MATCH(1,HU2:JR2,0),51) -> 14 | JV2: p(1st_class1) | JW2: =COUNTIF(FS2:FS1001,"=1")/N2_ -> 0.432 | JX2: =COUNTIF(HU2:HU1001,"=1")/N2_ -> 0.012 | KD2: Cooper_1st_class1 | KE2: =AVERAGE(first_class1) -> 24.141 | KF2: 95%CI_LB | KG2: =Cooper_1st_class1-1.96*STDEV(first_class1)/SQRT(N2_) -> 23.057415 | KH2: 95%CI_UB | KI2: =Cooper_1st_class1+1.96*STDEV(first_class1)/SQRT(N2_) -> 25.224585
B3: lower_level | C3: 3 | H3: 2 | I3: 1 | J3: 3 | K3: 2 | L3: 2 | M3: 1 | N3: 2 | O3: 2 | P3: 2 | Q3: 2 | R3: 2 | S3: 2 | T3: 1 | U3: 1 | V3: 2 | W3: 2 | X3: 2 | Y3: 3 | Z3: 2 | AA3: 2 | AB3: 2 | AC3: 2 | AD3: 2 | AE3: 3 | AF3: 2 | AG3: 1 | AH3: 1 | AI3: 2 | AJ3: 2 | AK3: 2 | AL3: 2 | AM3: 3 | AN3: 2 | AO3: 2 | AP3: 2 | AQ3: 2 | AR3: 2 | AS3: 2 | AT3: 2 | AU3: 3 | AV3: 3 | AW3: 3 | AX3: 3 | AY3: 2 | AZ3: 2 | BA3: 3 | BB3: 3 | BC3: 2 | BD3: 2 | BE3: 2 | BF3: 3 | BI3: 2 | BJ3: 1 | BK3: 1 | BL3: 1 | BM3: 1 | BN3: 2 | BO3: 2 | BP3: 3 | BQ3: 2 | BR3: 3 | BS3: 3 | BT3: 2 | BU3: 2 | BV3: 2 | BW3: 2 | BX3: 2 | BY3: 3 | BZ3: 3 | CA3: 2 | CB3: 3 | CC3: 3 | CD3: 2 | CE3: 3 | CF3: 2 | CG3: 2 | CH3: 2 | CI3: 2 | CJ3: 3 | CK3: 3 | CL3: 2 | CM3: 2 | CN3: 2 | CO3: 2 | CP3: 2 | CQ3: 2 | CR3: 2 | CS3: 2 | CT3: 2 | CU3: 1 | CV3: 1 | CW3: 2 | CX3: 1 | CY3: 2 | CZ3: 2 | DA3: 2 | DB3: 3 | DC3: 2 | DD3: 3 | DE3: 3 | DF3: 2 | DG3: 3 | DJ3: 2 | DK3: 3 | DL3: 2 | DM3: 2 | DN3: 2 | DO3: 2 | DP3: 2 | DQ3: 1 | DR3: 2 | DS3: 2 | DT3: 2 | DU3: 3 | DV3: 3 | DW3: 2 | DX3: 3 | DY3: 2 | DZ3: 2 | EA3: 3 | EB3: 3 | EC3: 2 | ED3: 3 | EE3: 2 | EF3: 3 | EG3: 2 | EH3: 2 | EI3: 2 | EJ3: 2 | EK3: 2 | EL3: 3 | EM3: 2 | EN3: 2 | EO3: 2 | EP3: 2 | EQ3: 2 | ER3: 2 | ES3: 1 | ET3: 1 | EU3: 2 | EV3: 1 | EW3: 3 | EX3: 2 | EY3: 3 | EZ3: 2 | FA3: 2 | FB3: 3 | FC3: 3 | FD3: 3 | FE3: 2 | FF3: 3 | FG3: 2 | FH3: 2 | FL3: 1 | FM3: =COUNTIF(x50_,"=1")/N2_ -> 0.06 | FQ3: 2 | FR3: 1 | FS3: =MATCH(RAND(),INDEX(Q_,FR3,0)) -> 2 | FT3: =MATCH(RAND(),INDEX(Q_,FS3,0)) -> 2 | FU3: =MATCH(RAND(),INDEX(Q_,FT3,0)) -> 2 | FV3: =MATCH(RAND(),INDEX(Q_,FU3,0)) -> 2 | FW3: =MATCH(RAND(),INDEX(Q_,FV3,0)) -> 2 | FX3: =MATCH(RAND(),INDEX(Q_,FW3,0)) -> 3 | FY3: =MATCH(RAND(),INDEX(Q_,FX3,0)) -> 3 | FZ3: =MATCH(RAND(),INDEX(Q_,FY3,0)) -> 3 | ... HP3: =MATCH(RAND(),INDEX(Q_,HO3,0)) -> 2 | HQ3: =IF(ISNUMBER(MATCH(3,FS3:HP3,0)),MATCH(3,FS3:HP3,0),51) -> 6 | HS3: 2 | HT3: 3 | HU3: =MATCH(RAND(),INDEX(Q_,HT3,0)) -> 2 | HV3: =MATCH(RAND(),INDEX(Q_,HU3,0)) -> 2 | HW3: =MATCH(RAND(),INDEX(Q_,HV3,0)) -> 2 | HX3: =MATCH(RAND(),INDEX(Q_,HW3,0)) -> 3 | HY3: =MATCH(RAND(),INDEX(Q_,HX3,0)) -> 3 | HZ3: =MATCH(RAND(),INDEX(Q_,HY3,0)) -> 3 | IA3: =MATCH(RAND(),INDEX(Q_,HZ3,0)) -> 2 | IB3: =MATCH(RAND(),INDEX(Q_,IA3,0)) -> 3 | ... JR3: =MATCH(RAND(),INDEX(Q_,JQ3,0)) -> 2 | JS3: =IF(ISNUMBER(MATCH(1,HU3:JR3,0)),MATCH(1,HU3:JR3,0),51) -> 45 | JV3: p(2nd_class1) | JW3: =COUNTIF(FT2:FT1001,"=1")/N2_ -> 0.209 | JX3: =COUNTIF(HV2:HV1001,"=1")/N2_ -> 0.037 | KD3: It takes more time for people who are initially in lower class to become an upper class
B4: P | C4: 0.45 | D4: 0.48 | E4: 0.07 | H4: 3 | I4: 1 | J4: 2 | K4: 2 | L4: 2 | M4: 1 | N4: 2 | O4: 1 | P4: 1 | Q4: 3 | R4: 2 | S4: 2 | T4: 2 | U4: 3 | V4: 2 | W4: 2 | X4: 3 | Y4: 2 | Z4: 2 | AA4: 3 | AB4: 2 | AC4: 2 | AD4: 2 | AE4: 2 | AF4: 2 | AG4: 2 | AH4: 1 | AI4: 1 | AJ4: 2 | AK4: 2 | AL4: 3 | AM4: 2 | AN4: 2 | AO4: 2 | AP4: 3 | AQ4: 2 | AR4: 3 | AS4: 2 | AT4: 2 | AU4: 3 | AV4: 3 | AW4: 3 | AX4: 3 | AY4: 2 | AZ4: 2 | BA4: 2 | BB4: 2 | BC4: 2 | BD4: 2 | BE4: 2 | BF4: 2 | BI4: 3 | BJ4: 1 | BK4: 1 | BL4: 2 | BM4: 2 | BN4: 2 | BO4: 2 | BP4: 2 | BQ4: 2 | BR4: 2 | BS4: 3 | BT4: 3 | BU4: 2 | BV4: 2 | BW4: 2 | BX4: 2 | BY4: 2 | BZ4: 2 | CA4: 3 | CB4: 3 | CC4: 3 | CD4: 3 | CE4: 3 | CF4: 3 | CG4: 3 | CH4: 3 | CI4: 2 | CJ4: 3 | CK4: 2 | CL4: 2 | CM4: 2 | CN4: 2 | CO4: 1 | CP4: 1 | CQ4: 2 | CR4: 2 | CS4: 2 | CT4: 3 | CU4: 2 | CV4: 2 | CW4: 1 | CX4: 1 | CY4: 1 | CZ4: 1 | DA4: 2 | DB4: 2 | DC4: 2 | DD4: 2 | DE4: 2 | DF4: 2 | DG4: 3 | DJ4: 3 | DK4: 3 | DL4: 3 | DM4: 3 | DN4: 3 | DO4: 2 | DP4: 2 | DQ4: 3 | DR4: 2 | DS4: 2 | DT4: 2 | DU4: 2 | DV4: 2 | DW4: 1 | DX4: 1 | DY4: 2 | DZ4: 2 | EA4: 3 | EB4: 3 | EC4: 3 | ED4: 2 | EE4: 2 | EF4: 2 | EG4: 2 | EH4: 3 | EI4: 3 | EJ4: 3 | EK4: 2 | EL4: 1 | EM4: 2 | EN4: 2 | EO4: 3 | EP4: 3 | EQ4: 3 | ER4: 2 | ES4: 2 | ET4: 2 | EU4: 2 | EV4: 2 | EW4: 3 | EX4: 3 | EY4: 2 | EZ4: 2 | FA4: 2 | FB4: 2 | FC4: 2 | FD4: 3 | FE4: 3 | FF4: 2 | FG4: 2 | FH4: 2 | FL4: 2 | FM4: =COUNTIF(x50_,"=2")/N2_ -> 0.64 | FQ4: 3 | FR4: 1 | FS4: =MATCH(RAND(),INDEX(Q_,FR4,0)) -> 2 | FT4: =MATCH(RAND(),INDEX(Q_,FS4,0)) -> 2 | FU4: =MATCH(RAND(),INDEX(Q_,FT4,0)) -> 3 | FV4: =MATCH(RAND(),INDEX(Q_,FU4,0)) -> 2 | FW4: =MATCH(RAND(),INDEX(Q_,FV4,0)) -> 2 | FX4: =MATCH(RAND(),INDEX(Q_,FW4,0)) -> 2 | FY4: =MATCH(RAND(),INDEX(Q_,FX4,0)) -> 2 | FZ4: =MATCH(RAND(),INDEX(Q_,FY4,0)) -> 3 | ... HP4: =MATCH(RAND(),INDEX(Q_,HO4,0)) -> 1 | HQ4: =IF(ISNUMBER(MATCH(3,FS4:HP4,0)),MATCH(3,FS4:HP4,0),51) -> 3 | HS4: 3 | HT4: 3 | HU4: =MATCH(RAND(),INDEX(Q_,HT4,0)) -> 3 | HV4: =MATCH(RAND(),INDEX(Q_,HU4,0)) -> 2 | HW4: =MATCH(RAND(),INDEX(Q_,HV4,0)) -> 3 | HX4: =MATCH(RAND(),INDEX(Q_,HW4,0)) -> 3 | HY4: =MATCH(RAND(),INDEX(Q_,HX4,0)) -> 3 | HZ4: =MATCH(RAND(),INDEX(Q_,HY4,0)) -> 3 | IA4: =MATCH(RAND(),INDEX(Q_,HZ4,0)) -> 3 | IB4: =MATCH(RAND(),INDEX(Q_,IA4,0)) -> 2 | ... JR4: =MATCH(RAND(),INDEX(Q_,JQ4,0)) -> 2 | JS4: =IF(ISNUMBER(MATCH(1,HU4:JR4,0)),MATCH(1,HU4:JR4,0),51) -> 42 | JV4: p(3rd_class1) | JW4: =COUNTIF(FU2:FU1001,"=1")/N2_ -> 0.135 | JX4: =COUNTIF(HW2:HW1001,"=1")/N2_ -> 0.037 | KD4: So the society ought to provide more help for people in the lower class, for example, education, tax deduction, and welfare.
C5: 0.05 | D5: 0.7 | E5: 0.25 | H5: 4 | I5: 1 | J5: 1 | K5: 2 | L5: 2 | M5: 2 | N5: 3 | O5: 2 | P5: 3 | Q5: 2 | R5: 2 | S5: 2 | T5: 2 | U5: 3 | V5: 2 | W5: 2 | X5: 2 | Y5: 2 | Z5: 3 | AA5: 2 | AB5: 2 | AC5: 3 | AD5: 2 | AE5: 2 | AF5: 2 | AG5: 1 | AH5: 1 | AI5: 2 | AJ5: 2 | AK5: 2 | AL5: 3 | AM5: 2 | AN5: 3 | AO5: 3 | AP5: 2 | AQ5: 2 | AR5: 2 | AS5: 2 | AT5: 2 | AU5: 1 | AV5: 2 | AW5: 2 | AX5: 2 | AY5: 2 | AZ5: 2 | BA5: 3 | BB5: 3 | BC5: 2 | BD5: 2 | BE5: 1 | BF5: 3 | BI5: 4 | BJ5: 1 | BK5: 2 | BL5: 2 | BM5: 2 | BN5: 2 | BO5: 2 | BP5: 2 | BQ5: 3 | BR5: 2 | BS5: 2 | BT5: 2 | BU5: 2 | BV5: 2 | BW5: 2 | BX5: 1 | BY5: 2 | BZ5: 1 | CA5: 3 | CB5: 2 | CC5: 2 | CD5: 2 | CE5: 2 | CF5: 2 | CG5: 2 | CH5: 2 | CI5: 2 | CJ5: 2 | CK5: 2 | CL5: 1 | CM5: 1 | CN5: 1 | CO5: 2 | CP5: 3 | CQ5: 2 | CR5: 3 | CS5: 2 | CT5: 2 | CU5: 2 | CV5: 2 | CW5: 3 | CX5: 2 | CY5: 3 | CZ5: 2 | DA5: 2 | DB5: 2 | DC5: 2 | DD5: 2 | DE5: 3 | DF5: 3 | DG5: 2 | DJ5: 4 | DK5: 3 | DL5: 2 | DM5: 3 | DN5: 2 | DO5: 1 | DP5: 2 | DQ5: 2 | DR5: 2 | DS5: 2 | DT5: 3 | DU5: 3 | DV5: 3 | DW5: 2 | DX5: 2 | DY5: 2 | DZ5: 2 | EA5: 3 | EB5: 3 | EC5: 2 | ED5: 3 | EE5: 2 | EF5: 2 | EG5: 2 | EH5: 2 | EI5: 3 | EJ5: 2 | EK5: 2 | EL5: 2 | EM5: 2 | EN5: 2 | EO5: 3 | EP5: 3 | EQ5: 2 | ER5: 2 | ES5: 3 | ET5: 2 | EU5: 2 | EV5: 2 | EW5: 3 | EX5: 2 | EY5: 3 | EZ5: 2 | FA5: 2 | FB5: 3 | FC5: 3 | FD5: 3 | FE5: 2 | FF5: 2 | FG5: 3 | FH5: 2 | FL5: 3 | FM5: =COUNTIF(x50_,"=3")/N2_ -> 0.3 | FQ5: 4 | FR5: 1 | FS5: =MATCH(RAND(),INDEX(Q_,FR5,0)) -> 2 | FT5: =MATCH(RAND(),INDEX(Q_,FS5,0)) -> 2 | FU5: =MATCH(RAND(),INDEX(Q_,FT5,0)) -> 2 | FV5: =MATCH(RAND(),INDEX(Q_,FU5,0)) -> 2 | FW5: =MATCH(RAND(),INDEX(Q_,FV5,0)) -> 2 | FX5: =MATCH(RAND(),INDEX(Q_,FW5,0)) -> 2 | FY5: =MATCH(RAND(),INDEX(Q_,FX5,0)) -> 2 | FZ5: =MATCH(RAND(),INDEX(Q_,FY5,0)) -> 2 | ... HP5: =MATCH(RAND(),INDEX(Q_,HO5,0)) -> 2 | HQ5: =IF(ISNUMBER(MATCH(3,FS5:HP5,0)),MATCH(3,FS5:HP5,0),51) -> 12 | HS5: 4 | HT5: 3 | HU5: =MATCH(RAND(),INDEX(Q_,HT5,0)) -> 2 | HV5: =MATCH(RAND(),INDEX(Q_,HU5,0)) -> 2 | HW5: =MATCH(RAND(),INDEX(Q_,HV5,0)) -> 2 | HX5: =MATCH(RAND(),INDEX(Q_,HW5,0)) -> 2 | HY5: =MATCH(RAND(),INDEX(Q_,HX5,0)) -> 3 | HZ5: =MATCH(RAND(),INDEX(Q_,HY5,0)) -> 2 | IA5: =MATCH(RAND(),INDEX(Q_,HZ5,0)) -> 3 | IB5: =MATCH(RAND(),INDEX(Q_,IA5,0)) -> 2 | ... JR5: =MATCH(RAND(),INDEX(Q_,JQ5,0)) -> 2 | JS5: =IF(ISNUMBER(MATCH(1,HU5:JR5,0)),MATCH(1,HU5:JR5,0),51) -> 10 | JV5: p(4th_class1) | JW5: =COUNTIF(FV2:FV1001,"=1")/N2_ -> 0.081 | JX5: =COUNTIF(HX2:HX1001,"=1")/N2_ -> 0.062
C6: 0.01 | D6: 0.5 | E6: 0.49 | H6: 5 | I6: 3 | J6: 3 | K6: 3 | L6: 3 | M6: 3 | N6: 2 | O6: 2 | P6: 2 | Q6: 1 | R6: 2 | S6: 2 | T6: 2 | U6: 2 | V6: 2 | W6: 3 | X6: 2 | Y6: 2 | Z6: 2 | AA6: 2 | AB6: 2 | AC6: 3 | AD6: 2 | AE6: 3 | AF6: 2 | AG6: 2 | AH6: 3 | AI6: 3 | AJ6: 3 | AK6: 2 | AL6: 2 | AM6: 2 | AN6: 3 | AO6: 2 | AP6: 2 | AQ6: 2 | AR6: 3 | AS6: 2 | AT6: 2 | AU6: 2 | AV6: 1 | AW6: 2 | AX6: 2 | AY6: 2 | AZ6: 3 | BA6: 3 | BB6: 3 | BC6: 3 | BD6: 3 | BE6: 2 | BF6: 2 | BI6: 5 | BJ6: 1 | BK6: 2 | BL6: 3 | BM6: 2 | BN6: 3 | BO6: 2 | BP6: 2 | BQ6: 2 | BR6: 3 | BS6: 3 | BT6: 2 | BU6: 3 | BV6: 2 | BW6: 2 | BX6: 2 | BY6: 3 | BZ6: 2 | CA6: 3 | CB6: 3 | CC6: 2 | CD6: 2 | CE6: 2 | CF6: 3 | CG6: 2 | CH6: 3 | CI6: 3 | CJ6: 3 | CK6: 3 | CL6: 2 | CM6: 3 | CN6: 2 | CO6: 2 | CP6: 2 | CQ6: 3 | CR6: 2 | CS6: 2 | CT6: 3 | CU6: 2 | CV6: 3 | CW6: 2 | CX6: 2 | CY6: 3 | CZ6: 3 | DA6: 3 | DB6: 3 | DC6: 3 | DD6: 2 | DE6: 1 | DF6: 2 | DG6: 2 | DJ6: 5 | DK6: 3 | DL6: 3 | DM6: 3 | DN6: 3 | DO6: 3 | DP6: 3 | DQ6: 3 | DR6: 3 | DS6: 3 | DT6: 3 | DU6: 2 | DV6: 2 | DW6: 2 | DX6: 1 | DY6: 1 | DZ6: 1 | EA6: 1 | EB6: 1 | EC6: 1 | ED6: 2 | EE6: 2 | EF6: 2 | EG6: 3 | EH6: 3 | EI6: 3 | EJ6: 3 | EK6: 3 | EL6: 3 | EM6: 3 | EN6: 3 | EO6: 3 | EP6: 2 | EQ6: 2 | ER6: 2 | ES6: 3 | ET6: 3 | EU6: 3 | EV6: 2 | EW6: 2 | EX6: 1 | EY6: 2 | EZ6: 2 | FA6: 2 | FB6: 2 | FC6: 2 | FD6: 2 | FE6: 2 | FF6: 3 | FG6: 3 | FH6: 2 | FQ6: 5 | FR6: 1 | FS6: =MATCH(RAND(),INDEX(Q_,FR6,0)) -> 2 | FT6: =MATCH(RAND(),INDEX(Q_,FS6,0)) -> 2 | FU6: =MATCH(RAND(),INDEX(Q_,FT6,0)) -> 3 | FV6: =MATCH(RAND(),INDEX(Q_,FU6,0)) -> 2 | FW6: =MATCH(RAND(),INDEX(Q_,FV6,0)) -> 3 | FX6: =MATCH(RAND(),INDEX(Q_,FW6,0)) -> 2 | FY6: =MATCH(RAND(),INDEX(Q_,FX6,0)) -> 3 | FZ6: =MATCH(RAND(),INDEX(Q_,FY6,0)) -> 2 | ... HP6: =MATCH(RAND(),INDEX(Q_,HO6,0)) -> 3 | HQ6: =IF(ISNUMBER(MATCH(3,FS6:HP6,0)),MATCH(3,FS6:HP6,0),51) -> 3 | HS6: 5 | HT6: 3 | HU6: =MATCH(RAND(),INDEX(Q_,HT6,0)) -> 2 | HV6: =MATCH(RAND(),INDEX(Q_,HU6,0)) -> 3 | HW6: =MATCH(RAND(),INDEX(Q_,HV6,0)) -> 2 | HX6: =MATCH(RAND(),INDEX(Q_,HW6,0)) -> 2 | HY6: =MATCH(RAND(),INDEX(Q_,HX6,0)) -> 2 | HZ6: =MATCH(RAND(),INDEX(Q_,HY6,0)) -> 2 | IA6: =MATCH(RAND(),INDEX(Q_,HZ6,0)) -> 2 | IB6: =MATCH(RAND(),INDEX(Q_,IA6,0)) -> 1 | ... JR6: =MATCH(RAND(),INDEX(Q_,JQ6,0)) -> 2 | JS6: =IF(ISNUMBER(MATCH(1,HU6:JR6,0)),MATCH(1,HU6:JR6,0),51) -> 8 | JV6: p(5th_class1) | JW6: =COUNTIF(FW2:FW1001,"=1")/N2_ -> 0.064 | JX6: =COUNTIF(HY2:HY1001,"=1")/N2_ -> 0.063
B7: Q | C7: 0 | D7: 0.45 | E7: =C4+D4 -> 0.93 | F7: =C4+D4+E4 -> 1 | H7: 6 | I7: 3 | J7: 3 | K7: 3 | L7: 3 | M7: 3 | N7: 3 | O7: 3 | P7: 2 | Q7: 2 | R7: 2 | S7: 3 | T7: 3 | U7: 2 | V7: 2 | W7: 2 | X7: 2 | Y7: 2 | Z7: 2 | AA7: 2 | AB7: 2 | AC7: 2 | AD7: 2 | AE7: 2 | AF7: 2 | AG7: 2 | AH7: 2 | AI7: 2 | AJ7: 2 | AK7: 3 | AL7: 2 | AM7: 2 | AN7: 2 | AO7: 1 | AP7: 2 | AQ7: 2 | AR7: 2 | AS7: 1 | AT7: 1 | AU7: 2 | AV7: 2 | AW7: 2 | AX7: 2 | AY7: 2 | AZ7: 2 | BA7: 2 | BB7: 3 | BC7: 2 | BD7: 2 | BE7: 2 | BF7: 2 | BI7: 6 | BJ7: 1 | BK7: 2 | BL7: 2 | BM7: 2 | BN7: 3 | BO7: 2 | BP7: 2 | BQ7: 3 | BR7: 2 | BS7: 2 | BT7: 2 | BU7: 2 | BV7: 2 | BW7: 2 | BX7: 2 | BY7: 2 | BZ7: 3 | CA7: 3 | CB7: 3 | CC7: 2 | CD7: 2 | CE7: 2 | CF7: 2 | CG7: 2 | CH7: 2 | CI7: 2 | CJ7: 2 | CK7: 2 | CL7: 1 | CM7: 2 | CN7: 2 | CO7: 2 | CP7: 2 | CQ7: 2 | CR7: 2 | CS7: 3 | CT7: 2 | CU7: 2 | CV7: 2 | CW7: 2 | CX7: 2 | CY7: 2 | CZ7: 2 | DA7: 2 | DB7: 3 | DC7: 2 | DD7: 2 | DE7: 2 | DF7: 2 | DG7: 2 | DJ7: 6 | DK7: 3 | DL7: 3 | DM7: 2 | DN7: 3 | DO7: 3 | DP7: 3 | DQ7: 2 | DR7: 2 | DS7: 3 | DT7: 2 | DU7: 3 | DV7: 3 | DW7: 2 | DX7: 2 | DY7: 2 | DZ7: 2 | EA7: 2 | EB7: 2 | EC7: 3 | ED7: 2 | EE7: 3 | EF7: 2 | EG7: 2 | EH7: 2 | EI7: 2 | EJ7: 2 | EK7: 2 | EL7: 2 | EM7: 2 | EN7: 2 | EO7: 2 | EP7: 2 | EQ7: 2 | ER7: 3 | ES7: 3 | ET7: 2 | EU7: 2 | EV7: 2 | EW7: 2 | EX7: 2 | EY7: 2 | EZ7: 2 | FA7: 3 | FB7: 3 | FC7: 3 | FD7: 2 | FE7: 3 | FF7: 2 | FG7: 2 | FH7: 2 | FQ7: 6 | FR7: 1 | FS7: =MATCH(RAND(),INDEX(Q_,FR7,0)) -> 2 | FT7: =MATCH(RAND(),INDEX(Q_,FS7,0)) -> 2 | FU7: =MATCH(RAND(),INDEX(Q_,FT7,0)) -> 2 | FV7: =MATCH(RAND(),INDEX(Q_,FU7,0)) -> 3 | FW7: =MATCH(RAND(),INDEX(Q_,FV7,0)) -> 2 | FX7: =MATCH(RAND(),INDEX(Q_,FW7,0)) -> 2 | FY7: =MATCH(RAND(),INDEX(Q_,FX7,0)) -> 2 | FZ7: =MATCH(RAND(),INDEX(Q_,FY7,0)) -> 1 | ... HP7: =MATCH(RAND(),INDEX(Q_,HO7,0)) -> 2 | HQ7: =IF(ISNUMBER(MATCH(3,FS7:HP7,0)),MATCH(3,FS7:HP7,0),51) -> 4 | HS7: 6 | HT7: 3 | HU7: =MATCH(RAND(),INDEX(Q_,HT7,0)) -> 2 | HV7: =MATCH(RAND(),INDEX(Q_,HU7,0)) -> 3 | HW7: =MATCH(RAND(),INDEX(Q_,HV7,0)) -> 2 | HX7: =MATCH(RAND(),INDEX(Q_,HW7,0)) -> 2 | HY7: =MATCH(RAND(),INDEX(Q_,HX7,0)) -> 2 | HZ7: =MATCH(RAND(),INDEX(Q_,HY7,0)) -> 3 | IA7: =MATCH(RAND(),INDEX(Q_,HZ7,0)) -> 2 | IB7: =MATCH(RAND(),INDEX(Q_,IA7,0)) -> 2 | ... JR7: =MATCH(RAND(),INDEX(Q_,JQ7,0)) -> 3 | JS7: =IF(ISNUMBER(MATCH(1,HU7:JR7,0)),MATCH(1,HU7:JR7,0),51) -> 21 | JV7: p(6th_class1) | JW7: =COUNTIF(FX2:FX1001,"=1")/N2_ -> 0.055 | JX7: =COUNTIF(HZ2:HZ1001,"=1")/N2_ -> 0.065
C8: 0 | D8: 0.05 | E8: =C5+D5 -> 0.75 | F8: =C5+D5+E5 -> 1 | H8: 7 | I8: 1 | J8: 2 | K8: 2 | L8: 2 | M8: 2 | N8: 2 | O8: 2 | P8: 2 | Q8: 3 | R8: 3 | S8: 3 | T8: 2 | U8: 3 | V8: 3 | W8: 3 | X8: 2 | Y8: 3 | Z8: 2 | AA8: 2 | AB8: 2 | AC8: 3 | AD8: 3 | AE8: 2 | AF8: 2 | AG8: 2 | AH8: 3 | AI8: 3 | AJ8: 3 | AK8: 2 | AL8: 3 | AM8: 2 | AN8: 2 | AO8: 2 | AP8: 3 | AQ8: 2 | AR8: 2 | AS8: 2 | AT8: 2 | AU8: 3 | AV8: 3 | AW8: 3 | AX8: 2 | AY8: 2 | AZ8: 2 | BA8: 2 | BB8: 2 | BC8: 2 | BD8: 3 | BE8: 2 | BF8: 2 | BI8: 7 | BJ8: 1 | BK8: 2 | BL8: 2 | BM8: 2 | BN8: 3 | BO8: 2 | BP8: 2 | BQ8: 3 | BR8: 2 | BS8: 3 | BT8: 2 | BU8: 3 | BV8: 3 | BW8: 3 | BX8: 2 | BY8: 2 | BZ8: 1 | CA8: 1 | CB8: 2 | CC8: 2 | CD8: 2 | CE8: 3 | CF8: 2 | CG8: 2 | CH8: 3 | CI8: 3 | CJ8: 2 | CK8: 3 | CL8: 2 | CM8: 2 | CN8: 2 | CO8: 2 | CP8: 3 | CQ8: 2 | CR8: 3 | CS8: 3 | CT8: 2 | CU8: 2 | CV8: 2 | CW8: 1 | CX8: 1 | CY8: 2 | CZ8: 3 | DA8: 3 | DB8: 2 | DC8: 1 | DD8: 2 | DE8: 3 | DF8: 2 | DG8: 2 | DJ8: 7 | DK8: 3 | DL8: 3 | DM8: 2 | DN8: 3 | DO8: 2 | DP8: 2 | DQ8: 2 | DR8: 2 | DS8: 3 | DT8: 2 | DU8: 3 | DV8: 2 | DW8: 2 | DX8: 2 | DY8: 3 | DZ8: 2 | EA8: 2 | EB8: 2 | EC8: 2 | ED8: 1 | EE8: 2 | EF8: 2 | EG8: 2 | EH8: 3 | EI8: 2 | EJ8: 3 | EK8: 2 | EL8: 2 | EM8: 2 | EN8: 2 | EO8: 2 | EP8: 3 | EQ8: 2 | ER8: 2 | ES8: 3 | ET8: 2 | EU8: 3 | EV8: 2 | EW8: 2 | EX8: 2 | EY8: 2 | EZ8: 2 | FA8: 3 | FB8: 3 | FC8: 2 | FD8: 1 | FE8: 2 | FF8: 1 | FG8: 3 | FH8: 2 | FQ8: 7 | FR8: 1 | FS8: =MATCH(RAND(),INDEX(Q_,FR8,0)) -> 2 | FT8: =MATCH(RAND(),INDEX(Q_,FS8,0)) -> 3 | FU8: =MATCH(RAND(),INDEX(Q_,FT8,0)) -> 2 | FV8: =MATCH(RAND(),INDEX(Q_,FU8,0)) -> 2 | FW8: =MATCH(RAND(),INDEX(Q_,FV8,0)) -> 1 | FX8: =MATCH(RAND(),INDEX(Q_,FW8,0)) -> 1 | FY8: =MATCH(RAND(),INDEX(Q_,FX8,0)) -> 1 | FZ8: =MATCH(RAND(),INDEX(Q_,FY8,0)) -> 2 | ... HP8: =MATCH(RAND(),INDEX(Q_,HO8,0)) -> 2 | HQ8: =IF(ISNUMBER(MATCH(3,FS8:HP8,0)),MATCH(3,FS8:HP8,0),51) -> 2 | HS8: 7 | HT8: 3 | HU8: =MATCH(RAND(),INDEX(Q_,HT8,0)) -> 2 | HV8: =MATCH(RAND(),INDEX(Q_,HU8,0)) -> 2 | HW8: =MATCH(RAND(),INDEX(Q_,HV8,0)) -> 3 | HX8: =MATCH(RAND(),INDEX(Q_,HW8,0)) -> 3 | HY8: =MATCH(RAND(),INDEX(Q_,HX8,0)) -> 2 | HZ8: =MATCH(RAND(),INDEX(Q_,HY8,0)) -> 1 | IA8: =MATCH(RAND(),INDEX(Q_,HZ8,0)) -> 1 | IB8: =MATCH(RAND(),INDEX(Q_,IA8,0)) -> 3 | ... JR8: =MATCH(RAND(),INDEX(Q_,JQ8,0)) -> 2 | JS8: =IF(ISNUMBER(MATCH(1,HU8:JR8,0)),MATCH(1,HU8:JR8,0),51) -> 6 | JV8: p(7th_class1) | JW8: =COUNTIF(FY2:FY1001,"=1")/N2_ -> 0.061 | JX8: =COUNTIF(IA2:IA1001,"=1")/N2_ -> 0.071
C9: 0 | D9: 0.01 | E9: =C6+D6 -> 0.51 | F9: =C6+D6+E6 -> 1 | H9: 8 | I9: 3 | J9: 2 | K9: 2 | L9: 3 | M9: 2 | N9: 2 | O9: 2 | P9: 2 | Q9: 2 | R9: 3 | S9: 2 | T9: 1 | U9: 3 | V9: 3 | W9: 3 | X9: 2 | Y9: 2 | Z9: 3 | AA9: 3 | AB9: 2 | AC9: 2 | AD9: 2 | AE9: 3 | AF9: 2 | AG9: 2 | AH9: 2 | AI9: 2 | AJ9: 2 | AK9: 2 | AL9: 3 | AM9: 3 | AN9: 3 | AO9: 2 | AP9: 2 | AQ9: 2 | AR9: 2 | AS9: 2 | AT9: 2 | AU9: 1 | AV9: 2 | AW9: 3 | AX9: 3 | AY9: 2 | AZ9: 1 | BA9: 1 | BB9: 1 | BC9: 2 | BD9: 2 | BE9: 3 | BF9: 3 | BI9: 8 | BJ9: 1 | BK9: 2 | BL9: 2 | BM9: 2 | BN9: 2 | BO9: 2 | BP9: 3 | BQ9: 2 | BR9: 3 | BS9: 3 | BT9: 3 | BU9: 3 | BV9: 3 | BW9: 2 | BX9: 2 | BY9: 1 | BZ9: 3 | CA9: 2 | CB9: 2 | CC9: 2 | CD9: 2 | CE9: 2 | CF9: 1 | CG9: 1 | CH9: 2 | CI9: 3 | CJ9: 2 | CK9: 2 | CL9: 3 | CM9: 2 | CN9: 2 | CO9: 2 | CP9: 3 | CQ9: 3 | CR9: 3 | CS9: 2 | CT9: 2 | CU9: 2 | CV9: 2 | CW9: 2 | CX9: 3 | CY9: 3 | CZ9: 2 | DA9: 3 | DB9: 3 | DC9: 3 | DD9: 3 | DE9: 2 | DF9: 2 | DG9: 2 | DJ9: 8 | DK9: 3 | DL9: 2 | DM9: 2 | DN9: 3 | DO9: 3 | DP9: 2 | DQ9: 3 | DR9: 1 | DS9: 3 | DT9: 3 | DU9: 2 | DV9: 2 | DW9: 1 | DX9: 2 | DY9: 3 | DZ9: 3 | EA9: 3 | EB9: 2 | EC9: 2 | ED9: 1 | EE9: 2 | EF9: 3 | EG9: 3 | EH9: 2 | EI9: 2 | EJ9: 2 | EK9: 2 | EL9: 2 | EM9: 3 | EN9: 2 | EO9: 3 | EP9: 3 | EQ9: 3 | ER9: 2 | ES9: 2 | ET9: 2 | EU9: 2 | EV9: 2 | EW9: 2 | EX9: 3 | EY9: 2 | EZ9: 3 | FA9: 3 | FB9: 2 | FC9: 2 | FD9: 3 | FE9: 3 | FF9: 1 | FG9: 2 | FH9: 2 | FQ9: 8 | FR9: 1 | FS9: =MATCH(RAND(),INDEX(Q_,FR9,0)) -> 2 | FT9: =MATCH(RAND(),INDEX(Q_,FS9,0)) -> 3 | FU9: =MATCH(RAND(),INDEX(Q_,FT9,0)) -> 3 | FV9: =MATCH(RAND(),INDEX(Q_,FU9,0)) -> 3 | FW9: =MATCH(RAND(),INDEX(Q_,FV9,0)) -> 3 | FX9: =MATCH(RAND(),INDEX(Q_,FW9,0)) -> 3 | FY9: =MATCH(RAND(),INDEX(Q_,FX9,0)) -> 3 | FZ9: =MATCH(RAND(),INDEX(Q_,FY9,0)) -> 2 | ... HP9: =MATCH(RAND(),INDEX(Q_,HO9,0)) -> 3 | HQ9: =IF(ISNUMBER(MATCH(3,FS9:HP9,0)),MATCH(3,FS9:HP9,0),51) -> 2 | HS9: 8 | HT9: 3 | HU9: =MATCH(RAND(),INDEX(Q_,HT9,0)) -> 2 | HV9: =MATCH(RAND(),INDEX(Q_,HU9,0)) -> 2 | HW9: =MATCH(RAND(),INDEX(Q_,HV9,0)) -> 2 | HX9: =MATCH(RAND(),INDEX(Q_,HW9,0)) -> 3 | HY9: =MATCH(RAND(),INDEX(Q_,HX9,0)) -> 3 | HZ9: =MATCH(RAND(),INDEX(Q_,HY9,0)) -> 3 | IA9: =MATCH(RAND(),INDEX(Q_,HZ9,0)) -> 3 | IB9: =MATCH(RAND(),INDEX(Q_,IA9,0)) -> 3 | ... JR9: =MATCH(RAND(),INDEX(Q_,JQ9,0)) -> 2 | JS9: =IF(ISNUMBER(MATCH(1,HU9:JR9,0)),MATCH(1,HU9:JR9,0),51) -> 51 | JV9: p(8th_class1) | JW9: =COUNTIF(FZ2:FZ1001,"=1")/N2_ -> 0.049 | JX9: =COUNTIF(IB2:IB1001,"=1")/N2_ -> 0.069
B10: f0 | C10: 0.5 | D10: 0 | E10: 0.5 | H10: 9 | I10: 3 | J10: 2 | K10: 2 | L10: 1 | M10: 1 | N10: 1 | O10: 2 | P10: 2 | Q10: 2 | R10: 2 | S10: 3 | T10: 2 | U10: 3 | V10: 3 | W10: 3 | X10: 2 | Y10: 3 | Z10: 2 | AA10: 2 | AB10: 2 | AC10: 3 | AD10: 2 | AE10: 2 | AF10: 2 | AG10: 2 | AH10: 3 | AI10: 2 | AJ10: 2 | AK10: 3 | AL10: 3 | AM10: 2 | AN10: 1 | AO10: 2 | AP10: 3 | AQ10: 2 | AR10: 3 | AS10: 3 | AT10: 3 | AU10: 2 | AV10: 2 | AW10: 2 | AX10: 2 | AY10: 2 | AZ10: 2 | BA10: 2 | BB10: 2 | BC10: 3 | BD10: 3 | BE10: 2 | BF10: 2 | BI10: 9 | BJ10: 1 | BK10: 2 | BL10: 2 | BM10: 1 | BN10: 2 | BO10: 2 | BP10: 2 | BQ10: 2 | BR10: 2 | BS10: 2 | BT10: 2 | BU10: 2 | BV10: 2 | BW10: 2 | BX10: 2 | BY10: 2 | BZ10: 2 | CA10: 2 | CB10: 2 | CC10: 2 | CD10: 2 | CE10: 2 | CF10: 3 | CG10: 2 | CH10: 3 | CI10: 2 | CJ10: 2 | CK10: 2 | CL10: 3 | CM10: 2 | CN10: 2 | CO10: 2 | CP10: 3 | CQ10: 3 | CR10: 2 | CS10: 3 | CT10: 3 | CU10: 3 | CV10: 2 | CW10: 2 | CX10: 3 | CY10: 3 | CZ10: 2 | DA10: 2 | DB10: 2 | DC10: 2 | DD10: 3 | DE10: 2 | DF10: 3 | DG10: 3 | DJ10: 9 | DK10: 3 | DL10: 2 | DM10: 3 | DN10: 3 | DO10: 3 | DP10: 2 | DQ10: 2 | DR10: 2 | DS10: 3 | DT10: 3 | DU10: 2 | DV10: 2 | DW10: 2 | DX10: 2 | DY10: 3 | DZ10: 3 | EA10: 3 | EB10: 2 | EC10: 3 | ED10: 3 | EE10: 3 | EF10: 3 | EG10: 3 | EH10: 2 | EI10: 2 | EJ10: 2 | EK10: 2 | EL10: 2 | EM10: 2 | EN10: 1 | EO10: 2 | EP10: 3 | EQ10: 2 | ER10: 2 | ES10: 2 | ET10: 3 | EU10: 2 | EV10: 2 | EW10: 2 | EX10: 3 | EY10: 2 | EZ10: 2 | FA10: 3 | FB10: 2 | FC10: 3 | FD10: 3 | FE10: 3 | FF10: 3 | FG10: 2 | FH10: 2 | FQ10: 9 | FR10: 1 | FS10: =MATCH(RAND(),INDEX(Q_,FR10,0)) -> 1 | FT10: =MATCH(RAND(),INDEX(Q_,FS10,0)) -> 1 | FU10: =MATCH(RAND(),INDEX(Q_,FT10,0)) -> 2 | FV10: =MATCH(RAND(),INDEX(Q_,FU10,0)) -> 2 | FW10: =MATCH(RAND(),INDEX(Q_,FV10,0)) -> 3 | FX10: =MATCH(RAND(),INDEX(Q_,FW10,0)) -> 2 | FY10: =MATCH(RAND(),INDEX(Q_,FX10,0)) -> 2 | FZ10: =MATCH(RAND(),INDEX(Q_,FY10,0)) -> 2 | ... HP10: =MATCH(RAND(),INDEX(Q_,HO10,0)) -> 3 | HQ10: =IF(ISNUMBER(MATCH(3,FS10:HP10,0)),MATCH(3,FS10:HP10,0),51) -> 5 | HS10: 9 | HT10: 3 | HU10: =MATCH(RAND(),INDEX(Q_,HT10,0)) -> 3 | HV10: =MATCH(RAND(),INDEX(Q_,HU10,0)) -> 2 | HW10: =MATCH(RAND(),INDEX(Q_,HV10,0)) -> 3 | HX10: =MATCH(RAND(),INDEX(Q_,HW10,0)) -> 3 | HY10: =MATCH(RAND(),INDEX(Q_,HX10,0)) -> 3 | HZ10: =MATCH(RAND(),INDEX(Q_,HY10,0)) -> 2 | IA10: =MATCH(RAND(),INDEX(Q_,HZ10,0)) -> 2 | IB10: =MATCH(RAND(),INDEX(Q_,IA10,0)) -> 3 | ... JR10: =MATCH(RAND(),INDEX(Q_,JQ10,0)) -> 3 | JS10: =IF(ISNUMBER(MATCH(1,HU10:JR10,0)),MATCH(1,HU10:JR10,0),51) -> 51 | JV10: p(9th_class1) | JW10: =COUNTIF(GA2:GA1001,"=1")/N2_ -> 0.064 | JX10: =COUNTIF(IC2:IC1001,"=1")/N2_ -> 0.069
C11: 1 | D11: 0 | E11: 0 | H11: 10 | I11: 3 | J11: 3 | K11: 2 | L11: 3 | M11: 2 | N11: 2 | O11: 2 | P11: 2 | Q11: 2 | R11: 2 | S11: 2 | T11: 2 | U11: 2 | V11: 2 | W11: 2 | X11: 2 | Y11: 2 | Z11: 2 | AA11: 2 | AB11: 2 | AC11: 3 | AD11: 2 | AE11: 1 | AF11: 2 | AG11: 2 | AH11: 2 | AI11: 3 | AJ11: 3 | AK11: 3 | AL11: 3 | AM11: 2 | AN11: 2 | AO11: 2 | AP11: 3 | AQ11: 2 | AR11: 2 | AS11: 2 | AT11: 2 | AU11: 2 | AV11: 2 | AW11: 3 | AX11: 3 | AY11: 2 | AZ11: 2 | BA11: 2 | BB11: 2 | BC11: 2 | BD11: 2 | BE11: 2 | BF11: 2 | BI11: 10 | BJ11: 1 | BK11: 1 | BL11: 2 | BM11: 2 | BN11: 2 | BO11: 1 | BP11: 2 | BQ11: 2 | BR11: 2 | BS11: 2 | BT11: 2 | BU11: 2 | BV11: 2 | BW11: 2 | BX11: 3 | BY11: 2 | BZ11: 2 | CA11: 2 | CB11: 2 | CC11: 2 | CD11: 2 | CE11: 2 | CF11: 2 | CG11: 3 | CH11: 3 | CI11: 2 | CJ11: 2 | CK11: 2 | CL11: 3 | CM11: 3 | CN11: 3 | CO11: 2 | CP11: 3 | CQ11: 3 | CR11: 2 | CS11: 2 | CT11: 3 | CU11: 2 | CV11: 2 | CW11: 2 | CX11: 3 | CY11: 2 | CZ11: 2 | DA11: 2 | DB11: 3 | DC11: 3 | DD11: 3 | DE11: 2 | DF11: 2 | DG11: 2 | DJ11: 10 | DK11: 3 | DL11: 3 | DM11: 2 | DN11: 2 | DO11: 2 | DP11: 2 | DQ11: 2 | DR11: 3 | DS11: 1 | DT11: 2 | DU11: 2 | DV11: 2 | DW11: 2 | DX11: 2 | DY11: 2 | DZ11: 2 | EA11: 2 | EB11: 2 | EC11: 3 | ED11: 3 | EE11: 2 | EF11: 2 | EG11: 2 | EH11: 2 | EI11: 1 | EJ11: 1 | EK11: 2 | EL11: 2 | EM11: 2 | EN11: 2 | EO11: 2 | EP11: 2 | EQ11: 2 | ER11: 3 | ES11: 2 | ET11: 3 | EU11: 2 | EV11: 2 | EW11: 3 | EX11: 2 | EY11: 2 | EZ11: 2 | FA11: 3 | FB11: 2 | FC11: 2 | FD11: 2 | FE11: 2 | FF11: 2 | FG11: 2 | FH11: 2 | FQ11: 10 | FR11: 1 | FS11: =MATCH(RAND(),INDEX(Q_,FR11,0)) -> 1 | FT11: =MATCH(RAND(),INDEX(Q_,FS11,0)) -> 1 | FU11: =MATCH(RAND(),INDEX(Q_,FT11,0)) -> 1 | FV11: =MATCH(RAND(),INDEX(Q_,FU11,0)) -> 2 | FW11: =MATCH(RAND(),INDEX(Q_,FV11,0)) -> 2 | FX11: =MATCH(RAND(),INDEX(Q_,FW11,0)) -> 2 | FY11: =MATCH(RAND(),INDEX(Q_,FX11,0)) -> 1 | FZ11: =MATCH(RAND(),INDEX(Q_,FY11,0)) -> 1 | ... HP11: =MATCH(RAND(),INDEX(Q_,HO11,0)) -> 1 | HQ11: =IF(ISNUMBER(MATCH(3,FS11:HP11,0)),MATCH(3,FS11:HP11,0),51) -> 11 | HS11: 10 | HT11: 3 | HU11: =MATCH(RAND(),INDEX(Q_,HT11,0)) -> 2 | HV11: =MATCH(RAND(),INDEX(Q_,HU11,0)) -> 3 | HW11: =MATCH(RAND(),INDEX(Q_,HV11,0)) -> 2 | HX11: =MATCH(RAND(),INDEX(Q_,HW11,0)) -> 2 | HY11: =MATCH(RAND(),INDEX(Q_,HX11,0)) -> 2 | HZ11: =MATCH(RAND(),INDEX(Q_,HY11,0)) -> 2 | IA11: =MATCH(RAND(),INDEX(Q_,HZ11,0)) -> 3 | IB11: =MATCH(RAND(),INDEX(Q_,IA11,0)) -> 3 | ... JR11: =MATCH(RAND(),INDEX(Q_,JQ11,0)) -> 2 | JS11: =IF(ISNUMBER(MATCH(1,HU11:JR11,0)),MATCH(1,HU11:JR11,0),51) -> 51 | JV11: p(10th_class1) | JW11: =COUNTIF(GB2:GB1001,"=1")/N2_ -> 0.066 | JX11: =COUNTIF(ID2:ID1001,"=1")/N2_ -> 0.059
C12: 0 | D12: 0 | E12: 1 | H12: 11 | I12: 1 | J12: 1 | K12: 2 | L12: 2 | M12: 1 | N12: 1 | O12: 1 | P12: 2 | Q12: 3 | R12: 2 | S12: 2 | T12: 2 | U12: 2 | V12: 2 | W12: 2 | X12: 2 | Y12: 1 | Z12: 2 | AA12: 2 | AB12: 2 | AC12: 3 | AD12: 3 | AE12: 3 | AF12: 2 | AG12: 2 | AH12: 2 | AI12: 2 | AJ12: 2 | AK12: 2 | AL12: 3 | AM12: 2 | AN12: 2 | AO12: 2 | AP12: 2 | AQ12: 2 | AR12: 3 | AS12: 2 | AT12: 2 | AU12: 3 | AV12: 3 | AW12: 3 | AX12: 2 | AY12: 3 | AZ12: 3 | BA12: 3 | BB12: 2 | BC12: 2 | BD12: 3 | BE12: 3 | BF12: 3 | BI12: 11 | BJ12: 1 | BK12: 1 | BL12: 2 | BM12: 2 | BN12: 3 | BO12: 3 | BP12: 2 | BQ12: 2 | BR12: 3 | BS12: 3 | BT12: 3 | BU12: 3 | BV12: 3 | BW12: 2 | BX12: 2 | BY12: 2 | BZ12: 2 | CA12: 2 | CB12: 2 | CC12: 2 | CD12: 2 | CE12: 3 | CF12: 2 | CG12: 2 | CH12: 2 | CI12: 2 | CJ12: 2 | CK12: 2 | CL12: 3 | CM12: 2 | CN12: 3 | CO12: 2 | CP12: 3 | CQ12: 2 | CR12: 3 | CS12: 2 | CT12: 3 | CU12: 3 | CV12: 3 | CW12: 3 | CX12: 3 | CY12: 3 | CZ12: 2 | DA12: 3 | DB12: 3 | DC12: 3 | DD12: 2 | DE12: 3 | DF12: 2 | DG12: 2 | DJ12: 11 | DK12: 3 | DL12: 3 | DM12: 3 | DN12: 3 | DO12: 2 | DP12: 2 | DQ12: 2 | DR12: 3 | DS12: 2 | DT12: 2 | DU12: 2 | DV12: 2 | DW12: 2 | DX12: 2 | DY12: 2 | DZ12: 2 | EA12: 2 | EB12: 2 | EC12: 2 | ED12: 2 | EE12: 2 | EF12: 2 | EG12: 2 | EH12: 2 | EI12: 2 | EJ12: 3 | EK12: 3 | EL12: 3 | EM12: 3 | EN12: 3 | EO12: 2 | EP12: 2 | EQ12: 2 | ER12: 2 | ES12: 3 | ET12: 3 | EU12: 3 | EV12: 3 | EW12: 3 | EX12: 3 | EY12: 3 | EZ12: 2 | FA12: 3 | FB12: 2 | FC12: 2 | FD12: 2 | FE12: 2 | FF12: 3 | FG12: 3 | FH12: 3 | FQ12: 11 | FR12: 1 | FS12: =MATCH(RAND(),INDEX(Q_,FR12,0)) -> 2 | FT12: =MATCH(RAND(),INDEX(Q_,FS12,0)) -> 2 | FU12: =MATCH(RAND(),INDEX(Q_,FT12,0)) -> 2 | FV12: =MATCH(RAND(),INDEX(Q_,FU12,0)) -> 3 | FW12: =MATCH(RAND(),INDEX(Q_,FV12,0)) -> 2 | FX12: =MATCH(RAND(),INDEX(Q_,FW12,0)) -> 2 | FY12: =MATCH(RAND(),INDEX(Q_,FX12,0)) -> 2 | FZ12: =MATCH(RAND(),INDEX(Q_,FY12,0)) -> 2 | ... HP12: =MATCH(RAND(),INDEX(Q_,HO12,0)) -> 2 | HQ12: =IF(ISNUMBER(MATCH(3,FS12:HP12,0)),MATCH(3,FS12:HP12,0),51) -> 4 | HS12: 11 | HT12: 3 | HU12: =MATCH(RAND(),INDEX(Q_,HT12,0)) -> 2 | HV12: =MATCH(RAND(),INDEX(Q_,HU12,0)) -> 2 | HW12: =MATCH(RAND(),INDEX(Q_,HV12,0)) -> 2 | HX12: =MATCH(RAND(),INDEX(Q_,HW12,0)) -> 2 | HY12: =MATCH(RAND(),INDEX(Q_,HX12,0)) -> 2 | HZ12: =MATCH(RAND(),INDEX(Q_,HY12,0)) -> 3 | IA12: =MATCH(RAND(),INDEX(Q_,HZ12,0)) -> 2 | IB12: =MATCH(RAND(),INDEX(Q_,IA12,0)) -> 2 | ... JR12: =MATCH(RAND(),INDEX(Q_,JQ12,0)) -> 3 | JS12: =IF(ISNUMBER(MATCH(1,HU12:JR12,0)),MATCH(1,HU12:JR12,0),51) -> 17
B13: F0 | C13: 0 | D13: 0.5 | E13: =C10+D10 -> 0.5 | F13: =C10+D10+E10 -> 1 | H13: 12 | I13: 3 | J13: 3 | K13: 2 | L13: 2 | M13: 1 | N13: 2 | O13: 2 | P13: 3 | Q13: 3 | R13: 1 | S13: 2 | T13: 2 | U13: 2 | V13: 2 | W13: 2 | X13: 2 | Y13: 3 | Z13: 2 | AA13: 2 | AB13: 2 | AC13: 3 | AD13: 2 | AE13: 1 | AF13: 2 | AG13: 2 | AH13: 1 | AI13: 2 | AJ13: 3 | AK13: 2 | AL13: 1 | AM13: 3 | AN13: 2 | AO13: 2 | AP13: 2 | AQ13: 2 | AR13: 3 | AS13: 2 | AT13: 2 | AU13: 2 | AV13: 3 | AW13: 3 | AX13: 2 | AY13: 2 | AZ13: 3 | BA13: 3 | BB13: 2 | BC13: 3 | BD13: 2 | BE13: 3 | BF13: 2 | BI13: 12 | BJ13: 1 | BK13: 1 | BL13: 1 | BM13: 1 | BN13: 2 | BO13: 2 | BP13: 2 | BQ13: 2 | BR13: 2 | BS13: 2 | BT13: 2 | BU13: 2 | BV13: 2 | BW13: 2 | BX13: 2 | BY13: 2 | BZ13: 3 | CA13: 3 | CB13: 2 | CC13: 2 | CD13: 3 | CE13: 3 | CF13: 2 | CG13: 3 | CH13: 3 | CI13: 2 | CJ13: 2 | CK13: 2 | CL13: 2 | CM13: 3 | CN13: 2 | CO13: 3 | CP13: 3 | CQ13: 2 | CR13: 2 | CS13: 3 | CT13: 2 | CU13: 2 | CV13: 2 | CW13: 2 | CX13: 2 | CY13: 2 | CZ13: 2 | DA13: 3 | DB13: 3 | DC13: 3 | DD13: 2 | DE13: 2 | DF13: 2 | DG13: 2 | DJ13: 12 | DK13: 3 | DL13: 3 | DM13: 3 | DN13: 2 | DO13: 2 | DP13: 2 | DQ13: 2 | DR13: 2 | DS13: 2 | DT13: 2 | DU13: 3 | DV13: 3 | DW13: 2 | DX13: 2 | DY13: 3 | DZ13: 3 | EA13: 3 | EB13: 3 | EC13: 2 | ED13: 3 | EE13: 3 | EF13: 2 | EG13: 2 | EH13: 2 | EI13: 2 | EJ13: 2 | EK13: 3 | EL13: 3 | EM13: 3 | EN13: 3 | EO13: 3 | EP13: 1 | EQ13: 2 | ER13: 2 | ES13: 3 | ET13: 3 | EU13: 3 | EV13: 2 | EW13: 2 | EX13: 3 | EY13: 2 | EZ13: 2 | FA13: 1 | FB13: 1 | FC13: 1 | FD13: 2 | FE13: 2 | FF13: 2 | FG13: 2 | FH13: 2 | FQ13: 12 | FR13: 1 | FS13: =MATCH(RAND(),INDEX(Q_,FR13,0)) -> 1 | FT13: =MATCH(RAND(),INDEX(Q_,FS13,0)) -> 1 | FU13: =MATCH(RAND(),INDEX(Q_,FT13,0)) -> 1 | FV13: =MATCH(RAND(),INDEX(Q_,FU13,0)) -> 1 | FW13: =MATCH(RAND(),INDEX(Q_,FV13,0)) -> 1 | FX13: =MATCH(RAND(),INDEX(Q_,FW13,0)) -> 3 | FY13: =MATCH(RAND(),INDEX(Q_,FX13,0)) -> 1 | FZ13: =MATCH(RAND(),INDEX(Q_,FY13,0)) -> 3 | ... HP13: =MATCH(RAND(),INDEX(Q_,HO13,0)) -> 3 | HQ13: =IF(ISNUMBER(MATCH(3,FS13:HP13,0)),MATCH(3,FS13:HP13,0),51) -> 6 | HS13: 12 | HT13: 3 | HU13: =MATCH(RAND(),INDEX(Q_,HT13,0)) -> 3 | HV13: =MATCH(RAND(),INDEX(Q_,HU13,0)) -> 2 | HW13: =MATCH(RAND(),INDEX(Q_,HV13,0)) -> 2 | HX13: =MATCH(RAND(),INDEX(Q_,HW13,0)) -> 3 | HY13: =MATCH(RAND(),INDEX(Q_,HX13,0)) -> 3 | HZ13: =MATCH(RAND(),INDEX(Q_,HY13,0)) -> 3 | IA13: =MATCH(RAND(),INDEX(Q_,HZ13,0)) -> 2 | IB13: =MATCH(RAND(),INDEX(Q_,IA13,0)) -> 2 | ... JR13: =MATCH(RAND(),INDEX(Q_,JQ13,0)) -> 3 | JS13: =IF(ISNUMBER(MATCH(1,HU13:JR13,0)),MATCH(1,HU13:JR13,0),51) -> 25
C14: 0 | D14: 1 | E14: =C11+D11 -> 1 | F14: =C11+D11+E11 -> 1 | H14: 13 | I14: 1 | J14: 1 | K14: 3 | L14: 2 | M14: 2 | N14: 3 | O14: 2 | P14: 2 | Q14: 2 | R14: 3 | S14: 2 | T14: 2 | U14: 2 | V14: 2 | W14: 2 | X14: 2 | Y14: 2 | Z14: 2 | AA14: 2 | AB14: 2 | AC14: 2 | AD14: 2 | AE14: 3 | AF14: 2 | AG14: 2 | AH14: 2 | AI14: 1 | AJ14: 2 | AK14: 2 | AL14: 2 | AM14: 1 | AN14: 1 | AO14: 1 | AP14: 1 | AQ14: 2 | AR14: 3 | AS14: 3 | AT14: 2 | AU14: 3 | AV14: 2 | AW14: 3 | AX14: 2 | AY14: 2 | AZ14: 2 | BA14: 2 | BB14: 2 | BC14: 3 | BD14: 3 | BE14: 3 | BF14: 3 | BI14: 13 | BJ14: 1 | BK14: 1 | BL14: 2 | BM14: 2 | BN14: 2 | BO14: 2 | BP14: 2 | BQ14: 2 | BR14: 3 | BS14: 3 | BT14: 3 | BU14: 2 | BV14: 2 | BW14: 2 | BX14: 2 | BY14: 2 | BZ14: 2 | CA14: 2 | CB14: 3 | CC14: 3 | CD14: 3 | CE14: 2 | CF14: 3 | CG14: 3 | CH14: 3 | CI14: 3 | CJ14: 3 | CK14: 2 | CL14: 2 | CM14: 2 | CN14: 3 | CO14: 1 | CP14: 1 | CQ14: 1 | CR14: 2 | CS14: 2 | CT14: 2 | CU14: 2 | CV14: 2 | CW14: 2 | CX14: 3 | CY14: 2 | CZ14: 2 | DA14: 2 | DB14: 2 | DC14: 1 | DD14: 1 | DE14: 2 | DF14: 2 | DG14: 3 | DJ14: 13 | DK14: 3 | DL14: 3 | DM14: 3 | DN14: 2 | DO14: 2 | DP14: 2 | DQ14: 2 | DR14: 2 | DS14: 3 | DT14: 2 | DU14: 3 | DV14: 2 | DW14: 3 | DX14: 2 | DY14: 2 | DZ14: 2 | EA14: 1 | EB14: 2 | EC14: 1 | ED14: 1 | EE14: 3 | EF14: 2 | EG14: 2 | EH14: 2 | EI14: 3 | EJ14: 3 | EK14: 2 | EL14: 3 | EM14: 2 | EN14: 2 | EO14: 2 | EP14: 2 | EQ14: 2 | ER14: 2 | ES14: 3 | ET14: 3 | EU14: 2 | EV14: 2 | EW14: 2 | EX14: 2 | EY14: 2 | EZ14: 2 | FA14: 3 | FB14: 2 | FC14: 2 | FD14: 2 | FE14: 2 | FF14: 2 | FG14: 2 | FH14: 2 | FQ14: 13 | FR14: 1 | FS14: =MATCH(RAND(),INDEX(Q_,FR14,0)) -> 2 | FT14: =MATCH(RAND(),INDEX(Q_,FS14,0)) -> 2 | FU14: =MATCH(RAND(),INDEX(Q_,FT14,0)) -> 2 | FV14: =MATCH(RAND(),INDEX(Q_,FU14,0)) -> 2 | FW14: =MATCH(RAND(),INDEX(Q_,FV14,0)) -> 2 | FX14: =MATCH(RAND(),INDEX(Q_,FW14,0)) -> 2 | FY14: =MATCH(RAND(),INDEX(Q_,FX14,0)) -> 2 | FZ14: =MATCH(RAND(),INDEX(Q_,FY14,0)) -> 2 | ... HP14: =MATCH(RAND(),INDEX(Q_,HO14,0)) -> 2 | HQ14: =IF(ISNUMBER(MATCH(3,FS14:HP14,0)),MATCH(3,FS14:HP14,0),51) -> 10 | HS14: 13 | HT14: 3 | HU14: =MATCH(RAND(),INDEX(Q_,HT14,0)) -> 3 | HV14: =MATCH(RAND(),INDEX(Q_,HU14,0)) -> 3 | HW14: =MATCH(RAND(),INDEX(Q_,HV14,0)) -> 2 | HX14: =MATCH(RAND(),INDEX(Q_,HW14,0)) -> 3 | HY14: =MATCH(RAND(),INDEX(Q_,HX14,0)) -> 3 | HZ14: =MATCH(RAND(),INDEX(Q_,HY14,0)) -> 2 | IA14: =MATCH(RAND(),INDEX(Q_,HZ14,0)) -> 3 | IB14: =MATCH(RAND(),INDEX(Q_,IA14,0)) -> 2 | ... JR14: =MATCH(RAND(),INDEX(Q_,JQ14,0)) -> 2 | JS14: =IF(ISNUMBER(MATCH(1,HU14:JR14,0)),MATCH(1,HU14:JR14,0),51) -> 51
C15: 0 | D15: 0 | E15: =C12+D12 -> 0 | F15: =C12+D12+E12 -> 1 | H15: 14 | I15: 1 | J15: 1 | K15: 1 | L15: 2 | M15: 2 | N15: 2 | O15: 2 | P15: 2 | Q15: 2 | R15: 2 | S15: 2 | T15: 3 | U15: 2 | V15: 2 | W15: 2 | X15: 2 | Y15: 3 | Z15: 3 | AA15: 2 | AB15: 2 | AC15: 3 | AD15: 2 | AE15: 3 | AF15: 2 | AG15: 2 | AH15: 2 | AI15: 3 | AJ15: 2 | AK15: 2 | AL15: 3 | AM15: 3 | AN15: 2 | AO15: 2 | AP15: 3 | AQ15: 3 | AR15: 3 | AS15: 2 | AT15: 2 | AU15: 2 | AV15: 2 | AW15: 3 | AX15: 2 | AY15: 2 | AZ15: 2 | BA15: 3 | BB15: 3 | BC15: 3 | BD15: 3 | BE15: 3 | BF15: 2 | BI15: 14 | BJ15: 1 | BK15: 2 | BL15: 2 | BM15: 2 | BN15: 2 | BO15: 2 | BP15: 2 | BQ15: 2 | BR15: 2 | BS15: 2 | BT15: 3 | BU15: 2 | BV15: 2 | BW15: 2 | BX15: 3 | BY15: 2 | BZ15: 2 | CA15: 2 | CB15: 2 | CC15: 2 | CD15: 1 | CE15: 1 | CF15: 2 | CG15: 2 | CH15: 2 | CI15: 2 | CJ15: 2 | CK15: 3 | CL15: 2 | CM15: 2 | CN15: 2 | CO15: 2 | CP15: 2 | CQ15: 3 | CR15: 3 | CS15: 2 | CT15: 1 | CU15: 1 | CV15: 1 | CW15: 1 | CX15: 3 | CY15: 2 | CZ15: 2 | DA15: 2 | DB15: 1 | DC15: 1 | DD15: 2 | DE15: 2 | DF15: 3 | DG15: 2 | DJ15: 14 | DK15: 3 | DL15: 3 | DM15: 2 | DN15: 3 | DO15: 3 | DP15: 3 | DQ15: 3 | DR15: 2 | DS15: 2 | DT15: 2 | DU15: 2 | DV15: 3 | DW15: 2 | DX15: 2 | DY15: 3 | DZ15: 2 | EA15: 2 | EB15: 3 | EC15: 3 | ED15: 3 | EE15: 2 | EF15: 2 | EG15: 2 | EH15: 2 | EI15: 2 | EJ15: 2 | EK15: 3 | EL15: 3 | EM15: 3 | EN15: 2 | EO15: 2 | EP15: 2 | EQ15: 2 | ER15: 3 | ES15: 2 | ET15: 2 | EU15: 2 | EV15: 3 | EW15: 3 | EX15: 3 | EY15: 3 | EZ15: 2 | FA15: 1 | FB15: 1 | FC15: 1 | FD15: 1 | FE15: 2 | FF15: 2 | FG15: 2 | FH15: 2 | FQ15: 14 | FR15: 1 | FS15: =MATCH(RAND(),INDEX(Q_,FR15,0)) -> 1 | FT15: =MATCH(RAND(),INDEX(Q_,FS15,0)) -> 1 | FU15: =MATCH(RAND(),INDEX(Q_,FT15,0)) -> 2 | FV15: =MATCH(RAND(),INDEX(Q_,FU15,0)) -> 2 | FW15: =MATCH(RAND(),INDEX(Q_,FV15,0)) -> 2 | FX15: =MATCH(RAND(),INDEX(Q_,FW15,0)) -> 3 | FY15: =MATCH(RAND(),INDEX(Q_,FX15,0)) -> 3 | FZ15: =MATCH(RAND(),INDEX(Q_,FY15,0)) -> 2 | ... HP15: =MATCH(RAND(),INDEX(Q_,HO15,0)) -> 2 | HQ15: =IF(ISNUMBER(MATCH(3,FS15:HP15,0)),MATCH(3,FS15:HP15,0),51) -> 6 | HS15: 14 | HT15: 3 | HU15: =MATCH(RAND(),INDEX(Q_,HT15,0)) -> 3 | HV15: =MATCH(RAND(),INDEX(Q_,HU15,0)) -> 3 | HW15: =MATCH(RAND(),INDEX(Q_,HV15,0)) -> 3 | HX15: =MATCH(RAND(),INDEX(Q_,HW15,0)) -> 3 | HY15: =MATCH(RAND(),INDEX(Q_,HX15,0)) -> 3 | HZ15: =MATCH(RAND(),INDEX(Q_,HY15,0)) -> 2 | IA15: =MATCH(RAND(),INDEX(Q_,HZ15,0)) -> 3 | IB15: =MATCH(RAND(),INDEX(Q_,IA15,0)) -> 2 | ... JR15: =MATCH(RAND(),INDEX(Q_,JQ15,0)) -> 3 | JS15: =IF(ISNUMBER(MATCH(1,HU15:JR15,0)),MATCH(1,HU15:JR15,0),51) -> 30
B16: T | C16: 50 | H16: 15 | I16: 1 | J16: 2 | K16: 3 | L16: 3 | M16: 2 | N16: 2 | O16: 2 | P16: 2 | Q16: 2 | R16: 2 | S16: 2 | T16: 2 | U16: 2 | V16: 3 | W16: 2 | X16: 2 | Y16: 2 | Z16: 2 | AA16: 2 | AB16: 2 | AC16: 2 | AD16: 2 | AE16: 3 | AF16: 2 | AG16: 2 | AH16: 3 | AI16: 3 | AJ16: 2 | AK16: 2 | AL16: 2 | AM16: 3 | AN16: 2 | AO16: 2 | AP16: 3 | AQ16: 2 | AR16: 2 | AS16: 1 | AT16: 2 | AU16: 1 | AV16: 1 | AW16: 2 | AX16: 2 | AY16: 3 | AZ16: 2 | BA16: 2 | BB16: 2 | BC16: 3 | BD16: 3 | BE16: 3 | BF16: 3 | BI16: 15 | BJ16: 1 | BK16: 3 | BL16: 3 | BM16: 2 | BN16: 2 | BO16: 2 | BP16: 3 | BQ16: 3 | BR16: 2 | BS16: 2 | BT16: 2 | BU16: 2 | BV16: 1 | BW16: 1 | BX16: 1 | BY16: 2 | BZ16: 2 | CA16: 2 | CB16: 2 | CC16: 3 | CD16: 3 | CE16: 2 | CF16: 3 | CG16: 3 | CH16: 2 | CI16: 3 | CJ16: 3 | CK16: 2 | CL16: 2 | CM16: 3 | CN16: 3 | CO16: 3 | CP16: 2 | CQ16: 3 | CR16: 2 | CS16: 3 | CT16: 2 | CU16: 1 | CV16: 1 | CW16: 2 | CX16: 2 | CY16: 2 | CZ16: 2 | DA16: 3 | DB16: 2 | DC16: 2 | DD16: 3 | DE16: 3 | DF16: 3 | DG16: 3 | DJ16: 15 | DK16: 3 | DL16: 3 | DM16: 3 | DN16: 2 | DO16: 2 | DP16: 2 | DQ16: 2 | DR16: 3 | DS16: 2 | DT16: 3 | DU16: 3 | DV16: 3 | DW16: 2 | DX16: 3 | DY16: 2 | DZ16: 2 | EA16: 2 | EB16: 3 | EC16: 2 | ED16: 3 | EE16: 2 | EF16: 2 | EG16: 2 | EH16: 2 | EI16: 2 | EJ16: 2 | EK16: 2 | EL16: 1 | EM16: 1 | EN16: 3 | EO16: 3 | EP16: 2 | EQ16: 3 | ER16: 3 | ES16: 2 | ET16: 2 | EU16: 3 | EV16: 2 | EW16: 2 | EX16: 2 | EY16: 3 | EZ16: 2 | FA16: 2 | FB16: 2 | FC16: 2 | FD16: 2 | FE16: 2 | FF16: 2 | FG16: 2 | FH16: 3 | FQ16: 15 | FR16: 1 | FS16: =MATCH(RAND(),INDEX(Q_,FR16,0)) -> 2 | FT16: =MATCH(RAND(),INDEX(Q_,FS16,0)) -> 2 | FU16: =MATCH(RAND(),INDEX(Q_,FT16,0)) -> 2 | FV16: =MATCH(RAND(),INDEX(Q_,FU16,0)) -> 2 | FW16: =MATCH(RAND(),INDEX(Q_,FV16,0)) -> 2 | FX16: =MATCH(RAND(),INDEX(Q_,FW16,0)) -> 3 | FY16: =MATCH(RAND(),INDEX(Q_,FX16,0)) -> 3 | FZ16: =MATCH(RAND(),INDEX(Q_,FY16,0)) -> 2 | ... HP16: =MATCH(RAND(),INDEX(Q_,HO16,0)) -> 2 | HQ16: =IF(ISNUMBER(MATCH(3,FS16:HP16,0)),MATCH(3,FS16:HP16,0),51) -> 6 | HS16: 15 | HT16: 3 | HU16: =MATCH(RAND(),INDEX(Q_,HT16,0)) -> 3 | HV16: =MATCH(RAND(),INDEX(Q_,HU16,0)) -> 3 | HW16: =MATCH(RAND(),INDEX(Q_,HV16,0)) -> 3 | HX16: =MATCH(RAND(),INDEX(Q_,HW16,0)) -> 3 | HY16: =MATCH(RAND(),INDEX(Q_,HX16,0)) -> 2 | HZ16: =MATCH(RAND(),INDEX(Q_,HY16,0)) -> 2 | IA16: =MATCH(RAND(),INDEX(Q_,HZ16,0)) -> 2 | IB16: =MATCH(RAND(),INDEX(Q_,IA16,0)) -> 2 | ... JR16: =MATCH(RAND(),INDEX(Q_,JQ16,0)) -> 3 | JS16: =IF(ISNUMBER(MATCH(1,HU16:JR16,0)),MATCH(1,HU16:JR16,0),51) -> 38
B17: N2 | C17: 1000 | H17: 16 | I17: 1 | J17: 2 | K17: 2 | L17: 2 | M17: 2 | N17: 2 | O17: 3 | P17: 3 | Q17: 2 | R17: 3 | S17: 3 | T17: 2 | U17: 2 | V17: 2 | W17: 2 | X17: 2 | Y17: 1 | Z17: 2 | AA17: 3 | AB17: 2 | AC17: 2 | AD17: 2 | AE17: 1 | AF17: 2 | AG17: 3 | AH17: 3 | AI17: 2 | AJ17: 2 | AK17: 2 | AL17: 3 | AM17: 2 | AN17: 3 | AO17: 2 | AP17: 3 | AQ17: 3 | AR17: 2 | AS17: 2 | AT17: 2 | AU17: 2 | AV17: 2 | AW17: 2 | AX17: 3 | AY17: 3 | AZ17: 3 | BA17: 3 | BB17: 3 | BC17: 3 | BD17: 2 | BE17: 2 | BF17: 2 | BI17: 16 | BJ17: 1 | BK17: 3 | BL17: 3 | BM17: 3 | BN17: 3 | BO17: 2 | BP17: 2 | BQ17: 2 | BR17: 3 | BS17: 2 | BT17: 2 | BU17: 2 | BV17: 2 | BW17: 2 | BX17: 3 | BY17: 3 | BZ17: 3 | CA17: 3 | CB17: 2 | CC17: 2 | CD17: 3 | CE17: 2 | CF17: 2 | CG17: 2 | CH17: 2 | CI17: 3 | CJ17: 3 | CK17: 2 | CL17: 3 | CM17: 3 | CN17: 2 | CO17: 2 | CP17: 2 | CQ17: 2 | CR17: 2 | CS17: 2 | CT17: 3 | CU17: 3 | CV17: 2 | CW17: 2 | CX17: 3 | CY17: 3 | CZ17: 2 | DA17: 2 | DB17: 2 | DC17: 2 | DD17: 2 | DE17: 2 | DF17: 2 | DG17: 2 | DJ17: 16 | DK17: 3 | DL17: 2 | DM17: 3 | DN17: 2 | DO17: 2 | DP17: 2 | DQ17: 1 | DR17: 2 | DS17: 2 | DT17: 1 | DU17: 1 | DV17: 2 | DW17: 2 | DX17: 2 | DY17: 3 | DZ17: 3 | EA17: 2 | EB17: 3 | EC17: 3 | ED17: 2 | EE17: 3 | EF17: 3 | EG17: 3 | EH17: 2 | EI17: 2 | EJ17: 2 | EK17: 2 | EL17: 2 | EM17: 2 | EN17: 1 | EO17: 1 | EP17: 2 | EQ17: 2 | ER17: 2 | ES17: 2 | ET17: 2 | EU17: 2 | EV17: 3 | EW17: 2 | EX17: 3 | EY17: 3 | EZ17: 3 | FA17: 2 | FB17: 2 | FC17: 2 | FD17: 2 | FE17: 2 | FF17: 3 | FG17: 2 | FH17: 2 | FQ17: 16 | FR17: 1 | FS17: =MATCH(RAND(),INDEX(Q_,FR17,0)) -> 2 | FT17: =MATCH(RAND(),INDEX(Q_,FS17,0)) -> 2 | FU17: =MATCH(RAND(),INDEX(Q_,FT17,0)) -> 2 | FV17: =MATCH(RAND(),INDEX(Q_,FU17,0)) -> 2 | FW17: =MATCH(RAND(),INDEX(Q_,FV17,0)) -> 2 | FX17: =MATCH(RAND(),INDEX(Q_,FW17,0)) -> 3 | FY17: =MATCH(RAND(),INDEX(Q_,FX17,0)) -> 3 | FZ17: =MATCH(RAND(),INDEX(Q_,FY17,0)) -> 3 | ... HP17: =MATCH(RAND(),INDEX(Q_,HO17,0)) -> 3 | HQ17: =IF(ISNUMBER(MATCH(3,FS17:HP17,0)),MATCH(3,FS17:HP17,0),51) -> 6 | HS17: 16 | HT17: 3 | HU17: =MATCH(RAND(),INDEX(Q_,HT17,0)) -> 2 | HV17: =MATCH(RAND(),INDEX(Q_,HU17,0)) -> 2 | HW17: =MATCH(RAND(),INDEX(Q_,HV17,0)) -> 2 | HX17: =MATCH(RAND(),INDEX(Q_,HW17,0)) -> 3 | HY17: =MATCH(RAND(),INDEX(Q_,HX17,0)) -> 2 | HZ17: =MATCH(RAND(),INDEX(Q_,HY17,0)) -> 2 | IA17: =MATCH(RAND(),INDEX(Q_,HZ17,0)) -> 2 | IB17: =MATCH(RAND(),INDEX(Q_,IA17,0)) -> 2 | ... JR17: =MATCH(RAND(),INDEX(Q_,JQ17,0)) -> 2 | JS17: =IF(ISNUMBER(MATCH(1,HU17:JR17,0)),MATCH(1,HU17:JR17,0),51) -> 17
H18: 17 | I18: 3 | J18: 3 | K18: 3 | L18: 2 | M18: 2 | N18: 3 | O18: 3 | P18: 2 | Q18: 3 | R18: 2 | S18: 2 | T18: 2 | U18: 2 | V18: 2 | W18: 2 | X18: 3 | Y18: 3 | Z18: 2 | AA18: 3 | AB18: 3 | AC18: 2 | AD18: 2 | AE18: 2 | AF18: 2 | AG18: 2 | AH18: 2 | AI18: 2 | AJ18: 2 | AK18: 3 | AL18: 3 | AM18: 2 | AN18: 2 | AO18: 3 | AP18: 3 | AQ18: 2 | AR18: 3 | AS18: 3 | AT18: 2 | AU18: 2 | AV18: 3 | AW18: 2 | AX18: 2 | AY18: 2 | AZ18: 2 | BA18: 2 | BB18: 2 | BC18: 2 | BD18: 2 | BE18: 2 | BF18: 3 | BI18: 17 | BJ18: 1 | BK18: 1 | BL18: 2 | BM18: 2 | BN18: 2 | BO18: 2 | BP18: 2 | BQ18: 2 | BR18: 2 | BS18: 2 | BT18: 2 | BU18: 2 | BV18: 3 | BW18: 2 | BX18: 2 | BY18: 2 | BZ18: 1 | CA18: 1 | CB18: 2 | CC18: 3 | CD18: 2 | CE18: 3 | CF18: 2 | CG18: 2 | CH18: 2 | CI18: 2 | CJ18: 2 | CK18: 2 | CL18: 2 | CM18: 3 | CN18: 3 | CO18: 2 | CP18: 3 | CQ18: 2 | CR18: 2 | CS18: 2 | CT18: 2 | CU18: 2 | CV18: 2 | CW18: 3 | CX18: 3 | CY18: 2 | CZ18: 2 | DA18: 2 | DB18: 2 | DC18: 3 | DD18: 3 | DE18: 2 | DF18: 2 | DG18: 3 | DJ18: 17 | DK18: 3 | DL18: 3 | DM18: 3 | DN18: 3 | DO18: 3 | DP18: 2 | DQ18: 2 | DR18: 2 | DS18: 3 | DT18: 3 | DU18: 2 | DV18: 2 | DW18: 2 | DX18: 2 | DY18: 3 | DZ18: 2 | EA18: 3 | EB18: 2 | EC18: 2 | ED18: 2 | EE18: 3 | EF18: 2 | EG18: 1 | EH18: 2 | EI18: 2 | EJ18: 2 | EK18: 2 | EL18: 2 | EM18: 3 | EN18: 3 | EO18: 2 | EP18: 1 | EQ18: 1 | ER18: 2 | ES18: 2 | ET18: 2 | EU18: 3 | EV18: 2 | EW18: 2 | EX18: 2 | EY18: 1 | EZ18: 2 | FA18: 2 | FB18: 2 | FC18: 2 | FD18: 2 | FE18: 2 | FF18: 2 | FG18: 2 | FH18: 3 | FQ18: 17 | FR18: 1 | FS18: =MATCH(RAND(),INDEX(Q_,FR18,0)) -> 2 | FT18: =MATCH(RAND(),INDEX(Q_,FS18,0)) -> 2 | FU18: =MATCH(RAND(),INDEX(Q_,FT18,0)) -> 3 | FV18: =MATCH(RAND(),INDEX(Q_,FU18,0)) -> 2 | FW18: =MATCH(RAND(),INDEX(Q_,FV18,0)) -> 2 | FX18: =MATCH(RAND(),INDEX(Q_,FW18,0)) -> 3 | FY18: =MATCH(RAND(),INDEX(Q_,FX18,0)) -> 2 | FZ18: =MATCH(RAND(),INDEX(Q_,FY18,0)) -> 2 | ... HP18: =MATCH(RAND(),INDEX(Q_,HO18,0)) -> 3 | HQ18: =IF(ISNUMBER(MATCH(3,FS18:HP18,0)),MATCH(3,FS18:HP18,0),51) -> 3 | HS18: 17 | HT18: 3 | HU18: =MATCH(RAND(),INDEX(Q_,HT18,0)) -> 2 | HV18: =MATCH(RAND(),INDEX(Q_,HU18,0)) -> 3 | HW18: =MATCH(RAND(),INDEX(Q_,HV18,0)) -> 2 | HX18: =MATCH(RAND(),INDEX(Q_,HW18,0)) -> 2 | HY18: =MATCH(RAND(),INDEX(Q_,HX18,0)) -> 2 | HZ18: =MATCH(RAND(),INDEX(Q_,HY18,0)) -> 2 | IA18: =MATCH(RAND(),INDEX(Q_,HZ18,0)) -> 2 | IB18: =MATCH(RAND(),INDEX(Q_,IA18,0)) -> 2 | ... JR18: =MATCH(RAND(),INDEX(Q_,JQ18,0)) -> 3 | JS18: =IF(ISNUMBER(MATCH(1,HU18:JR18,0)),MATCH(1,HU18:JR18,0),51) -> 51
H19: 18 | I19: 1 | J19: 1 | K19: 1 | L19: 2 | M19: 1 | N19: 2 | O19: 2 | P19: 2 | Q19: 3 | R19: 3 | S19: 3 | T19: 2 | U19: 3 | V19: 3 | W19: 3 | X19: 3 | Y19: 3 | Z19: 2 | AA19: 2 | AB19: 2 | AC19: 3 | AD19: 2 | AE19: 2 | AF19: 2 | AG19: 2 | AH19: 2 | AI19: 2 | AJ19: 2 | AK19: 2 | AL19: 3 | AM19: 3 | AN19: 2 | AO19: 2 | AP19: 3 | AQ19: 2 | AR19: 2 | AS19: 2 | AT19: 2 | AU19: 3 | AV19: 3 | AW19: 2 | AX19: 2 | AY19: 3 | AZ19: 3 | BA19: 2 | BB19: 2 | BC19: 2 | BD19: 2 | BE19: 2 | BF19: 3 | BI19: 18 | BJ19: 1 | BK19: 2 | BL19: 2 | BM19: 2 | BN19: 2 | BO19: 2 | BP19: 2 | BQ19: 2 | BR19: 2 | BS19: 3 | BT19: 2 | BU19: 2 | BV19: 2 | BW19: 2 | BX19: 2 | BY19: 2 | BZ19: 1 | CA19: 2 | CB19: 2 | CC19: 3 | CD19: 3 | CE19: 1 | CF19: 2 | CG19: 3 | CH19: 2 | CI19: 2 | CJ19: 2 | CK19: 2 | CL19: 3 | CM19: 3 | CN19: 3 | CO19: 3 | CP19: 3 | CQ19: 3 | CR19: 3 | CS19: 2 | CT19: 2 | CU19: 2 | CV19: 2 | CW19: 2 | CX19: 2 | CY19: 2 | CZ19: 2 | DA19: 2 | DB19: 3 | DC19: 2 | DD19: 2 | DE19: 3 | DF19: 3 | DG19: 1 | DJ19: 18 | DK19: 3 | DL19: 2 | DM19: 2 | DN19: 2 | DO19: 2 | DP19: 3 | DQ19: 1 | DR19: 2 | DS19: 3 | DT19: 3 | DU19: 3 | DV19: 3 | DW19: 2 | DX19: 2 | DY19: 2 | DZ19: 3 | EA19: 3 | EB19: 2 | EC19: 3 | ED19: 2 | EE19: 2 | EF19: 2 | EG19: 2 | EH19: 2 | EI19: 2 | EJ19: 2 | EK19: 2 | EL19: 2 | EM19: 2 | EN19: 2 | EO19: 2 | EP19: 2 | EQ19: 2 | ER19: 2 | ES19: 3 | ET19: 2 | EU19: 2 | EV19: 2 | EW19: 3 | EX19: 2 | EY19: 2 | EZ19: 2 | FA19: 2 | FB19: 2 | FC19: 2 | FD19: 2 | FE19: 2 | FF19: 2 | FG19: 2 | FH19: 2 | FQ19: 18 | FR19: 1 | FS19: =MATCH(RAND(),INDEX(Q_,FR19,0)) -> 2 | FT19: =MATCH(RAND(),INDEX(Q_,FS19,0)) -> 3 | FU19: =MATCH(RAND(),INDEX(Q_,FT19,0)) -> 3 | FV19: =MATCH(RAND(),INDEX(Q_,FU19,0)) -> 3 | FW19: =MATCH(RAND(),INDEX(Q_,FV19,0)) -> 3 | FX19: =MATCH(RAND(),INDEX(Q_,FW19,0)) -> 2 | FY19: =MATCH(RAND(),INDEX(Q_,FX19,0)) -> 3 | FZ19: =MATCH(RAND(),INDEX(Q_,FY19,0)) -> 3 | ... HP19: =MATCH(RAND(),INDEX(Q_,HO19,0)) -> 3 | HQ19: =IF(ISNUMBER(MATCH(3,FS19:HP19,0)),MATCH(3,FS19:HP19,0),51) -> 2 | HS19: 18 | HT19: 3 | HU19: =MATCH(RAND(),INDEX(Q_,HT19,0)) -> 2 | HV19: =MATCH(RAND(),INDEX(Q_,HU19,0)) -> 3 | HW19: =MATCH(RAND(),INDEX(Q_,HV19,0)) -> 3 | HX19: =MATCH(RAND(),INDEX(Q_,HW19,0)) -> 3 | HY19: =MATCH(RAND(),INDEX(Q_,HX19,0)) -> 2 | HZ19: =MATCH(RAND(),INDEX(Q_,HY19,0)) -> 3 | IA19: =MATCH(RAND(),INDEX(Q_,HZ19,0)) -> 3 | IB19: =MATCH(RAND(),INDEX(Q_,IA19,0)) -> 3 | ... JR19: =MATCH(RAND(),INDEX(Q_,JQ19,0)) -> 3 | JS19: =IF(ISNUMBER(MATCH(1,HU19:JR19,0)),MATCH(1,HU19:JR19,0),51) -> 51
A20: QUESTION GUIDE — analytical purpose of each output block | H20: 19 | I20: 1 | J20: 1 | K20: 1 | L20: 1 | M20: 2 | N20: 2 | O20: 2 | P20: 2 | Q20: 2 | R20: 2 | S20: 2 | T20: 2 | U20: 2 | V20: 2 | W20: 2 | X20: 2 | Y20: 3 | Z20: 3 | AA20: 2 | AB20: 2 | AC20: 2 | AD20: 2 | AE20: 2 | AF20: 2 | AG20: 2 | AH20: 2 | AI20: 2 | AJ20: 2 | AK20: 2 | AL20: 2 | AM20: 2 | AN20: 2 | AO20: 2 | AP20: 2 | AQ20: 2 | AR20: 2 | AS20: 2 | AT20: 2 | AU20: 3 | AV20: 3 | AW20: 2 | AX20: 2 | AY20: 2 | AZ20: 2 | BA20: 2 | BB20: 1 | BC20: 1 | BD20: 1 | BE20: 2 | BF20: 2 | BI20: 19 | BJ20: 1 | BK20: 1 | BL20: 1 | BM20: 2 | BN20: 2 | BO20: 2 | BP20: 2 | BQ20: 2 | BR20: 2 | BS20: 2 | BT20: 2 | BU20: 3 | BV20: 2 | BW20: 3 | BX20: 3 | BY20: 3 | BZ20: 3 | CA20: 3 | CB20: 3 | CC20: 2 | CD20: 2 | CE20: 3 | CF20: 2 | CG20: 3 | CH20: 2 | CI20: 2 | CJ20: 2 | CK20: 2 | CL20: 3 | CM20: 2 | CN20: 3 | CO20: 2 | CP20: 3 | CQ20: 3 | CR20: 2 | CS20: 3 | CT20: 2 | CU20: 2 | CV20: 2 | CW20: 1 | CX20: 2 | CY20: 2 | CZ20: 2 | DA20: 2 | DB20: 2 | DC20: 2 | DD20: 2 | DE20: 1 | DF20: 2 | DG20: 2 | DJ20: 19 | DK20: 3 | DL20: 3 | DM20: 3 | DN20: 3 | DO20: 3 | DP20: 3 | DQ20: 2 | DR20: 2 | DS20: 2 | DT20: 2 | DU20: 2 | DV20: 1 | DW20: 2 | DX20: 2 | DY20: 2 | DZ20: 2 | EA20: 3 | EB20: 2 | EC20: 2 | ED20: 1 | EE20: 1 | EF20: 1 | EG20: 2 | EH20: 2 | EI20: 2 | EJ20: 2 | EK20: 2 | EL20: 2 | EM20: 2 | EN20: 2 | EO20: 2 | EP20: 1 | EQ20: 2 | ER20: 2 | ES20: 2 | ET20: 3 | EU20: 2 | EV20: 2 | EW20: 2 | EX20: 3 | EY20: 3 | EZ20: 2 | FA20: 2 | FB20: 2 | FC20: 3 | FD20: 3 | FE20: 3 | FF20: 2 | FG20: 2 | FH20: 2 | FK20: When f0=[1,0,0] | FQ20: 19 | FR20: 1 | FS20: =MATCH(RAND(),INDEX(Q_,FR20,0)) -> 2 | FT20: =MATCH(RAND(),INDEX(Q_,FS20,0)) -> 3 | FU20: =MATCH(RAND(),INDEX(Q_,FT20,0)) -> 3 | FV20: =MATCH(RAND(),INDEX(Q_,FU20,0)) -> 2 | FW20: =MATCH(RAND(),INDEX(Q_,FV20,0)) -> 3 | FX20: =MATCH(RAND(),INDEX(Q_,FW20,0)) -> 2 | FY20: =MATCH(RAND(),INDEX(Q_,FX20,0)) -> 3 | FZ20: =MATCH(RAND(),INDEX(Q_,FY20,0)) -> 2 | ... HP20: =MATCH(RAND(),INDEX(Q_,HO20,0)) -> 3 | HQ20: =IF(ISNUMBER(MATCH(3,FS20:HP20,0)),MATCH(3,FS20:HP20,0),51) -> 2 | HS20: 19 | HT20: 3 | HU20: =MATCH(RAND(),INDEX(Q_,HT20,0)) -> 3 | HV20: =MATCH(RAND(),INDEX(Q_,HU20,0)) -> 2 | HW20: =MATCH(RAND(),INDEX(Q_,HV20,0)) -> 3 | HX20: =MATCH(RAND(),INDEX(Q_,HW20,0)) -> 3 | HY20: =MATCH(RAND(),INDEX(Q_,HX20,0)) -> 2 | HZ20: =MATCH(RAND(),INDEX(Q_,HY20,0)) -> 2 | IA20: =MATCH(RAND(),INDEX(Q_,HZ20,0)) -> 3 | IB20: =MATCH(RAND(),INDEX(Q_,IA20,0)) -> 3 | ... JR20: =MATCH(RAND(),INDEX(Q_,JQ20,0)) -> 2 | JS20: =IF(ISNUMBER(MATCH(1,HU20:JR20,0)),MATCH(1,HU20:JR20,0),51) -> 51
