Workbook
Name AOZ.mu: Model!#REF!
Name AOZ.sd: Model!#REF!
Name App.usage: Model!$BO$2:$BO$1001
Name AU.a: Model!$C$18
Name AU.b: Model!$C$19
Name average.demand: Model!$P$2
Name Average.order.size: Model!$BQ$2:$BQ$1001
Name average.profit: Model!$P$3
Name C0: Model!#REF!
Name CP: Model!#REF!
Name d.mu: Model!$C$10
Name d.sd: Model!$C$11
Name demand: Model!$G$2:$G$1001
Name Demand.3: Model!$BP$2:$BP$1001
Name demand.i: Model!$AK$2:$AK$1001
Name Ed: Model!$C$6
Name IR.a: Model!$C$7
Name IR.b: Model!$C$8
Name IR.effect: Model!$AI$2:$AI$1001
Name Labor.cost: Model!$BN$2:$BN$1001
Name LC.mu: Model!$C$16
Name LC.sd: Model!$C$17
Name N: Model!$C$14
Name new.profit: Model!$BS$2:$BS$1001
Name new.revenue: Model!$BR$2:$BR$1001
Name OR: Model!$C$13
Name p.revenue.i: Model!$AP$2:$AP$1001
Name P0: Model!$C$2
Name PR: Model!#REF!
Name price.change: Model!$AJ$2:$AJ$1001
Name profit: Model!$BR$2:$BR$1001
Name Q0: Model!$C$3
Name s.revenue.i: Model!$AM$2:$AM$1001
Name sale: Model!$H$2:$H$1001
Name sales_revenues: Model!$I$2:$I$1001
Name sales.i: Model!$AL$2:$AL$1001
Name SC0: Model!$C$4
Name SCP: Model!$C$5
Name total_cost: Model!$J$2:$J$1001
Name total.cost.i: Model!$AN$2:$AN$1001
Name total.profit: Model!$K$2:$K$1001
Name total.profit.i: Model!$AO$2:$AO$1001

Sheet Model
A1: Input | E1: Simulation 1 | F1: time | G1: demand | H1: sale | I1: sales revenues | J1: total cost | K1: total.profit | L1: potential revenue | N1: Output | Q1: 95% CI | T1: Data table 1 | U1: Run (1=baseline) | V1: Mean demand (cups) | W1: Mean profit ($) | Y1: Month | Z1: Demand (cups) | AA1: Profit ($) | AC1: Simution 2 | AD1: ASSUMPTIONS & UNCERTAINTY | AH1: time | AI1: IR.effect | AJ1: change.price | AK1: demand.i | AL1: sales.i | AM1: s.revenue.i | AN1: total.cost.i | AO1: total.profit.i | AP1: p.revenue.i | AR1: Output | AU1: 95% CI | AX1: Data Table 2 | AY1: month | AZ1: price | BA1: demand | BB1: profit | BD1: Month | BE1: Demand (cups) | BF1: Profit ($) | BH1: Simulation 3 | BI1: ASSUMPTIONS & OUTCOMES | BM1: Time | BN1: Labor.cost | BO1: App.usage | BP1: Demand.3 | BQ1: Coffee.price | BR1: new.revenue | BS1: new.profit | BT1: Profit.change | BU1: Output | BX1: 95% CI | CA1: data table | CB1: month | CC1: app usage | CD1: labor cost | CE1: profit | CG1: 12-MONTH OPERATING SCENARIO
A2: Starting price of a cup of coffee | B2: P0 | C2: 4 | F2: 1 | G2: =INT(MAX(0,_xlfn.NORM.INV(RAND(),d.mu,d.sd))) -> 8861 | H2: =IF(demand<Q0,demand,Q0) -> 8861 | I2: =sale*P0*(1+SCP) -> 42532.8 | J2: =Q0*SC0*(1+SCP) -> 30000 | K2: {=sales_revenues-total_cost} -> 12532.8 | L2: =(total.profit-OR)/OR -> -0.16448 | O2: average.demand | P2: =AVERAGE(demand) -> 7919.141 | Q2: =P2+1.96*STDEV(demand)/SQRT(N) -> 7982.9434 | R2: =P2-1.96*STDEV(demand)/SQRT(N) -> 7855.3386 | U2: 1 | V2: =P2 -> 7919.141 | W2: =P3 -> 7971.8928 | Y2: 1 | Z2: =G2 -> 8861 | AA2: =K2 -> 12532.8 | AD2: Metric | AE2: Value | AF2: Interpretation | AH2: {=_xlfn.SEQUENCE(N)} -> 1 | AI2: =(IR.a+(IR.b-IR.a)*RAND()+1) -> 1.0295975 | AJ2: =IR.effect*P0*(1+SCP) -> 4.9420681 | AK2: =INT(Q0*(1+Ed*(price.change-P0)/P0)) -> 7173 | AL2: =IF(demand.i<Q0,demand.i,Q0) -> 7173 | AM2: =sales.i*price.change -> 35449.454 | AN2: =(SC0*(1+SCP)*IR.effect)*Q0 -> 30887.926 | AO2: =s.revenue.i-total.cost.i -> 4561.5288 | AP2: =(total.profit.i-OR)/OR -> -0.69589808 | AS2: average price | AT2: =AVERAGE(price.change) -> 4.9660889 | AU2: =AT2+1.96*STDEV(price.change)/SQRT(N) -> 4.968715 | AV2: =AT2-1.96*STDEV(price.change)/SQRT(N) -> 4.9634627 | AY2: 1 | AZ2: =AT2 -> 4.9660889 | BA2: =AT3 -> 7101.235 | BB2: =AT4 -> 4221.9285 | BD2: 1 | BE2: =AK2 -> 7173 | BF2: =AO2 -> 4561.5288 | BI2: Metric | BJ2: Value | BK2: Interpretation | BM2: {=_xlfn.SEQUENCE(N)} -> 1 | BN2: =IF(BO2<=0.5,LC.mu,MIN(LC.mu,MAX(0,_xlfn.NORM.INV(RAND(),$C$20,LC.sd)))) -> 1915.9541 | BO2: =BETAINV(RAND(),AU.a,AU.b) -> 0.78494812 | BP2: =MAX(0,INT(Q0*(1+Ed*(BQ2-P0)/P0))) -> 14336 | BQ2: =P0*BN2/LC.mu -> 2.5546055 | BR2: =BQ2*BP2 -> 36622.824 | BS2: =BR2-BN2 -> 34706.87 | BT2: =(BS2-$C$21)/$C$21 -> -0.061976493 | BV2: average app usage | BW2: =AVERAGE(App.usage) -> 0.61939565 | BX2: =BW2+1.96*STDEV(App.usage)/SQRT(N) -> 0.62919683 | BY2: =BW2-1.96*STDEV(App.usage)/SQRT(N) -> 0.60959448 | CB2: 1 | CC2: =AVERAGE(Sim3_Replications!B2:B1001) -> 0.61245463 | CD2: =AVERAGE(Sim3_Replications!C2:C1001) -> 2265.9784 | CE2: =AVERAGE(Sim3_Replications!F2:F1001) -> 34953.907 | CG2: Month | CH2: App adoption | CI2: Demand | CJ2: Profit
A3: Starting quantity of coffee sold per month | B3: Q0 | C3: 10000 | F3: 2 | G3: =INT(MAX(0,_xlfn.NORM.INV(RAND(),d.mu,d.sd))) -> 7224 | H3: =IF(demand<Q0,demand,Q0) -> 7224 | I3: =sale*P0*(1+SCP) -> 34675.2 | J3: =Q0*SC0*(1+SCP) -> 30000 | K3: 4675.2 | L3: =(total.profit-OR)/OR -> -0.68832 | O3: average.profit | P3: =AVERAGE(total.profit) -> 7971.8928 | Q3: =P3+1.96*STDEV(total.profit)/SQRT(N) -> 8272.4163 | R3: =P3-1.96*STDEV(total.profit)/SQRT(N) -> 7671.3693 | U3: 2 | V3: 8020.043 | W3: 8454.4944 | Y3: 2 | Z3: =G3 -> 7224 | AA3: =K3 -> 4675.2 | AD3: Baseline price ($) | AE3: =P0 -> 4 | AF3: Pre-pandemic $4.00; NOT Simulation 1's $4.80 | AH3: 2 | AI3: =(IR.a+(IR.b-IR.a)*RAND()+1) -> 1.0274839 | AJ3: =IR.effect*P0*(1+SCP) -> 4.9319225 | AK3: =INT(Q0*(1+Ed*(price.change-P0)/P0)) -> 7204 | AL3: =IF(demand.i<Q0,demand.i,Q0) -> 7204 | AM3: =sales.i*price.change -> 35529.57 | AN3: =(SC0*(1+SCP)*IR.effect)*Q0 -> 30824.516 | AO3: =s.revenue.i-total.cost.i -> 4705.0541 | AP3: =(total.profit.i-OR)/OR -> -0.68632973 | AS3: average demand | AT3: =AVERAGE(demand.i) -> 7101.235 | AU3: =AT3+1.96*STDEV(demand.i)/SQRT(N) -> 7109.1132 | AV3: =AT3-1.96*STDEV(demand.i)/SQRT(N) -> 7093.3568 | AY3: 2 | AZ3: 4.9666276 | BA3: 7099.605 | BB3: 4214.402 | BD3: 2 | BE3: =AK3 -> 7204 | BF3: =AO3 -> 4705.0541 | BI3: Baseline price ($) | BJ3: =P0 -> 4 | BK3: Pre-pandemic price | BM3: 2 | BN3: =IF(BO3<=0.5,LC.mu,MIN(LC.mu,MAX(0,_xlfn.NORM.INV(RAND(),$C$20,LC.sd)))) -> 2387.5316 | BO3: =BETAINV(RAND(),AU.a,AU.b) -> 0.77397719 | BP3: =MAX(0,INT(Q0*(1+Ed*(BQ3-P0)/P0))) -> 12449 | BQ3: =P0*BN3/LC.mu -> 3.1833755 | BR3: =BQ3*BP3 -> 39629.841 | BS3: =BR3-BN3 -> 37242.31 | BT3: =(BS3-$C$21)/$C$21 -> 0.006548908 | BV3: average profit | BW3: =AVERAGE(new.profit) -> 34451.739 | BX3: =BW3+1.96*STDEV(new.profit)/SQRT(N) -> 34707.364 | BY3: =BW3-1.96*STDEV(new.profit)/SQRT(N) -> 34196.114 | CB3: 2 | CC3: =AVERAGE(Sim3_Replications!B1002:B2001) -> 0.60950262 | CD3: =AVERAGE(Sim3_Replications!C1002:C2001) -> 2222.1722 | CE3: =AVERAGE(Sim3_Replications!F1002:F2001) -> 34676.254 | CG3: 1 | CH3: =BO2 -> 0.78494812 | CI3: =BP2 -> 14336 | CJ3: =BS2 -> 34706.87
A4: Starting supply chain cost per cups | B4: SC0 | C4: 2.5 | F4: 3 | G4: =INT(MAX(0,_xlfn.NORM.INV(RAND(),d.mu,d.sd))) -> 5931 | H4: =IF(demand<Q0,demand,Q0) -> 5931 | I4: =sale*P0*(1+SCP) -> 28468.8 | J4: =Q0*SC0*(1+SCP) -> 30000 | K4: -1531.2 | L4: =(total.profit-OR)/OR -> -1.10208 | U4: 3 | V4: 7989.149 | W4: 8315.1744 | Y4: 3 | Z4: =G4 -> 5931 | AA4: =K4 -> -1531.2 | AD4: Baseline demand (cups) | AE4: =Q0 -> 10000 | AF4: Pre-pandemic 10,000 cups | AH4: 3 | AI4: =(IR.a+(IR.b-IR.a)*RAND()+1) -> 1.0210219 | AJ4: =IR.effect*P0*(1+SCP) -> 4.9009052 | AK4: =INT(Q0*(1+Ed*(price.change-P0)/P0)) -> 7297 | AL4: =IF(demand.i<Q0,demand.i,Q0) -> 7297 | AM4: =sales.i*price.change -> 35761.905 | AN4: =(SC0*(1+SCP)*IR.effect)*Q0 -> 30630.658 | AO4: =s.revenue.i-total.cost.i -> 5131.2478 | AP4: =(total.profit.i-OR)/OR -> -0.65791681 | AS4: average profit | AT4: =AVERAGE(total.profit.i) -> 4221.9285 | AU4: =AT4+1.96*STDEV(total.profit.i)/SQRT(N) -> 4258.8326 | AV4: =AT4-1.96*STDEV(total.profit.i)/SQRT(N) -> 4185.0243 | AY4: 3 | AZ4: 4.967599 | BA4: 7096.69 | BB4: 4200.6902 | BD4: 3 | BE4: =AK4 -> 7297 | BF4: =AO4 -> 5131.2478 | BI4: Baseline demand | BJ4: =Q0 -> 10000 | BK4: No sales cap | BM4: 3 | BN4: =IF(BO4<=0.5,LC.mu,MIN(LC.mu,MAX(0,_xlfn.NORM.INV(RAND(),$C$20,LC.sd)))) -> 3000 | BO4: =BETAINV(RAND(),AU.a,AU.b) -> 0.36781661 | BP4: =MAX(0,INT(Q0*(1+Ed*(BQ4-P0)/P0))) -> 10000 | BQ4: =P0*BN4/LC.mu -> 4 | BR4: =BQ4*BP4 -> 40000 | BS4: =BR4-BN4 -> 37000 | BT4: =(BS4-$C$21)/$C$21 -> 0 | BV4: average labor cost | BW4: =AVERAGE(Labor.cost) -> 2210.3529 | BX4: =BW4+1.96*STDEV(Labor.cost)/SQRT(N) -> 2249.4228 | BY4: =BW4-1.96*STDEV(Labor.cost)/SQRT(N) -> 2171.2829 | CB4: 3 | CC4: =AVERAGE(Sim3_Replications!B2002:B3001) -> 0.6225937 | CD4: =AVERAGE(Sim3_Replications!C2002:C3001) -> 2222.6335 | CE4: =AVERAGE(Sim3_Replications!F2002:F3001) -> 34699.566 | CG4: 2 | CH4: =BO3 -> 0.77397719 | CI4: =BP3 -> 12449 | CJ4: =BS3 -> 37242.31
A5: Percent increase in the cost of supply chain per cup | B5: SCP | C5: 0.2 | F5: 4 | G5: =INT(MAX(0,_xlfn.NORM.INV(RAND(),d.mu,d.sd))) -> 9229 | H5: =IF(demand<Q0,demand,Q0) -> 9229 | I5: =sale*P0*(1+SCP) -> 44299.2 | J5: =Q0*SC0*(1+SCP) -> 30000 | K5: 14299.2 | L5: =(total.profit-OR)/OR -> -0.04672 | U5: 4 | V5: 8077.937 | W5: 8723.0736 | Y5: 4 | Z5: =G5 -> 9229 | AA5: =K5 -> 14299.2 | AD5: Signed price elasticity | AE5: =Ed -> -1.2 | AF5: Negative sign: price up, demand down | AH5: 4 | AI5: =(IR.a+(IR.b-IR.a)*RAND()+1) -> 1.0366125 | AJ5: =IR.effect*P0*(1+SCP) -> 4.9757402 | AK5: =INT(Q0*(1+Ed*(price.change-P0)/P0)) -> 7072 | AL5: =IF(demand.i<Q0,demand.i,Q0) -> 7072 | AM5: =sales.i*price.change -> 35188.434 | AN5: =(SC0*(1+SCP)*IR.effect)*Q0 -> 31098.376 | AO5: =s.revenue.i-total.cost.i -> 4090.0584 | AP5: =(total.profit.i-OR)/OR -> -0.72732944 | AY5: 4 | AZ5: 4.9691031 | BA5: 7092.194 | BB5: 4179.652 | BD5: 4 | BE5: =AK5 -> 7072 | BF5: =AO5 -> 4090.0584 | BI5: Baseline labor cost ($) | BJ5: =LC.mu -> 3000 | BK5: Only modeled cost | BM5: 4 | BN5: =IF(BO5<=0.5,LC.mu,MIN(LC.mu,MAX(0,_xlfn.NORM.INV(RAND(),$C$20,LC.sd)))) -> 3000 | BO5: =BETAINV(RAND(),AU.a,AU.b) -> 0.46451505 | BP5: =MAX(0,INT(Q0*(1+Ed*(BQ5-P0)/P0))) -> 10000 | BQ5: =P0*BN5/LC.mu -> 4 | BR5: =BQ5*BP5 -> 40000 | BS5: =BR5-BN5 -> 37000 | BT5: =(BS5-$C$21)/$C$21 -> 0 | BV5: Average price ($) | BW5: =AVERAGE(BQ2:BQ1001) -> 2.9471371 | BX5: =BW5+1.96*STDEV(BQ2:BQ1001)/SQRT(N) -> 2.9992304 | BY5: =BW5-1.96*STDEV(BQ2:BQ1001)/SQRT(N) -> 2.8950439 | CB5: 4 | CC5: =AVERAGE(Sim3_Replications!B3002:B4001) -> 0.61270057 | CD5: =AVERAGE(Sim3_Replications!C3002:C4001) -> 2237.8077 | CE5: =AVERAGE(Sim3_Replications!F3002:F4001) -> 34770.067 | CG5: 3 | CH5: =BO4 -> 0.36781661 | CI5: =BP4 -> 10000 | CJ5: =BS4 -> 37000
A6: Elasticity of demaand | B6: Ed | C6: -1.2 | F6: 5 | G6: =INT(MAX(0,_xlfn.NORM.INV(RAND(),d.mu,d.sd))) -> 8554 | H6: =IF(demand<Q0,demand,Q0) -> 8554 | I6: =sale*P0*(1+SCP) -> 41059.2 | J6: =Q0*SC0*(1+SCP) -> 30000 | K6: 11059.2 | L6: =(total.profit-OR)/OR -> -0.26272 | N6: SIMULATION 1 — DISTRIBUTION & COMPARISON | U6: 5 | V6: 8024.333 | W6: 8475.9936 | Y6: 5 | Z6: =G6 -> 8554 | AA6: =K6 -> 11059.2 | AD6: Supply-chain shock | AE6: =SCP -> 0.2 | AF6: 20% applied before inflation | AH6: 5 | AI6: =(IR.a+(IR.b-IR.a)*RAND()+1) -> 1.0287555 | AJ6: =IR.effect*P0*(1+SCP) -> 4.9380264 | AK6: =INT(Q0*(1+Ed*(price.change-P0)/P0)) -> 7185 | AL6: =IF(demand.i<Q0,demand.i,Q0) -> 7185 | AM6: =sales.i*price.change -> 35479.72 | AN6: =(SC0*(1+SCP)*IR.effect)*Q0 -> 30862.665 | AO6: =s.revenue.i-total.cost.i -> 4617.0547 | AP6: =(total.profit.i-OR)/OR -> -0.69219635 | AY6: 5 | AZ6: 4.9671602 | BA6: 7098.028 | BB6: 4207.027 | BD6: 5 | BE6: =AK6 -> 7185 | BF6: =AO6 -> 4617.0547 | BI6: Post-app labor mean ($) | BJ6: =$C$20 -> 2000 | BK6: Clipped normal mean parameter | BM6: 5 | BN6: =IF(BO6<=0.5,LC.mu,MIN(LC.mu,MAX(0,_xlfn.NORM.INV(RAND(),$C$20,LC.sd)))) -> 1596.3981 | BO6: =BETAINV(RAND(),AU.a,AU.b) -> 0.5285013 | BP6: =MAX(0,INT(Q0*(1+Ed*(BQ6-P0)/P0))) -> 15614 | BQ6: =P0*BN6/LC.mu -> 2.1285308 | BR6: =BQ6*BP6 -> 33234.88 | BS6: =BR6-BN6 -> 31638.482 | BT6: =(BS6-$C$21)/$C$21 -> -0.1449059 | BV6: Average demand | BW6: =AVERAGE(BP2:BP1001) -> 13158.206 | BX6: =BW6+1.96*STDEV(BP2:BP1001)/SQRT(N) -> 13314.476 | BY6: =BW6-1.96*STDEV(BP2:BP1001)/SQRT(N) -> 13001.936 | CB6: 5 | CC6: =AVERAGE(Sim3_Replications!B4002:B5001) -> 0.62237191 | CD6: =AVERAGE(Sim3_Replications!C4002:C5001) -> 2230.6224 | CE6: =AVERAGE(Sim3_Replications!F4002:F5001) -> 34767.829 | CG6: 4 | CH6: =BO5 -> 0.46451505 | CI6: =BP5 -> 10000 | CJ6: =BS5 -> 37000
A7: Inflation rate | B7: IR.a | C7: 0.02 | F7: 6 | G7: =INT(MAX(0,_xlfn.NORM.INV(RAND(),d.mu,d.sd))) -> 8953 | H7: =IF(demand<Q0,demand,Q0) -> 8953 | I7: =sale*P0*(1+SCP) -> 42974.4 | J7: =Q0*SC0*(1+SCP) -> 30000 | K7: 12974.4 | L7: =(total.profit-OR)/OR -> -0.13504 | N7: Metric | P7: Value | U7: 6 | V7: 7958.349 | W7: 8152.1808 | Y7: 6 | Z7: =G7 -> 8953 | AA7: =K7 -> 12974.4 | AD7: Inflation minimum | AE7: =IR.a -> 0.02 | AF7: Uniform rate, 2% | AH7: 6 | AI7: =(IR.a+(IR.b-IR.a)*RAND()+1) -> 1.0334248 | AJ7: =IR.effect*P0*(1+SCP) -> 4.9604391 | AK7: =INT(Q0*(1+Ed*(price.change-P0)/P0)) -> 7118 | AL7: =IF(demand.i<Q0,demand.i,Q0) -> 7118 | AM7: =sales.i*price.change -> 35308.406 | AN7: =(SC0*(1+SCP)*IR.effect)*Q0 -> 31002.744 | AO7: =s.revenue.i-total.cost.i -> 4305.6611 | AP7: =(total.profit.i-OR)/OR -> -0.71295592 | AY7: 6 | AZ7: 4.9682945 | BA7: 7094.618 | BB7: 4191.2173 | BD7: 6 | BE7: =AK7 -> 7118 | BF7: =AO7 -> 4305.6611 | BI7: Post-app labor SD ($) | BJ7: =LC.sd -> 500 | BK7: Clipped normal SD parameter | BM7: 6 | BN7: =IF(BO7<=0.5,LC.mu,MIN(LC.mu,MAX(0,_xlfn.NORM.INV(RAND(),$C$20,LC.sd)))) -> 2119.8902 | BO7: =BETAINV(RAND(),AU.a,AU.b) -> 0.54206005 | BP7: =MAX(0,INT(Q0*(1+Ed*(BQ7-P0)/P0))) -> 13520 | BQ7: =P0*BN7/LC.mu -> 2.8265203 | BR7: =BQ7*BP7 -> 38214.554 | BS7: =BR7-BN7 -> 36094.664 | BT7: =(BS7-$C$21)/$C$21 -> -0.024468551 | CB7: 6 | CC7: =AVERAGE(Sim3_Replications!B5002:B6001) -> 0.61897119 | CD7: =AVERAGE(Sim3_Replications!C5002:C6001) -> 2242.3321 | CE7: =AVERAGE(Sim3_Replications!F5002:F6001) -> 34879.73 | CG7: 5 | CH7: =BO6 -> 0.5285013 | CI7: =BP6 -> 15614 | CJ7: =BS6 -> 31638.482
B8: IR.b | C8: 0.05 | F8: 7 | G8: =INT(MAX(0,_xlfn.NORM.INV(RAND(),d.mu,d.sd))) -> 7333 | H8: =IF(demand<Q0,demand,Q0) -> 7333 | I8: =sale*P0*(1+SCP) -> 35198.4 | J8: =Q0*SC0*(1+SCP) -> 30000 | K8: 5198.4 | L8: =(total.profit-OR)/OR -> -0.65344 | N8: Profit 2.5th percentile ($) | P8: =_xlfn.PERCENTILE.INC(K2:K1001,0.025) -> -1478.88 | U8: 7 | V8: 8020.605 | W8: 8470.224 | Y8: 7 | Z8: =G8 -> 7333 | AA8: =K8 -> 5198.4 | AD8: Inflation maximum | AE8: =IR.b -> 0.05 | AF8: Uniform rate, 5% | AH8: 7 | AI8: =(IR.a+(IR.b-IR.a)*RAND()+1) -> 1.0295566 | AJ8: =IR.effect*P0*(1+SCP) -> 4.9418718 | AK8: =INT(Q0*(1+Ed*(price.change-P0)/P0)) -> 7174 | AL8: =IF(demand.i<Q0,demand.i,Q0) -> 7174 | AM8: =sales.i*price.change -> 35452.988 | AN8: =(SC0*(1+SCP)*IR.effect)*Q0 -> 30886.699 | AO8: =s.revenue.i-total.cost.i -> 4566.2895 | AP8: =(total.profit.i-OR)/OR -> -0.6955807 | AY8: 7 | AZ8: 4.9691586 | BA8: 7092.031 | BB8: 4179.0421 | BD8: 7 | BE8: =AK8 -> 7174 | BF8: =AO8 -> 4566.2895 | BI8: Signed elasticity | BJ8: =Ed -> -1.2 | BK8: Negative: price down demand up | BM8: 7 | BN8: =IF(BO8<=0.5,LC.mu,MIN(LC.mu,MAX(0,_xlfn.NORM.INV(RAND(),$C$20,LC.sd)))) -> 3000 | BO8: =BETAINV(RAND(),AU.a,AU.b) -> 0.24526232 | BP8: =MAX(0,INT(Q0*(1+Ed*(BQ8-P0)/P0))) -> 10000 | BQ8: =P0*BN8/LC.mu -> 4 | BR8: =BQ8*BP8 -> 40000 | BS8: =BR8-BN8 -> 37000 | BT8: =(BS8-$C$21)/$C$21 -> 0 | CB8: 7 | CC8: =AVERAGE(Sim3_Replications!B6002:B7001) -> 0.61419605 | CD8: =AVERAGE(Sim3_Replications!C6002:C7001) -> 2227.6391 | CE8: =AVERAGE(Sim3_Replications!F6002:F7001) -> 34670.007 | CG8: 6 | CH8: =BO7 -> 0.54206005 | CI8: =BP7 -> 13520 | CJ8: =BS7 -> 36094.664
F9: 8 | G9: =INT(MAX(0,_xlfn.NORM.INV(RAND(),d.mu,d.sd))) -> 7768 | H9: =IF(demand<Q0,demand,Q0) -> 7768 | I9: =sale*P0*(1+SCP) -> 37286.4 | J9: =Q0*SC0*(1+SCP) -> 30000 | K9: 7286.4 | L9: =(total.profit-OR)/OR -> -0.51424 | N9: Profit 97.5th percentile ($) | P9: =_xlfn.PERCENTILE.INC(K2:K1001,0.975) -> 17904.48 | U9: 8 | V9: 7991.562 | W9: 8320.3776 | Y9: 8 | Z9: =G9 -> 7768 | AA9: =K9 -> 7286.4 | AD9: Inflation factor (example) | AE9: =AI2 -> 1.0295975 | AF9: Each row independently draws U(2%,5%) | AH9: 8 | AI9: =(IR.a+(IR.b-IR.a)*RAND()+1) -> 1.0226536 | AJ9: =IR.effect*P0*(1+SCP) -> 4.9087374 | AK9: =INT(Q0*(1+Ed*(price.change-P0)/P0)) -> 7273 | AL9: =IF(demand.i<Q0,demand.i,Q0) -> 7273 | AM9: =sales.i*price.change -> 35701.247 | AN9: =(SC0*(1+SCP)*IR.effect)*Q0 -> 30679.608 | AO9: =s.revenue.i-total.cost.i -> 5021.6383 | AP9: =(total.profit.i-OR)/OR -> -0.66522411 | AY9: 8 | AZ9: 4.9685247 | BA9: 7093.931 | BB9: 4188.0785 | BD9: 8 | BE9: =AK9 -> 7273 | BF9: =AO9 -> 5021.6383 | BI9: Baseline profit ($) | BJ9: =$C$21 -> 37000 | BK9: $37,000 | BM9: 8 | BN9: =IF(BO9<=0.5,LC.mu,MIN(LC.mu,MAX(0,_xlfn.NORM.INV(RAND(),$C$20,LC.sd)))) -> 3000 | BO9: =BETAINV(RAND(),AU.a,AU.b) -> 0.44371413 | BP9: =MAX(0,INT(Q0*(1+Ed*(BQ9-P0)/P0))) -> 10000 | BQ9: =P0*BN9/LC.mu -> 4 | BR9: =BQ9*BP9 -> 40000 | BS9: =BR9-BN9 -> 37000 | BT9: =(BS9-$C$21)/$C$21 -> 0 | CB9: 8 | CC9: =AVERAGE(Sim3_Replications!B7002:B8001) -> 0.61575761 | CD9: =AVERAGE(Sim3_Replications!C7002:C8001) -> 2219.2683 | CE9: =AVERAGE(Sim3_Replications!F7002:F8001) -> 34614.183 | CG9: 7 | CH9: =BO8 -> 0.24526232 | CI9: =BP8 -> 10000 | CJ9: =BS8 -> 37000
A10: Consumer demand | B10: d.mu | C10: 8000 | F10: 9 | G10: =INT(MAX(0,_xlfn.NORM.INV(RAND(),d.mu,d.sd))) -> 7464 | H10: =IF(demand<Q0,demand,Q0) -> 7464 | I10: =sale*P0*(1+SCP) -> 35827.2 | J10: =Q0*SC0*(1+SCP) -> 30000 | K10: 5827.2 | L10: =(total.profit-OR)/OR -> -0.61152 | N10: Demand 2.5th percentile (cups) | P10: =_xlfn.PERCENTILE.INC(G2:G1001,0.025) -> 5941.9 | U10: 9 | V10: 7978.057 | W10: 8269.416 | Y10: 9 | Z10: =G10 -> 7464 | AA10: =K10 -> 5827.2 | AD10: Price formula (example) | AE10: =AJ2 -> 4.9420681 | AF10: P0*(1+SCP)*(1+inflation) | AH10: 9 | AI10: =(IR.a+(IR.b-IR.a)*RAND()+1) -> 1.0298124 | AJ10: =IR.effect*P0*(1+SCP) -> 4.9430995 | AK10: =INT(Q0*(1+Ed*(price.change-P0)/P0)) -> 7170 | AL10: =IF(demand.i<Q0,demand.i,Q0) -> 7170 | AM10: =sales.i*price.change -> 35442.023 | AN10: =(SC0*(1+SCP)*IR.effect)*Q0 -> 30894.372 | AO10: =s.revenue.i-total.cost.i -> 4547.6515 | AP10: =(total.profit.i-OR)/OR -> -0.69682323 | AY10: 9 | AZ10: 4.9691691 | BA10: 7091.992 | BB10: 4178.8812 | BD10: 9 | BE10: =AK10 -> 7170 | BF10: =AO10 -> 4547.6515 | BI10: Mean app adoption | BJ10: =BW2 -> 0.61939565 | BK10: Beta(5,3) | BM10: 9 | BN10: =IF(BO10<=0.5,LC.mu,MIN(LC.mu,MAX(0,_xlfn.NORM.INV(RAND(),$C$20,LC.sd)))) -> 3000 | BO10: =BETAINV(RAND(),AU.a,AU.b) -> 0.43080941 | BP10: =MAX(0,INT(Q0*(1+Ed*(BQ10-P0)/P0))) -> 10000 | BQ10: =P0*BN10/LC.mu -> 4 | BR10: =BQ10*BP10 -> 40000 | BS10: =BR10-BN10 -> 37000 | BT10: =(BS10-$C$21)/$C$21 -> 0 | CB10: 9 | CC10: =AVERAGE(Sim3_Replications!B8002:B9001) -> 0.62303206 | CD10: =AVERAGE(Sim3_Replications!C8002:C9001) -> 2198.0192 | CE10: =AVERAGE(Sim3_Replications!F8002:F9001) -> 34495.536 | CG10: 8 | CH10: =BO9 -> 0.44371413 | CI10: =BP9 -> 10000 | CJ10: =BS9 -> 37000
B11: d.sd | C11: 1000 | F11: 10 | G11: =INT(MAX(0,_xlfn.NORM.INV(RAND(),d.mu,d.sd))) -> 8554 | H11: =IF(demand<Q0,demand,Q0) -> 8554 | I11: =sale*P0*(1+SCP) -> 41059.2 | J11: =Q0*SC0*(1+SCP) -> 30000 | K11: 11059.2 | L11: =(total.profit-OR)/OR -> -0.26272 | N11: Demand 97.5th percentile (cups) | P11: =_xlfn.PERCENTILE.INC(G2:G1001,0.975) -> 9980.1 | U11: 10 | V11: 7950.534 | W11: 8122.3728 | Y11: 10 | Z11: =G11 -> 8554 | AA11: =K11 -> 11059.2 | AD11: Demand formula (example) | AE11: =AK2 -> 7173 | AF11: INT(Q0*(1+Ed*(price-P0)/P0)) | AH11: 10 | AI11: =(IR.a+(IR.b-IR.a)*RAND()+1) -> 1.0483372 | AJ11: =IR.effect*P0*(1+SCP) -> 5.0320188 | AK11: =INT(Q0*(1+Ed*(price.change-P0)/P0)) -> 6903 | AL11: =IF(demand.i<Q0,demand.i,Q0) -> 6903 | AM11: =sales.i*price.change -> 34736.026 | AN11: =(SC0*(1+SCP)*IR.effect)*Q0 -> 31450.117 | AO11: =s.revenue.i-total.cost.i -> 3285.9083 | AP11: =(total.profit.i-OR)/OR -> -0.78093945 | AY11: 10 | AZ11: 4.9680625 | BA11: 7095.305 | BB11: 4194.4368 | BD11: 10 | BE11: =AK11 -> 6903 | BF11: =AO11 -> 3285.9083 | BI11: Mean profit ($) | BJ11: =BW3 -> 34451.739 | BK11: Monte Carlo mean | BM11: 10 | BN11: =IF(BO11<=0.5,LC.mu,MIN(LC.mu,MAX(0,_xlfn.NORM.INV(RAND(),$C$20,LC.sd)))) -> 2095.259 | BO11: =BETAINV(RAND(),AU.a,AU.b) -> 0.75547314 | BP11: =MAX(0,INT(Q0*(1+Ed*(BQ11-P0)/P0))) -> 13618 | BQ11: =P0*BN11/LC.mu -> 2.7936787 | BR11: =BQ11*BP11 -> 38044.316 | BS11: =BR11-BN11 -> 35949.057 | BT11: =(BS11-$C$21)/$C$21 -> -0.02840386 | CB11: 10 | CC11: =AVERAGE(Sim3_Replications!B9002:B10001) -> 0.61361893 | CD11: =AVERAGE(Sim3_Replications!C9002:C10001) -> 2248.4238 | CE11: =AVERAGE(Sim3_Replications!F9002:F10001) -> 34833.374 | CG11: 9 | CH11: =BO10 -> 0.43080941 | CI11: =BP10 -> 10000 | CJ11: =BS10 -> 37000
F12: 11 | G12: =INT(MAX(0,_xlfn.NORM.INV(RAND(),d.mu,d.sd))) -> 5968 | H12: =IF(demand<Q0,demand,Q0) -> 5968 | I12: =sale*P0*(1+SCP) -> 28646.4 | J12: =Q0*SC0*(1+SCP) -> 30000 | K12: -1353.6 | L12: =(total.profit-OR)/OR -> -1.09024 | N12: P(profit < baseline) | P12: =COUNTIF(K2:K1001,"<"&OR)/N -> 0.918 | U12: 11 | V12: 8032.236 | W12: 8503.4784 | Y12: 11 | Z12: =G12 -> 5968 | AA12: =K12 -> -1353.6 | AD12: Revenue formula (example) | AE12: =AM2 -> 35449.454 | AF12: Actual sales*new price | AH12: 11 | AI12: =(IR.a+(IR.b-IR.a)*RAND()+1) -> 1.0288883 | AJ12: =IR.effect*P0*(1+SCP) -> 4.9386637 | AK12: =INT(Q0*(1+Ed*(price.change-P0)/P0)) -> 7184 | AL12: =IF(demand.i<Q0,demand.i,Q0) -> 7184 | AM12: =sales.i*price.change -> 35479.36 | AN12: =(SC0*(1+SCP)*IR.effect)*Q0 -> 30866.648 | AO12: =s.revenue.i-total.cost.i -> 4612.7119 | AP12: =(total.profit.i-OR)/OR -> -0.69248588 | AY12: 11 | AZ12: 4.9684781 | BA12: 7094.074 | BB12: 4188.328 | BD12: 11 | BE12: =AK12 -> 7184 | BF12: =AO12 -> 4612.7119 | BI12: Profit outcome 2.5% | BJ12: =_xlfn.PERCENTILE.INC(BS2:BS1001,0.025) -> 22971.861 | BK12: Single simulated month | BM12: 11 | BN12: =IF(BO12<=0.5,LC.mu,MIN(LC.mu,MAX(0,_xlfn.NORM.INV(RAND(),$C$20,LC.sd)))) -> 1226.0132 | BO12: =BETAINV(RAND(),AU.a,AU.b) -> 0.71723237 | BP12: =MAX(0,INT(Q0*(1+Ed*(BQ12-P0)/P0))) -> 17095 | BQ12: =P0*BN12/LC.mu -> 1.6346843 | BR12: =BQ12*BP12 -> 27944.929 | BS12: =BR12-BN12 -> 26718.915 | BT12: =(BS12-$C$21)/$C$21 -> -0.27786715 | CB12: 11 | CC12: =AVERAGE(Sim3_Replications!B10002:B11001) -> 0.61423498 | CD12: =AVERAGE(Sim3_Replications!C10002:C11001) -> 2214.8234 | CE12: =AVERAGE(Sim3_Replications!F10002:F11001) -> 34623.848 | CG12: 10 | CH12: =BO11 -> 0.75547314 | CI12: =BP11 -> 13618 | CJ12: =BS11 -> 35949.057
A13: Total monthly profit | B13: OR | C13: =(P0-SC0)*Q0 -> 15000 | F13: 12 | G13: =INT(MAX(0,_xlfn.NORM.INV(RAND(),d.mu,d.sd))) -> 5844 | H13: =IF(demand<Q0,demand,Q0) -> 5844 | I13: =sale*P0*(1+SCP) -> 28051.2 | J13: =Q0*SC0*(1+SCP) -> 30000 | K13: -1948.8 | L13: =(total.profit-OR)/OR -> -1.12992 | N13: Mean profit change ($) | P13: =P3-OR -> -7028.1072 | U13: 12 | V13: 8036.442 | W13: 8527.8288 | Y13: 12 | Z13: =G13 -> 5844 | AA13: =K13 -> -1948.8 | AD13: Cost formula (example) | AE13: =AN2 -> 30887.926 | AF13: Q0*SC0*(1+SCP)*inflation factor | AH13: 12 | AI13: =(IR.a+(IR.b-IR.a)*RAND()+1) -> 1.0427389 | AJ13: =IR.effect*P0*(1+SCP) -> 5.0051467 | AK13: =INT(Q0*(1+Ed*(price.change-P0)/P0)) -> 6984 | AL13: =IF(demand.i<Q0,demand.i,Q0) -> 6984 | AM13: =sales.i*price.change -> 34955.945 | AN13: =(SC0*(1+SCP)*IR.effect)*Q0 -> 31282.167 | AO13: =s.revenue.i-total.cost.i -> 3673.7777 | AP13: =(total.profit.i-OR)/OR -> -0.75508149 | AY13: 12 | AZ13: 4.9662136 | BA13: 7100.855 | BB13: 4220.3116 | BD13: 12 | BE13: =AK13 -> 6984 | BF13: =AO13 -> 3673.7777 | BI13: Profit outcome 97.5% | BJ13: =_xlfn.PERCENTILE.INC(BS2:BS1001,0.975) -> 37614.462 | BK13: Single simulated month | BM13: 12 | BN13: =IF(BO13<=0.5,LC.mu,MIN(LC.mu,MAX(0,_xlfn.NORM.INV(RAND(),$C$20,LC.sd)))) -> 2157.9027 | BO13: =BETAINV(RAND(),AU.a,AU.b) -> 0.7600357 | BP13: =MAX(0,INT(Q0*(1+Ed*(BQ13-P0)/P0))) -> 13368 | BQ13: =P0*BN13/LC.mu -> 2.8772036 | BR13: =BQ13*BP13 -> 38462.458 | BS13: =BR13-BN13 -> 36304.555 | BT13: =(BS13-$C$21)/$C$21 -> -0.018795803 | CB13: 12 | CC13: =AVERAGE(Sim3_Replications!B11002:B12001) -> 0.61993473 | CD13: =AVERAGE(Sim3_Replications!C11002:C12001) -> 2234.8237 | CE13: =AVERAGE(Sim3_Replications!F11002:F12001) -> 34893.75 | CG13: 11 | CH13: =BO12 -> 0.71723237 | CI13: =BP12 -> 17095 | CJ13: =BS12 -> 26718.915
A14: Simulation times | B14: N | C14: 1000 | F14: 13 | G14: =INT(MAX(0,_xlfn.NORM.INV(RAND(),d.mu,d.sd))) -> 7162 | H14: =IF(demand<Q0,demand,Q0) -> 7162 | I14: =sale*P0*(1+SCP) -> 34377.6 | J14: =Q0*SC0*(1+SCP) -> 30000 | K14: 4377.6 | L14: =(total.profit-OR)/OR -> -0.70816 | N14: Mean profit change (%) | P14: =(P3-OR)/OR -> -0.46854048 | AD14: Profit formula (example) | AE14: =AO2 -> 4561.5288 | AF14: Revenue minus full procurement cost | AH14: 13 | AI14: =(IR.a+(IR.b-IR.a)*RAND()+1) -> 1.034666 | AJ14: =IR.effect*P0*(1+SCP) -> 4.9663968 | AK14: =INT(Q0*(1+Ed*(price.change-P0)/P0)) -> 7100 | AL14: =IF(demand.i<Q0,demand.i,Q0) -> 7100 | AM14: =sales.i*price.change -> 35261.417 | AN14: =(SC0*(1+SCP)*IR.effect)*Q0 -> 31039.98 | AO14: =s.revenue.i-total.cost.i -> 4221.4373 | AP14: =(total.profit.i-OR)/OR -> -0.71857085 | BI14: Demand outcome 2.5% | BJ14: =_xlfn.PERCENTILE.INC(BP2:BP1001,0.025) -> 10000 | BK14: Single simulated month | BM14: 13 | BN14: =IF(BO14<=0.5,LC.mu,MIN(LC.mu,MAX(0,_xlfn.NORM.INV(RAND(),$C$20,LC.sd)))) -> 1079.8516 | BO14: =BETAINV(RAND(),AU.a,AU.b) -> 0.78493465 | BP14: =MAX(0,INT(Q0*(1+Ed*(BQ14-P0)/P0))) -> 17680 | BQ14: =P0*BN14/LC.mu -> 1.4398021 | BR14: =BQ14*BP14 -> 25455.702 | BS14: =BR14-BN14 -> 24375.85 | BT14: =(BS14-$C$21)/$C$21 -> -0.34119324 | CG14: 12 | CH14: =BO13 -> 0.7600357 | CI14: =BP13 -> 13368 | CJ14: =BS13 -> 36304.555
F15: 14 | G15: =INT(MAX(0,_xlfn.NORM.INV(RAND(),d.mu,d.sd))) -> 8699 | H15: =IF(demand<Q0,demand,Q0) -> 8699 | I15: =sale*P0*(1+SCP) -> 41755.2 | J15: =Q0*SC0*(1+SCP) -> 30000 | K15: 11755.2 | L15: =(total.profit-OR)/OR -> -0.21632 | Y15: 12 independent draws from the same 1,000-run demand/profit simulation. | AD15: Mean profit ($) | AE15: =AT4 -> 4221.9285 | AF15: Monte Carlo estimate, N=1,000 | AH15: 14 | AI15: =(IR.a+(IR.b-IR.a)*RAND()+1) -> 1.0383228 | AJ15: =IR.effect*P0*(1+SCP) -> 4.9839494 | AK15: =INT(Q0*(1+Ed*(price.change-P0)/P0)) -> 7048 | AL15: =IF(demand.i<Q0,demand.i,Q0) -> 7048 | AM15: =sales.i*price.change -> 35126.875 | AN15: =(SC0*(1+SCP)*IR.effect)*Q0 -> 31149.684 | AO15: =s.revenue.i-total.cost.i -> 3977.1916 | AP15: =(total.profit.i-OR)/OR -> -0.73485389 | BD15: 12 independent inflation draws, each producing one demand/profit outcome. | BI15: Demand outcome 97.5% | BJ15: =_xlfn.PERCENTILE.INC(BP2:BP1001,0.975) -> 18005.475 | BK15: Single simulated month | BM15: 14 | BN15: =IF(BO15<=0.5,LC.mu,MIN(LC.mu,MAX(0,_xlfn.NORM.INV(RAND(),$C$20,LC.sd)))) -> 1584.0424 | BO15: =BETAINV(RAND(),AU.a,AU.b) -> 0.61661759 | BP15: =MAX(0,INT(Q0*(1+Ed*(BQ15-P0)/P0))) -> 15663 | BQ15: =P0*BN15/LC.mu -> 2.1120565 | BR15: =BQ15*BP15 -> 33081.141 | BS15: =BR15-BN15 -> 31497.098 | BT15: =(BS15-$C$21)/$C$21 -> -0.14872707
A16: labor cost | B16: LC.mu | C16: 3000 | F16: 15 | G16: =INT(MAX(0,_xlfn.NORM.INV(RAND(),d.mu,d.sd))) -> 7388 | H16: =IF(demand<Q0,demand,Q0) -> 7388 | I16: =sale*P0*(1+SCP) -> 35462.4 | J16: =Q0*SC0*(1+SCP) -> 30000 | K16: 5462.4 | L16: =(total.profit-OR)/OR -> -0.63584 | N16: P2:R3 = 95% CI for estimated means; P8:P11 = 95% simulated outcome intervals. | U16: Replication interpretation | Y16: No trend, seasonality, or inventory carryover is modeled. | AD16: Profit outcome lower 2.5% ($) | AE16: =_xlfn.PERCENTILE.INC(AO2:AO1001,0.025) -> 3232.9398 | AF16: Individual-month simulation outcome | AH16: 15 | AI16: =(IR.a+(IR.b-IR.a)*RAND()+1) -> 1.045227 | AJ16: =IR.effect*P0*(1+SCP) -> 5.0170896 | AK16: =INT(Q0*(1+Ed*(price.change-P0)/P0)) -> 6948 | AL16: =IF(demand.i<Q0,demand.i,Q0) -> 6948 | AM16: =sales.i*price.change -> 34858.738 | AN16: =(SC0*(1+SCP)*IR.effect)*Q0 -> 31356.81 | AO16: =s.revenue.i-total.cost.i -> 3501.9285 | AP16: ` | BD16: Illustrative scenarios, not a seasonal or time-series forecast. | BI16: Price outcome 2.5% | BJ16: =_xlfn.PERCENTILE.INC(BQ2:BQ1001,0.025) -> 1.3312797 | BK16: Single simulated month | BM16: 15 | BN16: =IF(BO16<=0.5,LC.mu,MIN(LC.mu,MAX(0,_xlfn.NORM.INV(RAND(),$C$20,LC.sd)))) -> 1364.6123 | BO16: =BETAINV(RAND(),AU.a,AU.b) -> 0.66818243 | BP16: =MAX(0,INT(Q0*(1+Ed*(BQ16-P0)/P0))) -> 16541 | BQ16: =P0*BN16/LC.mu -> 1.8194831 | BR16: =BQ16*BP16 -> 30096.07 | BS16: =BR16-BN16 -> 28731.458 | BT16: =(BS16-$C$21)/$C$21 -> -0.22347412 | CG16: 12 independent simulated months; no seasonality or inventory carryover.
B17: LC.sd | C17: 500 | F17: 16 | G17: =INT(MAX(0,_xlfn.NORM.INV(RAND(),d.mu,d.sd))) -> 7717 | H17: =IF(demand<Q0,demand,Q0) -> 7717 | I17: =sale*P0*(1+SCP) -> 37041.6 | J17: =Q0*SC0*(1+SCP) -> 30000 | K17: 7041.6 | L17: =(total.profit-OR)/OR -> -0.53056 | U17: Run 1 references current 1,000-draw means; Runs 2–12 are Excel What-if Data Table recalculations. | AD17: Profit outcome upper 97.5% ($) | AE17: =_xlfn.PERCENTILE.INC(AO2:AO1001,0.975) -> 5153.7909 | AF17: Individual-month simulation outcome | AH17: 16 | AI17: =(IR.a+(IR.b-IR.a)*RAND()+1) -> 1.045591 | AJ17: =IR.effect*P0*(1+SCP) -> 5.0188366 | AK17: =INT(Q0*(1+Ed*(price.change-P0)/P0)) -> 6943 | AL17: =IF(demand.i<Q0,demand.i,Q0) -> 6943 | AM17: =sales.i*price.change -> 34845.783 | AN17: =(SC0*(1+SCP)*IR.effect)*Q0 -> 31367.729 | AO17: =s.revenue.i-total.cost.i -> 3478.0538 | AP17: =(total.profit.i-OR)/OR -> -0.76812975 | BI17: Price outcome 97.5% | BJ17: =_xlfn.PERCENTILE.INC(BQ2:BQ1001,0.975) -> 4 | BK17: Single simulated month | BM17: 16 | BN17: =IF(BO17<=0.5,LC.mu,MIN(LC.mu,MAX(0,_xlfn.NORM.INV(RAND(),$C$20,LC.sd)))) -> 2405.5545 | BO17: =BETAINV(RAND(),AU.a,AU.b) -> 0.64632284 | BP17: =MAX(0,INT(Q0*(1+Ed*(BQ17-P0)/P0))) -> 12377 | BQ17: =P0*BN17/LC.mu -> 3.207406 | BR17: =BQ17*BP17 -> 39698.064 | BS17: =BR17-BN17 -> 37292.51 | BT17: =(BS17-$C$21)/$C$21 -> 0.0079056673
A18: App usage | B18: AU.a | C18: 5 | F18: 17 | G18: =INT(MAX(0,_xlfn.NORM.INV(RAND(),d.mu,d.sd))) -> 8088 | H18: =IF(demand<Q0,demand,Q0) -> 8088 | I18: =sale*P0*(1+SCP) -> 38822.4 | J18: =Q0*SC0*(1+SCP) -> 30000 | K18: 8822.4 | L18: =(total.profit-OR)/OR -> -0.41184 | U18: These are 12 Monte Carlo estimates, NOT 12 operating months. | AD18: Demand outcome lower 2.5% | AE18: =_xlfn.PERCENTILE.INC(AK2:AK1001,0.025) -> 6892 | AF18: Individual-month simulated demand | AH18: 17 | AI18: =(IR.a+(IR.b-IR.a)*RAND()+1) -> 1.0231255 | AJ18: =IR.effect*P0*(1+SCP) -> 4.9110023 | AK18: =INT(Q0*(1+Ed*(price.change-P0)/P0)) -> 7266 | AL18: =IF(demand.i<Q0,demand.i,Q0) -> 7266 | AM18: =sales.i*price.change -> 35683.343 | AN18: =(SC0*(1+SCP)*IR.effect)*Q0 -> 30693.765 | AO18: =s.revenue.i-total.cost.i -> 4989.5784 | AP18: =(total.profit.i-OR)/OR -> -0.66736144 | BI18: Mean profit change ($) | BJ18: =BW3-$C$21 -> -2548.2611 | BK18: Compared to $37,000 | BM18: 17 | BN18: =IF(BO18<=0.5,LC.mu,MIN(LC.mu,MAX(0,_xlfn.NORM.INV(RAND(),$C$20,LC.sd)))) -> 1255.5314 | BO18: =BETAINV(RAND(),AU.a,AU.b) -> 0.92009057 | BP18: =MAX(0,INT(Q0*(1+Ed*(BQ18-P0)/P0))) -> 16977 | BQ18: =P0*BN18/LC.mu -> 1.6740419 | BR18: =BQ18*BP18 -> 28420.21 | BS18: =BR18-BN18 -> 27164.678 | BT18: =(BS18-$C$21)/$C$21 -> -0.26581951
B19: AU.b | C19: 3 | F19: 18 | G19: =INT(MAX(0,_xlfn.NORM.INV(RAND(),d.mu,d.sd))) -> 8998 | H19: =IF(demand<Q0,demand,Q0) -> 8998 | I19: =sale*P0*(1+SCP) -> 43190.4 | J19: =Q0*SC0*(1+SCP) -> 30000 | K19: 13190.4 | L19: =(total.profit-OR)/OR -> -0.12064 | AD19: Demand outcome upper 97.5% | AE19: =_xlfn.PERCENTILE.INC(AK2:AK1001,0.975) -> 7302 | AF19: Individual-month simulated demand | AH19: 18 | AI19: =(IR.a+(IR.b-IR.a)*RAND()+1) -> 1.0454484 | AJ19: =IR.effect*P0*(1+SCP) -> 5.0181524 | AK19: =INT(Q0*(1+Ed*(price.change-P0)/P0)) -> 6945 | AL19: =IF(demand.i<Q0,demand.i,Q0) -> 6945 | AM19: =sales.i*price.change -> 34851.068 | AN19: =(SC0*(1+SCP)*IR.effect)*Q0 -> 31363.452 | AO19: =s.revenue.i-total.cost.i -> 3487.6159 | AP19: =(total.profit.i-OR)/OR -> -0.76749227 | BI19: Mean profit change (%) | BJ19: =(BW3-$C$21)/$C$21 -> -0.06887192 | BK19: Compared to $37,000 | BM19: 18 | BN19: =IF(BO19<=0.5,LC.mu,MIN(LC.mu,MAX(0,_xlfn.NORM.INV(RAND(),$C$20,LC.sd)))) -> 3000 | BO19: =BETAINV(RAND(),AU.a,AU.b) -> 0.49958788 | BP19: =MAX(0,INT(Q0*(1+Ed*(BQ19-P0)/P0))) -> 10000 | BQ19: =P0*BN19/LC.mu -> 4 | BR19: =BQ19*BP19 -> 40000 | BS19: =BR19-BN19 -> 37000 | BT19: =(BS19-$C$21)/$C$21 -> 0
B20: Post-app labor mean ($) | C20: 2000 | F20: 19 | G20: =INT(MAX(0,_xlfn.NORM.INV(RAND(),d.mu,d.sd))) -> 8315 | H20: =IF(demand<Q0,demand,Q0) -> 8315 | I20: =sale*P0*(1+SCP) -> 39912 | J20: =Q0*SC0*(1+SCP) -> 30000 | K20: 9912 | L20: =(total.profit-OR)/OR -> -0.3392 | AD20: Price outcome lower 2.5% ($) | AE20: =_xlfn.PERCENTILE.INC(AJ2:AJ1001,0.025) -> 4.8992539 | AF20: Individual-month simulated price | AH20: 19 | AI20: =(IR.a+(IR.b-IR.a)*RAND()+1) -> 1.0262005 | AJ20: =IR.effect*P0*(1+SCP) -> 4.9257624 | AK20: =INT(Q0*(1+Ed*(price.change-P0)/P0)) -> 7222 | AL20: =IF(demand.i<Q0,demand.i,Q0) -> 7222 | AM20: =sales.i*price.change -> 35573.856 | AN20: =(SC0*(1+SCP)*IR.effect)*Q0 -> 30786.015 | AO20: =s.revenue.i-total.cost.i -> 4787.8411 | AP20: =(total.profit.i-OR)/OR -> -0.68081059 | BI20: P(profit below baseline) | BJ20: =COUNTIF(BS2:BS1001,"<"&$C$21)/N -> 0.567 | BK20: Fraction of draws | BM20: 19 | BN20: =IF(BO20<=0.5,LC.mu,MIN(LC.mu,MAX(0,_xlfn.NORM.INV(RAND(),$C$20,LC.sd)))) -> 2102.4011 | BO20: =BETAINV(RAND(),AU.a,AU.b) -> 0.60634746 | BP20: =MAX(0,INT(Q0*(1+Ed*(BQ20-P0)/P0))) -> 13590 | BQ20: =P0*BN20/LC.mu -> 2.8032015 | BR20: =BQ20*BP20 -> 38095.509 | BS20: =BR20-BN20 -> 35993.108 | BT20: =(BS20-$C$21)/$C$21 -> -0.027213308
B21: Sim3 baseline profit ($) | C21: =P0*Q0-LC.mu -> 37000 | F21: 20 | G21: =INT(MAX(0,_xlfn.NORM.INV(RAND(),d.mu,d.sd))) -> 8511 | H21: =IF(demand<Q0,demand,Q0) -> 8511 | I21: =sale*P0*(1+SCP) -> 40852.8 | J21: =Q0*SC0*(1+SCP) -> 30000 | K21: 10852.8 | L21: =(total.profit-OR)/OR -> -0.27648 | AD21: Price outcome upper 97.5% ($) | AE21: =_xlfn.PERCENTILE.INC(AJ2:AJ1001,0.975) -> 5.035712 | AF21: Individual-month simulated price | AH21: 20 | AI21: =(IR.a+(IR.b-IR.a)*RAND()+1) -> 1.0200078 | AJ21: =IR.effect*P0*(1+SCP) -> 4.8960375 | AK21: =INT(Q0*(1+Ed*(price.change-P0)/P0)) -> 7311 | AL21: =IF(demand.i<Q0,demand.i,Q0) -> 7311 | AM21: =sales.i*price.change -> 35794.93 | AN21: =(SC0*(1+SCP)*IR.effect)*Q0 -> 30600.235 | AO21: =s.revenue.i-total.cost.i -> 5194.6958 | AP21: =(total.profit.i-OR)/OR -> -0.65368695 | BI21: P(app adoption > 50%) | BJ21: =COUNTIF(BO2:BO1001,">0.5")/N -> 0.766 | BK21: Labor reduction triggered | BM21: 20 | BN21: =IF(BO21<=0.5,LC.mu,MIN(LC.mu,MAX(0,_xlfn.NORM.INV(RAND(),$C$20,LC.sd)))) -> 3000 | BO21: =BETAINV(RAND(),AU.a,AU.b) -> 0.3705419 | BP21: =MAX(0,INT(Q0*(1+Ed*(BQ21-P0)/P0))) -> 10000 | BQ21: =P0*BN21/LC.mu -> 4 | BR21: =BQ21*BP21 -> 40000 | BS21: =BR21-BN21 -> 37000 | BT21: =(BS21-$C$21)/$C$21 -> 0
F22: 21 | G22: =INT(MAX(0,_xlfn.NORM.INV(RAND(),d.mu,d.sd))) -> 7642 | H22: =IF(demand<Q0,demand,Q0) -> 7642 | I22: =sale*P0*(1+SCP) -> 36681.6 | J22: =Q0*SC0*(1+SCP) -> 30000 | K22: 6681.6 | L22: =(total.profit-OR)/OR -> -0.55456 | AD22: Mean profit change ($) | AE22: =AT4-OR -> -10778.072 | AF22: Relative to $15,000 pre-pandemic profit | AH22: 21 | AI22: =(IR.a+(IR.b-IR.a)*RAND()+1) -> 1.0231254 | AJ22: =IR.effect*P0*(1+SCP) -> 4.9110018 | AK22: =INT(Q0*(1+Ed*(price.change-P0)/P0)) -> 7266 | AL22: =IF(demand.i<Q0,demand.i,Q0) -> 7266 | AM22: =sales.i*price.change -> 35683.339 | AN22: =(SC0*(1+SCP)*IR.effect)*Q0 -> 30693.761 | AO22: =s.revenue.i-total.cost.i -> 4989.5778 | AP22: =(total.profit.i-OR)/OR -> -0.66736148 | BM22: 21 | BN22: =IF(BO22<=0.5,LC.mu,MIN(LC.mu,MAX(0,_xlfn.NORM.INV(RAND(),$C$20,LC.sd)))) -> 2158.5974 | BO22: =BETAINV(RAND(),AU.a,AU.b) -> 0.57695795 | BP22: =MAX(0,INT(Q0*(1+Ed*(BQ22-P0)/P0))) -> 13365 | BQ22: =P0*BN22/LC.mu -> 2.8781299 | BR22: =BQ22*BP22 -> 38466.206 | BS22: =BR22-BN22 -> 36307.609 | BT22: =(BS22-$C$21)/$C$21 -> -0.018713276
F23: 22 | G23: =INT(MAX(0,_xlfn.NORM.INV(RAND(),d.mu,d.sd))) -> 8358 | H23: =IF(demand<Q0,demand,Q0) -> 8358 | I23: =sale*P0*(1+SCP) -> 40118.4 | J23: =Q0*SC0*(1+SCP) -> 30000 | K23: 10118.4 | L23: =(total.profit-OR)/OR -> -0.32544 | AD23: Mean profit change (%) | AE23: =(AT4-OR)/OR -> -0.7185381 | AF23: Relative to $15,000 pre-pandemic profit | AH23: 22 | AI23: =(IR.a+(IR.b-IR.a)*RAND()+1) -> 1.0298239 | AJ23: =IR.effect*P0*(1+SCP) -> 4.9431547 | AK23: =INT(Q0*(1+Ed*(price.change-P0)/P0)) -> 7170 | AL23: =IF(demand.i<Q0,demand.i,Q0) -> 7170 | AM23: =sales.i*price.change -> 35442.419 | AN23: =(SC0*(1+SCP)*IR.effect)*Q0 -> 30894.717 | AO23: =s.revenue.i-total.cost.i -> 4547.7023 | AP23: =(total.profit.i-OR)/OR -> -0.69681985 | BM23: 22 | BN23: =IF(BO23<=0.5,LC.mu,MIN(LC.mu,MAX(0,_xlfn.NORM.INV(RAND(),$C$20,LC.sd)))) -> 2713.8052 | BO23: =BETAINV(RAND(),AU.a,AU.b) -> 0.89344098 | BP23: =MAX(0,INT(Q0*(1+Ed*(BQ23-P0)/P0))) -> 11144 | BQ23: =P0*BN23/LC.mu -> 3.618407 | BR23: =BQ23*BP23 -> 40323.527 | BS23: =BR23-BN23 -> 37609.722 | BT23: =(BS23-$C$21)/$C$21 -> 0.016478974
F24: 23 | G24: =INT(MAX(0,_xlfn.NORM.INV(RAND(),d.mu,d.sd))) -> 8043 | H24: =IF(demand<Q0,demand,Q0) -> 8043 | I24: =sale*P0*(1+SCP) -> 38606.4 | J24: =Q0*SC0*(1+SCP) -> 30000 | K24: 8606.4 | L24: =(total.profit-OR)/OR -> -0.42624 | AD24: P(profit < baseline) | AE24: =COUNTIF(AO2:AO1001,"<"&OR)/N -> 1 | AF24: Fraction of draws below baseline | AH24: 23 | AI24: =(IR.a+(IR.b-IR.a)*RAND()+1) -> 1.0222336 | AJ24: =IR.effect*P0*(1+SCP) -> 4.9067215 | AK24: =INT(Q0*(1+Ed*(price.change-P0)/P0)) -> 7279 | AL24: =IF(demand.i<Q0,demand.i,Q0) -> 7279 | AM24: =sales.i*price.change -> 35716.026 | AN24: =(SC0*(1+SCP)*IR.effect)*Q0 -> 30667.009 | AO24: =s.revenue.i-total.cost.i -> 5049.0164 | AP24: =(total.profit.i-OR)/OR -> -0.6633989 | BI24: 95% mean confidence intervals: BG:BI (mean ± 1.96 SD / sqrt(N)). | BM24: 23 | BN24: =IF(BO24<=0.5,LC.mu,MIN(LC.mu,MAX(0,_xlfn.NORM.INV(RAND(),$C$20,LC.sd)))) -> 2328.6923 | BO24: =BETAINV(RAND(),AU.a,AU.b) -> 0.75547323 | BP24: =MAX(0,INT(Q0*(1+Ed*(BQ24-P0)/P0))) -> 12685 | BQ24: =P0*BN24/LC.mu -> 3.104923 | BR24: =BQ24*BP24 -> 39385.949 | BS24: =BR24-BN24 -> 37057.256 | BT24: =(BS24-$C$21)/$C$21 -> 0.0015474703
F25: 24 | G25: =INT(MAX(0,_xlfn.NORM.INV(RAND(),d.mu,d.sd))) -> 8833 | H25: =IF(demand<Q0,demand,Q0) -> 8833 | I25: =sale*P0*(1+SCP) -> 42398.4 | J25: =Q0*SC0*(1+SCP) -> 30000 | K25: 12398.4 | L25: =(total.profit-OR)/OR -> -0.17344 | AH25: 24 | AI25: =(IR.a+(IR.b-IR.a)*RAND()+1) -> 1.0234668 | AJ25: =IR.effect*P0*(1+SCP) -> 4.9126408 | AK25: =INT(Q0*(1+Ed*(price.change-P0)/P0)) -> 7262 | AL25: =IF(demand.i<Q0,demand.i,Q0) -> 7262 | AM25: =sales.i*price.change -> 35675.598 | AN25: =(SC0*(1+SCP)*IR.effect)*Q0 -> 30704.005 | AO25: =s.revenue.i-total.cost.i -> 4971.5925 | AP25: =(total.profit.i-OR)/OR -> -0.6685605 | BI25: 95% outcome intervals: CB12:CB17 (2.5th–97.5th percentiles). | BM25: 24 | BN25: =IF(BO25<=0.5,LC.mu,MIN(LC.mu,MAX(0,_xlfn.NORM.INV(RAND(),$C$20,LC.sd)))) -> 2056.6125 | BO25: =BETAINV(RAND(),AU.a,AU.b) -> 0.71469371 | BP25: =MAX(0,INT(Q0*(1+Ed*(BQ25-P0)/P0))) -> 13773 | BQ25: =P0*BN25/LC.mu -> 2.74215 | BR25: =BQ25*BP25 -> 37767.632 | BS25: =BR25-BN25 -> 35711.02 | BT25: =(BS25-$C$21)/$C$21 -> -0.0348373
F26: 25 | G26: =INT(MAX(0,_xlfn.NORM.INV(RAND(),d.mu,d.sd))) -> 7530 | H26: =IF(demand<Q0,demand,Q0) -> 7530 | I26: =sale*P0*(1+SCP) -> 36144 | J26: =Q0*SC0*(1+SCP) -> 30000 | K26: 6144 | L26: =(total.profit-OR)/OR -> -0.5904 | AD26: 95% CI for means: AL:AN (mean ± 1.96×SD/√N). | AH26: 25 | AI26: =(IR.a+(IR.b-IR.a)*RAND()+1) -> 1.0207531 | AJ26: =IR.effect*P0*(1+SCP) -> 4.8996151 | AK26: =INT(Q0*(1+Ed*(price.change-P0)/P0)) -> 7301 | AL26: =IF(demand.i<Q0,demand.i,Q0) -> 7301 | AM26: =sales.i*price.change -> 35772.09 | AN26: =(SC0*(1+SCP)*IR.effect)*Q0 -> 30622.594 | AO26: =s.revenue.i-total.cost.i -> 5149.4955 | AP26: =(total.profit.i-OR)/OR -> -0.6567003 | BI26: If adoption <=50%, labor=$3,000; else clipped Normal(2000,500). | BM26: 25 | BN26: =IF(BO26<=0.5,LC.mu,MIN(LC.mu,MAX(0,_xlfn.NORM.INV(RAND(),$C$20,LC.sd)))) -> 2672.4423 | BO26: =BETAINV(RAND(),AU.a,AU.b) -> 0.61502986 | BP26: =MAX(0,INT(Q0*(1+Ed*(BQ26-P0)/P0))) -> 11310 | BQ26: =P0*BN26/LC.mu -> 3.5632565 | BR26: =BQ26*BP26 -> 40300.431 | BS26: =BR26-BN26 -> 37627.988 | BT26: =(BS26-$C$21)/$C$21 -> 0.016972656
F27: 26 | G27: =INT(MAX(0,_xlfn.NORM.INV(RAND(),d.mu,d.sd))) -> 8228 | H27: =IF(demand<Q0,demand,Q0) -> 8228 | I27: =sale*P0*(1+SCP) -> 39494.4 | J27: =Q0*SC0*(1+SCP) -> 30000 | K27: 9494.4 | L27: =(total.profit-OR)/OR -> -0.36704 | AD27: 95% outcome intervals: BV16:BV21 (2.5th–97.5th percentiles). | AH27: 26 | AI27: =(IR.a+(IR.b-IR.a)*RAND()+1) -> 1.0322995 | AJ27: =IR.effect*P0*(1+SCP) -> 4.9550376 | AK27: =INT(Q0*(1+Ed*(price.change-P0)/P0)) -> 7134 | AL27: =IF(demand.i<Q0,demand.i,Q0) -> 7134 | AM27: =sales.i*price.change -> 35349.238 | AN27: =(SC0*(1+SCP)*IR.effect)*Q0 -> 30968.985 | AO27: =s.revenue.i-total.cost.i -> 4380.2532 | AP27: =(total.profit.i-OR)/OR -> -0.70798312 | BI27: Labor clipped to [$0,$3,000]; NOT resampled truncated normal. | BM27: 26 | BN27: =IF(BO27<=0.5,LC.mu,MIN(LC.mu,MAX(0,_xlfn.NORM.INV(RAND(),$C$20,LC.sd)))) -> 3000 | BO27: =BETAINV(RAND(),AU.a,AU.b) -> 0.46840251 | BP27: =MAX(0,INT(Q0*(1+Ed*(BQ27-P0)/P0))) -> 10000 | BQ27: =P0*BN27/LC.mu -> 4 | BR27: =BQ27*BP27 -> 40000 | BS27: =BR27-BN27 -> 37000 | BT27: =(BS27-$C$21)/$C$21 -> 0
F28: 27 | G28: =INT(MAX(0,_xlfn.NORM.INV(RAND(),d.mu,d.sd))) -> 7286 | H28: =IF(demand<Q0,demand,Q0) -> 7286 | I28: =sale*P0*(1+SCP) -> 34972.8 | J28: =Q0*SC0*(1+SCP) -> 30000 | K28: 4972.8 | L28: =(total.profit-OR)/OR -> -0.66848 | AD28: Only inflation rate is randomly sampled; demand is determined by price and Ed. | AH28: 27 | AI28: =(IR.a+(IR.b-IR.a)*RAND()+1) -> 1.0337624 | AJ28: =IR.effect*P0*(1+SCP) -> 4.9620596 | AK28: =INT(Q0*(1+Ed*(price.change-P0)/P0)) -> 7113 | AL28: =IF(demand.i<Q0,demand.i,Q0) -> 7113 | AM28: =sales.i*price.change -> 35295.13 | AN28: =(SC0*(1+SCP)*IR.effect)*Q0 -> 31012.873 | AO28: =s.revenue.i-total.cost.i -> 4282.2575 | AP28: =(total.profit.i-OR)/OR -> -0.71451617 | BI28: Price=P0*labor/3000; demand=Q0*[1+Ed*(price-P0)/P0]. | BM28: 27 | BN28: =IF(BO28<=0.5,LC.mu,MIN(LC.mu,MAX(0,_xlfn.NORM.INV(RAND(),$C$20,LC.sd)))) -> 1743.1821 | BO28: =BETAINV(RAND(),AU.a,AU.b) -> 0.72688705 | BP28: =MAX(0,INT(Q0*(1+Ed*(BQ28-P0)/P0))) -> 15027 | BQ28: =P0*BN28/LC.mu -> 2.3242428 | BR28: =BQ28*BP28 -> 34926.396 | BS28: =BR28-BN28 -> 33183.214 | BT28: =(BS28-$C$21)/$C$21 -> -0.10315637
F29: 28 | G29: =INT(MAX(0,_xlfn.NORM.INV(RAND(),d.mu,d.sd))) -> 6407 | H29: =IF(demand<Q0,demand,Q0) -> 6407 | I29: =sale*P0*(1+SCP) -> 30753.6 | J29: =Q0*SC0*(1+SCP) -> 30000 | K29: 753.6 | L29: =(total.profit-OR)/OR -> -0.94976 | AD29: AQ:AT = original repeated Monte Carlo estimates, not a 12-month operating series. | AH29: 28 | AI29: =(IR.a+(IR.b-IR.a)*RAND()+1) -> 1.0347852 | AJ29: =IR.effect*P0*(1+SCP) -> 4.9669687 | AK29: =INT(Q0*(1+Ed*(price.change-P0)/P0)) -> 7099 | AL29: =IF(demand.i<Q0,demand.i,Q0) -> 7099 | AM29: =sales.i*price.change -> 35260.511 | AN29: =(SC0*(1+SCP)*IR.effect)*Q0 -> 31043.555 | AO29: =s.revenue.i-total.cost.i -> 4216.9565 | AP29: =(total.profit.i-OR)/OR -> -0.71886957 | BI29: Only labor cost modeled; no inflation, supply chain, or sales cap. | BM29: 28 | BN29: =IF(BO29<=0.5,LC.mu,MIN(LC.mu,MAX(0,_xlfn.NORM.INV(RAND(),$C$20,LC.sd)))) -> 1904.4538 | BO29: =BETAINV(RAND(),AU.a,AU.b) -> 0.66975526 | BP29: =MAX(0,INT(Q0*(1+Ed*(BQ29-P0)/P0))) -> 14382 | BQ29: =P0*BN29/LC.mu -> 2.5392717 | BR29: =BQ29*BP29 -> 36519.805 | BS29: =BR29-BN29 -> 34615.351 | BT29: =(BS29-$C$21)/$C$21 -> -0.064449962
F30: 29 | G30: =INT(MAX(0,_xlfn.NORM.INV(RAND(),d.mu,d.sd))) -> 10709 | H30: =IF(demand<Q0,demand,Q0) -> 10000 | I30: =sale*P0*(1+SCP) -> 48000 | J30: =Q0*SC0*(1+SCP) -> 30000 | K30: 18000 | L30: =(total.profit-OR)/OR -> 0.2 | AD30: Unsold inventory yields no revenue; all 10,000 units' procurement cost is charged. | AH30: 29 | AI30: =(IR.a+(IR.b-IR.a)*RAND()+1) -> 1.0215383 | AJ30: =IR.effect*P0*(1+SCP) -> 4.9033837 | AK30: =INT(Q0*(1+Ed*(price.change-P0)/P0)) -> 7289 | AL30: =IF(demand.i<Q0,demand.i,Q0) -> 7289 | AM30: =sales.i*price.change -> 35740.764 | AN30: =(SC0*(1+SCP)*IR.effect)*Q0 -> 30646.148 | AO30: =s.revenue.i-total.cost.i -> 5094.6157 | AP30: =(total.profit.i-OR)/OR -> -0.66035895 | BI30: BK:BO retains original repeated Monte Carlo estimates, not months. | BM30: 29 | BN30: =IF(BO30<=0.5,LC.mu,MIN(LC.mu,MAX(0,_xlfn.NORM.INV(RAND(),$C$20,LC.sd)))) -> 1683.9892 | BO30: =BETAINV(RAND(),AU.a,AU.b) -> 0.77131306 | BP30: =MAX(0,INT(Q0*(1+Ed*(BQ30-P0)/P0))) -> 15264 | BQ30: =P0*BN30/LC.mu -> 2.245319 | BR30: =BQ30*BP30 -> 34272.549 | BS30: =BR30-BN30 -> 32588.56 | BT30: =(BS30-$C$21)/$C$21 -> -0.11922811
F31: 30 | G31: =INT(MAX(0,_xlfn.NORM.INV(RAND(),d.mu,d.sd))) -> 7536 | H31: =IF(demand<Q0,demand,Q0) -> 7536 | I31: =sale*P0*(1+SCP) -> 36172.8 | J31: =Q0*SC0*(1+SCP) -> 30000 | K31: 6172.8 | L31: =(total.profit-OR)/OR -> -0.58848 | AH31: 30 | AI31: =(IR.a+(IR.b-IR.a)*RAND()+1) -> 1.0266515 | AJ31: =IR.effect*P0*(1+SCP) -> 4.9279274 | AK31: =INT(Q0*(1+Ed*(price.change-P0)/P0)) -> 7216 | AL31: =IF(demand.i<Q0,demand.i,Q0) -> 7216 | AM31: =sales.i*price.change -> 35559.924 | AN31: =(SC0*(1+SCP)*IR.effect)*Q0 -> 30799.546 | AO31: =s.revenue.i-total.cost.i -> 4760.3779 | AP31: =(total.profit.i-OR)/OR -> -0.68264148 | BM31: 30 | BN31: =IF(BO31<=0.5,LC.mu,MIN(LC.mu,MAX(0,_xlfn.NORM.INV(RAND(),$C$20,LC.sd)))) -> 1510.0247 | BO31: =BETAINV(RAND(),AU.a,AU.b) -> 0.74721074 | BP31: =MAX(0,INT(Q0*(1+Ed*(BQ31-P0)/P0))) -> 15959 | BQ31: =P0*BN31/LC.mu -> 2.0133663 | BR31: =BQ31*BP31 -> 32131.313 | BS31: =BR31-BN31 -> 30621.288 | BT31: =(BS31-$C$21)/$C$21 -> -0.17239762
F32: 31 | G32: =INT(MAX(0,_xlfn.NORM.INV(RAND(),d.mu,d.sd))) -> 7138 | H32: =IF(demand<Q0,demand,Q0) -> 7138 | I32: =sale*P0*(1+SCP) -> 34262.4 | J32: =Q0*SC0*(1+SCP) -> 30000 | K32: 4262.4 | L32: =(total.profit-OR)/OR -> -0.71584 | AH32: 31 | AI32: =(IR.a+(IR.b-IR.a)*RAND()+1) -> 1.0430683 | AJ32: =IR.effect*P0*(1+SCP) -> 5.0067278 | AK32: =INT(Q0*(1+Ed*(price.change-P0)/P0)) -> 6979 | AL32: =IF(demand.i<Q0,demand.i,Q0) -> 6979 | AM32: =sales.i*price.change -> 34941.953 | AN32: =(SC0*(1+SCP)*IR.effect)*Q0 -> 31292.049 | AO32: =s.revenue.i-total.cost.i -> 3649.9046 | AP32: =(total.profit.i-OR)/OR -> -0.75667303 | BM32: 31 | BN32: =IF(BO32<=0.5,LC.mu,MIN(LC.mu,MAX(0,_xlfn.NORM.INV(RAND(),$C$20,LC.sd)))) -> 3000 | BO32: =BETAINV(RAND(),AU.a,AU.b) -> 0.28788807 | BP32: =MAX(0,INT(Q0*(1+Ed*(BQ32-P0)/P0))) -> 10000 | BQ32: =P0*BN32/LC.mu -> 4 | BR32: =BQ32*BP32 -> 40000 | BS32: =BR32-BN32 -> 37000 | BT32: =(BS32-$C$21)/$C$21 -> 0
F33: 32 | G33: =INT(MAX(0,_xlfn.NORM.INV(RAND(),d.mu,d.sd))) -> 7155 | H33: =IF(demand<Q0,demand,Q0) -> 7155 | I33: =sale*P0*(1+SCP) -> 34344 | J33: =Q0*SC0*(1+SCP) -> 30000 | K33: 4344 | L33: =(total.profit-OR)/OR -> -0.7104 | AH33: 32 | AI33: =(IR.a+(IR.b-IR.a)*RAND()+1) -> 1.0302596 | AJ33: =IR.effect*P0*(1+SCP) -> 4.9452463 | AK33: =INT(Q0*(1+Ed*(price.change-P0)/P0)) -> 7164 | AL33: =IF(demand.i<Q0,demand.i,Q0) -> 7164 | AM33: =sales.i*price.change -> 35427.744 | AN33: =(SC0*(1+SCP)*IR.effect)*Q0 -> 30907.789 | AO33: =s.revenue.i-total.cost.i -> 4519.9551 | AP33: =(total.profit.i-OR)/OR -> -0.69866966 | BM33: 32 | BN33: =IF(BO33<=0.5,LC.mu,MIN(LC.mu,MAX(0,_xlfn.NORM.INV(RAND(),$C$20,LC.sd)))) -> 1910.5555 | BO33: =BETAINV(RAND(),AU.a,AU.b) -> 0.83746365 | BP33: =MAX(0,INT(Q0*(1+Ed*(BQ33-P0)/P0))) -> 14357 | BQ33: =P0*BN33/LC.mu -> 2.5474073 | BR33: =BQ33*BP33 -> 36573.127 | BS33: =BR33-BN33 -> 34662.571 | BT33: =(BS33-$C$21)/$C$21 -> -0.063173746
F34: 33 | G34: =INT(MAX(0,_xlfn.NORM.INV(RAND(),d.mu,d.sd))) -> 8745 | H34: =IF(demand<Q0,demand,Q0) -> 8745 | I34: =sale*P0*(1+SCP) -> 41976 | J34: =Q0*SC0*(1+SCP) -> 30000 | K34: 11976 | L34: =(total.profit-OR)/OR -> -0.2016 | AH34: 33 | AI34: =(IR.a+(IR.b-IR.a)*RAND()+1) -> 1.0271125 | AJ34: =IR.effect*P0*(1+SCP) -> 4.9301399 | AK34: =INT(Q0*(1+Ed*(price.change-P0)/P0)) -> 7209 | AL34: =IF(demand.i<Q0,demand.i,Q0) -> 7209 | AM34: =sales.i*price.change -> 35541.379 | AN34: =(SC0*(1+SCP)*IR.effect)*Q0 -> 30813.375 | AO34: =s.revenue.i-total.cost.i -> 4728.0042 | AP34: =(total.profit.i-OR)/OR -> -0.68479972 | BM34: 33 | BN34: =IF(BO34<=0.5,LC.mu,MIN(LC.mu,MAX(0,_xlfn.NORM.INV(RAND(),$C$20,LC.sd)))) -> 3000 | BO34: =BETAINV(RAND(),AU.a,AU.b) -> 0.33213969 | BP34: =MAX(0,INT(Q0*(1+Ed*(BQ34-P0)/P0))) -> 10000 | BQ34: =P0*BN34/LC.mu -> 4 | BR34: =BQ34*BP34 -> 40000 | BS34: =BR34-BN34 -> 37000 | BT34: =(BS34-$C$21)/$C$21 -> 0
F35: 34 | G35: =INT(MAX(0,_xlfn.NORM.INV(RAND(),d.mu,d.sd))) -> 8511 | H35: =IF(demand<Q0,demand,Q0) -> 8511 | I35: =sale*P0*(1+SCP) -> 40852.8 | J35: =Q0*SC0*(1+SCP) -> 30000 | K35: 10852.8 | L35: =(total.profit-OR)/OR -> -0.27648 | AH35: 34 | AI35: =(IR.a+(IR.b-IR.a)*RAND()+1) -> 1.02815 | AJ35: =IR.effect*P0*(1+SCP) -> 4.9351198 | AK35: =INT(Q0*(1+Ed*(price.change-P0)/P0)) -> 7194 | AL35: =IF(demand.i<Q0,demand.i,Q0) -> 7194 | AM35: =sales.i*price.change -> 35503.252 | AN35: =(SC0*(1+SCP)*IR.effect)*Q0 -> 30844.499 | AO35: =s.revenue.i-total.cost.i -> 4658.7531 | AP35: =(total.profit.i-OR)/OR -> -0.68941646 | BM35: 34 | BN35: =IF(BO35<=0.5,LC.mu,MIN(LC.mu,MAX(0,_xlfn.NORM.INV(RAND(),$C$20,LC.sd)))) -> 926.03872 | BO35: =BETAINV(RAND(),AU.a,AU.b) -> 0.6063394 | BP35: =MAX(0,INT(Q0*(1+Ed*(BQ35-P0)/P0))) -> 18295 | BQ35: =P0*BN35/LC.mu -> 1.2347183 | BR35: =BQ35*BP35 -> 22589.171 | BS35: =BR35-BN35 -> 21663.133 | BT35: =(BS35-$C$21)/$C$21 -> -0.41450993
F36: 35 | G36: =INT(MAX(0,_xlfn.NORM.INV(RAND(),d.mu,d.sd))) -> 8441 | H36: =IF(demand<Q0,demand,Q0) -> 8441 | I36: =sale*P0*(1+SCP) -> 40516.8 | J36: =Q0*SC0*(1+SCP) -> 30000 | K36: 10516.8 | L36: =(total.profit-OR)/OR -> -0.29888 | AH36: 35 | AI36: =(IR.a+(IR.b-IR.a)*RAND()+1) -> 1.0476794 | AJ36: =IR.effect*P0*(1+SCP) -> 5.0288609 | AK36: =INT(Q0*(1+Ed*(price.change-P0)/P0)) -> 6913 | AL36: =IF(demand.i<Q0,demand.i,Q0) -> 6913 | AM36: =sales.i*price.change -> 34764.515 | AN36: =(SC0*(1+SCP)*IR.effect)*Q0 -> 31430.381 | AO36: =s.revenue.i-total.cost.i -> 3334.1348 | AP36: =(total.profit.i-OR)/OR -> -0.77772435 | BM36: 35 | BN36: =IF(BO36<=0.5,LC.mu,MIN(LC.mu,MAX(0,_xlfn.NORM.INV(RAND(),$C$20,LC.sd)))) -> 1340.4875 | BO36: =BETAINV(RAND(),AU.a,AU.b) -> 0.79647798 | BP36: =MAX(0,INT(Q0*(1+Ed*(BQ36-P0)/P0))) -> 16638 | BQ36: =P0*BN36/LC.mu -> 1.7873167 | BR36: =BQ36*BP36 -> 29737.376 | BS36: =BR36-BN36 -> 28396.888 | BT36: =(BS36-$C$21)/$C$21 -> -0.23251654
F37: 36 | G37: =INT(MAX(0,_xlfn.NORM.INV(RAND(),d.mu,d.sd))) -> 8795 | H37: =IF(demand<Q0,demand,Q0) -> 8795 | I37: =sale*P0*(1+SCP) -> 42216 | J37: =Q0*SC0*(1+SCP) -> 30000 | K37: 12216 | L37: =(total.profit-OR)/OR -> -0.1856 | AH37: 36 | AI37: =(IR.a+(IR.b-IR.a)*RAND()+1) -> 1.0247683 | AJ37: =IR.effect*P0*(1+SCP) -> 4.9188877 | AK37: =INT(Q0*(1+Ed*(price.change-P0)/P0)) -> 7243 | AL37: =IF(demand.i<Q0,demand.i,Q0) -> 7243 | AM37: =sales.i*price.change -> 35627.503 | AN37: =(SC0*(1+SCP)*IR.effect)*Q0 -> 30743.048 | AO37: =s.revenue.i-total.cost.i -> 4884.4554 | AP37: =(total.profit.i-OR)/OR -> -0.67436964 | BM37: 36 | BN37: =IF(BO37<=0.5,LC.mu,MIN(LC.mu,MAX(0,_xlfn.NORM.INV(RAND(),$C$20,LC.sd)))) -> 2502.2807 | BO37: =BETAINV(RAND(),AU.a,AU.b) -> 0.60695373 | BP37: =MAX(0,INT(Q0*(1+Ed*(BQ37-P0)/P0))) -> 11990 | BQ37: =P0*BN37/LC.mu -> 3.3363742 | BR37: =BQ37*BP37 -> 40003.127 | BS37: =BR37-BN37 -> 37500.846 | BT37: =(BS37-$C$21)/$C$21 -> 0.013536389
F38: 37 | G38: =INT(MAX(0,_xlfn.NORM.INV(RAND(),d.mu,d.sd))) -> 8232 | H38: =IF(demand<Q0,demand,Q0) -> 8232 | I38: =sale*P0*(1+SCP) -> 39513.6 | J38: =Q0*SC0*(1+SCP) -> 30000 | K38: 9513.6 | L38: =(total.profit-OR)/OR -> -0.36576 | AH38: 37 | AI38: =(IR.a+(IR.b-IR.a)*RAND()+1) -> 1.0211706 | AJ38: =IR.effect*P0*(1+SCP) -> 4.9016188 | AK38: =INT(Q0*(1+Ed*(price.change-P0)/P0)) -> 7295 | AL38: =IF(demand.i<Q0,demand.i,Q0) -> 7295 | AM38: =sales.i*price.change -> 35757.309 | AN38: =(SC0*(1+SCP)*IR.effect)*Q0 -> 30635.117 | AO38: =s.revenue.i-total.cost.i -> 5122.1916 | AP38: =(total.profit.i-OR)/OR -> -0.65852056 | BM38: 37 | BN38: =IF(BO38<=0.5,LC.mu,MIN(LC.mu,MAX(0,_xlfn.NORM.INV(RAND(),$C$20,LC.sd)))) -> 1084.7354 | BO38: =BETAINV(RAND(),AU.a,AU.b) -> 0.68404344 | BP38: =MAX(0,INT(Q0*(1+Ed*(BQ38-P0)/P0))) -> 17661 | BQ38: =P0*BN38/LC.mu -> 1.4463138 | BR38: =BQ38*BP38 -> 25543.349 | BS38: =BR38-BN38 -> 24458.613 | BT38: =(BS38-$C$21)/$C$21 -> -0.3389564
F39: 38 | G39: =INT(MAX(0,_xlfn.NORM.INV(RAND(),d.mu,d.sd))) -> 7047 | H39: =IF(demand<Q0,demand,Q0) -> 7047 | I39: =sale*P0*(1+SCP) -> 33825.6 | J39: =Q0*SC0*(1+SCP) -> 30000 | K39: 3825.6 | L39: =(total.profit-OR)/OR -> -0.74496 | AH39: 38 | AI39: =(IR.a+(IR.b-IR.a)*RAND()+1) -> 1.0298241 | AJ39: =IR.effect*P0*(1+SCP) -> 4.9431558 | AK39: =INT(Q0*(1+Ed*(price.change-P0)/P0)) -> 7170 | AL39: =IF(demand.i<Q0,demand.i,Q0) -> 7170 | AM39: =sales.i*price.change -> 35442.427 | AN39: =(SC0*(1+SCP)*IR.effect)*Q0 -> 30894.724 | AO39: =s.revenue.i-total.cost.i -> 4547.7033 | AP39: =(total.profit.i-OR)/OR -> -0.69681978 | BM39: 38 | BN39: =IF(BO39<=0.5,LC.mu,MIN(LC.mu,MAX(0,_xlfn.NORM.INV(RAND(),$C$20,LC.sd)))) -> 874.52489 | BO39: =BETAINV(RAND(),AU.a,AU.b) -> 0.77451449 | BP39: =MAX(0,INT(Q0*(1+Ed*(BQ39-P0)/P0))) -> 18501 | BQ39: =P0*BN39/LC.mu -> 1.1660332 | BR39: =BQ39*BP39 -> 21572.78 | BS39: =BR39-BN39 -> 20698.255 | BT39: =(BS39-$C$21)/$C$21 -> -0.4405877
F40: 39 | G40: =INT(MAX(0,_xlfn.NORM.INV(RAND(),d.mu,d.sd))) -> 8609 | H40: =IF(demand<Q0,demand,Q0) -> 8609 | I40: =sale*P0*(1+SCP) -> 41323.2 | J40: =Q0*SC0*(1+SCP) -> 30000 | K40: 11323.2 | L40: =(total.profit-OR)/OR -> -0.24512 | AH40: 39 | AI40: =(IR.a+(IR.b-IR.a)*RAND()+1) -> 1.0392632 | AJ40: =IR.effect*P0*(1+SCP) -> 4.9884632 | AK40: =INT(Q0*(1+Ed*(price.change-P0)/P0)) -> 7034 | AL40: =IF(demand.i<Q0,demand.i,Q0) -> 7034 | AM40: =sales.i*price.change -> 35088.85 | AN40: =(SC0*(1+SCP)*IR.effect)*Q0 -> 31177.895 | AO40: =s.revenue.i-total.cost.i -> 3910.9552 | AP40: =(total.profit.i-OR)/OR -> -0.73926966 | BM40: 39 | BN40: =IF(BO40<=0.5,LC.mu,MIN(LC.mu,MAX(0,_xlfn.NORM.INV(RAND(),$C$20,LC.sd)))) -> 1224.7559 | BO40: =BETAINV(RAND(),AU.a,AU.b) -> 0.94312917 | BP40: =MAX(0,INT(Q0*(1+Ed*(BQ40-P0)/P0))) -> 17100 | BQ40: =P0*BN40/LC.mu -> 1.6330079 | BR40: =BQ40*BP40 -> 27924.434 | BS40: =BR40-BN40 -> 26699.678 | BT40: =(BS40-$C$21)/$C$21 -> -0.27838707
...

Sheet Sim3_Replications
A1: Replication | B1: App adoption | C1: Labor cost | D1: Price | E1: Demand | F1: Profit
A2: 1 | B2: =BETAINV(RAND(),AU.a,AU.b) -> 0.60903954 | C2: =IF(B2<=0.5,LC.mu,MIN(LC.mu,MAX(0,_xlfn.NORM.INV(RAND(),2000,LC.sd)))) -> 1328.5689 | D2: =P0*C2/LC.mu -> 1.7714251 | E2: =MAX(0,INT(Q0*(1+Ed*(D2-P0)/P0))) -> 16685 | F2: =D2*E2-C2 -> 28227.66
A3: 1 | B3: =BETAINV(RAND(),AU.a,AU.b) -> 0.57899025 | C3: =IF(B3<=0.5,LC.mu,MIN(LC.mu,MAX(0,_xlfn.NORM.INV(RAND(),2000,LC.sd)))) -> 1079.2521 | D3: =P0*C3/LC.mu -> 1.4390029 | E3: =MAX(0,INT(Q0*(1+Ed*(D3-P0)/P0))) -> 17682 | F3: =D3*E3-C3 -> 24365.196
A4: 1 | B4: =BETAINV(RAND(),AU.a,AU.b) -> 0.37054833 | C4: =IF(B4<=0.5,LC.mu,MIN(LC.mu,MAX(0,_xlfn.NORM.INV(RAND(),2000,LC.sd)))) -> 3000 | D4: =P0*C4/LC.mu -> 4 | E4: =MAX(0,INT(Q0*(1+Ed*(D4-P0)/P0))) -> 10000 | F4: =D4*E4-C4 -> 37000
A5: 1 | B5: =BETAINV(RAND(),AU.a,AU.b) -> 0.75447221 | C5: =IF(B5<=0.5,LC.mu,MIN(LC.mu,MAX(0,_xlfn.NORM.INV(RAND(),2000,LC.sd)))) -> 2321.0404 | D5: =P0*C5/LC.mu -> 3.0947205 | E5: =MAX(0,INT(Q0*(1+Ed*(D5-P0)/P0))) -> 12715 | F5: =D5*E5-C5 -> 37028.331
A6: 1 | B6: =BETAINV(RAND(),AU.a,AU.b) -> 0.20293726 | C6: =IF(B6<=0.5,LC.mu,MIN(LC.mu,MAX(0,_xlfn.NORM.INV(RAND(),2000,LC.sd)))) -> 3000 | D6: =P0*C6/LC.mu -> 4 | E6: =MAX(0,INT(Q0*(1+Ed*(D6-P0)/P0))) -> 10000 | F6: =D6*E6-C6 -> 37000
A7: 1 | B7: =BETAINV(RAND(),AU.a,AU.b) -> 0.68347827 | C7: =IF(B7<=0.5,LC.mu,MIN(LC.mu,MAX(0,_xlfn.NORM.INV(RAND(),2000,LC.sd)))) -> 1938.3472 | D7: =P0*C7/LC.mu -> 2.5844629 | E7: =MAX(0,INT(Q0*(1+Ed*(D7-P0)/P0))) -> 14246 | F7: =D7*E7-C7 -> 34879.911
A8: 1 | B8: =BETAINV(RAND(),AU.a,AU.b) -> 0.54489494 | C8: =IF(B8<=0.5,LC.mu,MIN(LC.mu,MAX(0,_xlfn.NORM.INV(RAND(),2000,LC.sd)))) -> 1393.6207 | D8: =P0*C8/LC.mu -> 1.858161 | E8: =MAX(0,INT(Q0*(1+Ed*(D8-P0)/P0))) -> 16425 | F8: =D8*E8-C8 -> 29126.673
A9: 1 | B9: =BETAINV(RAND(),AU.a,AU.b) -> 0.51490201 | C9: =IF(B9<=0.5,LC.mu,MIN(LC.mu,MAX(0,_xlfn.NORM.INV(RAND(),2000,LC.sd)))) -> 2237.3894 | D9: =P0*C9/LC.mu -> 2.9831858 | E9: =MAX(0,INT(Q0*(1+Ed*(D9-P0)/P0))) -> 13050 | F9: =D9*E9-C9 -> 36693.185
A10: 1 | B10: =BETAINV(RAND(),AU.a,AU.b) -> 0.86166198 | C10: =IF(B10<=0.5,LC.mu,MIN(LC.mu,MAX(0,_xlfn.NORM.INV(RAND(),2000,LC.sd)))) -> 2079.4103 | D10: =P0*C10/LC.mu -> 2.772547 | E10: =MAX(0,INT(Q0*(1+Ed*(D10-P0)/P0))) -> 13682 | F10: =D10*E10-C10 -> 35854.578
A11: 1 | B11: =BETAINV(RAND(),AU.a,AU.b) -> 0.571929 | C11: =IF(B11<=0.5,LC.mu,MIN(LC.mu,MAX(0,_xlfn.NORM.INV(RAND(),2000,LC.sd)))) -> 2346.8466 | D11: =P0*C11/LC.mu -> 3.1291288 | E11: =MAX(0,INT(Q0*(1+Ed*(D11-P0)/P0))) -> 12612 | F11: =D11*E11-C11 -> 37117.725
A12: 1 | B12: =BETAINV(RAND(),AU.a,AU.b) -> 0.7418074 | C12: =IF(B12<=0.5,LC.mu,MIN(LC.mu,MAX(0,_xlfn.NORM.INV(RAND(),2000,LC.sd)))) -> 1258.0632 | D12: =P0*C12/LC.mu -> 1.6774176 | E12: =MAX(0,INT(Q0*(1+Ed*(D12-P0)/P0))) -> 16967 | F12: =D12*E12-C12 -> 27202.682
A13: 1 | B13: =BETAINV(RAND(),AU.a,AU.b) -> 0.58219418 | C13: =IF(B13<=0.5,LC.mu,MIN(LC.mu,MAX(0,_xlfn.NORM.INV(RAND(),2000,LC.sd)))) -> 1519.961 | D13: =P0*C13/LC.mu -> 2.0266147 | E13: =MAX(0,INT(Q0*(1+Ed*(D13-P0)/P0))) -> 15920 | F13: =D13*E13-C13 -> 30743.745
... A12001: 12 | B12001: =BETAINV(RAND(),AU.a,AU.b) -> 0.58051606 | C12001: =IF(B12001<=0.5,LC.mu,MIN(LC.mu,MAX(0,_xlfn.NORM.INV(RAND(),2000,LC.sd)))) -> 2129.1337 | D12001: =P0*C12001/LC.mu -> 2.8388449 | E12001: =MAX(0,INT(Q0*(1+Ed*(D12001-P0)/P0))) -> 13483 | F12001: =D12001*E12001-C12001 -> 36147.012
