Workbook
Name K: '1_First_Price'!$C$3
Name K_2: '2_Second_Price'!$C$3
Name N_a: '1_First_Price'!$C$1
Name N_a2: '2_Second_Price'!$C$1
Name N_c1: '1_First_Price'!$C$4
Name N_c12: '2_Second_Price'!$C$4
Name N_c2: '1_First_Price'!$C$5
Name N_c22: '2_Second_Price'!$C$5
Name xi: '1_First_Price'!$C$2
Name xi_2: '2_Second_Price'!$C$2

Sheet 00_READ_ME
A1: AUCTION MECHANISMS | RESEARCH PORTFOLIO
A2: Optimal bidding, seller revenue and Monte Carlo evidence | Keman Xiang
A4: THE DECISION PROBLEM
A5: Case context
A6: A seller (CA) allocates a single parcel of land through a sealed-bid auction. Competing buyers privately know their willingness to pay; neither the seller nor competing buyers observes another buyer’s true value before bidding.
A8: Two competing auction designs
A9: First-price: the highest bidder wins and pays their own bid (Dutch-equivalent allocation/payment). Second-price: the highest bidder wins but pays the second-highest bid (English-equivalent allocation/payment).
A11: The buyer’s optimization problem
A12: You are bidder 1. Select a bidding fraction x of your private valuation to maximize expected net surplus, balancing the probability of winning against the payment conditional on winning.
A14: The seller’s decision problem
A15: CA evaluates expected revenue across bidder populations and bidding behavior. A strategy that raises revenue for the seller need not be individually optimal for bidder 1.
A17: Research questions
... A48: 1_First_Price and 2_Second_Price contain the original auction calculations and 12 original charts. MC_Random_N2, N5 and N10 contain frozen private valuations.

Sheet 01_RESEARCH_MODEL
A1: RESEARCH MODEL | ECONOMIC ENVIRONMENT
A2: A one-unit, independent-private-values auction with risk-neutral buyers
A4: MARKET AND INFORMATION STRUCTURE
A5: Asset and seller
A6: CA sells one indivisible parcel of land. There is exactly one winner; competition is among N = 2, 5 or 10 prospective buyers.
A8: Private values
A9: Each buyer i draws v_i independently from Uniform[0,1] million dollars. Each buyer knows their own v_i and the common distribution, but not the realized values of competitors.
A11: Risk neutrality and incentives
A12: A buyer receives value v_i only upon winning and pays according to the mechanism. The optimization criterion is expected monetary surplus, not risk-adjusted utility.
A14: Strategy set and focal bidder
A15: Bidder 1 chooses b_1(x) = x*v_1, x in {0.1,0.2,...,1.0}. Other bidders follow mechanism-specific bidding rules held fixed within each experiment.
A19: ALLOCATION, PAYMENT AND PAYOFFS
... A49: Revenue equivalence concerns equilibrium expected revenue, not revenue for every off-equilibrium x or identical revenue on each simulated path. Deviations at K=1,000 can arise from sampling variability.

Sheet 02_SIMULATION_DESIGN
A1: SIMULATION DESIGN | CONTROLLED COMPARISON
A2: A reproducible 2 x 3 x 10 experiment with 1,000 independent valuation draws per N
A4: EXPERIMENT FACTORS
A5: Dimension | B5: Setting | C5: Why it matters
A6: Mechanism | B6: First-price; second-price | C6: Changes payment rule and competing-bid assumptions
A7: Bidders (N) | B7: 2, 5, 10 | C7: Tests how competition changes surplus and revenue
A8: Bidder 1 fraction (x) | B8: 0.1 to 1.0, step 0.1 | C8: Tests bid shading against win probability
A9: Replications (K) | B9: 1,000 for each N | C9: Monte Carlo estimation of conditional expected outcomes
A10: Random valuations | B10: Frozen Uniform[0,1] draws | C10: Makes numerical results reproducible
A11: Outputs | B11: Surplus and seller revenue | C11: Separates buyer and seller objectives
A14: REPLICATION PROCEDURE
A15: 1 | Generate a valuation vector
A16: For each N and replicate k, read one row of MC_Random_N2/N5/N10. Columns B onward are private valuations for bidder 1 and N-1 competitors.
A18: 2 | Form the bids
A19: Set b_1=x*v_1. For first-price, competitor bids are (1-1/N)*v_i. For second-price, competitor bids are v_i.
A21: 3 | Determine allocation and payment
A22: The highest bid wins. First-price winner pays highest bid; second-price winner pays second-highest bid. Bidder 1 receives zero surplus if they lose.
A24: 4 | Store the sample-path outcome
A25: Each of the 12 data tables records 1,000 rows (replications) by 10 columns (strategy x). One table per mechanism x N x outcome.
A27: 5 | Estimate and compare
A28: Take column averages to obtain ES_N(x) and ER_N(x). Find surplus-maximizing x; compare seller revenue at the respective equilibrium strategies.
A30: 6 | Diagnose simulation noise
... A47: Continuous Uniform valuations imply exact ties occur with probability zero theoretically. The spreadsheet uses >= comparisons to assign a win in a numerical tie; ties are not a material theoretical driver.

Sheet 08_CALCULATION_GUIDE
A1: CALCULATION GUIDE | MODEL AUDIT TRAIL
A2: A cell-level reader’s guide to sample paths, simulation grids, STAT and questions
A4: ORIGINAL WORKSHEETS AND THE SAMPLE PATH
A5: 1_First_Price | sample path
A6: Inputs C1:C5 specify bidder count N, strategy x, replications K and alternative bidder counts. Columns G:L contain bidder ID, valuation v, bid, winning indicator, payment and surplus for a representative auction. P2 records the highest bid, the seller’s first-price revenue.
A8: 2_Second_Price | sample path
A9: The same bidder-level logic applies, but opponents bid their full valuations and the winning payment equals the second-highest bid. P2 uses the second-largest bid to represent seller revenue.
A11: What a sample path is
A12: One simulated auction realization: draw private values, calculate each bid, identify the winner, apply the payment rule and compute each bidder’s realized surplus. It is a single outcome, not an expected value.
A14: STAT / expected-value summaries
A15: STAT-style summary cells average the 1,000 sample-path outputs for each strategy. ES(x) estimates bidder 1 expected surplus; ER(x) estimates CA expected revenue. Averages are Monte Carlo estimators, not individual bids or probabilities.
A17: Frozen valuation worksheets
... A22: ALL 12 MONTE CARLO TABLES | EXACT CELL MAP
A23: Mechanism | B23: N | C23: Outcome | D23: Sample-path grid | E23: Strategies (x) | F23: STAT range | G23: Meaning | H23: Replications
A24: First-price | B24: 2 | C24: Surplus | D24: T2:AC1001 | E24: T1:AC1 | F24: AG1:AG10 | G24: Bidder 1 net surplus | H24: 1000
A25: First-price | B25: 2 | C25: Revenue | D25: AQ2:AZ1001 | E25: AQ1:AZ1 | F25: BD1:BD10 | G25: Seller payment | H25: 1000
A26: Second-price | B26: 2 | C26: Surplus | D26: T2:AC1001 | E26: T1:AC1 | F26: AG1:AG10 | G26: Bidder 1 net surplus | H26: 1000
A27: Second-price | B27: 2 | C27: Revenue | D27: AP2:AY1001 | E27: AP1:AY1 | F27: BC1:BC10 | G27: Seller payment | H27: 1000
A28: First-price | B28: 5 | C28: Surplus | D28: CH2:CQ1001 | E28: CH1:CQ1 | F28: CU1:CU10 | G28: Bidder 1 net surplus | H28: 1000
A29: First-price | B29: 5 | C29: Revenue | D29: DE2:DN1001 | E29: DE1:DN1 | F29: DR1:DR10 | G29: Seller payment | H29: 1000
A30: Second-price | B30: 5 | C30: Surplus | D30: BU2:CD1001 | E30: BU1:CD1 | F30: CH1:CH10 | G30: Bidder 1 net surplus | H30: 1000
A31: Second-price | B31: 5 | C31: Revenue | D31: CQ2:CZ1001 | E31: CQ1:CZ1 | F31: DD1:DD10 | G31: Seller payment | H31: 1000
A32: First-price | B32: 10 | C32: Surplus | D32: EK2:ET1001 | E32: EK1:ET1 | F32: EX1:EX10 | G32: Bidder 1 net surplus | H32: 1000
A33: First-price | B33: 10 | C33: Revenue | D33: FG2:FP1001 | E33: FG1:FP1 | F33: FT1:FT10 | G33: Seller payment | H33: 1000
A34: Second-price | B34: 10 | C34: Surplus | D34: DV2:EE1001 | E34: DV1:EE1 | F34: EI1:EI10 | G34: Bidder 1 net surplus | H34: 1000
A35: Second-price | B35: 10 | C35: Revenue | D35: ER2:FA1001 | E35: ER1:FA1 | F35: FE1:FE10 | G35: Seller payment | H35: 1000
A38: QUESTION-BY-QUESTION RESEARCH OBJECTIVES
A39: First-price | Q(a)
A40: For N=2, calculate and plot bidder 1 ES(x) across ten x values; find surplus-maximizing x*; calculate and plot seller ER(x). Separates the two objective functions in a simple two-bidder market.
A42: First-price | Q(b)
A43: Ask whether CA can attain the highest revenue shown across x. Tests the distinction between an ex-post seller-favorable bid and the bidder’s privately optimal strategy.
A45: First-price | Q(c)
A46: Repeat the surplus and revenue exercise for N=5 and N=10. Isolate the effect of stronger competition on bid shading, surplus and revenue.
A48: First-price | Q(d)
A49: Generalize to arbitrary N. Identify equilibrium x*=(N-1)/N and equilibrium expected seller revenue (N-1)/(N+1).
A51: Second-price | Q(a)
A52: For N=2, evaluate surplus-maximizing x and seller revenue across x. Highlight the payment rule based on the second-highest bid.
A54: Second-price | Q(b)
... A91: SD measures path-to-path dispersion; SE=SD/sqrt(K) measures uncertainty in the estimated mean; approximate 95% CI uses mean +/-1.96 SE.

Sheet 1_First_Price
A1: INPUT | B1: N_a | C1: 10 | E1: Qa) | F1: SAMPLE PATH | G1: ID | H1: vi | I1: bi | J1: wi | K1: payi | L1: Si | N1: STAT | O1: S1(x) | P1: =L2 -> 0 | R1: DATA TABLE | S1: =P1 -> 0 | T1: 0.1 | U1: 0.2 | V1: 0.3 | W1: 0.4 | X1: 0.5 | Y1: 0.6 | Z1: 0.7 | AA1: 0.8 | AB1: 0.9 | AC1: 1 | AE1: 0.1 | AF1: ES(0.1) | AG1: =AVERAGE(T2:T1001) -> 0.059761192 | AO1: DATA TABLE | AP1: =P2 -> 0.74418577 | AQ1: 0.1 | AR1: 0.2 | AS1: 0.3 | AT1: 0.4 | AU1: 0.5 | AV1: 0.6 | AW1: 0.7 | AX1: 0.8 | AY1: 0.9 | AZ1: 1 | BB1: 0.1 | BC1: ER(0.1) | BD1: =AVERAGE(AQ2:AQ1001) -> 0.25572136 | BH1: Qb) | BI1: CA can not achieve the maximal expected revenue among R2(x). | BS1: Qc) | BT1: N=5 | BU1: ID | BV1: vi | BW1: bi | BX1: wi | BY1: payi | BZ1: Si | CB1: STAT | CC1: S1(x) | CD1: =BZ2 -> 0 | CF1: DATA TABLE | CG1: =CD1 -> 0 | CH1: 0.1 | CI1: 0.2 | CJ1: 0.3 | CK1: 0.4 | CL1: 0.5 | CM1: 0.6 | CN1: 0.7 | CO1: 0.8 | CP1: 0.9 | CQ1: 1 | CS1: 0.1 | CT1: ES(0.1) | CU1: =AVERAGE(CH2:CH1001) -> 0 | DC1: DATA TABLE | DD1: =CD2 -> 0.76371113 | DE1: 0.1 | DF1: 0.2 | DG1: 0.3 | DH1: 0.4 | DI1: 0.5 | DJ1: 0.6 | DK1: 0.7 | DL1: 0.8 | DM1: 0.9 | DN1: 1 | DP1: 0.1 | DQ1: ER(0.1) | DR1: =AVERAGE(DE2:DE1001) -> 0.63560466 | DV1: N=10 | DW1: SAMPLE PATH | DX1: ID | DY1: vi | DZ1: bi | EA1: wi | EB1: payi | EC1: Si | EE1: STAT | EF1: S1(x) | EG1: =EC2 -> 0 | EI1: DATA TABLE | EJ1: =EG1 -> 0 | EK1: 0.1 | EL1: 0.2 | EM1: 0.3 | EN1: 0.4 | EO1: 0.5 | EP1: 0.6 | EQ1: 0.7 | ER1: 0.8 | ES1: 0.9 | ET1: 1 | EV1: 0.1 | EW1: ES(0.1) | EX1: =AVERAGE(EK2:EK1001) -> 0 | FE1: DATA TABLE | FF1: =EG2 -> 0.86317859 | FG1: 0.1 | FH1: 0.2 | FI1: 0.3 | FJ1: 0.4 | FK1: 0.5 | FL1: 0.6 | FM1: 0.7 | FN1: 0.8 | FO1: 0.9 | FP1: 1 | FR1: 0.1 | FS1: ER(0.1) | FT1: =AVERAGE(FG2:FG1001) -> 0.80898303 | FV1: Qd) | FW1: Under the assumed independent uniform private valuations and symmetric risk-neutral equilibrium, the optimal first-price bidding strategy is x*=(N-1)/N. Thus, x*=0.5, 0.8, and 0.9 for N=2, 5, and 10, respectively.
B2: xi | C2: 0.1 | G2: 1 | H2: =RAND() -> 0.72843531 | I2: =xi*H2 -> 0.072843531 | J2: =IF(I2=MAX(I2:I3),1,0) -> 0 | K2: =J2*I2 -> 0 | L2: =J2*(H2-K2) -> 0 | O2: R2(x) | P2: =MAX(I2:I3) -> 0.74418577 | S2: {=_xlfn.SEQUENCE(1000)} -> 1 | T2: =IF(T$1*MC_Random_N2!$B2>=0.5*MC_Random_N2!$C2,MC_Random_N2!$B2*(1-T$1),0) -> 0 | U2: =IF(U$1*MC_Random_N2!$B2>=0.5*MC_Random_N2!$C2,MC_Random_N2!$B2*(1-U$1),0) -> 0 | V2: =IF(V$1*MC_Random_N2!$B2>=0.5*MC_Random_N2!$C2,MC_Random_N2!$B2*(1-V$1),0) -> 0 | W2: =IF(W$1*MC_Random_N2!$B2>=0.5*MC_Random_N2!$C2,MC_Random_N2!$B2*(1-W$1),0) -> 0 | X2: =IF(X$1*MC_Random_N2!$B2>=0.5*MC_Random_N2!$C2,MC_Random_N2!$B2*(1-X$1),0) -> 0 | Y2: =IF(Y$1*MC_Random_N2!$B2>=0.5*MC_Random_N2!$C2,MC_Random_N2!$B2*(1-Y$1),0) -> 0 | Z2: =IF(Z$1*MC_Random_N2!$B2>=0.5*MC_Random_N2!$C2,MC_Random_N2!$B2*(1-Z$1),0) -> 0 | AA2: =IF(AA$1*MC_Random_N2!$B2>=0.5*MC_Random_N2!$C2,MC_Random_N2!$B2*(1-AA$1),0) -> 0.098422842 | ... AC2: =IF(AC$1*MC_Random_N2!$B2>=0.5*MC_Random_N2!$C2,MC_Random_N2!$B2*(1-AC$1),0) -> 0 | AE2: 0.2 | AF2: ES(0.2) | AG2: =AVERAGE(U2:U1001) -> 0.10789344 | AP2: {=_xlfn.SEQUENCE(1000)} -> 1 | AQ2: =MAX(AQ$1*MC_Random_N2!$B2,0.5*MC_Random_N2!$C2) -> 0.36866346 | AR2: =MAX(AR$1*MC_Random_N2!$B2,0.5*MC_Random_N2!$C2) -> 0.36866346 | AS2: =MAX(AS$1*MC_Random_N2!$B2,0.5*MC_Random_N2!$C2) -> 0.36866346 | AT2: =MAX(AT$1*MC_Random_N2!$B2,0.5*MC_Random_N2!$C2) -> 0.36866346 | AU2: =MAX(AU$1*MC_Random_N2!$B2,0.5*MC_Random_N2!$C2) -> 0.36866346 | AV2: =MAX(AV$1*MC_Random_N2!$B2,0.5*MC_Random_N2!$C2) -> 0.36866346 | AW2: =MAX(AW$1*MC_Random_N2!$B2,0.5*MC_Random_N2!$C2) -> 0.36866346 | AX2: =MAX(AX$1*MC_Random_N2!$B2,0.5*MC_Random_N2!$C2) -> 0.39369137 | ... AZ2: =MAX(AZ$1*MC_Random_N2!$B2,0.5*MC_Random_N2!$C2) -> 0.49211421 | BB2: 0.2 | BC2: ER(0.2) | BD2: =AVERAGE(AR2:AR1001) -> 0.26535513 | BI2: Because the bider will choose the optimal strategy x* to maximaze his surplus, thus R2(x*) will not be the maximal value. | BU2: {=_xlfn.SEQUENCE(5)} -> 1 | BV2: =RAND() -> 0.035776351 | BW2: =xi*BV2 -> 0.0035776351 | BX2: =IF(BW2=MAX($BW$2:$BW$6),1,0) -> 0 | BY2: =BX2*BW2 -> 0 | BZ2: =BX2*(BV2-BY2) -> 0 | CC2: R2(x) | CD2: =MAX(BW2:BW6) -> 0.76371113 | CG2: {=_xlfn.SEQUENCE(1000)} -> 1 | CH2: =IF(CH$1*MC_Random_N5!$B2>=0.8*MAX(MC_Random_N5!$C2:$F2),MC_Random_N5!$B2*(1-CH$1),0) -> 0 | CI2: =IF(CI$1*MC_Random_N5!$B2>=0.8*MAX(MC_Random_N5!$C2:$F2),MC_Random_N5!$B2*(1-CI$1),0) -> 0 | CJ2: =IF(CJ$1*MC_Random_N5!$B2>=0.8*MAX(MC_Random_N5!$C2:$F2),MC_Random_N5!$B2*(1-CJ$1),0) -> 0 | CK2: =IF(CK$1*MC_Random_N5!$B2>=0.8*MAX(MC_Random_N5!$C2:$F2),MC_Random_N5!$B2*(1-CK$1),0) -> 0 | CL2: =IF(CL$1*MC_Random_N5!$B2>=0.8*MAX(MC_Random_N5!$C2:$F2),MC_Random_N5!$B2*(1-CL$1),0) -> 0 | CM2: =IF(CM$1*MC_Random_N5!$B2>=0.8*MAX(MC_Random_N5!$C2:$F2),MC_Random_N5!$B2*(1-CM$1),0) -> 0 | CN2: =IF(CN$1*MC_Random_N5!$B2>=0.8*MAX(MC_Random_N5!$C2:$F2),MC_Random_N5!$B2*(1-CN$1),0) -> 0 | CO2: =IF(CO$1*MC_Random_N5!$B2>=0.8*MAX(MC_Random_N5!$C2:$F2),MC_Random_N5!$B2*(1-CO$1),0) -> 0 | ... CQ2: =IF(CQ$1*MC_Random_N5!$B2>=0.8*MAX(MC_Random_N5!$C2:$F2),MC_Random_N5!$B2*(1-CQ$1),0) -> 0 | CS2: 0.2 | CT2: ES(0.2) | CU2: =AVERAGE(CI2:CI1001) -> 0.0014045626 | DD2: {=_xlfn.SEQUENCE(1000)} -> 1 | DE2: =MAX(DE$1*MC_Random_N5!$B2,0.8*MAX(MC_Random_N5!$C2:$F2)) -> 0.78035436 | DF2: =MAX(DF$1*MC_Random_N5!$B2,0.8*MAX(MC_Random_N5!$C2:$F2)) -> 0.78035436 | DG2: =MAX(DG$1*MC_Random_N5!$B2,0.8*MAX(MC_Random_N5!$C2:$F2)) -> 0.78035436 | DH2: =MAX(DH$1*MC_Random_N5!$B2,0.8*MAX(MC_Random_N5!$C2:$F2)) -> 0.78035436 | DI2: =MAX(DI$1*MC_Random_N5!$B2,0.8*MAX(MC_Random_N5!$C2:$F2)) -> 0.78035436 | DJ2: =MAX(DJ$1*MC_Random_N5!$B2,0.8*MAX(MC_Random_N5!$C2:$F2)) -> 0.78035436 | DK2: =MAX(DK$1*MC_Random_N5!$B2,0.8*MAX(MC_Random_N5!$C2:$F2)) -> 0.78035436 | DL2: =MAX(DL$1*MC_Random_N5!$B2,0.8*MAX(MC_Random_N5!$C2:$F2)) -> 0.78035436 | ... DN2: =MAX(DN$1*MC_Random_N5!$B2,0.8*MAX(MC_Random_N5!$C2:$F2)) -> 0.78035436 | DP2: 0.2 | DQ2: ER(0.2) | DR2: =AVERAGE(DF2:DF1001) -> 0.63565573 | DX2: {=_xlfn.SEQUENCE(10)} -> 1 | DY2: =RAND() -> 0.79417796 | DZ2: =xi*DY2 -> 0.079417796 | EA2: =IF(DZ2=MAX($DZ$2:$DZ$11),1,0) -> 0 | EB2: =EA2*DZ2 -> 0 | EC2: =EA2*(DY2-EB2) -> 0 | EF2: R2(x) | EG2: =MAX(DZ2:DZ11) -> 0.86317859 | EJ2: {=_xlfn.SEQUENCE(1000)} -> 1 | EK2: =IF(EK$1*MC_Random_N10!$B2>=0.9*MAX(MC_Random_N10!$C2:$K2),MC_Random_N10!$B2*(1-EK$1),0) -> 0 | EL2: =IF(EL$1*MC_Random_N10!$B2>=0.9*MAX(MC_Random_N10!$C2:$K2),MC_Random_N10!$B2*(1-EL$1),0) -> 0 | EM2: =IF(EM$1*MC_Random_N10!$B2>=0.9*MAX(MC_Random_N10!$C2:$K2),MC_Random_N10!$B2*(1-EM$1),0) -> 0 | EN2: =IF(EN$1*MC_Random_N10!$B2>=0.9*MAX(MC_Random_N10!$C2:$K2),MC_Random_N10!$B2*(1-EN$1),0) -> 0 | EO2: =IF(EO$1*MC_Random_N10!$B2>=0.9*MAX(MC_Random_N10!$C2:$K2),MC_Random_N10!$B2*(1-EO$1),0) -> 0 | EP2: =IF(EP$1*MC_Random_N10!$B2>=0.9*MAX(MC_Random_N10!$C2:$K2),MC_Random_N10!$B2*(1-EP$1),0) -> 0 | EQ2: =IF(EQ$1*MC_Random_N10!$B2>=0.9*MAX(MC_Random_N10!$C2:$K2),MC_Random_N10!$B2*(1-EQ$1),0) -> 0 | ER2: =IF(ER$1*MC_Random_N10!$B2>=0.9*MAX(MC_Random_N10!$C2:$K2),MC_Random_N10!$B2*(1-ER$1),0) -> 0 | ... ET2: =IF(ET$1*MC_Random_N10!$B2>=0.9*MAX(MC_Random_N10!$C2:$K2),MC_Random_N10!$B2*(1-ET$1),0) -> 0 | EV2: 0.2 | EW2: ES(0.2) | EX2: =AVERAGE(EL2:EL1001) -> 0 | FF2: {=_xlfn.SEQUENCE(1000)} -> 1 | FG2: =MAX(FG$1*MC_Random_N10!$B2,0.9*MAX(MC_Random_N10!$C2:$K2)) -> 0.86230175 | FH2: =MAX(FH$1*MC_Random_N10!$B2,0.9*MAX(MC_Random_N10!$C2:$K2)) -> 0.86230175 | FI2: =MAX(FI$1*MC_Random_N10!$B2,0.9*MAX(MC_Random_N10!$C2:$K2)) -> 0.86230175 | FJ2: =MAX(FJ$1*MC_Random_N10!$B2,0.9*MAX(MC_Random_N10!$C2:$K2)) -> 0.86230175 | FK2: =MAX(FK$1*MC_Random_N10!$B2,0.9*MAX(MC_Random_N10!$C2:$K2)) -> 0.86230175 | FL2: =MAX(FL$1*MC_Random_N10!$B2,0.9*MAX(MC_Random_N10!$C2:$K2)) -> 0.86230175 | FM2: =MAX(FM$1*MC_Random_N10!$B2,0.9*MAX(MC_Random_N10!$C2:$K2)) -> 0.86230175 | FN2: =MAX(FN$1*MC_Random_N10!$B2,0.9*MAX(MC_Random_N10!$C2:$K2)) -> 0.86230175 | ... FP2: =MAX(FP$1*MC_Random_N10!$B2,0.9*MAX(MC_Random_N10!$C2:$K2)) -> 0.86230175 | FR2: 0.2 | FS2: ER(0.2) | FT2: =AVERAGE(FH2:FH1001) -> 0.80898303 | FW2: The bidding strategy that maximizes Bidder 1's expected surplus does not necessarily maximize the auctioneer's revenue. These are different optimization objectives.
B3: K | C3: 1000 | G3: 2 | H3: =RAND() -> 0.82687308 | I3: =(1-1/N_a)*H3 -> 0.74418577 | J3: =IF(I3=MAX(I2:I3),1,0) -> 1 | K3: =J3*I3 -> 0.74418577 | L3: =J3*(H3-K3) -> 0.082687308 | S3: 2 | T3: =IF(T$1*MC_Random_N2!$B3>=0.5*MC_Random_N2!$C3,MC_Random_N2!$B3*(1-T$1),0) -> 0 | U3: =IF(U$1*MC_Random_N2!$B3>=0.5*MC_Random_N2!$C3,MC_Random_N2!$B3*(1-U$1),0) -> 0 | V3: =IF(V$1*MC_Random_N2!$B3>=0.5*MC_Random_N2!$C3,MC_Random_N2!$B3*(1-V$1),0) -> 0 | W3: =IF(W$1*MC_Random_N2!$B3>=0.5*MC_Random_N2!$C3,MC_Random_N2!$B3*(1-W$1),0) -> 0 | X3: =IF(X$1*MC_Random_N2!$B3>=0.5*MC_Random_N2!$C3,MC_Random_N2!$B3*(1-X$1),0) -> 0 | Y3: =IF(Y$1*MC_Random_N2!$B3>=0.5*MC_Random_N2!$C3,MC_Random_N2!$B3*(1-Y$1),0) -> 0 | Z3: =IF(Z$1*MC_Random_N2!$B3>=0.5*MC_Random_N2!$C3,MC_Random_N2!$B3*(1-Z$1),0) -> 0 | AA3: =IF(AA$1*MC_Random_N2!$B3>=0.5*MC_Random_N2!$C3,MC_Random_N2!$B3*(1-AA$1),0) -> 0 | ... AC3: =IF(AC$1*MC_Random_N2!$B3>=0.5*MC_Random_N2!$C3,MC_Random_N2!$B3*(1-AC$1),0) -> 0 | AE3: 0.3 | AF3: ES(0.3) | AG3: =AVERAGE(V2:V1001) -> 0.13555542 | AP3: 2 | AQ3: =MAX(AQ$1*MC_Random_N2!$B3,0.5*MC_Random_N2!$C3) -> 0.34061444 | AR3: =MAX(AR$1*MC_Random_N2!$B3,0.5*MC_Random_N2!$C3) -> 0.34061444 | AS3: =MAX(AS$1*MC_Random_N2!$B3,0.5*MC_Random_N2!$C3) -> 0.34061444 | AT3: =MAX(AT$1*MC_Random_N2!$B3,0.5*MC_Random_N2!$C3) -> 0.34061444 | AU3: =MAX(AU$1*MC_Random_N2!$B3,0.5*MC_Random_N2!$C3) -> 0.34061444 | AV3: =MAX(AV$1*MC_Random_N2!$B3,0.5*MC_Random_N2!$C3) -> 0.34061444 | AW3: =MAX(AW$1*MC_Random_N2!$B3,0.5*MC_Random_N2!$C3) -> 0.34061444 | AX3: =MAX(AX$1*MC_Random_N2!$B3,0.5*MC_Random_N2!$C3) -> 0.34061444 | ... AZ3: =MAX(AZ$1*MC_Random_N2!$B3,0.5*MC_Random_N2!$C3) -> 0.34061444 | BB3: 0.3 | BC3: ER(0.3) | BD3: =AVERAGE(AS2:AS1001) -> 0.28180076 | BU3: 2 | BV3: =RAND() -> 0.49287614 | BW3: =(1-1/N_c1)*BV3 -> 0.39430091 | BX3: =IF(BW3=MAX($BW$2:$BW$6),1,0) -> 0 | BY3: =BX3*BW3 -> 0 | BZ3: =BX3*(BV3-BY3) -> 0 | CG3: 2 | CH3: =IF(CH$1*MC_Random_N5!$B3>=0.8*MAX(MC_Random_N5!$C3:$F3),MC_Random_N5!$B3*(1-CH$1),0) -> 0 | CI3: =IF(CI$1*MC_Random_N5!$B3>=0.8*MAX(MC_Random_N5!$C3:$F3),MC_Random_N5!$B3*(1-CI$1),0) -> 0 | CJ3: =IF(CJ$1*MC_Random_N5!$B3>=0.8*MAX(MC_Random_N5!$C3:$F3),MC_Random_N5!$B3*(1-CJ$1),0) -> 0 | CK3: =IF(CK$1*MC_Random_N5!$B3>=0.8*MAX(MC_Random_N5!$C3:$F3),MC_Random_N5!$B3*(1-CK$1),0) -> 0 | CL3: =IF(CL$1*MC_Random_N5!$B3>=0.8*MAX(MC_Random_N5!$C3:$F3),MC_Random_N5!$B3*(1-CL$1),0) -> 0 | CM3: =IF(CM$1*MC_Random_N5!$B3>=0.8*MAX(MC_Random_N5!$C3:$F3),MC_Random_N5!$B3*(1-CM$1),0) -> 0 | CN3: =IF(CN$1*MC_Random_N5!$B3>=0.8*MAX(MC_Random_N5!$C3:$F3),MC_Random_N5!$B3*(1-CN$1),0) -> 0 | CO3: =IF(CO$1*MC_Random_N5!$B3>=0.8*MAX(MC_Random_N5!$C3:$F3),MC_Random_N5!$B3*(1-CO$1),0) -> 0 | ... CQ3: =IF(CQ$1*MC_Random_N5!$B3>=0.8*MAX(MC_Random_N5!$C3:$F3),MC_Random_N5!$B3*(1-CQ$1),0) -> 0 | CS3: 0.3 | CT3: ES(0.3) | CU3: =AVERAGE(CJ2:CJ1001) -> 0.002438488 | DD3: 2 | DE3: =MAX(DE$1*MC_Random_N5!$B3,0.8*MAX(MC_Random_N5!$C3:$F3)) -> 0.60867849 | DF3: =MAX(DF$1*MC_Random_N5!$B3,0.8*MAX(MC_Random_N5!$C3:$F3)) -> 0.60867849 | DG3: =MAX(DG$1*MC_Random_N5!$B3,0.8*MAX(MC_Random_N5!$C3:$F3)) -> 0.60867849 | DH3: =MAX(DH$1*MC_Random_N5!$B3,0.8*MAX(MC_Random_N5!$C3:$F3)) -> 0.60867849 | DI3: =MAX(DI$1*MC_Random_N5!$B3,0.8*MAX(MC_Random_N5!$C3:$F3)) -> 0.60867849 | DJ3: =MAX(DJ$1*MC_Random_N5!$B3,0.8*MAX(MC_Random_N5!$C3:$F3)) -> 0.60867849 | DK3: =MAX(DK$1*MC_Random_N5!$B3,0.8*MAX(MC_Random_N5!$C3:$F3)) -> 0.60867849 | DL3: =MAX(DL$1*MC_Random_N5!$B3,0.8*MAX(MC_Random_N5!$C3:$F3)) -> 0.60867849 | ... DN3: =MAX(DN$1*MC_Random_N5!$B3,0.8*MAX(MC_Random_N5!$C3:$F3)) -> 0.60867849 | DP3: 0.3 | DQ3: ER(0.3) | DR3: =AVERAGE(DG2:DG1001) -> 0.63589002 | DX3: 2 | DY3: =RAND() -> 0.95908732 | DZ3: =(1-1/N_c2)*DY3 -> 0.86317859 | EA3: =IF(DZ3=MAX($DZ$2:$DZ$11),1,0) -> 1 | EB3: =EA3*DZ3 -> 0.86317859 | EC3: =EA3*(DY3-EB3) -> 0.095908732 | EJ3: 2 | EK3: =IF(EK$1*MC_Random_N10!$B3>=0.9*MAX(MC_Random_N10!$C3:$K3),MC_Random_N10!$B3*(1-EK$1),0) -> 0 | EL3: =IF(EL$1*MC_Random_N10!$B3>=0.9*MAX(MC_Random_N10!$C3:$K3),MC_Random_N10!$B3*(1-EL$1),0) -> 0 | EM3: =IF(EM$1*MC_Random_N10!$B3>=0.9*MAX(MC_Random_N10!$C3:$K3),MC_Random_N10!$B3*(1-EM$1),0) -> 0 | EN3: =IF(EN$1*MC_Random_N10!$B3>=0.9*MAX(MC_Random_N10!$C3:$K3),MC_Random_N10!$B3*(1-EN$1),0) -> 0 | EO3: =IF(EO$1*MC_Random_N10!$B3>=0.9*MAX(MC_Random_N10!$C3:$K3),MC_Random_N10!$B3*(1-EO$1),0) -> 0 | EP3: =IF(EP$1*MC_Random_N10!$B3>=0.9*MAX(MC_Random_N10!$C3:$K3),MC_Random_N10!$B3*(1-EP$1),0) -> 0 | EQ3: =IF(EQ$1*MC_Random_N10!$B3>=0.9*MAX(MC_Random_N10!$C3:$K3),MC_Random_N10!$B3*(1-EQ$1),0) -> 0 | ER3: =IF(ER$1*MC_Random_N10!$B3>=0.9*MAX(MC_Random_N10!$C3:$K3),MC_Random_N10!$B3*(1-ER$1),0) -> 0 | ... ET3: =IF(ET$1*MC_Random_N10!$B3>=0.9*MAX(MC_Random_N10!$C3:$K3),MC_Random_N10!$B3*(1-ET$1),0) -> 0 | EV3: 0.3 | EW3: ES(0.3) | EX3: =AVERAGE(EM2:EM1001) -> 0 | FF3: 2 | FG3: =MAX(FG$1*MC_Random_N10!$B3,0.9*MAX(MC_Random_N10!$C3:$K3)) -> 0.78770555 | FH3: =MAX(FH$1*MC_Random_N10!$B3,0.9*MAX(MC_Random_N10!$C3:$K3)) -> 0.78770555 | FI3: =MAX(FI$1*MC_Random_N10!$B3,0.9*MAX(MC_Random_N10!$C3:$K3)) -> 0.78770555 | FJ3: =MAX(FJ$1*MC_Random_N10!$B3,0.9*MAX(MC_Random_N10!$C3:$K3)) -> 0.78770555 | FK3: =MAX(FK$1*MC_Random_N10!$B3,0.9*MAX(MC_Random_N10!$C3:$K3)) -> 0.78770555 | FL3: =MAX(FL$1*MC_Random_N10!$B3,0.9*MAX(MC_Random_N10!$C3:$K3)) -> 0.78770555 | FM3: =MAX(FM$1*MC_Random_N10!$B3,0.9*MAX(MC_Random_N10!$C3:$K3)) -> 0.78770555 | FN3: =MAX(FN$1*MC_Random_N10!$B3,0.9*MAX(MC_Random_N10!$C3:$K3)) -> 0.78770555 | ... FP3: =MAX(FP$1*MC_Random_N10!$B3,0.9*MAX(MC_Random_N10!$C3:$K3)) -> 0.78770555 | FR3: 0.3 | FS3: ER(0.3) | FT3: =AVERAGE(FI2:FI1001) -> 0.80898303
B4: N_c1 | C4: 5 | S4: 3 | T4: =IF(T$1*MC_Random_N2!$B4>=0.5*MC_Random_N2!$C4,MC_Random_N2!$B4*(1-T$1),0) -> 0 | U4: =IF(U$1*MC_Random_N2!$B4>=0.5*MC_Random_N2!$C4,MC_Random_N2!$B4*(1-U$1),0) -> 0 | V4: =IF(V$1*MC_Random_N2!$B4>=0.5*MC_Random_N2!$C4,MC_Random_N2!$B4*(1-V$1),0) -> 0 | W4: =IF(W$1*MC_Random_N2!$B4>=0.5*MC_Random_N2!$C4,MC_Random_N2!$B4*(1-W$1),0) -> 0 | X4: =IF(X$1*MC_Random_N2!$B4>=0.5*MC_Random_N2!$C4,MC_Random_N2!$B4*(1-X$1),0) -> 0 | Y4: =IF(Y$1*MC_Random_N2!$B4>=0.5*MC_Random_N2!$C4,MC_Random_N2!$B4*(1-Y$1),0) -> 0 | Z4: =IF(Z$1*MC_Random_N2!$B4>=0.5*MC_Random_N2!$C4,MC_Random_N2!$B4*(1-Z$1),0) -> 0.12272349 | AA4: =IF(AA$1*MC_Random_N2!$B4>=0.5*MC_Random_N2!$C4,MC_Random_N2!$B4*(1-AA$1),0) -> 0.081815662 | ... AC4: =IF(AC$1*MC_Random_N2!$B4>=0.5*MC_Random_N2!$C4,MC_Random_N2!$B4*(1-AC$1),0) -> 0 | AE4: 0.4 | AF4: ES(0.4) | AG4: =AVERAGE(W2:W1001) -> 0.15958057 | AP4: 3 | AQ4: =MAX(AQ$1*MC_Random_N2!$B4,0.5*MC_Random_N2!$C4) -> 0.2863389 | AR4: =MAX(AR$1*MC_Random_N2!$B4,0.5*MC_Random_N2!$C4) -> 0.2863389 | AS4: =MAX(AS$1*MC_Random_N2!$B4,0.5*MC_Random_N2!$C4) -> 0.2863389 | AT4: =MAX(AT$1*MC_Random_N2!$B4,0.5*MC_Random_N2!$C4) -> 0.2863389 | AU4: =MAX(AU$1*MC_Random_N2!$B4,0.5*MC_Random_N2!$C4) -> 0.2863389 | AV4: =MAX(AV$1*MC_Random_N2!$B4,0.5*MC_Random_N2!$C4) -> 0.2863389 | AW4: =MAX(AW$1*MC_Random_N2!$B4,0.5*MC_Random_N2!$C4) -> 0.28635482 | AX4: =MAX(AX$1*MC_Random_N2!$B4,0.5*MC_Random_N2!$C4) -> 0.32726265 | ... AZ4: =MAX(AZ$1*MC_Random_N2!$B4,0.5*MC_Random_N2!$C4) -> 0.40907831 | BB4: 0.4 | BC4: ER(0.4) | BD4: =AVERAGE(AT2:AT1001) -> 0.30473106 | BU4: 3 | BV4: =RAND() -> 0.95463891 | BW4: =(1-1/N_c1)*BV4 -> 0.76371113 | BX4: =IF(BW4=MAX($BW$2:$BW$6),1,0) -> 1 | BY4: =BX4*BW4 -> 0.76371113 | BZ4: =BX4*(BV4-BY4) -> 0.19092778 | CG4: 3 | CH4: =IF(CH$1*MC_Random_N5!$B4>=0.8*MAX(MC_Random_N5!$C4:$F4),MC_Random_N5!$B4*(1-CH$1),0) -> 0 | CI4: =IF(CI$1*MC_Random_N5!$B4>=0.8*MAX(MC_Random_N5!$C4:$F4),MC_Random_N5!$B4*(1-CI$1),0) -> 0 | CJ4: =IF(CJ$1*MC_Random_N5!$B4>=0.8*MAX(MC_Random_N5!$C4:$F4),MC_Random_N5!$B4*(1-CJ$1),0) -> 0 | CK4: =IF(CK$1*MC_Random_N5!$B4>=0.8*MAX(MC_Random_N5!$C4:$F4),MC_Random_N5!$B4*(1-CK$1),0) -> 0 | CL4: =IF(CL$1*MC_Random_N5!$B4>=0.8*MAX(MC_Random_N5!$C4:$F4),MC_Random_N5!$B4*(1-CL$1),0) -> 0 | CM4: =IF(CM$1*MC_Random_N5!$B4>=0.8*MAX(MC_Random_N5!$C4:$F4),MC_Random_N5!$B4*(1-CM$1),0) -> 0 | CN4: =IF(CN$1*MC_Random_N5!$B4>=0.8*MAX(MC_Random_N5!$C4:$F4),MC_Random_N5!$B4*(1-CN$1),0) -> 0 | CO4: =IF(CO$1*MC_Random_N5!$B4>=0.8*MAX(MC_Random_N5!$C4:$F4),MC_Random_N5!$B4*(1-CO$1),0) -> 0.16187966 | ... CQ4: =IF(CQ$1*MC_Random_N5!$B4>=0.8*MAX(MC_Random_N5!$C4:$F4),MC_Random_N5!$B4*(1-CQ$1),0) -> 0 | CS4: 0.4 | CT4: ES(0.4) | CU4: =AVERAGE(CK2:CK1001) -> 0.0064399818 | DD4: 3 | DE4: =MAX(DE$1*MC_Random_N5!$B4,0.8*MAX(MC_Random_N5!$C4:$F4)) -> 0.58526341 | DF4: =MAX(DF$1*MC_Random_N5!$B4,0.8*MAX(MC_Random_N5!$C4:$F4)) -> 0.58526341 | DG4: =MAX(DG$1*MC_Random_N5!$B4,0.8*MAX(MC_Random_N5!$C4:$F4)) -> 0.58526341 | DH4: =MAX(DH$1*MC_Random_N5!$B4,0.8*MAX(MC_Random_N5!$C4:$F4)) -> 0.58526341 | DI4: =MAX(DI$1*MC_Random_N5!$B4,0.8*MAX(MC_Random_N5!$C4:$F4)) -> 0.58526341 | DJ4: =MAX(DJ$1*MC_Random_N5!$B4,0.8*MAX(MC_Random_N5!$C4:$F4)) -> 0.58526341 | DK4: =MAX(DK$1*MC_Random_N5!$B4,0.8*MAX(MC_Random_N5!$C4:$F4)) -> 0.58526341 | DL4: =MAX(DL$1*MC_Random_N5!$B4,0.8*MAX(MC_Random_N5!$C4:$F4)) -> 0.64751862 | ... DN4: =MAX(DN$1*MC_Random_N5!$B4,0.8*MAX(MC_Random_N5!$C4:$F4)) -> 0.80939828 | DP4: 0.4 | DQ4: ER(0.4) | DR4: =AVERAGE(DH2:DH1001) -> 0.63652022 | DX4: 3 | DY4: =RAND() -> 0.51235596 | DZ4: =(1-1/N_c2)*DY4 -> 0.46112036 | EA4: =IF(DZ4=MAX($DZ$2:$DZ$11),1,0) -> 0 | EB4: =EA4*DZ4 -> 0 | EC4: =EA4*(DY4-EB4) -> 0 | EJ4: 3 | EK4: =IF(EK$1*MC_Random_N10!$B4>=0.9*MAX(MC_Random_N10!$C4:$K4),MC_Random_N10!$B4*(1-EK$1),0) -> 0 | EL4: =IF(EL$1*MC_Random_N10!$B4>=0.9*MAX(MC_Random_N10!$C4:$K4),MC_Random_N10!$B4*(1-EL$1),0) -> 0 | EM4: =IF(EM$1*MC_Random_N10!$B4>=0.9*MAX(MC_Random_N10!$C4:$K4),MC_Random_N10!$B4*(1-EM$1),0) -> 0 | EN4: =IF(EN$1*MC_Random_N10!$B4>=0.9*MAX(MC_Random_N10!$C4:$K4),MC_Random_N10!$B4*(1-EN$1),0) -> 0 | EO4: =IF(EO$1*MC_Random_N10!$B4>=0.9*MAX(MC_Random_N10!$C4:$K4),MC_Random_N10!$B4*(1-EO$1),0) -> 0 | EP4: =IF(EP$1*MC_Random_N10!$B4>=0.9*MAX(MC_Random_N10!$C4:$K4),MC_Random_N10!$B4*(1-EP$1),0) -> 0 | EQ4: =IF(EQ$1*MC_Random_N10!$B4>=0.9*MAX(MC_Random_N10!$C4:$K4),MC_Random_N10!$B4*(1-EQ$1),0) -> 0 | ER4: =IF(ER$1*MC_Random_N10!$B4>=0.9*MAX(MC_Random_N10!$C4:$K4),MC_Random_N10!$B4*(1-ER$1),0) -> 0 | ... ET4: =IF(ET$1*MC_Random_N10!$B4>=0.9*MAX(MC_Random_N10!$C4:$K4),MC_Random_N10!$B4*(1-ET$1),0) -> 0 | EV4: 0.4 | EW4: ES(0.4) | EX4: =AVERAGE(EN2:EN1001) -> 0 | FF4: 3 | FG4: =MAX(FG$1*MC_Random_N10!$B4,0.9*MAX(MC_Random_N10!$C4:$K4)) -> 0.86348889 | FH4: =MAX(FH$1*MC_Random_N10!$B4,0.9*MAX(MC_Random_N10!$C4:$K4)) -> 0.86348889 | FI4: =MAX(FI$1*MC_Random_N10!$B4,0.9*MAX(MC_Random_N10!$C4:$K4)) -> 0.86348889 | FJ4: =MAX(FJ$1*MC_Random_N10!$B4,0.9*MAX(MC_Random_N10!$C4:$K4)) -> 0.86348889 | FK4: =MAX(FK$1*MC_Random_N10!$B4,0.9*MAX(MC_Random_N10!$C4:$K4)) -> 0.86348889 | FL4: =MAX(FL$1*MC_Random_N10!$B4,0.9*MAX(MC_Random_N10!$C4:$K4)) -> 0.86348889 | FM4: =MAX(FM$1*MC_Random_N10!$B4,0.9*MAX(MC_Random_N10!$C4:$K4)) -> 0.86348889 | FN4: =MAX(FN$1*MC_Random_N10!$B4,0.9*MAX(MC_Random_N10!$C4:$K4)) -> 0.86348889 | ... FP4: =MAX(FP$1*MC_Random_N10!$B4,0.9*MAX(MC_Random_N10!$C4:$K4)) -> 0.86348889 | FR4: 0.4 | FS4: ER(0.4) | FT4: =AVERAGE(FJ2:FJ1001) -> 0.80898303
B5: N_c2 | C5: 10 | S5: 4 | T5: =IF(T$1*MC_Random_N2!$B5>=0.5*MC_Random_N2!$C5,MC_Random_N2!$B5*(1-T$1),0) -> 0 | U5: =IF(U$1*MC_Random_N2!$B5>=0.5*MC_Random_N2!$C5,MC_Random_N2!$B5*(1-U$1),0) -> 0 | V5: =IF(V$1*MC_Random_N2!$B5>=0.5*MC_Random_N2!$C5,MC_Random_N2!$B5*(1-V$1),0) -> 0.50876577 | W5: =IF(W$1*MC_Random_N2!$B5>=0.5*MC_Random_N2!$C5,MC_Random_N2!$B5*(1-W$1),0) -> 0.43608495 | X5: =IF(X$1*MC_Random_N2!$B5>=0.5*MC_Random_N2!$C5,MC_Random_N2!$B5*(1-X$1),0) -> 0.36340412 | Y5: =IF(Y$1*MC_Random_N2!$B5>=0.5*MC_Random_N2!$C5,MC_Random_N2!$B5*(1-Y$1),0) -> 0.2907233 | Z5: =IF(Z$1*MC_Random_N2!$B5>=0.5*MC_Random_N2!$C5,MC_Random_N2!$B5*(1-Z$1),0) -> 0.21804247 | AA5: =IF(AA$1*MC_Random_N2!$B5>=0.5*MC_Random_N2!$C5,MC_Random_N2!$B5*(1-AA$1),0) -> 0.14536165 | ... AC5: =IF(AC$1*MC_Random_N2!$B5>=0.5*MC_Random_N2!$C5,MC_Random_N2!$B5*(1-AC$1),0) -> 0 | AE5: 0.5 | AF5: ES(0.5) | AG5: =AVERAGE(X2:X1001) -> 0.16441459 | AP5: 4 | AQ5: =MAX(AQ$1*MC_Random_N2!$B5,0.5*MC_Random_N2!$C5) -> 0.17755018 | AR5: =MAX(AR$1*MC_Random_N2!$B5,0.5*MC_Random_N2!$C5) -> 0.17755018 | AS5: =MAX(AS$1*MC_Random_N2!$B5,0.5*MC_Random_N2!$C5) -> 0.21804247 | AT5: =MAX(AT$1*MC_Random_N2!$B5,0.5*MC_Random_N2!$C5) -> 0.2907233 | AU5: =MAX(AU$1*MC_Random_N2!$B5,0.5*MC_Random_N2!$C5) -> 0.36340412 | AV5: =MAX(AV$1*MC_Random_N2!$B5,0.5*MC_Random_N2!$C5) -> 0.43608495 | AW5: =MAX(AW$1*MC_Random_N2!$B5,0.5*MC_Random_N2!$C5) -> 0.50876577 | AX5: =MAX(AX$1*MC_Random_N2!$B5,0.5*MC_Random_N2!$C5) -> 0.5814466 | ... AZ5: =MAX(AZ$1*MC_Random_N2!$B5,0.5*MC_Random_N2!$C5) -> 0.72680825 | BB5: 0.5 | BC5: ER(0.5) | BD5: =AVERAGE(AU2:AU1001) -> 0.33432021 | BU5: 4 | BV5: =RAND() -> 0.24079777 | BW5: =(1-1/N_c1)*BV5 -> 0.19263822 | BX5: =IF(BW5=MAX($BW$2:$BW$6),1,0) -> 0 | BY5: =BX5*BW5 -> 0 | BZ5: =BX5*(BV5-BY5) -> 0 | CG5: 4 | CH5: =IF(CH$1*MC_Random_N5!$B5>=0.8*MAX(MC_Random_N5!$C5:$F5),MC_Random_N5!$B5*(1-CH$1),0) -> 0 | CI5: =IF(CI$1*MC_Random_N5!$B5>=0.8*MAX(MC_Random_N5!$C5:$F5),MC_Random_N5!$B5*(1-CI$1),0) -> 0 | CJ5: =IF(CJ$1*MC_Random_N5!$B5>=0.8*MAX(MC_Random_N5!$C5:$F5),MC_Random_N5!$B5*(1-CJ$1),0) -> 0 | CK5: =IF(CK$1*MC_Random_N5!$B5>=0.8*MAX(MC_Random_N5!$C5:$F5),MC_Random_N5!$B5*(1-CK$1),0) -> 0 | CL5: =IF(CL$1*MC_Random_N5!$B5>=0.8*MAX(MC_Random_N5!$C5:$F5),MC_Random_N5!$B5*(1-CL$1),0) -> 0 | CM5: =IF(CM$1*MC_Random_N5!$B5>=0.8*MAX(MC_Random_N5!$C5:$F5),MC_Random_N5!$B5*(1-CM$1),0) -> 0 | CN5: =IF(CN$1*MC_Random_N5!$B5>=0.8*MAX(MC_Random_N5!$C5:$F5),MC_Random_N5!$B5*(1-CN$1),0) -> 0.26721502 | CO5: =IF(CO$1*MC_Random_N5!$B5>=0.8*MAX(MC_Random_N5!$C5:$F5),MC_Random_N5!$B5*(1-CO$1),0) -> 0.17814335 | ... CQ5: =IF(CQ$1*MC_Random_N5!$B5>=0.8*MAX(MC_Random_N5!$C5:$F5),MC_Random_N5!$B5*(1-CQ$1),0) -> 0 | CS5: 0.5 | CT5: ES(0.5) | CU5: =AVERAGE(CL2:CL1001) -> 0.013085082 | DD5: 4 | DE5: =MAX(DE$1*MC_Random_N5!$B5,0.8*MAX(MC_Random_N5!$C5:$F5)) -> 0.59811104 | DF5: =MAX(DF$1*MC_Random_N5!$B5,0.8*MAX(MC_Random_N5!$C5:$F5)) -> 0.59811104 | DG5: =MAX(DG$1*MC_Random_N5!$B5,0.8*MAX(MC_Random_N5!$C5:$F5)) -> 0.59811104 | DH5: =MAX(DH$1*MC_Random_N5!$B5,0.8*MAX(MC_Random_N5!$C5:$F5)) -> 0.59811104 | DI5: =MAX(DI$1*MC_Random_N5!$B5,0.8*MAX(MC_Random_N5!$C5:$F5)) -> 0.59811104 | DJ5: =MAX(DJ$1*MC_Random_N5!$B5,0.8*MAX(MC_Random_N5!$C5:$F5)) -> 0.59811104 | DK5: =MAX(DK$1*MC_Random_N5!$B5,0.8*MAX(MC_Random_N5!$C5:$F5)) -> 0.62350171 | DL5: =MAX(DL$1*MC_Random_N5!$B5,0.8*MAX(MC_Random_N5!$C5:$F5)) -> 0.71257338 | ... DN5: =MAX(DN$1*MC_Random_N5!$B5,0.8*MAX(MC_Random_N5!$C5:$F5)) -> 0.89071673 | DP5: 0.5 | DQ5: ER(0.5) | DR5: =AVERAGE(DI2:DI1001) -> 0.63825017 | DX5: 4 | DY5: =RAND() -> 0.73225255 | DZ5: =(1-1/N_c2)*DY5 -> 0.6590273 | EA5: =IF(DZ5=MAX($DZ$2:$DZ$11),1,0) -> 0 | EB5: =EA5*DZ5 -> 0 | EC5: =EA5*(DY5-EB5) -> 0 | EJ5: 4 | EK5: =IF(EK$1*MC_Random_N10!$B5>=0.9*MAX(MC_Random_N10!$C5:$K5),MC_Random_N10!$B5*(1-EK$1),0) -> 0 | EL5: =IF(EL$1*MC_Random_N10!$B5>=0.9*MAX(MC_Random_N10!$C5:$K5),MC_Random_N10!$B5*(1-EL$1),0) -> 0 | EM5: =IF(EM$1*MC_Random_N10!$B5>=0.9*MAX(MC_Random_N10!$C5:$K5),MC_Random_N10!$B5*(1-EM$1),0) -> 0 | EN5: =IF(EN$1*MC_Random_N10!$B5>=0.9*MAX(MC_Random_N10!$C5:$K5),MC_Random_N10!$B5*(1-EN$1),0) -> 0 | EO5: =IF(EO$1*MC_Random_N10!$B5>=0.9*MAX(MC_Random_N10!$C5:$K5),MC_Random_N10!$B5*(1-EO$1),0) -> 0 | EP5: =IF(EP$1*MC_Random_N10!$B5>=0.9*MAX(MC_Random_N10!$C5:$K5),MC_Random_N10!$B5*(1-EP$1),0) -> 0 | EQ5: =IF(EQ$1*MC_Random_N10!$B5>=0.9*MAX(MC_Random_N10!$C5:$K5),MC_Random_N10!$B5*(1-EQ$1),0) -> 0 | ER5: =IF(ER$1*MC_Random_N10!$B5>=0.9*MAX(MC_Random_N10!$C5:$K5),MC_Random_N10!$B5*(1-ER$1),0) -> 0 | ... ET5: =IF(ET$1*MC_Random_N10!$B5>=0.9*MAX(MC_Random_N10!$C5:$K5),MC_Random_N10!$B5*(1-ET$1),0) -> 0 | EV5: 0.5 | EW5: ES(0.5) | EX5: =AVERAGE(EO2:EO1001) -> 0.00043401312 | FF5: 4 | FG5: =MAX(FG$1*MC_Random_N10!$B5,0.9*MAX(MC_Random_N10!$C5:$K5)) -> 0.80101948 | FH5: =MAX(FH$1*MC_Random_N10!$B5,0.9*MAX(MC_Random_N10!$C5:$K5)) -> 0.80101948 | FI5: =MAX(FI$1*MC_Random_N10!$B5,0.9*MAX(MC_Random_N10!$C5:$K5)) -> 0.80101948 | FJ5: =MAX(FJ$1*MC_Random_N10!$B5,0.9*MAX(MC_Random_N10!$C5:$K5)) -> 0.80101948 | FK5: =MAX(FK$1*MC_Random_N10!$B5,0.9*MAX(MC_Random_N10!$C5:$K5)) -> 0.80101948 | FL5: =MAX(FL$1*MC_Random_N10!$B5,0.9*MAX(MC_Random_N10!$C5:$K5)) -> 0.80101948 | FM5: =MAX(FM$1*MC_Random_N10!$B5,0.9*MAX(MC_Random_N10!$C5:$K5)) -> 0.80101948 | FN5: =MAX(FN$1*MC_Random_N10!$B5,0.9*MAX(MC_Random_N10!$C5:$K5)) -> 0.80101948 | ... FP5: =MAX(FP$1*MC_Random_N10!$B5,0.9*MAX(MC_Random_N10!$C5:$K5)) -> 0.80101948 | FR5: 0.5 | FS5: ER(0.5) | FT5: =AVERAGE(FK2:FK1001) -> 0.80901445
S6: 5 | T6: =IF(T$1*MC_Random_N2!$B6>=0.5*MC_Random_N2!$C6,MC_Random_N2!$B6*(1-T$1),0) -> 0 | U6: =IF(U$1*MC_Random_N2!$B6>=0.5*MC_Random_N2!$C6,MC_Random_N2!$B6*(1-U$1),0) -> 0 | V6: =IF(V$1*MC_Random_N2!$B6>=0.5*MC_Random_N2!$C6,MC_Random_N2!$B6*(1-V$1),0) -> 0 | W6: =IF(W$1*MC_Random_N2!$B6>=0.5*MC_Random_N2!$C6,MC_Random_N2!$B6*(1-W$1),0) -> 0 | X6: =IF(X$1*MC_Random_N2!$B6>=0.5*MC_Random_N2!$C6,MC_Random_N2!$B6*(1-X$1),0) -> 0 | Y6: =IF(Y$1*MC_Random_N2!$B6>=0.5*MC_Random_N2!$C6,MC_Random_N2!$B6*(1-Y$1),0) -> 0.19572457 | Z6: =IF(Z$1*MC_Random_N2!$B6>=0.5*MC_Random_N2!$C6,MC_Random_N2!$B6*(1-Z$1),0) -> 0.14679343 | AA6: =IF(AA$1*MC_Random_N2!$B6>=0.5*MC_Random_N2!$C6,MC_Random_N2!$B6*(1-AA$1),0) -> 0.097862284 | ... AC6: =IF(AC$1*MC_Random_N2!$B6>=0.5*MC_Random_N2!$C6,MC_Random_N2!$B6*(1-AC$1),0) -> 0 | AE6: 0.6 | AF6: ES(0.6) | AG6: =AVERAGE(Y2:Y1001) -> 0.15105112 | AP6: 5 | AQ6: =MAX(AQ$1*MC_Random_N2!$B6,0.5*MC_Random_N2!$C6) -> 0.26560191 | AR6: =MAX(AR$1*MC_Random_N2!$B6,0.5*MC_Random_N2!$C6) -> 0.26560191 | AS6: =MAX(AS$1*MC_Random_N2!$B6,0.5*MC_Random_N2!$C6) -> 0.26560191 | AT6: =MAX(AT$1*MC_Random_N2!$B6,0.5*MC_Random_N2!$C6) -> 0.26560191 | AU6: =MAX(AU$1*MC_Random_N2!$B6,0.5*MC_Random_N2!$C6) -> 0.26560191 | AV6: =MAX(AV$1*MC_Random_N2!$B6,0.5*MC_Random_N2!$C6) -> 0.29358685 | AW6: =MAX(AW$1*MC_Random_N2!$B6,0.5*MC_Random_N2!$C6) -> 0.342518 | AX6: =MAX(AX$1*MC_Random_N2!$B6,0.5*MC_Random_N2!$C6) -> 0.39144914 | ... AZ6: =MAX(AZ$1*MC_Random_N2!$B6,0.5*MC_Random_N2!$C6) -> 0.48931142 | BB6: 0.6 | BC6: ER(0.6) | BD6: =AVERAGE(AV2:AV1001) -> 0.36991817 | BU6: 5 | BV6: =RAND() -> 0.50488258 | BW6: =(1-1/N_c1)*BV6 -> 0.40390606 | BX6: =IF(BW6=MAX($BW$2:$BW$6),1,0) -> 0 | BY6: =BX6*BW6 -> 0 | BZ6: =BX6*(BV6-BY6) -> 0 | CG6: 5 | CH6: =IF(CH$1*MC_Random_N5!$B6>=0.8*MAX(MC_Random_N5!$C6:$F6),MC_Random_N5!$B6*(1-CH$1),0) -> 0 | CI6: =IF(CI$1*MC_Random_N5!$B6>=0.8*MAX(MC_Random_N5!$C6:$F6),MC_Random_N5!$B6*(1-CI$1),0) -> 0 | CJ6: =IF(CJ$1*MC_Random_N5!$B6>=0.8*MAX(MC_Random_N5!$C6:$F6),MC_Random_N5!$B6*(1-CJ$1),0) -> 0 | CK6: =IF(CK$1*MC_Random_N5!$B6>=0.8*MAX(MC_Random_N5!$C6:$F6),MC_Random_N5!$B6*(1-CK$1),0) -> 0 | CL6: =IF(CL$1*MC_Random_N5!$B6>=0.8*MAX(MC_Random_N5!$C6:$F6),MC_Random_N5!$B6*(1-CL$1),0) -> 0 | CM6: =IF(CM$1*MC_Random_N5!$B6>=0.8*MAX(MC_Random_N5!$C6:$F6),MC_Random_N5!$B6*(1-CM$1),0) -> 0.25912016 | CN6: =IF(CN$1*MC_Random_N5!$B6>=0.8*MAX(MC_Random_N5!$C6:$F6),MC_Random_N5!$B6*(1-CN$1),0) -> 0.19434012 | CO6: =IF(CO$1*MC_Random_N5!$B6>=0.8*MAX(MC_Random_N5!$C6:$F6),MC_Random_N5!$B6*(1-CO$1),0) -> 0.12956008 | ... CQ6: =IF(CQ$1*MC_Random_N5!$B6>=0.8*MAX(MC_Random_N5!$C6:$F6),MC_Random_N5!$B6*(1-CQ$1),0) -> 0 | CS6: 0.6 | CT6: ES(0.6) | CU6: =AVERAGE(CM2:CM1001) -> 0.02100506 | DD6: 5 | DE6: =MAX(DE$1*MC_Random_N5!$B6,0.8*MAX(MC_Random_N5!$C6:$F6)) -> 0.32755736 | DF6: =MAX(DF$1*MC_Random_N5!$B6,0.8*MAX(MC_Random_N5!$C6:$F6)) -> 0.32755736 | DG6: =MAX(DG$1*MC_Random_N5!$B6,0.8*MAX(MC_Random_N5!$C6:$F6)) -> 0.32755736 | DH6: =MAX(DH$1*MC_Random_N5!$B6,0.8*MAX(MC_Random_N5!$C6:$F6)) -> 0.32755736 | DI6: =MAX(DI$1*MC_Random_N5!$B6,0.8*MAX(MC_Random_N5!$C6:$F6)) -> 0.32755736 | DJ6: =MAX(DJ$1*MC_Random_N5!$B6,0.8*MAX(MC_Random_N5!$C6:$F6)) -> 0.38868024 | DK6: =MAX(DK$1*MC_Random_N5!$B6,0.8*MAX(MC_Random_N5!$C6:$F6)) -> 0.45346028 | DL6: =MAX(DL$1*MC_Random_N5!$B6,0.8*MAX(MC_Random_N5!$C6:$F6)) -> 0.51824032 | ... DN6: =MAX(DN$1*MC_Random_N5!$B6,0.8*MAX(MC_Random_N5!$C6:$F6)) -> 0.6478004 | DP6: 0.6 | DQ6: ER(0.6) | DR6: =AVERAGE(DJ2:DJ1001) -> 0.64205505 | DX6: 5 | DY6: =RAND() -> 0.73647479 | DZ6: =(1-1/N_c2)*DY6 -> 0.66282732 | EA6: =IF(DZ6=MAX($DZ$2:$DZ$11),1,0) -> 0 | EB6: =EA6*DZ6 -> 0 | EC6: =EA6*(DY6-EB6) -> 0 | EJ6: 5 | EK6: =IF(EK$1*MC_Random_N10!$B6>=0.9*MAX(MC_Random_N10!$C6:$K6),MC_Random_N10!$B6*(1-EK$1),0) -> 0 | EL6: =IF(EL$1*MC_Random_N10!$B6>=0.9*MAX(MC_Random_N10!$C6:$K6),MC_Random_N10!$B6*(1-EL$1),0) -> 0 | EM6: =IF(EM$1*MC_Random_N10!$B6>=0.9*MAX(MC_Random_N10!$C6:$K6),MC_Random_N10!$B6*(1-EM$1),0) -> 0 | EN6: =IF(EN$1*MC_Random_N10!$B6>=0.9*MAX(MC_Random_N10!$C6:$K6),MC_Random_N10!$B6*(1-EN$1),0) -> 0 | EO6: =IF(EO$1*MC_Random_N10!$B6>=0.9*MAX(MC_Random_N10!$C6:$K6),MC_Random_N10!$B6*(1-EO$1),0) -> 0 | EP6: =IF(EP$1*MC_Random_N10!$B6>=0.9*MAX(MC_Random_N10!$C6:$K6),MC_Random_N10!$B6*(1-EP$1),0) -> 0 | EQ6: =IF(EQ$1*MC_Random_N10!$B6>=0.9*MAX(MC_Random_N10!$C6:$K6),MC_Random_N10!$B6*(1-EQ$1),0) -> 0 | ER6: =IF(ER$1*MC_Random_N10!$B6>=0.9*MAX(MC_Random_N10!$C6:$K6),MC_Random_N10!$B6*(1-ER$1),0) -> 0 | ... ET6: =IF(ET$1*MC_Random_N10!$B6>=0.9*MAX(MC_Random_N10!$C6:$K6),MC_Random_N10!$B6*(1-ET$1),0) -> 0 | EV6: 0.6 | EW6: ES(0.6) | EX6: =AVERAGE(EP2:EP1001) -> 0.00074127 | FF6: 5 | FG6: =MAX(FG$1*MC_Random_N10!$B6,0.9*MAX(MC_Random_N10!$C6:$K6)) -> 0.88066064 | FH6: =MAX(FH$1*MC_Random_N10!$B6,0.9*MAX(MC_Random_N10!$C6:$K6)) -> 0.88066064 | FI6: =MAX(FI$1*MC_Random_N10!$B6,0.9*MAX(MC_Random_N10!$C6:$K6)) -> 0.88066064 | FJ6: =MAX(FJ$1*MC_Random_N10!$B6,0.9*MAX(MC_Random_N10!$C6:$K6)) -> 0.88066064 | FK6: =MAX(FK$1*MC_Random_N10!$B6,0.9*MAX(MC_Random_N10!$C6:$K6)) -> 0.88066064 | FL6: =MAX(FL$1*MC_Random_N10!$B6,0.9*MAX(MC_Random_N10!$C6:$K6)) -> 0.88066064 | FM6: =MAX(FM$1*MC_Random_N10!$B6,0.9*MAX(MC_Random_N10!$C6:$K6)) -> 0.88066064 | FN6: =MAX(FN$1*MC_Random_N10!$B6,0.9*MAX(MC_Random_N10!$C6:$K6)) -> 0.88066064 | ... FP6: =MAX(FP$1*MC_Random_N10!$B6,0.9*MAX(MC_Random_N10!$C6:$K6)) -> 0.88066064 | FR6: 0.6 | FS6: ER(0.6) | FT6: =AVERAGE(FL2:FL1001) -> 0.8091578
S7: 6 | T7: =IF(T$1*MC_Random_N2!$B7>=0.5*MC_Random_N2!$C7,MC_Random_N2!$B7*(1-T$1),0) -> 0.88736884 | U7: =IF(U$1*MC_Random_N2!$B7>=0.5*MC_Random_N2!$C7,MC_Random_N2!$B7*(1-U$1),0) -> 0.7887723 | V7: =IF(V$1*MC_Random_N2!$B7>=0.5*MC_Random_N2!$C7,MC_Random_N2!$B7*(1-V$1),0) -> 0.69017576 | W7: =IF(W$1*MC_Random_N2!$B7>=0.5*MC_Random_N2!$C7,MC_Random_N2!$B7*(1-W$1),0) -> 0.59157922 | X7: =IF(X$1*MC_Random_N2!$B7>=0.5*MC_Random_N2!$C7,MC_Random_N2!$B7*(1-X$1),0) -> 0.49298269 | Y7: =IF(Y$1*MC_Random_N2!$B7>=0.5*MC_Random_N2!$C7,MC_Random_N2!$B7*(1-Y$1),0) -> 0.39438615 | Z7: =IF(Z$1*MC_Random_N2!$B7>=0.5*MC_Random_N2!$C7,MC_Random_N2!$B7*(1-Z$1),0) -> 0.29578961 | AA7: =IF(AA$1*MC_Random_N2!$B7>=0.5*MC_Random_N2!$C7,MC_Random_N2!$B7*(1-AA$1),0) -> 0.19719307 | ... AC7: =IF(AC$1*MC_Random_N2!$B7>=0.5*MC_Random_N2!$C7,MC_Random_N2!$B7*(1-AC$1),0) -> 0 | AE7: 0.7 | AF7: ES(0.7) | AG7: =AVERAGE(Z2:Z1001) -> 0.12319928 | AP7: 6 | AQ7: =MAX(AQ$1*MC_Random_N2!$B7,0.5*MC_Random_N2!$C7) -> 0.098596537 | AR7: =MAX(AR$1*MC_Random_N2!$B7,0.5*MC_Random_N2!$C7) -> 0.19719307 | AS7: =MAX(AS$1*MC_Random_N2!$B7,0.5*MC_Random_N2!$C7) -> 0.29578961 | AT7: =MAX(AT$1*MC_Random_N2!$B7,0.5*MC_Random_N2!$C7) -> 0.39438615 | AU7: =MAX(AU$1*MC_Random_N2!$B7,0.5*MC_Random_N2!$C7) -> 0.49298269 | AV7: =MAX(AV$1*MC_Random_N2!$B7,0.5*MC_Random_N2!$C7) -> 0.59157922 | AW7: =MAX(AW$1*MC_Random_N2!$B7,0.5*MC_Random_N2!$C7) -> 0.69017576 | AX7: =MAX(AX$1*MC_Random_N2!$B7,0.5*MC_Random_N2!$C7) -> 0.7887723 | ... AZ7: =MAX(AZ$1*MC_Random_N2!$B7,0.5*MC_Random_N2!$C7) -> 0.98596537 | BB7: 0.7 | BC7: ER(0.7) | BD7: =AVERAGE(AW2:AW1001) -> 0.40943762 | CG7: 6 | CH7: =IF(CH$1*MC_Random_N5!$B7>=0.8*MAX(MC_Random_N5!$C7:$F7),MC_Random_N5!$B7*(1-CH$1),0) -> 0 | CI7: =IF(CI$1*MC_Random_N5!$B7>=0.8*MAX(MC_Random_N5!$C7:$F7),MC_Random_N5!$B7*(1-CI$1),0) -> 0 | CJ7: =IF(CJ$1*MC_Random_N5!$B7>=0.8*MAX(MC_Random_N5!$C7:$F7),MC_Random_N5!$B7*(1-CJ$1),0) -> 0 | CK7: =IF(CK$1*MC_Random_N5!$B7>=0.8*MAX(MC_Random_N5!$C7:$F7),MC_Random_N5!$B7*(1-CK$1),0) -> 0 | CL7: =IF(CL$1*MC_Random_N5!$B7>=0.8*MAX(MC_Random_N5!$C7:$F7),MC_Random_N5!$B7*(1-CL$1),0) -> 0 | CM7: =IF(CM$1*MC_Random_N5!$B7>=0.8*MAX(MC_Random_N5!$C7:$F7),MC_Random_N5!$B7*(1-CM$1),0) -> 0 | CN7: =IF(CN$1*MC_Random_N5!$B7>=0.8*MAX(MC_Random_N5!$C7:$F7),MC_Random_N5!$B7*(1-CN$1),0) -> 0 | CO7: =IF(CO$1*MC_Random_N5!$B7>=0.8*MAX(MC_Random_N5!$C7:$F7),MC_Random_N5!$B7*(1-CO$1),0) -> 0 | ... CQ7: =IF(CQ$1*MC_Random_N5!$B7>=0.8*MAX(MC_Random_N5!$C7:$F7),MC_Random_N5!$B7*(1-CQ$1),0) -> 0 | CS7: 0.7 | CT7: ES(0.7) | CU7: =AVERAGE(CN2:CN1001) -> 0.029544427 | DD7: 6 | DE7: =MAX(DE$1*MC_Random_N5!$B7,0.8*MAX(MC_Random_N5!$C7:$F7)) -> 0.49980532 | DF7: =MAX(DF$1*MC_Random_N5!$B7,0.8*MAX(MC_Random_N5!$C7:$F7)) -> 0.49980532 | DG7: =MAX(DG$1*MC_Random_N5!$B7,0.8*MAX(MC_Random_N5!$C7:$F7)) -> 0.49980532 | DH7: =MAX(DH$1*MC_Random_N5!$B7,0.8*MAX(MC_Random_N5!$C7:$F7)) -> 0.49980532 | DI7: =MAX(DI$1*MC_Random_N5!$B7,0.8*MAX(MC_Random_N5!$C7:$F7)) -> 0.49980532 | DJ7: =MAX(DJ$1*MC_Random_N5!$B7,0.8*MAX(MC_Random_N5!$C7:$F7)) -> 0.49980532 | DK7: =MAX(DK$1*MC_Random_N5!$B7,0.8*MAX(MC_Random_N5!$C7:$F7)) -> 0.49980532 | DL7: =MAX(DL$1*MC_Random_N5!$B7,0.8*MAX(MC_Random_N5!$C7:$F7)) -> 0.49980532 | ... DN7: =MAX(DN$1*MC_Random_N5!$B7,0.8*MAX(MC_Random_N5!$C7:$F7)) -> 0.49980532 | DP7: 0.7 | DQ7: ER(0.7) | DR7: =AVERAGE(DK2:DK1001) -> 0.64947503 | DX7: 6 | DY7: =RAND() -> 0.21911589 | DZ7: =(1-1/N_c2)*DY7 -> 0.1972043 | EA7: =IF(DZ7=MAX($DZ$2:$DZ$11),1,0) -> 0 | EB7: =EA7*DZ7 -> 0 | EC7: =EA7*(DY7-EB7) -> 0 | EJ7: 6 | EK7: =IF(EK$1*MC_Random_N10!$B7>=0.9*MAX(MC_Random_N10!$C7:$K7),MC_Random_N10!$B7*(1-EK$1),0) -> 0 | EL7: =IF(EL$1*MC_Random_N10!$B7>=0.9*MAX(MC_Random_N10!$C7:$K7),MC_Random_N10!$B7*(1-EL$1),0) -> 0 | EM7: =IF(EM$1*MC_Random_N10!$B7>=0.9*MAX(MC_Random_N10!$C7:$K7),MC_Random_N10!$B7*(1-EM$1),0) -> 0 | EN7: =IF(EN$1*MC_Random_N10!$B7>=0.9*MAX(MC_Random_N10!$C7:$K7),MC_Random_N10!$B7*(1-EN$1),0) -> 0 | EO7: =IF(EO$1*MC_Random_N10!$B7>=0.9*MAX(MC_Random_N10!$C7:$K7),MC_Random_N10!$B7*(1-EO$1),0) -> 0 | EP7: =IF(EP$1*MC_Random_N10!$B7>=0.9*MAX(MC_Random_N10!$C7:$K7),MC_Random_N10!$B7*(1-EP$1),0) -> 0 | EQ7: =IF(EQ$1*MC_Random_N10!$B7>=0.9*MAX(MC_Random_N10!$C7:$K7),MC_Random_N10!$B7*(1-EQ$1),0) -> 0 | ER7: =IF(ER$1*MC_Random_N10!$B7>=0.9*MAX(MC_Random_N10!$C7:$K7),MC_Random_N10!$B7*(1-ER$1),0) -> 0 | ... ET7: =IF(ET$1*MC_Random_N10!$B7>=0.9*MAX(MC_Random_N10!$C7:$K7),MC_Random_N10!$B7*(1-ET$1),0) -> 0 | EV7: 0.7 | EW7: ES(0.7) | EX7: =AVERAGE(EQ2:EQ1001) -> 0.0024878134 | FF7: 6 | FG7: =MAX(FG$1*MC_Random_N10!$B7,0.9*MAX(MC_Random_N10!$C7:$K7)) -> 0.76094603 | FH7: =MAX(FH$1*MC_Random_N10!$B7,0.9*MAX(MC_Random_N10!$C7:$K7)) -> 0.76094603 | FI7: =MAX(FI$1*MC_Random_N10!$B7,0.9*MAX(MC_Random_N10!$C7:$K7)) -> 0.76094603 | FJ7: =MAX(FJ$1*MC_Random_N10!$B7,0.9*MAX(MC_Random_N10!$C7:$K7)) -> 0.76094603 | FK7: =MAX(FK$1*MC_Random_N10!$B7,0.9*MAX(MC_Random_N10!$C7:$K7)) -> 0.76094603 | FL7: =MAX(FL$1*MC_Random_N10!$B7,0.9*MAX(MC_Random_N10!$C7:$K7)) -> 0.76094603 | FM7: =MAX(FM$1*MC_Random_N10!$B7,0.9*MAX(MC_Random_N10!$C7:$K7)) -> 0.76094603 | FN7: =MAX(FN$1*MC_Random_N10!$B7,0.9*MAX(MC_Random_N10!$C7:$K7)) -> 0.76094603 | ... FP7: =MAX(FP$1*MC_Random_N10!$B7,0.9*MAX(MC_Random_N10!$C7:$K7)) -> 0.76094603 | FR7: 0.7 | FS7: ER(0.7) | FT7: =AVERAGE(FM2:FM1001) -> 0.80959206
S8: 7 | T8: =IF(T$1*MC_Random_N2!$B8>=0.5*MC_Random_N2!$C8,MC_Random_N2!$B8*(1-T$1),0) -> 0 | U8: =IF(U$1*MC_Random_N2!$B8>=0.5*MC_Random_N2!$C8,MC_Random_N2!$B8*(1-U$1),0) -> 0 | V8: =IF(V$1*MC_Random_N2!$B8>=0.5*MC_Random_N2!$C8,MC_Random_N2!$B8*(1-V$1),0) -> 0.47766553 | W8: =IF(W$1*MC_Random_N2!$B8>=0.5*MC_Random_N2!$C8,MC_Random_N2!$B8*(1-W$1),0) -> 0.4094276 | X8: =IF(X$1*MC_Random_N2!$B8>=0.5*MC_Random_N2!$C8,MC_Random_N2!$B8*(1-X$1),0) -> 0.34118966 | Y8: =IF(Y$1*MC_Random_N2!$B8>=0.5*MC_Random_N2!$C8,MC_Random_N2!$B8*(1-Y$1),0) -> 0.27295173 | Z8: =IF(Z$1*MC_Random_N2!$B8>=0.5*MC_Random_N2!$C8,MC_Random_N2!$B8*(1-Z$1),0) -> 0.2047138 | AA8: =IF(AA$1*MC_Random_N2!$B8>=0.5*MC_Random_N2!$C8,MC_Random_N2!$B8*(1-AA$1),0) -> 0.13647587 | ... AC8: =IF(AC$1*MC_Random_N2!$B8>=0.5*MC_Random_N2!$C8,MC_Random_N2!$B8*(1-AC$1),0) -> 0 | AE8: 0.8 | AF8: ES(0.8) | AG8: =AVERAGE(AA2:AA1001) -> 0.0870401 | AP8: 7 | AQ8: =MAX(AQ$1*MC_Random_N2!$B8,0.5*MC_Random_N2!$C8) -> 0.14516016 | AR8: =MAX(AR$1*MC_Random_N2!$B8,0.5*MC_Random_N2!$C8) -> 0.14516016 | AS8: =MAX(AS$1*MC_Random_N2!$B8,0.5*MC_Random_N2!$C8) -> 0.2047138 | AT8: =MAX(AT$1*MC_Random_N2!$B8,0.5*MC_Random_N2!$C8) -> 0.27295173 | AU8: =MAX(AU$1*MC_Random_N2!$B8,0.5*MC_Random_N2!$C8) -> 0.34118966 | AV8: =MAX(AV$1*MC_Random_N2!$B8,0.5*MC_Random_N2!$C8) -> 0.4094276 | AW8: =MAX(AW$1*MC_Random_N2!$B8,0.5*MC_Random_N2!$C8) -> 0.47766553 | AX8: =MAX(AX$1*MC_Random_N2!$B8,0.5*MC_Random_N2!$C8) -> 0.54590346 | ... AZ8: =MAX(AZ$1*MC_Random_N2!$B8,0.5*MC_Random_N2!$C8) -> 0.68237933 | BB8: 0.8 | BC8: ER(0.8) | BD8: =AVERAGE(AX2:AX1001) -> 0.45189325 | CG8: 7 | CH8: =IF(CH$1*MC_Random_N5!$B8>=0.8*MAX(MC_Random_N5!$C8:$F8),MC_Random_N5!$B8*(1-CH$1),0) -> 0 | CI8: =IF(CI$1*MC_Random_N5!$B8>=0.8*MAX(MC_Random_N5!$C8:$F8),MC_Random_N5!$B8*(1-CI$1),0) -> 0 | CJ8: =IF(CJ$1*MC_Random_N5!$B8>=0.8*MAX(MC_Random_N5!$C8:$F8),MC_Random_N5!$B8*(1-CJ$1),0) -> 0 | CK8: =IF(CK$1*MC_Random_N5!$B8>=0.8*MAX(MC_Random_N5!$C8:$F8),MC_Random_N5!$B8*(1-CK$1),0) -> 0 | CL8: =IF(CL$1*MC_Random_N5!$B8>=0.8*MAX(MC_Random_N5!$C8:$F8),MC_Random_N5!$B8*(1-CL$1),0) -> 0 | CM8: =IF(CM$1*MC_Random_N5!$B8>=0.8*MAX(MC_Random_N5!$C8:$F8),MC_Random_N5!$B8*(1-CM$1),0) -> 0 | CN8: =IF(CN$1*MC_Random_N5!$B8>=0.8*MAX(MC_Random_N5!$C8:$F8),MC_Random_N5!$B8*(1-CN$1),0) -> 0 | CO8: =IF(CO$1*MC_Random_N5!$B8>=0.8*MAX(MC_Random_N5!$C8:$F8),MC_Random_N5!$B8*(1-CO$1),0) -> 0 | ... CQ8: =IF(CQ$1*MC_Random_N5!$B8>=0.8*MAX(MC_Random_N5!$C8:$F8),MC_Random_N5!$B8*(1-CQ$1),0) -> 0 | CS8: 0.8 | CT8: ES(0.8) | CU8: =AVERAGE(CO2:CO1001) -> 0.033928457 | DD8: 7 | DE8: =MAX(DE$1*MC_Random_N5!$B8,0.8*MAX(MC_Random_N5!$C8:$F8)) -> 0.65236069 | DF8: =MAX(DF$1*MC_Random_N5!$B8,0.8*MAX(MC_Random_N5!$C8:$F8)) -> 0.65236069 | DG8: =MAX(DG$1*MC_Random_N5!$B8,0.8*MAX(MC_Random_N5!$C8:$F8)) -> 0.65236069 | DH8: =MAX(DH$1*MC_Random_N5!$B8,0.8*MAX(MC_Random_N5!$C8:$F8)) -> 0.65236069 | DI8: =MAX(DI$1*MC_Random_N5!$B8,0.8*MAX(MC_Random_N5!$C8:$F8)) -> 0.65236069 | DJ8: =MAX(DJ$1*MC_Random_N5!$B8,0.8*MAX(MC_Random_N5!$C8:$F8)) -> 0.65236069 | DK8: =MAX(DK$1*MC_Random_N5!$B8,0.8*MAX(MC_Random_N5!$C8:$F8)) -> 0.65236069 | DL8: =MAX(DL$1*MC_Random_N5!$B8,0.8*MAX(MC_Random_N5!$C8:$F8)) -> 0.65236069 | ... DN8: =MAX(DN$1*MC_Random_N5!$B8,0.8*MAX(MC_Random_N5!$C8:$F8)) -> 0.65236069 | DP8: 0.8 | DQ8: ER(0.8) | DR8: =AVERAGE(DL2:DL1001) -> 0.66273906 | DX8: 7 | DY8: =RAND() -> 0.013467021 | DZ8: =(1-1/N_c2)*DY8 -> 0.012120319 | EA8: =IF(DZ8=MAX($DZ$2:$DZ$11),1,0) -> 0 | EB8: =EA8*DZ8 -> 0 | EC8: =EA8*(DY8-EB8) -> 0 | EJ8: 7 | EK8: =IF(EK$1*MC_Random_N10!$B8>=0.9*MAX(MC_Random_N10!$C8:$K8),MC_Random_N10!$B8*(1-EK$1),0) -> 0 | EL8: =IF(EL$1*MC_Random_N10!$B8>=0.9*MAX(MC_Random_N10!$C8:$K8),MC_Random_N10!$B8*(1-EL$1),0) -> 0 | EM8: =IF(EM$1*MC_Random_N10!$B8>=0.9*MAX(MC_Random_N10!$C8:$K8),MC_Random_N10!$B8*(1-EM$1),0) -> 0 | EN8: =IF(EN$1*MC_Random_N10!$B8>=0.9*MAX(MC_Random_N10!$C8:$K8),MC_Random_N10!$B8*(1-EN$1),0) -> 0 | EO8: =IF(EO$1*MC_Random_N10!$B8>=0.9*MAX(MC_Random_N10!$C8:$K8),MC_Random_N10!$B8*(1-EO$1),0) -> 0 | EP8: =IF(EP$1*MC_Random_N10!$B8>=0.9*MAX(MC_Random_N10!$C8:$K8),MC_Random_N10!$B8*(1-EP$1),0) -> 0 | EQ8: =IF(EQ$1*MC_Random_N10!$B8>=0.9*MAX(MC_Random_N10!$C8:$K8),MC_Random_N10!$B8*(1-EQ$1),0) -> 0 | ER8: =IF(ER$1*MC_Random_N10!$B8>=0.9*MAX(MC_Random_N10!$C8:$K8),MC_Random_N10!$B8*(1-ER$1),0) -> 0 | ... ET8: =IF(ET$1*MC_Random_N10!$B8>=0.9*MAX(MC_Random_N10!$C8:$K8),MC_Random_N10!$B8*(1-ET$1),0) -> 0 | EV8: 0.8 | EW8: ES(0.8) | EX8: =AVERAGE(ER2:ER1001) -> 0.0068866623 | FF8: 7 | FG8: =MAX(FG$1*MC_Random_N10!$B8,0.9*MAX(MC_Random_N10!$C8:$K8)) -> 0.83898814 | FH8: =MAX(FH$1*MC_Random_N10!$B8,0.9*MAX(MC_Random_N10!$C8:$K8)) -> 0.83898814 | FI8: =MAX(FI$1*MC_Random_N10!$B8,0.9*MAX(MC_Random_N10!$C8:$K8)) -> 0.83898814 | FJ8: =MAX(FJ$1*MC_Random_N10!$B8,0.9*MAX(MC_Random_N10!$C8:$K8)) -> 0.83898814 | FK8: =MAX(FK$1*MC_Random_N10!$B8,0.9*MAX(MC_Random_N10!$C8:$K8)) -> 0.83898814 | FL8: =MAX(FL$1*MC_Random_N10!$B8,0.9*MAX(MC_Random_N10!$C8:$K8)) -> 0.83898814 | FM8: =MAX(FM$1*MC_Random_N10!$B8,0.9*MAX(MC_Random_N10!$C8:$K8)) -> 0.83898814 | FN8: =MAX(FN$1*MC_Random_N10!$B8,0.9*MAX(MC_Random_N10!$C8:$K8)) -> 0.83898814 | ... FP8: =MAX(FP$1*MC_Random_N10!$B8,0.9*MAX(MC_Random_N10!$C8:$K8)) -> 0.83898814 | FR8: 0.8 | FS8: ER(0.8) | FT8: =AVERAGE(FN2:FN1001) -> 0.81141921
S9: 8 | T9: =IF(T$1*MC_Random_N2!$B9>=0.5*MC_Random_N2!$C9,MC_Random_N2!$B9*(1-T$1),0) -> 0 | U9: =IF(U$1*MC_Random_N2!$B9>=0.5*MC_Random_N2!$C9,MC_Random_N2!$B9*(1-U$1),0) -> 0 | V9: =IF(V$1*MC_Random_N2!$B9>=0.5*MC_Random_N2!$C9,MC_Random_N2!$B9*(1-V$1),0) -> 0 | W9: =IF(W$1*MC_Random_N2!$B9>=0.5*MC_Random_N2!$C9,MC_Random_N2!$B9*(1-W$1),0) -> 0.57306651 | X9: =IF(X$1*MC_Random_N2!$B9>=0.5*MC_Random_N2!$C9,MC_Random_N2!$B9*(1-X$1),0) -> 0.47755542 | Y9: =IF(Y$1*MC_Random_N2!$B9>=0.5*MC_Random_N2!$C9,MC_Random_N2!$B9*(1-Y$1),0) -> 0.38204434 | Z9: =IF(Z$1*MC_Random_N2!$B9>=0.5*MC_Random_N2!$C9,MC_Random_N2!$B9*(1-Z$1),0) -> 0.28653325 | AA9: =IF(AA$1*MC_Random_N2!$B9>=0.5*MC_Random_N2!$C9,MC_Random_N2!$B9*(1-AA$1),0) -> 0.19102217 | ... AC9: =IF(AC$1*MC_Random_N2!$B9>=0.5*MC_Random_N2!$C9,MC_Random_N2!$B9*(1-AC$1),0) -> 0 | AE9: 0.9 | AF9: ES(0.9) | AG9: =AVERAGE(AB2:AB1001) -> 0.045099016 | AP9: 8 | AQ9: =MAX(AQ$1*MC_Random_N2!$B9,0.5*MC_Random_N2!$C9) -> 0.34595629 | AR9: =MAX(AR$1*MC_Random_N2!$B9,0.5*MC_Random_N2!$C9) -> 0.34595629 | AS9: =MAX(AS$1*MC_Random_N2!$B9,0.5*MC_Random_N2!$C9) -> 0.34595629 | AT9: =MAX(AT$1*MC_Random_N2!$B9,0.5*MC_Random_N2!$C9) -> 0.38204434 | AU9: =MAX(AU$1*MC_Random_N2!$B9,0.5*MC_Random_N2!$C9) -> 0.47755542 | AV9: =MAX(AV$1*MC_Random_N2!$B9,0.5*MC_Random_N2!$C9) -> 0.57306651 | AW9: =MAX(AW$1*MC_Random_N2!$B9,0.5*MC_Random_N2!$C9) -> 0.66857759 | AX9: =MAX(AX$1*MC_Random_N2!$B9,0.5*MC_Random_N2!$C9) -> 0.76408868 | ... AZ9: =MAX(AZ$1*MC_Random_N2!$B9,0.5*MC_Random_N2!$C9) -> 0.95511084 | BB9: 0.9 | BC9: ER(0.9) | BD9: =AVERAGE(AY2:AY1001) -> 0.49636484 | CG9: 8 | CH9: =IF(CH$1*MC_Random_N5!$B9>=0.8*MAX(MC_Random_N5!$C9:$F9),MC_Random_N5!$B9*(1-CH$1),0) -> 0 | CI9: =IF(CI$1*MC_Random_N5!$B9>=0.8*MAX(MC_Random_N5!$C9:$F9),MC_Random_N5!$B9*(1-CI$1),0) -> 0 | CJ9: =IF(CJ$1*MC_Random_N5!$B9>=0.8*MAX(MC_Random_N5!$C9:$F9),MC_Random_N5!$B9*(1-CJ$1),0) -> 0 | CK9: =IF(CK$1*MC_Random_N5!$B9>=0.8*MAX(MC_Random_N5!$C9:$F9),MC_Random_N5!$B9*(1-CK$1),0) -> 0 | CL9: =IF(CL$1*MC_Random_N5!$B9>=0.8*MAX(MC_Random_N5!$C9:$F9),MC_Random_N5!$B9*(1-CL$1),0) -> 0 | CM9: =IF(CM$1*MC_Random_N5!$B9>=0.8*MAX(MC_Random_N5!$C9:$F9),MC_Random_N5!$B9*(1-CM$1),0) -> 0 | CN9: =IF(CN$1*MC_Random_N5!$B9>=0.8*MAX(MC_Random_N5!$C9:$F9),MC_Random_N5!$B9*(1-CN$1),0) -> 0 | CO9: =IF(CO$1*MC_Random_N5!$B9>=0.8*MAX(MC_Random_N5!$C9:$F9),MC_Random_N5!$B9*(1-CO$1),0) -> 0 | ... CQ9: =IF(CQ$1*MC_Random_N5!$B9>=0.8*MAX(MC_Random_N5!$C9:$F9),MC_Random_N5!$B9*(1-CQ$1),0) -> 0 | CS9: 0.9 | CT9: ES(0.9) | CU9: =AVERAGE(CP2:CP1001) -> 0.024814799 | DD9: 8 | DE9: =MAX(DE$1*MC_Random_N5!$B9,0.8*MAX(MC_Random_N5!$C9:$F9)) -> 0.77267871 | DF9: =MAX(DF$1*MC_Random_N5!$B9,0.8*MAX(MC_Random_N5!$C9:$F9)) -> 0.77267871 | DG9: =MAX(DG$1*MC_Random_N5!$B9,0.8*MAX(MC_Random_N5!$C9:$F9)) -> 0.77267871 | DH9: =MAX(DH$1*MC_Random_N5!$B9,0.8*MAX(MC_Random_N5!$C9:$F9)) -> 0.77267871 | DI9: =MAX(DI$1*MC_Random_N5!$B9,0.8*MAX(MC_Random_N5!$C9:$F9)) -> 0.77267871 | DJ9: =MAX(DJ$1*MC_Random_N5!$B9,0.8*MAX(MC_Random_N5!$C9:$F9)) -> 0.77267871 | DK9: =MAX(DK$1*MC_Random_N5!$B9,0.8*MAX(MC_Random_N5!$C9:$F9)) -> 0.77267871 | DL9: =MAX(DL$1*MC_Random_N5!$B9,0.8*MAX(MC_Random_N5!$C9:$F9)) -> 0.77267871 | ... DN9: =MAX(DN$1*MC_Random_N5!$B9,0.8*MAX(MC_Random_N5!$C9:$F9)) -> 0.81113931 | DP9: 0.9 | DQ9: ER(0.9) | DR9: =AVERAGE(DM2:DM1001) -> 0.6837866 | DX9: 8 | DY9: =RAND() -> 0.60106439 | DZ9: =(1-1/N_c2)*DY9 -> 0.54095795 | EA9: =IF(DZ9=MAX($DZ$2:$DZ$11),1,0) -> 0 | EB9: =EA9*DZ9 -> 0 | EC9: =EA9*(DY9-EB9) -> 0 | EJ9: 8 | EK9: =IF(EK$1*MC_Random_N10!$B9>=0.9*MAX(MC_Random_N10!$C9:$K9),MC_Random_N10!$B9*(1-EK$1),0) -> 0 | EL9: =IF(EL$1*MC_Random_N10!$B9>=0.9*MAX(MC_Random_N10!$C9:$K9),MC_Random_N10!$B9*(1-EL$1),0) -> 0 | EM9: =IF(EM$1*MC_Random_N10!$B9>=0.9*MAX(MC_Random_N10!$C9:$K9),MC_Random_N10!$B9*(1-EM$1),0) -> 0 | EN9: =IF(EN$1*MC_Random_N10!$B9>=0.9*MAX(MC_Random_N10!$C9:$K9),MC_Random_N10!$B9*(1-EN$1),0) -> 0 | EO9: =IF(EO$1*MC_Random_N10!$B9>=0.9*MAX(MC_Random_N10!$C9:$K9),MC_Random_N10!$B9*(1-EO$1),0) -> 0 | EP9: =IF(EP$1*MC_Random_N10!$B9>=0.9*MAX(MC_Random_N10!$C9:$K9),MC_Random_N10!$B9*(1-EP$1),0) -> 0 | EQ9: =IF(EQ$1*MC_Random_N10!$B9>=0.9*MAX(MC_Random_N10!$C9:$K9),MC_Random_N10!$B9*(1-EQ$1),0) -> 0 | ER9: =IF(ER$1*MC_Random_N10!$B9>=0.9*MAX(MC_Random_N10!$C9:$K9),MC_Random_N10!$B9*(1-ER$1),0) -> 0 | ... ET9: =IF(ET$1*MC_Random_N10!$B9>=0.9*MAX(MC_Random_N10!$C9:$K9),MC_Random_N10!$B9*(1-ET$1),0) -> 0 | EV9: 0.9 | EW9: ES(0.9) | EX9: =AVERAGE(ES2:ES1001) -> 0.010406304 | FF9: 8 | FG9: =MAX(FG$1*MC_Random_N10!$B9,0.9*MAX(MC_Random_N10!$C9:$K9)) -> 0.80428863 | FH9: =MAX(FH$1*MC_Random_N10!$B9,0.9*MAX(MC_Random_N10!$C9:$K9)) -> 0.80428863 | FI9: =MAX(FI$1*MC_Random_N10!$B9,0.9*MAX(MC_Random_N10!$C9:$K9)) -> 0.80428863 | FJ9: =MAX(FJ$1*MC_Random_N10!$B9,0.9*MAX(MC_Random_N10!$C9:$K9)) -> 0.80428863 | FK9: =MAX(FK$1*MC_Random_N10!$B9,0.9*MAX(MC_Random_N10!$C9:$K9)) -> 0.80428863 | FL9: =MAX(FL$1*MC_Random_N10!$B9,0.9*MAX(MC_Random_N10!$C9:$K9)) -> 0.80428863 | FM9: =MAX(FM$1*MC_Random_N10!$B9,0.9*MAX(MC_Random_N10!$C9:$K9)) -> 0.80428863 | FN9: =MAX(FN$1*MC_Random_N10!$B9,0.9*MAX(MC_Random_N10!$C9:$K9)) -> 0.80428863 | ... FP9: =MAX(FP$1*MC_Random_N10!$B9,0.9*MAX(MC_Random_N10!$C9:$K9)) -> 0.80428863 | FR9: 0.9 | FS9: ER(0.9) | FT9: =AVERAGE(FO2:FO1001) -> 0.8185027
