Workbook
Name a: '2_Insurance'!$C$3
Name alive: '1_Investment_Stategy1'!$K$2:$K$51
Name alive_2: '1_Investment_Stategy2'!$J$2:$J$51
Name b: '2_Insurance'!$C$4
Name B0: '1_Investment_Stategy1'!$C$1
Name B0_2: '1_Investment_Stategy2'!$C$1
Name bin: '1_Investment_Stategy1'!$V$5:$V$21
Name bin_1: '2_Insurance'!$AC$9:$AC$15
Name bin2_: '1_Investment_Stategy2'!$U$5:$U$26
Name Bt: '1_Investment_Stategy1'!$G$2:$G$51
Name Bt_2: '1_Investment_Stategy2'!$G$2:$G$51
Name Dt: '1_Investment_Stategy1'!$C$5
Name Dt_2: '1_Investment_Stategy2'!$C$5
Name E_R: '2_Insurance'!$Z$1
Name E_ST1: '1_Investment_Stategy1'!$Z$1
Name E_ST2: '1_Investment_Stategy2'!$Y$1
Name ID: '2_Insurance'!$G$2:$G$201
Name k: '2_Insurance'!$C$16
Name loss: '2_Insurance'!$K$2:$K$201
Name max_R: '2_Insurance'!$Z$3
Name min_R: '2_Insurance'!$Z$4
Name mu: '1_Investment_Stategy1'!$C$3
Name mu_2: '1_Investment_Stategy2'!$C$3
Name mu_insur: '2_Insurance'!$C$1
Name N: '1_Investment_Stategy1'!$C$8
Name N_2: '1_Investment_Stategy2'!$C$8
Name N_insur: '2_Insurance'!$C$5
Name P: '2_Insurance'!$C$10:$D$13
Name P_R_1: '2_Insurance'!$Z$5
Name pc: '2_Insurance'!$C$15
Name pc_: '2_Insurance'!$C$15
Name pe: '2_Insurance'!$C$7
Name pick: '2_Insurance'!$L$2:$L$201
Name premium: '2_Insurance'!$J$2:$J$201
Name R_: '2_Insurance'!$U$2:$U$501
Name R_1: '2_Insurance'!$V$2:$V$501
Name ratio: '2_Insurance'!$Q$3
Name rc_: '2_Insurance'!$C$14
Name real_loss: '2_Insurance'!$N$2:$N$201
Name real_premium: '2_Insurance'!$M$2:$M$201
Name rs: '1_Investment_Stategy1'!$C$7
Name rs_2: '1_Investment_Stategy2'!$C$7
Name S: '2_Insurance'!$C$8
Name s_R: '2_Insurance'!$Z$2
Name S0: '1_Investment_Stategy1'!$C$2
Name S0_2: '1_Investment_Stategy2'!$C$2
Name SBt: '1_Investment_Stategy1'!$I$2:$I$51
Name SBt_2: '1_Investment_Stategy2'!$I$2:$I$51
Name sigma: '1_Investment_Stategy1'!$C$4
Name sigma_2: '1_Investment_Stategy2'!$C$4
Name sigma_insur: '2_Insurance'!$C$2
Name SSt: '1_Investment_Stategy1'!$J$2:$J$51
Name St: '1_Investment_Stategy1'!$H$2:$H$51
Name ST_1: '1_Investment_Stategy1'!$O$1
Name ST_2: '1_Investment_Stategy2'!$N$1
Name STS: '1_Investment_Stategy1'!$S$2:$S$2001
Name STS2_: '1_Investment_Stategy2'!$R$2:$R$2001
Name T: '1_Investment_Stategy1'!$C$6
Name T_2: '1_Investment_Stategy2'!$C$6
Name TL: '2_Insurance'!$Q$2

Sheet Portfolio Overview
A1: MGT239 Simulation for Business — Finance Simulation Portfolio
A4: PORTFOLIO SCOPE
A5: Two Monte Carlo simulation studies examine business decisions under uncertainty. The investment study compares withdrawal policies for a mixed stock-and-bond fund. The insurance study models annual loss-ratio risk when policy volume, coverage choice, claim occurrence, and claim severity are random. The portfolio emphasizes distributions, tail behavior, simulation precision, and managerial interpretation.
A10: PROJECT MAP
A11: Project | B11: Business Question | C11: Core Model | D11: Simulation Design | E11: Primary Output | F11: Decision Lens | G11: Original Model | H11: Analysis
A12: Investment Withdrawal Strategies | B12: How does withdrawal sequencing change fund longevity? | C12: GBM stock process + bond growth + recursive shortages + stopping time | D12: =TEXT('1_Investment_Stategy1'!C8,"#,##0")&" simulated paths; maximum "&TEXT(MAX('1_Investment_Stategy1'!F2:F51),"0")&" years" -> 2,000 simulated paths; maximum 50 years | E12: Fund-life distribution | F12: Capital preservation / withdrawal policy | G12: 1_Investment_Stategy1 & 1_Investment_Stategy2 | H12: Investment Analysis
A13: Insurance Loss-Ratio Risk | B13: How do claim frequency and severity shape annual performance risk? | C13: Random sample size + coverage choice + Bernoulli claims + exponential severity | D13: =TEXT('2_Insurance'!C5,"#,##0")&" simulated years" -> 500 simulated years | E13: Annual loss-ratio distribution | F13: Performance risk / tail exposure | G13: 2_Insurance | H13: Insurance Analysis
A15: ANALYTICAL WORKFLOW
A16: Problem | B16: Define the business decision and uncertainty.
A17: Model | B17: Translate the system into state variables, probability distributions, recursive equations, and risk/stopping criteria.
A18: Simulation Design | B18: Generate repeated stochastic outcomes to approximate the outcome distribution.
A19: Results | B19: Summarize expected outcomes, dispersion, confidence intervals, tail probabilities, and distribution shape.
A20: Interpretation | B20: Explain what the simulated distribution means for the decision.
A21: Managerial / Analytical Implications | B21: Connect output to policy choice and risk management.
A22: Limitations | B22: State structural assumptions and finite-simulation uncertainty.

Sheet Investment Analysis
A1: Investment Withdrawal Strategies — Monte Carlo Fund-Life Analysis
A4: PROBLEM
A5: A $1,000,000 fund begins with $500,000 in stocks and $500,000 in bonds. Stocks follow geometric Brownian motion with 8% drift and 12% volatility; bonds earn 5% annually. The investor withdraws $120,000 at each year-end. Strategy 1 withdraws $60,000 from each fund and covers shortages from the other fund. Strategy 2 draws from bonds first and uses stocks after the bond fund cannot cover the withdrawal. The question is how withdrawal sequencing changes the distribution of time until depletion.
A8: MODEL
A9: Let S_t and B_t denote stock and bond balances before withdrawal. Strategy 1 uses shortage variables to transfer any unmet $60,000 withdrawal between funds. Stock evolves with geometric Brownian motion, while bonds grow deterministically after withdrawals. Strategy 2 withdraws $120,000 from bonds first and covers bond shortage from stock. Fund life is the stopping time measured by the number of periods for which total funds remain positive.
A12: SIMULATION DESIGN
A13: ="Each strategy generates a stochastic path for up to "&TEXT(MAX('1_Investment_Stategy1'!F2:F51),"0")&" years. The alive indicator equals 1 while total funds remain positive, and its sum gives the stopping time. The original model replicates this calculation "&TEXT('1_Investment_Stategy1'!C8,"#,##0")&" times per strategy. All results and narrative statements below reference the original model outputs dynamically." -> Each strategy generates a stochastic path for up to 50 years. The alive indicator equals 1 while total funds remain positive, and its sum gives the stopping time. The original model replicates this calculation 2,000 times per strategy. All results and narrative statements below reference the original model outputs dynamically.
A16: MODEL PARAMETERS | F16: RESULTS
A17: Parameter | B17: Meaning | C17: Value | D17: Units | F17: Metric | G17: Parallel | H17: Bond-First | I17: Difference | J17: Interpretation
A18: B0 | B18: Initial bond fund | C18: ='1_Investment_Stategy1'!C1 -> 500 | D18: $000s | F18: Mean fund life | G18: =AVERAGE('1_Investment_Stategy1'!S2:S2001) -> 11.9445 | H18: =AVERAGE('1_Investment_Stategy2'!R2:R2001) -> 12.5695 | I18: =H18-G18 -> 0.625 | J18: Expected simulated years until depletion
A19: S0 | B19: Initial stock fund | C19: ='1_Investment_Stategy1'!C2 -> 500 | D19: $000s | F19: Std. deviation | G19: =_xlfn.STDEV.S('1_Investment_Stategy1'!S2:S2001) -> 1.5635351 | H19: =_xlfn.STDEV.S('1_Investment_Stategy2'!R2:R2001) -> 2.3003947 | I19: =H19-G19 -> 0.73685955 | J19: Dispersion of stopping times
A20: μ | B20: Stock drift | C20: ='1_Investment_Stategy1'!C3 -> 0.08 | D20: annual | F20: 95% CI — lower | G20: =AVERAGE('1_Investment_Stategy1'!S2:S2001)-1.96*_xlfn.STDEV.S('1_Investment_Stategy1'!S2:S2001)/SQRT('1_Investment_Stategy1'!C8) -> 11.875975 | H20: =AVERAGE('1_Investment_Stategy2'!R2:R2001)-1.96*_xlfn.STDEV.S('1_Investment_Stategy2'!R2:R2001)/SQRT('1_Investment_Stategy2'!C8) -> 12.468681 | I20: =H20-G20 -> 0.59270571 | J20: Monte Carlo CI for estimated mean
A21: σ | B21: Stock volatility | C21: ='1_Investment_Stategy1'!C4 -> 0.12 | D21: annual | F21: 95% CI — upper | G21: =AVERAGE('1_Investment_Stategy1'!S2:S2001)+1.96*_xlfn.STDEV.S('1_Investment_Stategy1'!S2:S2001)/SQRT('1_Investment_Stategy1'!C8) -> 12.013025 | H21: =AVERAGE('1_Investment_Stategy2'!R2:R2001)+1.96*_xlfn.STDEV.S('1_Investment_Stategy2'!R2:R2001)/SQRT('1_Investment_Stategy2'!C8) -> 12.670319 | I21: =H21-G21 -> 0.65729429 | J21: Monte Carlo CI for estimated mean
A22: r | B22: Bond return | C22: ='1_Investment_Stategy1'!C7 -> 0.05 | D22: annual | F22: Minimum | G22: =MIN('1_Investment_Stategy1'!S2:S2001) -> 9 | H22: =MIN('1_Investment_Stategy2'!R2:R2001) -> 8 | I22: =H22-G22 -> -1 | J22: Shortest observed fund life
A23: N | B23: Monte Carlo replications | C23: ='1_Investment_Stategy1'!C8 -> 2000 | D23: paths | F23: Maximum | G23: =MAX('1_Investment_Stategy1'!S2:S2001) -> 33 | H23: =MAX('1_Investment_Stategy2'!R2:R2001) -> 30 | I23: =H23-G23 -> -3 | J23: Longest observed fund life
A26: INTERPRETATION | F26: DISTRIBUTION VISUALIZATION
A27: ="Across "&TEXT('1_Investment_Stategy1'!C8,"#,##0")&" simulated paths, the bond-first policy has an estimated mean fund life of "&TEXT(H18,"0.00")&" years versus "&TEXT(G18,"0.00")&" years for parallel withdrawals, a difference of "&TEXT(I18,"0.00")&" years. The 95% confidence intervals for the estimated means are ["&TEXT(G20,"0.00")&", "&TEXT(G21,"0.00")&"] and ["&TEXT(H20,"0.00")&", "&TEXT(H21,"0.00")&"]. Because these values are linked to the simulation output, this interpretation updates whenever the original simulation recalculates." -> Across 2,000 simulated paths, the bond-first policy has an estimated mean fund life of 12.57 years versus 11.94 years for parallel withdrawals, a difference of 0.63 years. The 95% confidence intervals for the estimated means are [11.88, 12.01] and [12.47, 12.67]. Because these values are linked to the simulation output, this interpretation updates whenever the original simulation recalculates. | F27: Upper Bin | G27: Parallel % | H27: Bond-First % | I27: Parallel Bar | J27: Bond-First Bar
F28: 8 | G28: =COUNTIFS('1_Investment_Stategy1'!$S$2:$S$2001,">6",'1_Investment_Stategy1'!$S$2:$S$2001,"<=8")/'1_Investment_Stategy1'!C8 -> 0 | H28: =COUNTIFS('1_Investment_Stategy2'!$R$2:$R$2001,">6",'1_Investment_Stategy2'!$R$2:$R$2001,"<=8")/'1_Investment_Stategy2'!C8 -> 0.0005 | I28: =REPT("|",ROUND(G28*40,0)) | J28: =REPT("|",ROUND(H28*40,0))
F29: 10 | G29: =COUNTIFS('1_Investment_Stategy1'!$S$2:$S$2001,">8",'1_Investment_Stategy1'!$S$2:$S$2001,"<=10")/'1_Investment_Stategy1'!C8 -> 0.1115 | H29: =COUNTIFS('1_Investment_Stategy2'!$R$2:$R$2001,">8",'1_Investment_Stategy2'!$R$2:$R$2001,"<=10")/'1_Investment_Stategy2'!C8 -> 0.1385 | I29: =REPT("|",ROUND(G29*40,0)) -> |||| | J29: =REPT("|",ROUND(H29*40,0)) -> ||||||
F30: 12 | G30: =COUNTIFS('1_Investment_Stategy1'!$S$2:$S$2001,">10",'1_Investment_Stategy1'!$S$2:$S$2001,"<=12")/'1_Investment_Stategy1'!C8 -> 0.6285 | H30: =COUNTIFS('1_Investment_Stategy2'!$R$2:$R$2001,">10",'1_Investment_Stategy2'!$R$2:$R$2001,"<=12")/'1_Investment_Stategy2'!C8 -> 0.4425 | I30: =REPT("|",ROUND(G30*40,0)) -> ||||||||||||||||||||||||| | J30: =REPT("|",ROUND(H30*40,0)) -> ||||||||||||||||||
F31: 14 | G31: =COUNTIFS('1_Investment_Stategy1'!$S$2:$S$2001,">12",'1_Investment_Stategy1'!$S$2:$S$2001,"<=14")/'1_Investment_Stategy1'!C8 -> 0.208 | H31: =COUNTIFS('1_Investment_Stategy2'!$R$2:$R$2001,">12",'1_Investment_Stategy2'!$R$2:$R$2001,"<=14")/'1_Investment_Stategy2'!C8 -> 0.2665 | I31: =REPT("|",ROUND(G31*40,0)) -> |||||||| | J31: =REPT("|",ROUND(H31*40,0)) -> |||||||||||
F32: 16 | G32: =COUNTIFS('1_Investment_Stategy1'!$S$2:$S$2001,">14",'1_Investment_Stategy1'!$S$2:$S$2001,"<=16")/'1_Investment_Stategy1'!C8 -> 0.041 | H32: =COUNTIFS('1_Investment_Stategy2'!$R$2:$R$2001,">14",'1_Investment_Stategy2'!$R$2:$R$2001,"<=16")/'1_Investment_Stategy2'!C8 -> 0.094 | I32: =REPT("|",ROUND(G32*40,0)) -> || | J32: =REPT("|",ROUND(H32*40,0)) -> ||||
F33: 18 | G33: =COUNTIFS('1_Investment_Stategy1'!$S$2:$S$2001,">16",'1_Investment_Stategy1'!$S$2:$S$2001,"<=18")/'1_Investment_Stategy1'!C8 -> 0.007 | H33: =COUNTIFS('1_Investment_Stategy2'!$R$2:$R$2001,">16",'1_Investment_Stategy2'!$R$2:$R$2001,"<=18")/'1_Investment_Stategy2'!C8 -> 0.035 | I33: =REPT("|",ROUND(G33*40,0)) | J33: =REPT("|",ROUND(H33*40,0)) -> |
A34: MANAGERIAL / ANALYTICAL IMPLICATIONS | F34: 20 | G34: =COUNTIFS('1_Investment_Stategy1'!$S$2:$S$2001,">18",'1_Investment_Stategy1'!$S$2:$S$2001,"<=20")/'1_Investment_Stategy1'!C8 -> 0.001 | H34: =COUNTIFS('1_Investment_Stategy2'!$R$2:$R$2001,">18",'1_Investment_Stategy2'!$R$2:$R$2001,"<=20")/'1_Investment_Stategy2'!C8 -> 0.015 | I34: =REPT("|",ROUND(G34*40,0)) | J34: =REPT("|",ROUND(H34*40,0)) -> |
A35: ="In the current simulation, "&IF(H18>G18,"bond-first withdrawal","parallel withdrawal")&" produces the longer estimated mean fund life by "&TEXT(ABS(I18),"0.00")&" years. Withdrawal sequencing changes the amount of capital left exposed to compounding, so the decision should be evaluated using the full simulated distribution and confidence intervals rather than a single path." -> In the current simulation, bond-first withdrawal produces the longer estimated mean fund life by 0.63 years. Withdrawal sequencing changes the amount of capital left exposed to compounding, so the decision should be evaluated using the full simulated distribution and confidence intervals rather than a single path. | F35: 22 | G35: =COUNTIFS('1_Investment_Stategy1'!$S$2:$S$2001,">20",'1_Investment_Stategy1'!$S$2:$S$2001,"<=22")/'1_Investment_Stategy1'!C8 -> 0.002 | H35: =COUNTIFS('1_Investment_Stategy2'!$R$2:$R$2001,">20",'1_Investment_Stategy2'!$R$2:$R$2001,"<=22")/'1_Investment_Stategy2'!C8 -> 0.003 | I35: =REPT("|",ROUND(G35*40,0)) | J35: =REPT("|",ROUND(H35*40,0))
F36: 24 | G36: =COUNTIFS('1_Investment_Stategy1'!$S$2:$S$2001,">22",'1_Investment_Stategy1'!$S$2:$S$2001,"<=24")/'1_Investment_Stategy1'!C8 -> 0 | H36: =COUNTIFS('1_Investment_Stategy2'!$R$2:$R$2001,">22",'1_Investment_Stategy2'!$R$2:$R$2001,"<=24")/'1_Investment_Stategy2'!C8 -> 0.0025 | I36: =REPT("|",ROUND(G36*40,0)) | J36: =REPT("|",ROUND(H36*40,0))
F37: 26 | G37: =COUNTIFS('1_Investment_Stategy1'!$S$2:$S$2001,">24",'1_Investment_Stategy1'!$S$2:$S$2001,"<=26")/'1_Investment_Stategy1'!C8 -> 0 | H37: =COUNTIFS('1_Investment_Stategy2'!$R$2:$R$2001,">24",'1_Investment_Stategy2'!$R$2:$R$2001,"<=26")/'1_Investment_Stategy2'!C8 -> 0.001 | I37: =REPT("|",ROUND(G37*40,0)) | J37: =REPT("|",ROUND(H37*40,0))
F38: 28 | G38: =COUNTIFS('1_Investment_Stategy1'!$S$2:$S$2001,">26",'1_Investment_Stategy1'!$S$2:$S$2001,"<=28")/'1_Investment_Stategy1'!C8 -> 0 | H38: =COUNTIFS('1_Investment_Stategy2'!$R$2:$R$2001,">26",'1_Investment_Stategy2'!$R$2:$R$2001,"<=28")/'1_Investment_Stategy2'!C8 -> 0.001 | I38: =REPT("|",ROUND(G38*40,0)) | J38: =REPT("|",ROUND(H38*40,0))
F39: 30 | G39: =COUNTIFS('1_Investment_Stategy1'!$S$2:$S$2001,">28",'1_Investment_Stategy1'!$S$2:$S$2001,"<=30")/'1_Investment_Stategy1'!C8 -> 0.0005 | H39: =COUNTIFS('1_Investment_Stategy2'!$R$2:$R$2001,">28",'1_Investment_Stategy2'!$R$2:$R$2001,"<=30")/'1_Investment_Stategy2'!C8 -> 0.0005 | I39: =REPT("|",ROUND(G39*40,0)) | J39: =REPT("|",ROUND(H39*40,0))
F40: 32 | G40: =COUNTIFS('1_Investment_Stategy1'!$S$2:$S$2001,">30",'1_Investment_Stategy1'!$S$2:$S$2001,"<=32")/'1_Investment_Stategy1'!C8 -> 0 | H40: =COUNTIFS('1_Investment_Stategy2'!$R$2:$R$2001,">30",'1_Investment_Stategy2'!$R$2:$R$2001,"<=32")/'1_Investment_Stategy2'!C8 -> 0 | I40: =REPT("|",ROUND(G40*40,0)) | J40: =REPT("|",ROUND(H40*40,0))
F41: 34 | G41: =COUNTIFS('1_Investment_Stategy1'!$S$2:$S$2001,">32",'1_Investment_Stategy1'!$S$2:$S$2001,"<=34")/'1_Investment_Stategy1'!C8 -> 0.0005 | H41: =COUNTIFS('1_Investment_Stategy2'!$R$2:$R$2001,">32",'1_Investment_Stategy2'!$R$2:$R$2001,"<=34")/'1_Investment_Stategy2'!C8 -> 0 | I41: =REPT("|",ROUND(G41*40,0)) | J41: =REPT("|",ROUND(H41*40,0))
A42: LIMITATIONS | F42: 36 | G42: =COUNTIFS('1_Investment_Stategy1'!$S$2:$S$2001,">34",'1_Investment_Stategy1'!$S$2:$S$2001,"<=36")/'1_Investment_Stategy1'!C8 -> 0 | H42: =COUNTIFS('1_Investment_Stategy2'!$R$2:$R$2001,">34",'1_Investment_Stategy2'!$R$2:$R$2001,"<=36")/'1_Investment_Stategy2'!C8 -> 0 | I42: =REPT("|",ROUND(G42*40,0)) | J42: =REPT("|",ROUND(H42*40,0))
A43: ="The stock process assumes constant drift and volatility, normally distributed shocks, annual time steps, and no transaction costs, taxes, fees, inflation, or regime changes. Bond returns are fixed at "&TEXT(C22,"0.0%")&". The reported Monte Carlo estimates use "&TEXT(C23,"#,##0")&" replications per strategy and therefore contain sampling error, which is examined in the convergence sheet." -> The stock process assumes constant drift and volatility, normally distributed shocks, annual time steps, and no transaction costs, taxes, fees, inflation, or regime changes. Bond returns are fixed at 5.0%. The reported Monte Carlo estimates use 2,000 replications per strategy and therefore contain sampling error, which is examined in the convergence sheet. | F43: 38 | G43: =COUNTIFS('1_Investment_Stategy1'!$S$2:$S$2001,">36",'1_Investment_Stategy1'!$S$2:$S$2001,"<=38")/'1_Investment_Stategy1'!C8 -> 0 | H43: =COUNTIFS('1_Investment_Stategy2'!$R$2:$R$2001,">36",'1_Investment_Stategy2'!$R$2:$R$2001,"<=38")/'1_Investment_Stategy2'!C8 -> 0 | I43: =REPT("|",ROUND(G43*40,0)) | J43: =REPT("|",ROUND(H43*40,0))
F44: 40 | G44: =COUNTIFS('1_Investment_Stategy1'!$S$2:$S$2001,">38",'1_Investment_Stategy1'!$S$2:$S$2001,"<=40")/'1_Investment_Stategy1'!C8 -> 0 | H44: =COUNTIFS('1_Investment_Stategy2'!$R$2:$R$2001,">38",'1_Investment_Stategy2'!$R$2:$R$2001,"<=40")/'1_Investment_Stategy2'!C8 -> 0 | I44: =REPT("|",ROUND(G44*40,0)) | J44: =REPT("|",ROUND(H44*40,0))

Sheet 1_Investment_Stategy1
A1: INPUT | B1: B0 | C1: 500 | E1: Sample Path | F1: years | G1: Bt | H1: St | I1: SBt | J1: SSt | K1: alive | M1: STAT | N1: ST_1 | O1: =SUM(alive) -> 11 | Q1: Data Table | R1: run | S1: STS | U1: OUTPUT | V1: max | W1: =MAX(STS) -> 33 | Y1: E(ST1) | Z1: =AVERAGE(STS) -> 11.9445
B2: S0 | C2: 500 | F2: {=_xlfn.SEQUENCE(50)} -> 1 | G2: =B0 -> 500 | H2: =S0 -> 500 | I2: =(60-G2)*(G2<60) -> 0 | J2: =(60-H2)*(H2<60) -> 0 | K2: =IF(G2+H2>0,1,0) -> 1 | R2: {=_xlfn.SEQUENCE(2000)} -> 1 | S2: =ST_1 -> 11 | V2: min | W2: =MIN(STS) -> 9 | Y2: 95%CI_LB | Z2: =E_ST1-1.96*STDEV(STS)/SQRT(N) -> 11.875975
B3: mu | C3: 0.08 | F3: 2 | G3: =1*(G2>60)*(G2-60-J2)*(1+rs) -> 462 | H3: =1*(H2>60)*(H2-60-I2)*EXP((mu-sigma^2/2)*Dt+sigma*SQRT(Dt)*_xlfn.NORM.INV(RAND(),0,1)) -> 484.78285 | I3: =(60-G3)*(G3<60) -> 0 | J3: =(60-H3)*(H3<60) -> 0 | K3: =IF(G3+H3>0,1,0) -> 1 | R3: 2 | S3: 10 | Y3: 95%CI_UB | Z3: =E_ST1+1.96*STDEV(STS)/SQRT(N) -> 12.013025
B4: sigma | C4: 0.12 | F4: 3 | G4: =1*(G3>60)*(G3-60-J3)*(1+rs) -> 422.1 | H4: =1*(H3>60)*(H3-60-I3)*EXP((mu-sigma^2/2)*Dt+sigma*SQRT(Dt)*_xlfn.NORM.INV(RAND(),0,1)) -> 407.04631 | I4: =(60-G4)*(G4<60) -> 0 | J4: =(60-H4)*(H4<60) -> 0 | K4: =IF(G4+H4>0,1,0) -> 1 | R4: 3 | S4: 13 | V4: bin | W4: f_sts
B5: Dt | C5: 1 | F5: 4 | G5: =1*(G4>60)*(G4-60-J4)*(1+rs) -> 380.205 | H5: =1*(H4>60)*(H4-60-I4)*EXP((mu-sigma^2/2)*Dt+sigma*SQRT(Dt)*_xlfn.NORM.INV(RAND(),0,1)) -> 392.77298 | I5: =(60-G5)*(G5<60) -> 0 | J5: =(60-H5)*(H5<60) -> 0 | K5: =IF(G5+H5>0,1,0) -> 1 | R5: 4 | S5: 12 | V5: 8 | W5: {=FREQUENCY(STS,bin)/N} -> 0
B6: T | C6: 1 | F6: 5 | G6: =1*(G5>60)*(G5-60-J5)*(1+rs) -> 336.21525 | H6: =1*(H5>60)*(H5-60-I5)*EXP((mu-sigma^2/2)*Dt+sigma*SQRT(Dt)*_xlfn.NORM.INV(RAND(),0,1)) -> 344.14852 | I6: =(60-G6)*(G6<60) -> 0 | J6: =(60-H6)*(H6<60) -> 0 | K6: =IF(G6+H6>0,1,0) -> 1 | R6: 5 | S6: 12 | V6: 10 | W6: 0.1115
B7: rs | C7: 0.05 | F7: 6 | G7: =1*(G6>60)*(G6-60-J6)*(1+rs) -> 290.02601 | H7: =1*(H6>60)*(H6-60-I6)*EXP((mu-sigma^2/2)*Dt+sigma*SQRT(Dt)*_xlfn.NORM.INV(RAND(),0,1)) -> 296.55068 | I7: =(60-G7)*(G7<60) -> 0 | J7: =(60-H7)*(H7<60) -> 0 | K7: =IF(G7+H7>0,1,0) -> 1 | R7: 6 | S7: 13 | V7: 12 | W7: 0.6285
B8: N | C8: 2000 | F8: 7 | G8: =1*(G7>60)*(G7-60-J7)*(1+rs) -> 241.52731 | H8: =1*(H7>60)*(H7-60-I7)*EXP((mu-sigma^2/2)*Dt+sigma*SQRT(Dt)*_xlfn.NORM.INV(RAND(),0,1)) -> 311.13942 | I8: =(60-G8)*(G8<60) -> 0 | J8: =(60-H8)*(H8<60) -> 0 | K8: =IF(G8+H8>0,1,0) -> 1 | R8: 7 | S8: 12 | V8: 14 | W8: 0.208
B9: year | C9: 1 | F9: 8 | G9: =1*(G8>60)*(G8-60-J8)*(1+rs) -> 190.60368 | H9: =1*(H8>60)*(H8-60-I8)*EXP((mu-sigma^2/2)*Dt+sigma*SQRT(Dt)*_xlfn.NORM.INV(RAND(),0,1)) -> 260.03439 | I9: =(60-G9)*(G9<60) -> 0 | J9: =(60-H9)*(H9<60) -> 0 | K9: =IF(G9+H9>0,1,0) -> 1 | R9: 8 | S9: 12 | V9: 16 | W9: 0.041
F10: 9 | G10: =1*(G9>60)*(G9-60-J9)*(1+rs) -> 137.13386 | H10: =1*(H9>60)*(H9-60-I9)*EXP((mu-sigma^2/2)*Dt+sigma*SQRT(Dt)*_xlfn.NORM.INV(RAND(),0,1)) -> 205.64364 | I10: =(60-G10)*(G10<60) -> 0 | J10: =(60-H10)*(H10<60) -> 0 | K10: =IF(G10+H10>0,1,0) -> 1 | R10: 9 | S10: 14 | V10: 18 | W10: 0.007
F11: 10 | G11: =1*(G10>60)*(G10-60-J10)*(1+rs) -> 80.990556 | H11: =1*(H10>60)*(H10-60-I10)*EXP((mu-sigma^2/2)*Dt+sigma*SQRT(Dt)*_xlfn.NORM.INV(RAND(),0,1)) -> 148.45179 | I11: =(60-G11)*(G11<60) -> 0 | J11: =(60-H11)*(H11<60) -> 0 | K11: =IF(G11+H11>0,1,0) -> 1 | R11: 10 | S11: 12 | V11: 20 | W11: 0.001
F12: 11 | G12: =1*(G11>60)*(G11-60-J11)*(1+rs) -> 22.040084 | H12: =1*(H11>60)*(H11-60-I11)*EXP((mu-sigma^2/2)*Dt+sigma*SQRT(Dt)*_xlfn.NORM.INV(RAND(),0,1)) -> 82.772995 | I12: =(60-G12)*(G12<60) -> 37.959916 | J12: =(60-H12)*(H12<60) -> 0 | K12: =IF(G12+H12>0,1,0) -> 1 | R12: 11 | S12: 11 | V12: 22 | W12: 0.002
F13: 12 | G13: =1*(G12>60)*(G12-60-J12)*(1+rs) -> 0 | H13: =1*(H12>60)*(H12-60-I12)*EXP((mu-sigma^2/2)*Dt+sigma*SQRT(Dt)*_xlfn.NORM.INV(RAND(),0,1)) -> -18.514634 | I13: =(60-G13)*(G13<60) -> 60 | J13: =(60-H13)*(H13<60) -> 78.514634 | K13: =IF(G13+H13>0,1,0) -> 0 | R13: 12 | S13: 11 | V13: 24 | W13: 0
F14: 13 | G14: =1*(G13>60)*(G13-60-J13)*(1+rs) -> 0 | H14: =1*(H13>60)*(H13-60-I13)*EXP((mu-sigma^2/2)*Dt+sigma*SQRT(Dt)*_xlfn.NORM.INV(RAND(),0,1)) -> 0 | I14: =(60-G14)*(G14<60) -> 60 | J14: =(60-H14)*(H14<60) -> 60 | K14: =IF(G14+H14>0,1,0) -> 0 | R14: 13 | S14: 11 | V14: 26 | W14: 0
F15: 14 | G15: =1*(G14>60)*(G14-60-J14)*(1+rs) -> 0 | H15: =1*(H14>60)*(H14-60-I14)*EXP((mu-sigma^2/2)*Dt+sigma*SQRT(Dt)*_xlfn.NORM.INV(RAND(),0,1)) -> 0 | I15: =(60-G15)*(G15<60) -> 60 | J15: =(60-H15)*(H15<60) -> 60 | K15: =IF(G15+H15>0,1,0) -> 0 | R15: 14 | S15: 11 | V15: 28 | W15: 0
F16: 15 | G16: =1*(G15>60)*(G15-60-J15)*(1+rs) -> 0 | H16: =1*(H15>60)*(H15-60-I15)*EXP((mu-sigma^2/2)*Dt+sigma*SQRT(Dt)*_xlfn.NORM.INV(RAND(),0,1)) -> 0 | I16: =(60-G16)*(G16<60) -> 60 | J16: =(60-H16)*(H16<60) -> 60 | K16: =IF(G16+H16>0,1,0) -> 0 | R16: 15 | S16: 12 | V16: 30 | W16: 0.0005
F17: 16 | G17: =1*(G16>60)*(G16-60-J16)*(1+rs) -> 0 | H17: =1*(H16>60)*(H16-60-I16)*EXP((mu-sigma^2/2)*Dt+sigma*SQRT(Dt)*_xlfn.NORM.INV(RAND(),0,1)) -> 0 | I17: =(60-G17)*(G17<60) -> 60 | J17: =(60-H17)*(H17<60) -> 60 | K17: =IF(G17+H17>0,1,0) -> 0 | R17: 16 | S17: 10 | V17: 32 | W17: 0
F18: 17 | G18: =1*(G17>60)*(G17-60-J17)*(1+rs) -> 0 | H18: =1*(H17>60)*(H17-60-I17)*EXP((mu-sigma^2/2)*Dt+sigma*SQRT(Dt)*_xlfn.NORM.INV(RAND(),0,1)) -> 0 | I18: =(60-G18)*(G18<60) -> 60 | J18: =(60-H18)*(H18<60) -> 60 | K18: =IF(G18+H18>0,1,0) -> 0 | R18: 17 | S18: 11 | V18: 34 | W18: 0.0005
F19: 18 | G19: =1*(G18>60)*(G18-60-J18)*(1+rs) -> 0 | H19: =1*(H18>60)*(H18-60-I18)*EXP((mu-sigma^2/2)*Dt+sigma*SQRT(Dt)*_xlfn.NORM.INV(RAND(),0,1)) -> 0 | I19: =(60-G19)*(G19<60) -> 60 | J19: =(60-H19)*(H19<60) -> 60 | K19: =IF(G19+H19>0,1,0) -> 0 | R19: 18 | S19: 12 | V19: 36 | W19: 0
F20: 19 | G20: =1*(G19>60)*(G19-60-J19)*(1+rs) -> 0 | H20: =1*(H19>60)*(H19-60-I19)*EXP((mu-sigma^2/2)*Dt+sigma*SQRT(Dt)*_xlfn.NORM.INV(RAND(),0,1)) -> 0 | I20: =(60-G20)*(G20<60) -> 60 | J20: =(60-H20)*(H20<60) -> 60 | K20: =IF(G20+H20>0,1,0) -> 0 | R20: 19 | S20: 15 | V20: 38 | W20: 0
F21: 20 | G21: =1*(G20>60)*(G20-60-J20)*(1+rs) -> 0 | H21: =1*(H20>60)*(H20-60-I20)*EXP((mu-sigma^2/2)*Dt+sigma*SQRT(Dt)*_xlfn.NORM.INV(RAND(),0,1)) -> 0 | I21: =(60-G21)*(G21<60) -> 60 | J21: =(60-H21)*(H21<60) -> 60 | K21: =IF(G21+H21>0,1,0) -> 0 | R21: 20 | S21: 15 | V21: 40 | W21: 0
F22: 21 | G22: =1*(G21>60)*(G21-60-J21)*(1+rs) -> 0 | H22: =1*(H21>60)*(H21-60-I21)*EXP((mu-sigma^2/2)*Dt+sigma*SQRT(Dt)*_xlfn.NORM.INV(RAND(),0,1)) -> 0 | I22: =(60-G22)*(G22<60) -> 60 | J22: =(60-H22)*(H22<60) -> 60 | K22: =IF(G22+H22>0,1,0) -> 0 | R22: 21 | S22: 11 | W22: 0
F23: 22 | G23: =1*(G22>60)*(G22-60-J22)*(1+rs) -> 0 | H23: =1*(H22>60)*(H22-60-I22)*EXP((mu-sigma^2/2)*Dt+sigma*SQRT(Dt)*_xlfn.NORM.INV(RAND(),0,1)) -> 0 | I23: =(60-G23)*(G23<60) -> 60 | J23: =(60-H23)*(H23<60) -> 60 | K23: =IF(G23+H23>0,1,0) -> 0 | R23: 22 | S23: 11
F24: 23 | G24: =1*(G23>60)*(G23-60-J23)*(1+rs) -> 0 | H24: =1*(H23>60)*(H23-60-I23)*EXP((mu-sigma^2/2)*Dt+sigma*SQRT(Dt)*_xlfn.NORM.INV(RAND(),0,1)) -> 0 | I24: =(60-G24)*(G24<60) -> 60 | J24: =(60-H24)*(H24<60) -> 60 | K24: =IF(G24+H24>0,1,0) -> 0 | R24: 23 | S24: 12
F25: 24 | G25: =1*(G24>60)*(G24-60-J24)*(1+rs) -> 0 | H25: =1*(H24>60)*(H24-60-I24)*EXP((mu-sigma^2/2)*Dt+sigma*SQRT(Dt)*_xlfn.NORM.INV(RAND(),0,1)) -> 0 | I25: =(60-G25)*(G25<60) -> 60 | J25: =(60-H25)*(H25<60) -> 60 | K25: =IF(G25+H25>0,1,0) -> 0 | R25: 24 | S25: 11
F26: 25 | G26: =1*(G25>60)*(G25-60-J25)*(1+rs) -> 0 | H26: =1*(H25>60)*(H25-60-I25)*EXP((mu-sigma^2/2)*Dt+sigma*SQRT(Dt)*_xlfn.NORM.INV(RAND(),0,1)) -> 0 | I26: =(60-G26)*(G26<60) -> 60 | J26: =(60-H26)*(H26<60) -> 60 | K26: =IF(G26+H26>0,1,0) -> 0 | R26: 25 | S26: 10
F27: 26 | G27: =1*(G26>60)*(G26-60-J26)*(1+rs) -> 0 | H27: =1*(H26>60)*(H26-60-I26)*EXP((mu-sigma^2/2)*Dt+sigma*SQRT(Dt)*_xlfn.NORM.INV(RAND(),0,1)) -> 0 | I27: =(60-G27)*(G27<60) -> 60 | J27: =(60-H27)*(H27<60) -> 60 | K27: =IF(G27+H27>0,1,0) -> 0 | R27: 26 | S27: 11
F28: 27 | G28: =1*(G27>60)*(G27-60-J27)*(1+rs) -> 0 | H28: =1*(H27>60)*(H27-60-I27)*EXP((mu-sigma^2/2)*Dt+sigma*SQRT(Dt)*_xlfn.NORM.INV(RAND(),0,1)) -> 0 | I28: =(60-G28)*(G28<60) -> 60 | J28: =(60-H28)*(H28<60) -> 60 | K28: =IF(G28+H28>0,1,0) -> 0 | R28: 27 | S28: 13
F29: 28 | G29: =1*(G28>60)*(G28-60-J28)*(1+rs) -> 0 | H29: =1*(H28>60)*(H28-60-I28)*EXP((mu-sigma^2/2)*Dt+sigma*SQRT(Dt)*_xlfn.NORM.INV(RAND(),0,1)) -> 0 | I29: =(60-G29)*(G29<60) -> 60 | J29: =(60-H29)*(H29<60) -> 60 | K29: =IF(G29+H29>0,1,0) -> 0 | R29: 28 | S29: 10
F30: 29 | G30: =1*(G29>60)*(G29-60-J29)*(1+rs) -> 0 | H30: =1*(H29>60)*(H29-60-I29)*EXP((mu-sigma^2/2)*Dt+sigma*SQRT(Dt)*_xlfn.NORM.INV(RAND(),0,1)) -> 0 | I30: =(60-G30)*(G30<60) -> 60 | J30: =(60-H30)*(H30<60) -> 60 | K30: =IF(G30+H30>0,1,0) -> 0 | R30: 29 | S30: 11
F31: 30 | G31: =1*(G30>60)*(G30-60-J30)*(1+rs) -> 0 | H31: =1*(H30>60)*(H30-60-I30)*EXP((mu-sigma^2/2)*Dt+sigma*SQRT(Dt)*_xlfn.NORM.INV(RAND(),0,1)) -> 0 | I31: =(60-G31)*(G31<60) -> 60 | J31: =(60-H31)*(H31<60) -> 60 | K31: =IF(G31+H31>0,1,0) -> 0 | R31: 30 | S31: 10
F32: 31 | G32: =1*(G31>60)*(G31-60-J31)*(1+rs) -> 0 | H32: =1*(H31>60)*(H31-60-I31)*EXP((mu-sigma^2/2)*Dt+sigma*SQRT(Dt)*_xlfn.NORM.INV(RAND(),0,1)) -> 0 | I32: =(60-G32)*(G32<60) -> 60 | J32: =(60-H32)*(H32<60) -> 60 | K32: =IF(G32+H32>0,1,0) -> 0 | R32: 31 | S32: 17
F33: 32 | G33: =1*(G32>60)*(G32-60-J32)*(1+rs) -> 0 | H33: =1*(H32>60)*(H32-60-I32)*EXP((mu-sigma^2/2)*Dt+sigma*SQRT(Dt)*_xlfn.NORM.INV(RAND(),0,1)) -> 0 | I33: =(60-G33)*(G33<60) -> 60 | J33: =(60-H33)*(H33<60) -> 60 | K33: =IF(G33+H33>0,1,0) -> 0 | R33: 32 | S33: 11
F34: 33 | G34: =1*(G33>60)*(G33-60-J33)*(1+rs) -> 0 | H34: =1*(H33>60)*(H33-60-I33)*EXP((mu-sigma^2/2)*Dt+sigma*SQRT(Dt)*_xlfn.NORM.INV(RAND(),0,1)) -> 0 | I34: =(60-G34)*(G34<60) -> 60 | J34: =(60-H34)*(H34<60) -> 60 | K34: =IF(G34+H34>0,1,0) -> 0 | R34: 33 | S34: 11
... F51: 50 | G51: =1*(G50>60)*(G50-60-J50)*(1+rs) -> 0 | H51: =1*(H50>60)*(H50-60-I50)*EXP((mu-sigma^2/2)*Dt+sigma*SQRT(Dt)*_xlfn.NORM.INV(RAND(),0,1)) -> 0 | I51: =(60-G51)*(G51<60) -> 60 | J51: =(60-H51)*(H51<60) -> 60 | K51: =IF(G51+H51>0,1,0) -> 0 | R51: 50 | S51: 16
R52: 51 | S52: 12
R53: 52 | S53: 11
R54: 53 | S54: 11
R55: 54 | S55: 17
R56: 55 | S56: 13
...

Sheet 1_Investment_Stategy2
A1: INPUT | B1: B0_2 | C1: 500 | E1: Sample Path | F1: years | G1: Bt_2 | H1: St_2 | I1: SBt_2 | J1: alive_2 | L1: STAT | M1: ST_2 | N1: =SUM(alive_2) -> 13 | P1: Data Table | Q1: run | R1: STS2 | T1: OUTPUT | U1: max | V1: =MAX(STS2_) -> 30 | X1: E(ST2) | Y1: =AVERAGE(STS2_) -> 12.5695
B2: S0_2 | C2: 500 | F2: {=_xlfn.SEQUENCE(50)} -> 1 | G2: =B0_2 -> 500 | H2: =S0_2 -> 500 | I2: =(120-G2)*(120>G2) -> 0 | J2: =IF(G2+H2>0,1,0) -> 1 | Q2: {=_xlfn.SEQUENCE(2000)} -> 1 | R2: =ST_2 -> 13 | U2: min | V2: =MIN(STS2_) -> 8 | X2: 95%CI_LB | Y2: =E_ST2-1.96*STDEV(STS2_)/SQRT(N_2) -> 12.468681
B3: mu_2 | C3: 0.08 | F3: 2 | G3: =1*(G2>=120)*(G2-120)*(1+rs_2) -> 399 | H3: =1*(H2>=120)*(H2-I2)*EXP((mu_2-sigma_2^2/2)*Dt_2+sigma_2*SQRT(Dt_2)*_xlfn.NORM.INV(RAND(),0,1)) -> 601.04394 | I3: =(120-G3)*(120>G3) -> 0 | J3: =IF(G3+H3>0,1,0) -> 1 | Q3: 2 | R3: 10 | X3: 95%CI_UB | Y3: =E_ST2+1.96*STDEV(STS2_)/SQRT(N_2) -> 12.670319
B4: sigma_2 | C4: 0.12 | F4: 3 | G4: =1*(G3>=120)*(G3-120)*(1+rs_2) -> 292.95 | H4: =1*(H3>=120)*(H3-I3)*EXP((mu_2-sigma_2^2/2)*Dt_2+sigma_2*SQRT(Dt_2)*_xlfn.NORM.INV(RAND(),0,1)) -> 559.82864 | I4: =(120-G4)*(120>G4) -> 0 | J4: =IF(G4+H4>0,1,0) -> 1 | Q4: 3 | R4: 12 | U4: bin2 | V4: f_sts2
B5: Dt_2 | C5: 1 | F5: 4 | G5: =1*(G4>=120)*(G4-120)*(1+rs_2) -> 181.5975 | H5: =1*(H4>=120)*(H4-I4)*EXP((mu_2-sigma_2^2/2)*Dt_2+sigma_2*SQRT(Dt_2)*_xlfn.NORM.INV(RAND(),0,1)) -> 605.35882 | I5: =(120-G5)*(120>G5) -> 0 | J5: =IF(G5+H5>0,1,0) -> 1 | Q5: 4 | R5: 11 | U5: 8 | V5: {=FREQUENCY(STS2_,bin2_)/N_2} -> 0.0005
B6: T_2 | C6: 1 | F6: 5 | G6: =1*(G5>=120)*(G5-120)*(1+rs_2) -> 64.677375 | H6: =1*(H5>=120)*(H5-I5)*EXP((mu_2-sigma_2^2/2)*Dt_2+sigma_2*SQRT(Dt_2)*_xlfn.NORM.INV(RAND(),0,1)) -> 754.05558 | I6: =(120-G6)*(120>G6) -> 55.322625 | J6: =IF(G6+H6>0,1,0) -> 1 | Q6: 5 | R6: 10 | U6: 10 | V6: 0.1385
B7: rs_2 | C7: 0.05 | F7: 6 | G7: =1*(G6>=120)*(G6-120)*(1+rs_2) -> 0 | H7: =1*(H6>=120)*(H6-I6)*EXP((mu_2-sigma_2^2/2)*Dt_2+sigma_2*SQRT(Dt_2)*_xlfn.NORM.INV(RAND(),0,1)) -> 831.67659 | I7: =(120-G7)*(120>G7) -> 120 | J7: =IF(G7+H7>0,1,0) -> 1 | Q7: 6 | R7: 9 | U7: 12 | V7: 0.4425
B8: N_2 | C8: 2000 | F8: 7 | G8: =1*(G7>=120)*(G7-120)*(1+rs_2) -> 0 | H8: =1*(H7>=120)*(H7-I7)*EXP((mu_2-sigma_2^2/2)*Dt_2+sigma_2*SQRT(Dt_2)*_xlfn.NORM.INV(RAND(),0,1)) -> 719.52184 | I8: =(120-G8)*(120>G8) -> 120 | J8: =IF(G8+H8>0,1,0) -> 1 | Q8: 7 | R8: 15 | U8: 14 | V8: 0.2665
B9: year_2 | C9: 1 | F9: 8 | G9: =1*(G8>=120)*(G8-120)*(1+rs_2) -> 0 | H9: =1*(H8>=120)*(H8-I8)*EXP((mu_2-sigma_2^2/2)*Dt_2+sigma_2*SQRT(Dt_2)*_xlfn.NORM.INV(RAND(),0,1)) -> 686.45514 | I9: =(120-G9)*(120>G9) -> 120 | J9: =IF(G9+H9>0,1,0) -> 1 | Q9: 8 | R9: 12 | U9: 16 | V9: 0.094
F10: 9 | G10: =1*(G9>=120)*(G9-120)*(1+rs_2) -> 0 | H10: =1*(H9>=120)*(H9-I9)*EXP((mu_2-sigma_2^2/2)*Dt_2+sigma_2*SQRT(Dt_2)*_xlfn.NORM.INV(RAND(),0,1)) -> 542.98619 | I10: =(120-G10)*(120>G10) -> 120 | J10: =IF(G10+H10>0,1,0) -> 1 | Q10: 9 | R10: 11 | U10: 18 | V10: 0.035
F11: 10 | G11: =1*(G10>=120)*(G10-120)*(1+rs_2) -> 0 | H11: =1*(H10>=120)*(H10-I10)*EXP((mu_2-sigma_2^2/2)*Dt_2+sigma_2*SQRT(Dt_2)*_xlfn.NORM.INV(RAND(),0,1)) -> 461.41268 | I11: =(120-G11)*(120>G11) -> 120 | J11: =IF(G11+H11>0,1,0) -> 1 | Q11: 10 | R11: 10 | U11: 20 | V11: 0.015
F12: 11 | G12: =1*(G11>=120)*(G11-120)*(1+rs_2) -> 0 | H12: =1*(H11>=120)*(H11-I11)*EXP((mu_2-sigma_2^2/2)*Dt_2+sigma_2*SQRT(Dt_2)*_xlfn.NORM.INV(RAND(),0,1)) -> 350.35902 | I12: =(120-G12)*(120>G12) -> 120 | J12: =IF(G12+H12>0,1,0) -> 1 | Q12: 11 | R12: 12 | U12: 22 | V12: 0.003
F13: 12 | G13: =1*(G12>=120)*(G12-120)*(1+rs_2) -> 0 | H13: =1*(H12>=120)*(H12-I12)*EXP((mu_2-sigma_2^2/2)*Dt_2+sigma_2*SQRT(Dt_2)*_xlfn.NORM.INV(RAND(),0,1)) -> 192.29676 | I13: =(120-G13)*(120>G13) -> 120 | J13: =IF(G13+H13>0,1,0) -> 1 | Q13: 12 | R13: 10 | U13: 24 | V13: 0.0025
F14: 13 | G14: =1*(G13>=120)*(G13-120)*(1+rs_2) -> 0 | H14: =1*(H13>=120)*(H13-I13)*EXP((mu_2-sigma_2^2/2)*Dt_2+sigma_2*SQRT(Dt_2)*_xlfn.NORM.INV(RAND(),0,1)) -> 72.792003 | I14: =(120-G14)*(120>G14) -> 120 | J14: =IF(G14+H14>0,1,0) -> 1 | Q14: 13 | R14: 12 | U14: 26 | V14: 0.001
F15: 14 | G15: =1*(G14>=120)*(G14-120)*(1+rs_2) -> 0 | H15: =1*(H14>=120)*(H14-I14)*EXP((mu_2-sigma_2^2/2)*Dt_2+sigma_2*SQRT(Dt_2)*_xlfn.NORM.INV(RAND(),0,1)) -> 0 | I15: =(120-G15)*(120>G15) -> 120 | J15: =IF(G15+H15>0,1,0) -> 0 | Q15: 14 | R15: 11 | U15: 28 | V15: 0.001
F16: 15 | G16: =1*(G15>=120)*(G15-120)*(1+rs_2) -> 0 | H16: =1*(H15>=120)*(H15-I15)*EXP((mu_2-sigma_2^2/2)*Dt_2+sigma_2*SQRT(Dt_2)*_xlfn.NORM.INV(RAND(),0,1)) -> 0 | I16: =(120-G16)*(120>G16) -> 120 | J16: =IF(G16+H16>0,1,0) -> 0 | Q16: 15 | R16: 10 | U16: 30 | V16: 0.0005
F17: 16 | G17: =1*(G16>=120)*(G16-120)*(1+rs_2) -> 0 | H17: =1*(H16>=120)*(H16-I16)*EXP((mu_2-sigma_2^2/2)*Dt_2+sigma_2*SQRT(Dt_2)*_xlfn.NORM.INV(RAND(),0,1)) -> 0 | I17: =(120-G17)*(120>G17) -> 120 | J17: =IF(G17+H17>0,1,0) -> 0 | Q17: 16 | R17: 15 | U17: 32 | V17: 0
F18: 17 | G18: =1*(G17>=120)*(G17-120)*(1+rs_2) -> 0 | H18: =1*(H17>=120)*(H17-I17)*EXP((mu_2-sigma_2^2/2)*Dt_2+sigma_2*SQRT(Dt_2)*_xlfn.NORM.INV(RAND(),0,1)) -> 0 | I18: =(120-G18)*(120>G18) -> 120 | J18: =IF(G18+H18>0,1,0) -> 0 | Q18: 17 | R18: 11 | U18: 34 | V18: 0
F19: 18 | G19: =1*(G18>=120)*(G18-120)*(1+rs_2) -> 0 | H19: =1*(H18>=120)*(H18-I18)*EXP((mu_2-sigma_2^2/2)*Dt_2+sigma_2*SQRT(Dt_2)*_xlfn.NORM.INV(RAND(),0,1)) -> 0 | I19: =(120-G19)*(120>G19) -> 120 | J19: =IF(G19+H19>0,1,0) -> 0 | Q19: 18 | R19: 23 | U19: 36 | V19: 0
F20: 19 | G20: =1*(G19>=120)*(G19-120)*(1+rs_2) -> 0 | H20: =1*(H19>=120)*(H19-I19)*EXP((mu_2-sigma_2^2/2)*Dt_2+sigma_2*SQRT(Dt_2)*_xlfn.NORM.INV(RAND(),0,1)) -> 0 | I20: =(120-G20)*(120>G20) -> 120 | J20: =IF(G20+H20>0,1,0) -> 0 | Q20: 19 | R20: 10 | U20: 38 | V20: 0
F21: 20 | G21: =1*(G20>=120)*(G20-120)*(1+rs_2) -> 0 | H21: =1*(H20>=120)*(H20-I20)*EXP((mu_2-sigma_2^2/2)*Dt_2+sigma_2*SQRT(Dt_2)*_xlfn.NORM.INV(RAND(),0,1)) -> 0 | I21: =(120-G21)*(120>G21) -> 120 | J21: =IF(G21+H21>0,1,0) -> 0 | Q21: 20 | R21: 12 | U21: 40 | V21: 0
... F26: 25 | G26: =1*(G25>=120)*(G25-120)*(1+rs_2) -> 0 | H26: =1*(H25>=120)*(H25-I25)*EXP((mu_2-sigma_2^2/2)*Dt_2+sigma_2*SQRT(Dt_2)*_xlfn.NORM.INV(RAND(),0,1)) -> 0 | I26: =(120-G26)*(120>G26) -> 120 | J26: =IF(G26+H26>0,1,0) -> 0 | Q26: 25 | R26: 14 | U26: 50 | V26: 0
F27: 26 | G27: =1*(G26>=120)*(G26-120)*(1+rs_2) -> 0 | H27: =1*(H26>=120)*(H26-I26)*EXP((mu_2-sigma_2^2/2)*Dt_2+sigma_2*SQRT(Dt_2)*_xlfn.NORM.INV(RAND(),0,1)) -> 0 | I27: =(120-G27)*(120>G27) -> 120 | J27: =IF(G27+H27>0,1,0) -> 0 | Q27: 26 | R27: 11 | V27: 0
F28: 27 | G28: =1*(G27>=120)*(G27-120)*(1+rs_2) -> 0 | H28: =1*(H27>=120)*(H27-I27)*EXP((mu_2-sigma_2^2/2)*Dt_2+sigma_2*SQRT(Dt_2)*_xlfn.NORM.INV(RAND(),0,1)) -> 0 | I28: =(120-G28)*(120>G28) -> 120 | J28: =IF(G28+H28>0,1,0) -> 0 | Q28: 27 | R28: 12
F29: 28 | G29: =1*(G28>=120)*(G28-120)*(1+rs_2) -> 0 | H29: =1*(H28>=120)*(H28-I28)*EXP((mu_2-sigma_2^2/2)*Dt_2+sigma_2*SQRT(Dt_2)*_xlfn.NORM.INV(RAND(),0,1)) -> 0 | I29: =(120-G29)*(120>G29) -> 120 | J29: =IF(G29+H29>0,1,0) -> 0 | Q29: 28 | R29: 11
F30: 29 | G30: =1*(G29>=120)*(G29-120)*(1+rs_2) -> 0 | H30: =1*(H29>=120)*(H29-I29)*EXP((mu_2-sigma_2^2/2)*Dt_2+sigma_2*SQRT(Dt_2)*_xlfn.NORM.INV(RAND(),0,1)) -> 0 | I30: =(120-G30)*(120>G30) -> 120 | J30: =IF(G30+H30>0,1,0) -> 0 | Q30: 29 | R30: 11
F31: 30 | G31: =1*(G30>=120)*(G30-120)*(1+rs_2) -> 0 | H31: =1*(H30>=120)*(H30-I30)*EXP((mu_2-sigma_2^2/2)*Dt_2+sigma_2*SQRT(Dt_2)*_xlfn.NORM.INV(RAND(),0,1)) -> 0 | I31: =(120-G31)*(120>G31) -> 120 | J31: =IF(G31+H31>0,1,0) -> 0 | Q31: 30 | R31: 13
F32: 31 | G32: =1*(G31>=120)*(G31-120)*(1+rs_2) -> 0 | H32: =1*(H31>=120)*(H31-I31)*EXP((mu_2-sigma_2^2/2)*Dt_2+sigma_2*SQRT(Dt_2)*_xlfn.NORM.INV(RAND(),0,1)) -> 0 | I32: =(120-G32)*(120>G32) -> 120 | J32: =IF(G32+H32>0,1,0) -> 0 | Q32: 31 | R32: 10
F33: 32 | G33: =1*(G32>=120)*(G32-120)*(1+rs_2) -> 0 | H33: =1*(H32>=120)*(H32-I32)*EXP((mu_2-sigma_2^2/2)*Dt_2+sigma_2*SQRT(Dt_2)*_xlfn.NORM.INV(RAND(),0,1)) -> 0 | I33: =(120-G33)*(120>G33) -> 120 | J33: =IF(G33+H33>0,1,0) -> 0 | Q33: 32 | R33: 12
F34: 33 | G34: =1*(G33>=120)*(G33-120)*(1+rs_2) -> 0 | H34: =1*(H33>=120)*(H33-I33)*EXP((mu_2-sigma_2^2/2)*Dt_2+sigma_2*SQRT(Dt_2)*_xlfn.NORM.INV(RAND(),0,1)) -> 0 | I34: =(120-G34)*(120>G34) -> 120 | J34: =IF(G34+H34>0,1,0) -> 0 | Q34: 33 | R34: 15
F35: 34 | G35: =1*(G34>=120)*(G34-120)*(1+rs_2) -> 0 | H35: =1*(H34>=120)*(H34-I34)*EXP((mu_2-sigma_2^2/2)*Dt_2+sigma_2*SQRT(Dt_2)*_xlfn.NORM.INV(RAND(),0,1)) -> 0 | I35: =(120-G35)*(120>G35) -> 120 | J35: =IF(G35+H35>0,1,0) -> 0 | Q35: 34 | R35: 11
F36: 35 | G36: =1*(G35>=120)*(G35-120)*(1+rs_2) -> 0 | H36: =1*(H35>=120)*(H35-I35)*EXP((mu_2-sigma_2^2/2)*Dt_2+sigma_2*SQRT(Dt_2)*_xlfn.NORM.INV(RAND(),0,1)) -> 0 | I36: =(120-G36)*(120>G36) -> 120 | J36: =IF(G36+H36>0,1,0) -> 0 | Q36: 35 | R36: 13
F37: 36 | G37: =1*(G36>=120)*(G36-120)*(1+rs_2) -> 0 | H37: =1*(H36>=120)*(H36-I36)*EXP((mu_2-sigma_2^2/2)*Dt_2+sigma_2*SQRT(Dt_2)*_xlfn.NORM.INV(RAND(),0,1)) -> 0 | I37: =(120-G37)*(120>G37) -> 120 | J37: =IF(G37+H37>0,1,0) -> 0 | Q37: 36 | R37: 11
F38: 37 | G38: =1*(G37>=120)*(G37-120)*(1+rs_2) -> 0 | H38: =1*(H37>=120)*(H37-I37)*EXP((mu_2-sigma_2^2/2)*Dt_2+sigma_2*SQRT(Dt_2)*_xlfn.NORM.INV(RAND(),0,1)) -> 0 | I38: =(120-G38)*(120>G38) -> 120 | J38: =IF(G38+H38>0,1,0) -> 0 | Q38: 37 | R38: 13
F39: 38 | G39: =1*(G38>=120)*(G38-120)*(1+rs_2) -> 0 | H39: =1*(H38>=120)*(H38-I38)*EXP((mu_2-sigma_2^2/2)*Dt_2+sigma_2*SQRT(Dt_2)*_xlfn.NORM.INV(RAND(),0,1)) -> 0 | I39: =(120-G39)*(120>G39) -> 120 | J39: =IF(G39+H39>0,1,0) -> 0 | Q39: 38 | R39: 10
... F51: 50 | G51: =1*(G50>=120)*(G50-120)*(1+rs_2) -> 0 | H51: =1*(H50>=120)*(H50-I50)*EXP((mu_2-sigma_2^2/2)*Dt_2+sigma_2*SQRT(Dt_2)*_xlfn.NORM.INV(RAND(),0,1)) -> 0 | I51: =(120-G51)*(120>G51) -> 120 | J51: =IF(G51+H51>0,1,0) -> 0 | Q51: 50 | R51: 10
Q52: 51 | R52: 11
Q53: 52 | R53: 12
Q54: 53 | R54: 12
Q55: 54 | R55: 16
...

Sheet Insurance Analysis
A1: Insurance Loss-Ratio Risk — Monte Carlo Analysis
A4: PROBLEM
A5: An insurance sales agent's compensation depends on annual loss performance. The number of policies sold is uncertain; customers may purchase excess coverage; claims occur randomly; and claim severity is uncertain. The objective is to estimate the annual loss-ratio distribution R=TL/TP and the probability of an F-grade year, defined as R>1.
A8: MODEL
A9: Annual sales S follow N(100,10²) and are converted to an integer. Basic liability X is Uniform[50,200]. Every customer buys basic coverage and 40% buy excess coverage equal to 20% of X. Claim occurrence is Bernoulli with probability p_c. Conditional claim severity is exponential with mean r_c times premium. Because S varies by year, 200 potential policies are simulated and pick=1(ID≤S) selects actual sales.
A12: SIMULATION DESIGN
A13: ="A simulated year generates policy count, coverage choices, premiums, claim events, and claim severities, then computes R=TL/TP. The original model replicates "&TEXT('2_Insurance'!C5,"#,##0")&" years. Four frequency-severity scenarios are defined by (r_c,p_c)=(5,.16),(10,.08),(20,.04),(80,.01), with r_c×p_c held at 0.80. All result-dependent narrative below is linked dynamically to the original simulation outputs." -> A simulated year generates policy count, coverage choices, premiums, claim events, and claim severities, then computes R=TL/TP. The original model replicates 500 years. Four frequency-severity scenarios are defined by (r_c,p_c)=(5,.16),(10,.08),(20,.04),(80,.01), with r_c×p_c held at 0.80. All result-dependent narrative below is linked dynamically to the original simulation outputs.
A16: MODEL INPUTS | G16: SCENARIO DESIGN
A17: Input | B17: Meaning | C17: Value | D17: Units | E17: Role | G17: Scenario | H17: r_c | I17: p_c | J17: r_c × p_c
A18: μ | B18: Mean annual policy sales | C18: ='2_Insurance'!C1 -> 100 | D18: policies | E18: Volume uncertainty | G18: 1 | H18: 5 | I18: 0.16 | J18: =H18*I18 -> 0.8
A19: σ | B19: SD annual policy sales | C19: ='2_Insurance'!C2 -> 10 | D19: policies | E19: Volume uncertainty | G19: 2 | H19: 10 | I19: 0.08 | J19: =H19*I19 -> 0.8
A20: a | B20: Lower basic liability | C20: ='2_Insurance'!C3 -> 50 | D20: liability units | E20: Premium heterogeneity | G20: 3 | H20: 20 | I20: 0.04 | J20: =H20*I20 -> 0.8
A21: b | B21: Upper basic liability | C21: ='2_Insurance'!C4 -> 200 | D21: liability units | E21: Premium heterogeneity | G21: 4 | H21: 80 | I21: 0.01 | J21: =H21*I21 -> 0.8
A22: p_e | B22: Excess coverage probability | C22: ='2_Insurance'!C7 -> 0.4 | D22: probability | E22: Coverage choice
A23: N | B23: Simulated years | C23: ='2_Insurance'!C5 -> 500 | D23: years | E23: Monte Carlo sample size
A25: RESULTS — ORIGINAL SIMULATION | G25: LOSS-RATIO DISTRIBUTION
A26: Metric | B26: Value | C26: Interpretation | G26: Upper Bin | H26: Frequency | I26: Visual
A27: Mean loss ratio | B27: =AVERAGE('2_Insurance'!U2:U501) -> 0.83672862 | C27: Average annual loss per dollar of premium | G27: 0 | H27: =COUNTIF('2_Insurance'!$U$2:$U$501,"<=0")/'2_Insurance'!C5 -> 0 | I27: =REPT("|",ROUND(H27*40,0))
A28: Standard deviation | B28: =_xlfn.STDEV.S('2_Insurance'!U2:U501) -> 0.89049847 | C28: Year-to-year dispersion | G28: 1 | H28: =COUNTIFS('2_Insurance'!$U$2:$U$501,">0",'2_Insurance'!$U$2:$U$501,"<=1")/'2_Insurance'!C5 -> 0.706 | I28: =REPT("|",ROUND(H28*40,0)) -> ||||||||||||||||||||||||||||
A29: Maximum R | B29: =MAX('2_Insurance'!U2:U501) -> 7.3910059 | C29: Most severe observed annual ratio | G29: 2 | H29: =COUNTIFS('2_Insurance'!$U$2:$U$501,">1",'2_Insurance'!$U$2:$U$501,"<=2")/'2_Insurance'!C5 -> 0.204 | I29: =REPT("|",ROUND(H29*40,0)) -> ||||||||
A30: Minimum R | B30: =MIN('2_Insurance'!U2:U501) -> 0.00065644425 | C30: Lowest observed annual ratio | G30: 3 | H30: =COUNTIFS('2_Insurance'!$U$2:$U$501,">2",'2_Insurance'!$U$2:$U$501,"<=3")/'2_Insurance'!C5 -> 0.064 | I30: =REPT("|",ROUND(H30*40,0)) -> |||
A31: P(R>1) | B31: =AVERAGE('2_Insurance'!V2:V501) -> 0.294 | C31: Estimated probability of an F-grade loss year | G31: 4 | H31: =COUNTIFS('2_Insurance'!$U$2:$U$501,">3",'2_Insurance'!$U$2:$U$501,"<=4")/'2_Insurance'!C5 -> 0.014 | I31: =REPT("|",ROUND(H31*40,0)) -> |
A32: Standard error | B32: =_xlfn.STDEV.S('2_Insurance'!U2:U501)/SQRT('2_Insurance'!C5) -> 0.039824302 | C32: Monte Carlo precision of estimated mean | G32: 5 | H32: =COUNTIFS('2_Insurance'!$U$2:$U$501,">4",'2_Insurance'!$U$2:$U$501,"<=5")/'2_Insurance'!C5 -> 0.004 | I32: =REPT("|",ROUND(H32*40,0))
G33: 6 | H33: =COUNTIFS('2_Insurance'!$U$2:$U$501,">5",'2_Insurance'!$U$2:$U$501,"<=6")/'2_Insurance'!C5 -> 0.004 | I33: =REPT("|",ROUND(H33*40,0))
A35: INTERPRETATION
A36: ="Across the current "&TEXT(C23,"#,##0")&"-year simulation, the estimated mean loss ratio is "&TEXT(B27,"0.000")&", with a standard deviation of "&TEXT(B28,"0.000")&". The estimated probability of R>1 is "&TEXT(B31,"0.0%")&", while the observed range is "&TEXT(B30,"0.000")&" to "&TEXT(B29,"0.000")&". These values update whenever the original simulation output changes." -> Across the current 500-year simulation, the estimated mean loss ratio is 0.837, with a standard deviation of 0.890. The estimated probability of R>1 is 29.4%, while the observed range is 0.001 to 7.391. These values update whenever the original simulation output changes.
A42: MANAGERIAL / ANALYTICAL IMPLICATIONS
A43: ="The current simulation estimates P(R>1) at "&TEXT(B31,"0.0%")&" and a standard deviation of "&TEXT(B28,"0.000")&". This indicates that performance evaluation should consider dispersion and tail probability in addition to the mean loss ratio of "&TEXT(B27,"0.000")&". The scenario design separately varies claim frequency and severity while holding r_c×p_c constant." -> The current simulation estimates P(R>1) at 29.4% and a standard deviation of 0.890. This indicates that performance evaluation should consider dispersion and tail probability in addition to the mean loss ratio of 0.837. The scenario design separately varies claim frequency and severity while holding r_c×p_c constant.
A50: LIMITATIONS
A51: The model assumes independent policy outcomes, a fixed excess-coverage probability, Normal annual sales, Uniform basic liability, and exponential claim severity. It does not model claim dependence, richer policyholder heterogeneity, pricing changes, underwriting selection, inflation, deductibles, reinsurance, or multi-year learning. The 200-policy capacity is an implementation choice, and the 500-year simulation still contains Monte Carlo sampling error.

Sheet 2_Insurance
A1: INPUT | B1: mu_insur | C1: 100 | F1: Sample Path | G1: ID | H1: X | I1: Y | J1: premium | K1: loss | L1: pick | M1: real_premium | N1: real_loss | P1: TP | Q1: =SUM(real_premium) -> 11533.763 | S1: Data Table | T1: years | U1: R | V1: R>1 | X1: OUTPUT | Y1: E(R) | Z1: =AVERAGE(R_) -> 0.83672862 | AB1: Data_Table_Scenarios | AC1: rc | AD1: pc | AE1: k | AF1: E(R) | AG1: s_R | AH1: max_R | AI1: min_R | AJ1: P(R>1) | AK1: standard_error
B2: sigma_insur | C2: 10 | G2: {=_xlfn.SEQUENCE(200)} -> 1 | H2: =a+(b-a)*RAND() -> 53.606682 | I2: {=-rc_*premium*LN(RAND())} -> 47.258016 | J2: {=IF(_xlfn.BINOM.INV(1,pe,RAND()),1.2*X,X)} -> 64.328019 | K2: =IF(_xlfn.BINOM.INV(1,pc_,RAND()),Y,0) -> 0 | L2: {=IF(ID<=S,1,0)} -> 1 | M2: {=pick*premium} -> 64.328019 | N2: {=pick*loss} -> 0 | P2: TL | Q2: =SUM(real_loss) -> 7458.6372 | T2: {=_xlfn.SEQUENCE(500)} -> 1 | U2: =ratio -> 0.64667859 | V2: {=IF(R_>1,1,0)} -> 0 | Y2: s_R | Z2: =STDEV(R_) -> 0.89049847 | AF2: =E_R -> 0.83672862 | AG2: =s_R -> 0.89049847 | AH2: =max_R -> 7.3910059 | AI2: =min_R -> 0.00065644425 | AJ2: =P_R_1 -> 0.294 | AK2: =Z6 -> 0.039824302
B3: a | C3: 50 | G3: 2 | H3: =a+(b-a)*RAND() -> 145.74624 | I3: 172.1659 | J3: 145.74624 | K3: =IF(_xlfn.BINOM.INV(1,pc_,RAND()),Y,0) -> 0 | L3: 1 | M3: 145.74624 | N3: 0 | P3: ratio | Q3: =TL/TP -> 0.64667859 | T3: 2 | U3: 0.11903276 | V3: 0 | Y3: max_R | Z3: =MAX(R_) -> 7.3910059 | AC3: 5 | AD3: 0.16 | AE3: 1 | AF3: 0.81560038 | AG3: 0.78168796 | AH3: 6.336391 | AI3: 0.0070999815 | AJ3: 0.322 | AK3: 0.034958148
B4: b | C4: 200 | G4: 3 | H4: =a+(b-a)*RAND() -> 190.90796 | I4: 910.36305 | J4: 190.90796 | K4: =IF(_xlfn.BINOM.INV(1,pc_,RAND()),Y,0) -> 0 | L4: 1 | M4: 190.90796 | N4: 0 | T4: 3 | U4: 2.0540253 | V4: 1 | Y4: min_R | Z4: =MIN(R_) -> 0.00065644425 | AC4: 10 | AD4: 0.08 | AE4: 2 | AF4: 0.81508511 | AG4: 0.78208572 | AH4: 6.336391 | AI4: 0.0070999815 | AJ4: 0.322 | AK4: 0.034975937
B5: N_insur | C5: 500 | G5: 4 | H5: =a+(b-a)*RAND() -> 155.27667 | I5: 2464.394 | J5: 155.27667 | K5: =IF(_xlfn.BINOM.INV(1,pc_,RAND()),Y,0) -> 0 | L5: 1 | M5: 155.27667 | N5: 0 | T5: 4 | U5: 0.16200849 | V5: 0 | Y5: P(R>1) | Z5: =AVERAGE(R_1) -> 0.294 | AC5: 20 | AD5: 0.04 | AE5: 3 | AF5: 0.81645449 | AG5: 0.78140249 | AH5: 6.336391 | AI5: 0.0070999815 | AJ5: 0.322 | AK5: 0.034945382
B6: year_insur | C6: 1 | G6: 5 | H6: =a+(b-a)*RAND() -> 175.73102 | I6: 2462.406 | J6: 210.87722 | K6: =IF(_xlfn.BINOM.INV(1,pc_,RAND()),Y,0) -> 0 | L6: 1 | M6: 210.87722 | N6: 0 | T6: 5 | U6: 0.55221891 | V6: 0 | Y6: standard_error | Z6: =s_R/SQRT(N_insur) -> 0.039824302 | AC6: 80 | AD6: 0.01 | AE6: 4 | AF6: 0.81502471 | AG6: 0.78214345 | AH6: 6.336391 | AI6: 0.0070999815 | AJ6: 0.322 | AK6: 0.034978518
B7: pe | C7: 0.4 | G7: 6 | H7: =a+(b-a)*RAND() -> 128.71169 | I7: 264.60024 | J7: 154.45403 | K7: =IF(_xlfn.BINOM.INV(1,pc_,RAND()),Y,0) -> 0 | L7: 1 | M7: 154.45403 | N7: 0 | T7: 6 | U7: 0.7817639 | V7: 0
B8: S | C8: =INT(_xlfn.NORM.INV(RAND(),mu_insur,sigma_insur)) -> 85 | G8: 7 | H8: =a+(b-a)*RAND() -> 147.59522 | I8: 1971.3887 | J8: 147.59522 | K8: =IF(_xlfn.BINOM.INV(1,pc_,RAND()),Y,0) -> 0 | L8: 1 | M8: 147.59522 | N8: 0 | T8: 7 | U8: 0.19415811 | V8: 0 | AC8: bin_1 | AD8: f_k1
B9: k | C9: rc | D9: pc | G9: 8 | H9: =a+(b-a)*RAND() -> 175.35934 | I9: 19.807771 | J9: 175.35934 | K9: =IF(_xlfn.BINOM.INV(1,pc_,RAND()),Y,0) -> 0 | L9: 1 | M9: 175.35934 | N9: 0 | T9: 8 | U9: 1.2566714 | V9: 1 | AC9: 0 | AD9: {=FREQUENCY(R_,bin_1)/N_insur} -> 0
B10: 1 | C10: 5 | D10: 0.16 | G10: 9 | H10: =a+(b-a)*RAND() -> 81.157655 | I10: 220.8235 | J10: 81.157655 | K10: =IF(_xlfn.BINOM.INV(1,pc_,RAND()),Y,0) -> 0 | L10: 1 | M10: 81.157655 | N10: 0 | T10: 9 | U10: 0.98837618 | V10: 0 | AC10: 1 | AD10: 0.706
B11: 2 | C11: 10 | D11: 0.08 | G11: 10 | H11: =a+(b-a)*RAND() -> 199.02074 | I11: 205.84543 | J11: 238.82488 | K11: =IF(_xlfn.BINOM.INV(1,pc_,RAND()),Y,0) -> 0 | L11: 1 | M11: 238.82488 | N11: 0 | T11: 10 | U11: 0.20058014 | V11: 0 | AC11: 2 | AD11: 0.204
B12: 3 | C12: 20 | D12: 0.04 | G12: 11 | H12: =a+(b-a)*RAND() -> 192.99051 | I12: 239.30068 | J12: 192.99051 | K12: =IF(_xlfn.BINOM.INV(1,pc_,RAND()),Y,0) -> 0 | L12: 1 | M12: 192.99051 | N12: 0 | T12: 11 | U12: 2.2262845 | V12: 1 | AC12: 3 | AD12: 0.064
B13: 4 | C13: 80 | D13: 0.01 | G13: 12 | H13: =a+(b-a)*RAND() -> 169.23535 | I13: 220.79781 | J13: 169.23535 | K13: =IF(_xlfn.BINOM.INV(1,pc_,RAND()),Y,0) -> 0 | L13: 1 | M13: 169.23535 | N13: 0 | T13: 12 | U13: 4.8336074 | V13: 1 | AC13: 4 | AD13: 0.014
B14: rc | C14: {=INDEX(P,k,1)} -> 5 | G14: 13 | H14: =a+(b-a)*RAND() -> 153.33478 | I14: 13.326796 | J14: 153.33478 | K14: =IF(_xlfn.BINOM.INV(1,pc_,RAND()),Y,0) -> 0 | L14: 1 | M14: 153.33478 | N14: 0 | T14: 13 | U14: 1.7313442 | V14: 1 | AC14: 5 | AD14: 0.004
B15: pc | C15: {=INDEX(P,k,2)} -> 0.16 | G15: 14 | H15: =a+(b-a)*RAND() -> 183.12179 | I15: 1235.2507 | J15: 183.12179 | K15: =IF(_xlfn.BINOM.INV(1,pc_,RAND()),Y,0) -> 0 | L15: 1 | M15: 183.12179 | N15: 0 | T15: 14 | U15: 0.33215045 | V15: 0 | AC15: 6 | AD15: 0.004
B16: k | C16: 1 | G16: 15 | H16: =a+(b-a)*RAND() -> 166.79326 | I16: 1246.9863 | J16: 200.15191 | K16: =IF(_xlfn.BINOM.INV(1,pc_,RAND()),Y,0) -> 0 | L16: 1 | M16: 200.15191 | N16: 0 | T16: 15 | U16: 0.4550981 | V16: 0 | AD16: 0.004
G17: 16 | H17: =a+(b-a)*RAND() -> 102.03518 | I17: 1276.6464 | J17: 122.44222 | K17: =IF(_xlfn.BINOM.INV(1,pc_,RAND()),Y,0) -> 0 | L17: 1 | M17: 122.44222 | N17: 0 | T17: 16 | U17: 0.99899654 | V17: 0
G18: 17 | H18: =a+(b-a)*RAND() -> 146.13822 | I18: 1423.0313 | J18: 146.13822 | K18: =IF(_xlfn.BINOM.INV(1,pc_,RAND()),Y,0) -> 0 | L18: 1 | M18: 146.13822 | N18: 0 | T18: 17 | U18: 0.72593241 | V18: 0
G19: 18 | H19: =a+(b-a)*RAND() -> 174.78329 | I19: 29.910005 | J19: 174.78329 | K19: =IF(_xlfn.BINOM.INV(1,pc_,RAND()),Y,0) -> 0 | L19: 1 | M19: 174.78329 | N19: 0 | T19: 18 | U19: 0.64033923 | V19: 0
G20: 19 | H20: =a+(b-a)*RAND() -> 88.15012 | I20: 49.265552 | J20: 88.15012 | K20: =IF(_xlfn.BINOM.INV(1,pc_,RAND()),Y,0) -> 0 | L20: 1 | M20: 88.15012 | N20: 0 | T20: 19 | U20: 2.334868 | V20: 1
G21: 20 | H21: =a+(b-a)*RAND() -> 118.84238 | I21: 76.414991 | J21: 118.84238 | K21: =IF(_xlfn.BINOM.INV(1,pc_,RAND()),Y,0) -> 76.414991 | L21: 1 | M21: 118.84238 | N21: 76.414991 | T21: 20 | U21: 0.73434004 | V21: 0
G22: 21 | H22: =a+(b-a)*RAND() -> 76.287763 | I22: 60.899843 | J22: 91.545316 | K22: =IF(_xlfn.BINOM.INV(1,pc_,RAND()),Y,0) -> 60.899843 | L22: 1 | M22: 91.545316 | N22: 60.899843 | T22: 21 | U22: 3.3961001 | V22: 1
G23: 22 | H23: =a+(b-a)*RAND() -> 133.82626 | I23: 835.80456 | J23: 133.82626 | K23: =IF(_xlfn.BINOM.INV(1,pc_,RAND()),Y,0) -> 0 | L23: 1 | M23: 133.82626 | N23: 0 | T23: 22 | U23: 2.2570923 | V23: 1
G24: 23 | H24: =a+(b-a)*RAND() -> 76.506097 | I24: 235.57838 | J24: 76.506097 | K24: =IF(_xlfn.BINOM.INV(1,pc_,RAND()),Y,0) -> 0 | L24: 1 | M24: 76.506097 | N24: 0 | T24: 23 | U24: 0.20560323 | V24: 0
G25: 24 | H25: =a+(b-a)*RAND() -> 53.61544 | I25: 153.18418 | J25: 53.61544 | K25: =IF(_xlfn.BINOM.INV(1,pc_,RAND()),Y,0) -> 0 | L25: 1 | M25: 53.61544 | N25: 0 | T25: 24 | U25: 0.98825235 | V25: 0
G26: 25 | H26: =a+(b-a)*RAND() -> 139.5177 | I26: 2635.1491 | J26: 139.5177 | K26: =IF(_xlfn.BINOM.INV(1,pc_,RAND()),Y,0) -> 0 | L26: 1 | M26: 139.5177 | N26: 0 | T26: 25 | U26: 0.1276499 | V26: 0
G27: 26 | H27: =a+(b-a)*RAND() -> 115.1507 | I27: 5.6852372 | J27: 115.1507 | K27: =IF(_xlfn.BINOM.INV(1,pc_,RAND()),Y,0) -> 5.6852372 | L27: 1 | M27: 115.1507 | N27: 5.6852372 | T27: 26 | U27: 0.0017068359 | V27: 0
G28: 27 | H28: =a+(b-a)*RAND() -> 58.398424 | I28: 41.453368 | J28: 58.398424 | K28: =IF(_xlfn.BINOM.INV(1,pc_,RAND()),Y,0) -> 0 | L28: 1 | M28: 58.398424 | N28: 0 | T28: 27 | U28: 0.24748353 | V28: 0
... G201: 200 | H201: =a+(b-a)*RAND() -> 129.13012 | I201: 1258.5096 | J201: 129.13012 | K201: =IF(_xlfn.BINOM.INV(1,pc_,RAND()),Y,0) -> 0 | L201: 0 | M201: 0 | N201: 0 | T201: 200 | U201: 0.25372146 | V201: 0
T202: 201 | U202: 0.22794737 | V202: 0
T203: 202 | U203: 0.19121639 | V203: 0
T204: 203 | U204: 0.69798739 | V204: 0
T205: 204 | U205: 0.50554364 | V205: 0
T206: 205 | U206: 0.57465148 | V206: 0
T207: 206 | U207: 3.0853059 | V207: 1
T208: 207 | U208: 0.12957088 | V208: 0
T209: 208 | U209: 0.17940846 | V209: 0
T210: 209 | U210: 1.0928235 | V210: 1
T211: 210 | U211: 1.7173214 | V211: 1
T212: 211 | U212: 0.32365913 | V212: 0
...

Sheet Convergence
A1: Monte Carlo Convergence Diagnostics
A4: Running estimates show how Monte Carlo output changes as more replications are included. Stabilization indicates declining sampling noise for the specified model; it does not validate the structural assumptions.
A8: INVESTMENT RUNNING MEANS | F8: INTERPRETATION
A9: Replications | B9: Parallel Mean | C9: Bond-First Mean | D9: Difference | F9: ="The final investment comparison uses "&TEXT('1_Investment_Stategy1'!C8,"#,##0")&" simulated paths per strategy. The running means below show how the estimated difference evolves as the Monte Carlo sample grows." -> The final investment comparison uses 2,000 simulated paths per strategy. The running means below show how the estimated difference evolves as the Monte Carlo sample grows.
A10: 50 | B10: =AVERAGE('1_Investment_Stategy1'!$S$2:$S$51) -> 11.84 | C10: =AVERAGE('1_Investment_Stategy2'!$R$2:$R$51) -> 11.86 | D10: =C10-B10 -> 0.02
A11: 100 | B11: =AVERAGE('1_Investment_Stategy1'!$S$2:$S$101) -> 12.22 | C11: =AVERAGE('1_Investment_Stategy2'!$R$2:$R$101) -> 12.12 | D11: =C11-B11 -> -0.1
A12: 250 | B12: =AVERAGE('1_Investment_Stategy1'!$S$2:$S$251) -> 12.072 | C12: =AVERAGE('1_Investment_Stategy2'!$R$2:$R$251) -> 12.176 | D12: =C12-B12 -> 0.104
A13: 500 | B13: =AVERAGE('1_Investment_Stategy1'!$S$2:$S$501) -> 11.93 | C13: =AVERAGE('1_Investment_Stategy2'!$R$2:$R$501) -> 12.344 | D13: =C13-B13 -> 0.414
A14: 1000 | B14: =AVERAGE('1_Investment_Stategy1'!$S$2:$S$1001) -> 11.955 | C14: =AVERAGE('1_Investment_Stategy2'!$R$2:$R$1001) -> 12.5 | D14: =C14-B14 -> 0.545
A15: 1500 | B15: =AVERAGE('1_Investment_Stategy1'!$S$2:$S$1501) -> 11.95 | C15: =AVERAGE('1_Investment_Stategy2'!$R$2:$R$1501) -> 12.559333 | D15: =C15-B15 -> 0.60933333
A16: 2000 | B16: =AVERAGE('1_Investment_Stategy1'!$S$2:$S$2001) -> 11.9445 | C16: =AVERAGE('1_Investment_Stategy2'!$R$2:$R$2001) -> 12.5695 | D16: =C16-B16 -> 0.625
A20: INSURANCE RUNNING ESTIMATES | F20: INTERPRETATION
A21: Simulated Years | B21: Mean R | C21: P(R>1) | F21: ="The insurance model contains "&TEXT('2_Insurance'!C5,"#,##0")&" simulated years. The running mean and P(R>1) below show how estimates change as additional years are included." -> The insurance model contains 500 simulated years. The running mean and P(R>1) below show how estimates change as additional years are included.
A22: 25 | B22: =AVERAGE('2_Insurance'!$U$2:$U$26) -> 1.1577269 | C22: =AVERAGE('2_Insurance'!$V$2:$V$26) -> 0.32
A23: 50 | B23: =AVERAGE('2_Insurance'!$U$2:$U$51) -> 0.9818801 | C23: =AVERAGE('2_Insurance'!$V$2:$V$51) -> 0.3
A24: 100 | B24: =AVERAGE('2_Insurance'!$U$2:$U$101) -> 0.97709271 | C24: =AVERAGE('2_Insurance'!$V$2:$V$101) -> 0.35
A25: 200 | B25: =AVERAGE('2_Insurance'!$U$2:$U$201) -> 0.863574 | C25: =AVERAGE('2_Insurance'!$V$2:$V$201) -> 0.305
A26: 300 | B26: =AVERAGE('2_Insurance'!$U$2:$U$301) -> 0.90629617 | C26: =AVERAGE('2_Insurance'!$V$2:$V$301) -> 0.32333333
A27: 400 | B27: =AVERAGE('2_Insurance'!$U$2:$U$401) -> 0.84455375 | C27: =AVERAGE('2_Insurance'!$V$2:$V$401) -> 0.3025
A28: 500 | B28: =AVERAGE('2_Insurance'!$U$2:$U$501) -> 0.83672862 | C28: =AVERAGE('2_Insurance'!$V$2:$V$501) -> 0.294
A32: HOW TO READ CONVERGENCE
A33: Convergence addresses numerical precision, not structural validity. A stable estimate can still come from unrealistic assumptions. Final results should therefore be interpreted together with simulation size, standard error/confidence intervals, and model limitations.
